11/20/2012 00:01:37;0002;PBS_Server.1833;Svr;Log;Log opened
11/20/2012 00:01:37;0002;PBS_Server.1833;Svr;PBS_Server;Torque Server Version = 4.1.2, loglevel = 0
11/20/2012 00:03:30;0040;PBS_Server.10590;Svr;csg.bcmd.bcm.edu;Scheduler was sent the command time
11/20/2012 00:06:42;0002;PBS_Server.1833;Svr;PBS_Server;Torque Server Version = 4.1.2, loglevel = 0
11/20/2012 00:11:47;0002;PBS_Server.1827;Svr;PBS_Server;Torque Server Version = 4.1.2, loglevel = 0
11/20/2012 00:13:40;0040;PBS_Server.10685;Svr;csg.bcmd.bcm.edu;Scheduler was sent the command time
11/20/2012 00:16:52;0002;PBS_Server.1833;Svr;PBS_Server;Torque Server Version = 4.1.2, loglevel = 0
11/20/2012 00:21:57;0002;PBS_Server.1835;Svr;PBS_Server;Torque Server Version = 4.1.2, loglevel = 0
11/20/2012 00:23:50;0040;PBS_Server.10780;Svr;csg.bcmd.bcm.edu;Scheduler was sent the command time
11/20/2012 00:27:02;0002;PBS_Server.1825;Svr;PBS_Server;Torque Server Version = 4.1.2, loglevel = 0
11/20/2012 00:32:07;0002;PBS_Server.1830;Svr;PBS_Server;Torque Server Version = 4.1.2, loglevel = 0
11/20/2012 00:34:00;0040;PBS_Server.10874;Svr;csg.bcmd.bcm.edu;Scheduler was sent the command time
11/20/2012 00:37:12;0002;PBS_Server.1835;Svr;PBS_Server;Torque Server Version = 4.1.2, loglevel = 0
11/20/2012 00:42:17;0002;PBS_Server.1836;Svr;PBS_Server;Torque Server Version = 4.1.2, loglevel = 0
11/20/2012 00:44:10;0040;PBS_Server.10976;Svr;csg.bcmd.bcm.edu;Scheduler was sent the command time
11/20/2012 00:47:22;0002;PBS_Server.1830;Svr;PBS_Server;Torque Server Version = 4.1.2, loglevel = 0
11/20/2012 00:52:27;0002;PBS_Server.1826;Svr;PBS_Server;Torque Server Version = 4.1.2, loglevel = 0
11/20/2012 00:54:20;0040;PBS_Server.11071;Svr;csg.bcmd.bcm.edu;Scheduler was sent the command time
11/20/2012 00:57:32;0002;PBS_Server.1833;Svr;PBS_Server;Torque Server Version = 4.1.2, loglevel = 0
11/20/2012 01:02:37;0002;PBS_Server.1830;Svr;PBS_Server;Torque Server Version = 4.1.2, loglevel = 0
11/20/2012 01:04:30;0040;PBS_Server.11135;Svr;csg.bcmd.bcm.edu;Scheduler was sent the command time
11/20/2012 01:07:42;0002;PBS_Server.1830;Svr;PBS_Server;Torque Server Version = 4.1.2, loglevel = 0
11/20/2012 01:12:47;0002;PBS_Server.1831;Svr;PBS_Server;Torque Server Version = 4.1.2, loglevel = 0
11/20/2012 01:14:40;0040;PBS_Server.11148;Svr;csg.bcmd.bcm.edu;Scheduler was sent the command time
11/20/2012 01:17:52;0002;PBS_Server.1835;Svr;PBS_Server;Torque Server Version = 4.1.2, loglevel = 0
11/20/2012 01:22:57;0002;PBS_Server.1837;Svr;PBS_Server;Torque Server Version = 4.1.2, loglevel = 0
11/20/2012 01:24:50;0040;PBS_Server.11163;Svr;csg.bcmd.bcm.edu;Scheduler was sent the command time
11/20/2012 01:28:02;0002;PBS_Server.1829;Svr;PBS_Server;Torque Server Version = 4.1.2, loglevel = 0
11/20/2012 01:33:07;0002;PBS_Server.1833;Svr;PBS_Server;Torque Server Version = 4.1.2, loglevel = 0
11/20/2012 01:35:00;0040;PBS_Server.11177;Svr;csg.bcmd.bcm.edu;Scheduler was sent the command time
11/20/2012 01:38:12;0002;PBS_Server.1833;Svr;PBS_Server;Torque Server Version = 4.1.2, loglevel = 0
11/20/2012 01:43:17;0002;PBS_Server.1829;Svr;PBS_Server;Torque Server Version = 4.1.2, loglevel = 0
11/20/2012 01:45:10;0040;PBS_Server.11197;Svr;csg.bcmd.bcm.edu;Scheduler was sent the command time
11/20/2012 01:48:22;0002;PBS_Server.1830;Svr;PBS_Server;Torque Server Version = 4.1.2, loglevel = 0
11/20/2012 01:53:27;0002;PBS_Server.1829;Svr;PBS_Server;Torque Server Version = 4.1.2, loglevel = 0
11/20/2012 01:55:20;0040;PBS_Server.11212;Svr;csg.bcmd.bcm.edu;Scheduler was sent the command time
11/20/2012 01:58:32;0002;PBS_Server.1829;Svr;PBS_Server;Torque Server Version = 4.1.2, loglevel = 0
11/20/2012 02:03:37;0002;PBS_Server.1828;Svr;PBS_Server;Torque Server Version = 4.1.2, loglevel = 0
11/20/2012 02:05:30;0040;PBS_Server.11342;Svr;csg.bcmd.bcm.edu;Scheduler was sent the command time
11/20/2012 02:08:42;0002;PBS_Server.1825;Svr;PBS_Server;Torque Server Version = 4.1.2, loglevel = 0
11/20/2012 02:13:47;0002;PBS_Server.1828;Svr;PBS_Server;Torque Server Version = 4.1.2, loglevel = 0
11/20/2012 02:15:40;0040;PBS_Server.11436;Svr;csg.bcmd.bcm.edu;Scheduler was sent the command time
11/20/2012 02:18:52;0002;PBS_Server.1827;Svr;PBS_Server;Torque Server Version = 4.1.2, loglevel = 0
11/20/2012 02:23:57;0002;PBS_Server.1826;Svr;PBS_Server;Torque Server Version = 4.1.2, loglevel = 0
11/20/2012 02:25:50;0040;PBS_Server.11531;Svr;csg.bcmd.bcm.edu;Scheduler was sent the command time
11/20/2012 02:29:02;0002;PBS_Server.1829;Svr;PBS_Server;Torque Server Version = 4.1.2, loglevel = 0
11/20/2012 02:34:07;0002;PBS_Server.1828;Svr;PBS_Server;Torque Server Version = 4.1.2, loglevel = 0
11/20/2012 02:36:00;0040;PBS_Server.11624;Svr;csg.bcmd.bcm.edu;Scheduler was sent the command time
11/20/2012 02:39:12;0002;PBS_Server.1833;Svr;PBS_Server;Torque Server Version = 4.1.2, loglevel = 0
11/20/2012 02:44:17;0002;PBS_Server.1836;Svr;PBS_Server;Torque Server Version = 4.1.2, loglevel = 0
11/20/2012 02:46:10;0040;PBS_Server.11727;Svr;csg.bcmd.bcm.edu;Scheduler was sent the command time
11/20/2012 02:49:22;0002;PBS_Server.1828;Svr;PBS_Server;Torque Server Version = 4.1.2, loglevel = 0
11/20/2012 02:54:27;0002;PBS_Server.1836;Svr;PBS_Server;Torque Server Version = 4.1.2, loglevel = 0
11/20/2012 02:56:20;0040;PBS_Server.11822;Svr;csg.bcmd.bcm.edu;Scheduler was sent the command time
11/20/2012 02:59:32;0002;PBS_Server.1828;Svr;PBS_Server;Torque Server Version = 4.1.2, loglevel = 0
11/20/2012 03:04:37;0002;PBS_Server.1837;Svr;PBS_Server;Torque Server Version = 4.1.2, loglevel = 0
11/20/2012 03:06:30;0040;PBS_Server.11869;Svr;csg.bcmd.bcm.edu;Scheduler was sent the command time
11/20/2012 03:09:42;0002;PBS_Server.1835;Svr;PBS_Server;Torque Server Version = 4.1.2, loglevel = 0
11/20/2012 03:14:47;0002;PBS_Server.1831;Svr;PBS_Server;Torque Server Version = 4.1.2, loglevel = 0
11/20/2012 03:16:40;0040;PBS_Server.11886;Svr;csg.bcmd.bcm.edu;Scheduler was sent the command time
11/20/2012 03:19:52;0002;PBS_Server.1829;Svr;PBS_Server;Torque Server Version = 4.1.2, loglevel = 0
11/20/2012 03:24:57;0002;PBS_Server.1827;Svr;PBS_Server;Torque Server Version = 4.1.2, loglevel = 0
11/20/2012 03:26:50;0040;PBS_Server.11902;Svr;csg.bcmd.bcm.edu;Scheduler was sent the command time
11/20/2012 03:30:02;0002;PBS_Server.1831;Svr;PBS_Server;Torque Server Version = 4.1.2, loglevel = 0
11/20/2012 03:35:07;0002;PBS_Server.1834;Svr;PBS_Server;Torque Server Version = 4.1.2, loglevel = 0
11/20/2012 03:37:00;0040;PBS_Server.11918;Svr;csg.bcmd.bcm.edu;Scheduler was sent the command time
11/20/2012 03:40:12;0002;PBS_Server.1833;Svr;PBS_Server;Torque Server Version = 4.1.2, loglevel = 0
11/20/2012 03:45:17;0002;PBS_Server.1827;Svr;PBS_Server;Torque Server Version = 4.1.2, loglevel = 0
11/20/2012 03:47:10;0040;PBS_Server.11933;Svr;csg.bcmd.bcm.edu;Scheduler was sent the command time
11/20/2012 03:50:22;0002;PBS_Server.1835;Svr;PBS_Server;Torque Server Version = 4.1.2, loglevel = 0
11/20/2012 03:55:27;0002;PBS_Server.1827;Svr;PBS_Server;Torque Server Version = 4.1.2, loglevel = 0
11/20/2012 03:57:20;0040;PBS_Server.11959;Svr;csg.bcmd.bcm.edu;Scheduler was sent the command time
11/20/2012 04:00:32;0002;PBS_Server.1833;Svr;PBS_Server;Torque Server Version = 4.1.2, loglevel = 0
11/20/2012 04:05:37;0002;PBS_Server.1831;Svr;PBS_Server;Torque Server Version = 4.1.2, loglevel = 0
11/20/2012 04:07:30;0040;PBS_Server.12104;Svr;csg.bcmd.bcm.edu;Scheduler was sent the command time
11/20/2012 04:10:42;0002;PBS_Server.1836;Svr;PBS_Server;Torque Server Version = 4.1.2, loglevel = 0
11/20/2012 04:15:47;0002;PBS_Server.1826;Svr;PBS_Server;Torque Server Version = 4.1.2, loglevel = 0
11/20/2012 04:17:40;0040;PBS_Server.12198;Svr;csg.bcmd.bcm.edu;Scheduler was sent the command time
11/20/2012 04:20:52;0002;PBS_Server.1829;Svr;PBS_Server;Torque Server Version = 4.1.2, loglevel = 0
11/20/2012 04:25:57;0002;PBS_Server.1830;Svr;PBS_Server;Torque Server Version = 4.1.2, loglevel = 0
11/20/2012 04:27:50;0040;PBS_Server.12294;Svr;csg.bcmd.bcm.edu;Scheduler was sent the command time
11/20/2012 04:31:02;0002;PBS_Server.1832;Svr;PBS_Server;Torque Server Version = 4.1.2, loglevel = 0
11/20/2012 04:36:07;0002;PBS_Server.1836;Svr;PBS_Server;Torque Server Version = 4.1.2, loglevel = 0
11/20/2012 04:38:00;0040;PBS_Server.12388;Svr;csg.bcmd.bcm.edu;Scheduler was sent the command time
11/20/2012 04:41:12;0002;PBS_Server.1830;Svr;PBS_Server;Torque Server Version = 4.1.2, loglevel = 0
11/20/2012 04:46:17;0002;PBS_Server.1834;Svr;PBS_Server;Torque Server Version = 4.1.2, loglevel = 0
11/20/2012 04:48:10;0040;PBS_Server.12490;Svr;csg.bcmd.bcm.edu;Scheduler was sent the command time
11/20/2012 04:51:22;0002;PBS_Server.1835;Svr;PBS_Server;Torque Server Version = 4.1.2, loglevel = 0
11/20/2012 04:56:27;0002;PBS_Server.1828;Svr;PBS_Server;Torque Server Version = 4.1.2, loglevel = 0
11/20/2012 04:58:20;0040;PBS_Server.12584;Svr;csg.bcmd.bcm.edu;Scheduler was sent the command time
11/20/2012 05:01:32;0002;PBS_Server.1831;Svr;PBS_Server;Torque Server Version = 4.1.2, loglevel = 0
11/20/2012 05:06:37;0002;PBS_Server.1826;Svr;PBS_Server;Torque Server Version = 4.1.2, loglevel = 0
11/20/2012 05:08:30;0040;PBS_Server.12613;Svr;csg.bcmd.bcm.edu;Scheduler was sent the command time
11/20/2012 05:11:42;0002;PBS_Server.1827;Svr;PBS_Server;Torque Server Version = 4.1.2, loglevel = 0
11/20/2012 05:16:47;0002;PBS_Server.1835;Svr;PBS_Server;Torque Server Version = 4.1.2, loglevel = 0
11/20/2012 05:18:40;0040;PBS_Server.12627;Svr;csg.bcmd.bcm.edu;Scheduler was sent the command time
11/20/2012 05:21:52;0002;PBS_Server.1833;Svr;PBS_Server;Torque Server Version = 4.1.2, loglevel = 0
11/20/2012 05:26:57;0002;PBS_Server.1830;Svr;PBS_Server;Torque Server Version = 4.1.2, loglevel = 0
11/20/2012 05:28:50;0040;PBS_Server.12642;Svr;csg.bcmd.bcm.edu;Scheduler was sent the command time
11/20/2012 05:32:02;0002;PBS_Server.1826;Svr;PBS_Server;Torque Server Version = 4.1.2, loglevel = 0
11/20/2012 05:37:07;0002;PBS_Server.1829;Svr;PBS_Server;Torque Server Version = 4.1.2, loglevel = 0
11/20/2012 05:39:00;0040;PBS_Server.12656;Svr;csg.bcmd.bcm.edu;Scheduler was sent the command time
11/20/2012 05:42:12;0002;PBS_Server.1834;Svr;PBS_Server;Torque Server Version = 4.1.2, loglevel = 0
11/20/2012 05:47:17;0002;PBS_Server.1828;Svr;PBS_Server;Torque Server Version = 4.1.2, loglevel = 0
11/20/2012 05:49:10;0040;PBS_Server.12671;Svr;csg.bcmd.bcm.edu;Scheduler was sent the command time
11/20/2012 05:52:22;0002;PBS_Server.1831;Svr;PBS_Server;Torque Server Version = 4.1.2, loglevel = 0
11/20/2012 05:57:27;0002;PBS_Server.1830;Svr;PBS_Server;Torque Server Version = 4.1.2, loglevel = 0
11/20/2012 05:59:20;0040;PBS_Server.12684;Svr;csg.bcmd.bcm.edu;Scheduler was sent the command time
11/20/2012 06:02:32;0002;PBS_Server.1827;Svr;PBS_Server;Torque Server Version = 4.1.2, loglevel = 0
11/20/2012 06:07:37;0002;PBS_Server.1832;Svr;PBS_Server;Torque Server Version = 4.1.2, loglevel = 0
11/20/2012 06:09:30;0040;PBS_Server.12845;Svr;csg.bcmd.bcm.edu;Scheduler was sent the command time
11/20/2012 06:12:42;0002;PBS_Server.1825;Svr;PBS_Server;Torque Server Version = 4.1.2, loglevel = 0
11/20/2012 06:17:47;0002;PBS_Server.1835;Svr;PBS_Server;Torque Server Version = 4.1.2, loglevel = 0
11/20/2012 06:19:40;0040;PBS_Server.12939;Svr;csg.bcmd.bcm.edu;Scheduler was sent the command time
11/20/2012 06:22:52;0002;PBS_Server.1829;Svr;PBS_Server;Torque Server Version = 4.1.2, loglevel = 0
11/20/2012 06:27:57;0002;PBS_Server.1829;Svr;PBS_Server;Torque Server Version = 4.1.2, loglevel = 0
11/20/2012 06:29:50;0040;PBS_Server.13034;Svr;csg.bcmd.bcm.edu;Scheduler was sent the command time
11/20/2012 06:33:02;0002;PBS_Server.1835;Svr;PBS_Server;Torque Server Version = 4.1.2, loglevel = 0
11/20/2012 06:38:07;0002;PBS_Server.1831;Svr;PBS_Server;Torque Server Version = 4.1.2, loglevel = 0
11/20/2012 06:40:00;0040;PBS_Server.13127;Svr;csg.bcmd.bcm.edu;Scheduler was sent the command time
11/20/2012 06:43:12;0002;PBS_Server.1829;Svr;PBS_Server;Torque Server Version = 4.1.2, loglevel = 0
11/20/2012 06:48:17;0002;PBS_Server.1826;Svr;PBS_Server;Torque Server Version = 4.1.2, loglevel = 0
11/20/2012 06:50:10;0040;PBS_Server.13234;Svr;csg.bcmd.bcm.edu;Scheduler was sent the command time
11/20/2012 06:53:22;0002;PBS_Server.1828;Svr;PBS_Server;Torque Server Version = 4.1.2, loglevel = 0
11/20/2012 06:58:27;0002;PBS_Server.1834;Svr;PBS_Server;Torque Server Version = 4.1.2, loglevel = 0
11/20/2012 07:00:20;0040;PBS_Server.13321;Svr;csg.bcmd.bcm.edu;Scheduler was sent the command time
11/20/2012 07:03:32;0002;PBS_Server.1825;Svr;PBS_Server;Torque Server Version = 4.1.2, loglevel = 0
11/20/2012 07:08:37;0002;PBS_Server.1834;Svr;PBS_Server;Torque Server Version = 4.1.2, loglevel = 0
11/20/2012 07:10:30;0040;PBS_Server.13342;Svr;csg.bcmd.bcm.edu;Scheduler was sent the command time
11/20/2012 07:13:42;0002;PBS_Server.1826;Svr;PBS_Server;Torque Server Version = 4.1.2, loglevel = 0
11/20/2012 07:18:47;0002;PBS_Server.1825;Svr;PBS_Server;Torque Server Version = 4.1.2, loglevel = 0
11/20/2012 07:20:40;0040;PBS_Server.13356;Svr;csg.bcmd.bcm.edu;Scheduler was sent the command time
11/20/2012 07:23:52;0002;PBS_Server.1834;Svr;PBS_Server;Torque Server Version = 4.1.2, loglevel = 0
11/20/2012 07:28:57;0002;PBS_Server.1831;Svr;PBS_Server;Torque Server Version = 4.1.2, loglevel = 0
11/20/2012 07:30:50;0040;PBS_Server.13371;Svr;csg.bcmd.bcm.edu;Scheduler was sent the command time
11/20/2012 07:34:02;0002;PBS_Server.1830;Svr;PBS_Server;Torque Server Version = 4.1.2, loglevel = 0
11/20/2012 07:39:07;0002;PBS_Server.1833;Svr;PBS_Server;Torque Server Version = 4.1.2, loglevel = 0
11/20/2012 07:41:00;0040;PBS_Server.13384;Svr;csg.bcmd.bcm.edu;Scheduler was sent the command time
11/20/2012 07:44:12;0002;PBS_Server.1836;Svr;PBS_Server;Torque Server Version = 4.1.2, loglevel = 0
11/20/2012 07:49:17;0002;PBS_Server.1835;Svr;PBS_Server;Torque Server Version = 4.1.2, loglevel = 0
11/20/2012 07:51:10;0040;PBS_Server.13400;Svr;csg.bcmd.bcm.edu;Scheduler was sent the command time
11/20/2012 07:54:22;0002;PBS_Server.1829;Svr;PBS_Server;Torque Server Version = 4.1.2, loglevel = 0
11/20/2012 07:59:27;0002;PBS_Server.1829;Svr;PBS_Server;Torque Server Version = 4.1.2, loglevel = 0
11/20/2012 08:01:20;0040;PBS_Server.13495;Svr;csg.bcmd.bcm.edu;Scheduler was sent the command time
11/20/2012 08:04:32;0002;PBS_Server.1835;Svr;PBS_Server;Torque Server Version = 4.1.2, loglevel = 0
11/20/2012 08:09:37;0002;PBS_Server.1831;Svr;PBS_Server;Torque Server Version = 4.1.2, loglevel = 0
11/20/2012 08:11:30;0040;PBS_Server.13590;Svr;csg.bcmd.bcm.edu;Scheduler was sent the command time
11/20/2012 08:14:42;0002;PBS_Server.1833;Svr;PBS_Server;Torque Server Version = 4.1.2, loglevel = 0
11/20/2012 08:19:47;0002;PBS_Server.1828;Svr;PBS_Server;Torque Server Version = 4.1.2, loglevel = 0
11/20/2012 08:21:40;0040;PBS_Server.13693;Svr;csg.bcmd.bcm.edu;Scheduler was sent the command time
11/20/2012 08:24:52;0002;PBS_Server.1831;Svr;PBS_Server;Torque Server Version = 4.1.2, loglevel = 0
11/20/2012 08:29:57;0002;PBS_Server.1829;Svr;PBS_Server;Torque Server Version = 4.1.2, loglevel = 0
11/20/2012 08:31:50;0040;PBS_Server.13855;Svr;csg.bcmd.bcm.edu;Scheduler was sent the command time
11/20/2012 08:35:02;0002;PBS_Server.1827;Svr;PBS_Server;Torque Server Version = 4.1.2, loglevel = 0
11/20/2012 08:40:07;0002;PBS_Server.1827;Svr;PBS_Server;Torque Server Version = 4.1.2, loglevel = 0
11/20/2012 08:42:00;0040;PBS_Server.13959;Svr;csg.bcmd.bcm.edu;Scheduler was sent the command time
11/20/2012 08:45:12;0002;PBS_Server.1832;Svr;PBS_Server;Torque Server Version = 4.1.2, loglevel = 0
11/20/2012 08:50:17;0002;PBS_Server.1826;Svr;PBS_Server;Torque Server Version = 4.1.2, loglevel = 0
11/20/2012 08:52:10;0040;PBS_Server.14164;Svr;csg.bcmd.bcm.edu;Scheduler was sent the command time
11/20/2012 08:55:22;0002;PBS_Server.1828;Svr;PBS_Server;Torque Server Version = 4.1.2, loglevel = 0
11/20/2012 09:00:27;0002;PBS_Server.1832;Svr;PBS_Server;Torque Server Version = 4.1.2, loglevel = 0
11/20/2012 09:02:20;0040;PBS_Server.14251;Svr;csg.bcmd.bcm.edu;Scheduler was sent the command time
11/20/2012 09:05:32;0002;PBS_Server.1827;Svr;PBS_Server;Torque Server Version = 4.1.2, loglevel = 0
11/20/2012 09:10:37;0002;PBS_Server.1833;Svr;PBS_Server;Torque Server Version = 4.1.2, loglevel = 0
11/20/2012 09:12:30;0040;PBS_Server.14271;Svr;csg.bcmd.bcm.edu;Scheduler was sent the command time
11/20/2012 09:15:42;0002;PBS_Server.1837;Svr;PBS_Server;Torque Server Version = 4.1.2, loglevel = 0
11/20/2012 09:20:47;0002;PBS_Server.1826;Svr;PBS_Server;Torque Server Version = 4.1.2, loglevel = 0
11/20/2012 09:22:40;0040;PBS_Server.14294;Svr;csg.bcmd.bcm.edu;Scheduler was sent the command time
11/20/2012 09:25:52;0002;PBS_Server.1832;Svr;PBS_Server;Torque Server Version = 4.1.2, loglevel = 0
11/20/2012 09:30:57;0002;PBS_Server.1830;Svr;PBS_Server;Torque Server Version = 4.1.2, loglevel = 0
11/20/2012 09:32:50;0040;PBS_Server.14312;Svr;csg.bcmd.bcm.edu;Scheduler was sent the command time
11/20/2012 09:36:02;0002;PBS_Server.1832;Svr;PBS_Server;Torque Server Version = 4.1.2, loglevel = 0
11/20/2012 09:41:07;0002;PBS_Server.1828;Svr;PBS_Server;Torque Server Version = 4.1.2, loglevel = 0
11/20/2012 09:43:00;0040;PBS_Server.14328;Svr;csg.bcmd.bcm.edu;Scheduler was sent the command time
11/20/2012 09:46:12;0002;PBS_Server.1836;Svr;PBS_Server;Torque Server Version = 4.1.2, loglevel = 0
11/20/2012 09:51:17;0002;PBS_Server.1834;Svr;PBS_Server;Torque Server Version = 4.1.2, loglevel = 0
11/20/2012 09:53:10;0040;PBS_Server.14342;Svr;csg.bcmd.bcm.edu;Scheduler was sent the command time
11/20/2012 09:56:22;0002;PBS_Server.1829;Svr;PBS_Server;Torque Server Version = 4.1.2, loglevel = 0
11/20/2012 10:01:27;0002;PBS_Server.1836;Svr;PBS_Server;Torque Server Version = 4.1.2, loglevel = 0
11/20/2012 10:03:20;0040;PBS_Server.14516;Svr;csg.bcmd.bcm.edu;Scheduler was sent the command time
11/20/2012 10:06:32;0002;PBS_Server.1835;Svr;PBS_Server;Torque Server Version = 4.1.2, loglevel = 0
11/20/2012 10:11:37;0002;PBS_Server.1837;Svr;PBS_Server;Torque Server Version = 4.1.2, loglevel = 0
11/20/2012 10:13:30;0040;PBS_Server.14731;Svr;csg.bcmd.bcm.edu;Scheduler was sent the command time
11/20/2012 10:16:42;0002;PBS_Server.1833;Svr;PBS_Server;Torque Server Version = 4.1.2, loglevel = 0
11/20/2012 10:17:19;0100;PBS_Server.1836;Job;524.csg.bcmd.bcm.edu;enqueuing into high, state 1 hop 1
11/20/2012 10:17:19;0002;PBS_Server.1836;Svr;Act;Account file /var/spool/torque/server_priv/accounting/20121120 opened
11/20/2012 10:17:19;0008;PBS_Server.1836;Job;524.csg.bcmd.bcm.edu;Job Queued at request of lacuesta@csg.bcmd.bcm.edu, owner = lacuesta@csg.bcmd.bcm.edu, job name = kbjob_AA_HDL_SNV_PCSK7, queue = high
11/20/2012 10:17:23;0040;PBS_Server.14805;Svr;csg.bcmd.bcm.edu;Scheduler was sent the command new
11/20/2012 10:17:24;0008;PBS_Server.1829;Job;524.csg.bcmd.bcm.edu;Job Run at request of root@csg.bcmd.bcm.edu
11/20/2012 10:17:24;000d;PBS_Server.1829;Job;524.csg.bcmd.bcm.edu;Not sending email: User does not want mail of this type.
11/20/2012 10:21:49;0002;PBS_Server.1827;Svr;PBS_Server;Torque Server Version = 4.1.2, loglevel = 0
11/20/2012 10:26:49;0002;PBS_Server.1835;Svr;PBS_Server;Torque Server Version = 4.1.2, loglevel = 0
11/20/2012 10:27:35;0040;PBS_Server.17071;Svr;csg.bcmd.bcm.edu;Scheduler was sent the command time
11/20/2012 10:32:00;0002;PBS_Server.1835;Svr;PBS_Server;Torque Server Version = 4.1.2, loglevel = 0
11/20/2012 10:37:01;0002;PBS_Server.1833;Svr;PBS_Server;Torque Server Version = 4.1.2, loglevel = 0
11/20/2012 10:37:51;0040;PBS_Server.17962;Svr;csg.bcmd.bcm.edu;Scheduler was sent the command time
11/20/2012 10:42:01;0002;PBS_Server.1831;Svr;PBS_Server;Torque Server Version = 4.1.2, loglevel = 0
11/20/2012 10:47:12;0002;PBS_Server.1830;Svr;PBS_Server;Torque Server Version = 4.1.2, loglevel = 0
11/20/2012 10:48:02;0040;PBS_Server.18099;Svr;csg.bcmd.bcm.edu;Scheduler was sent the command time
11/20/2012 10:49:14;0008;PBS_Server.1834;Job;524.csg.bcmd.bcm.edu;Job deleted at request of lacuesta@csg.bcmd.bcm.edu
11/20/2012 10:49:14;0008;PBS_Server.1834;Job;524.csg.bcmd.bcm.edu;Job sent signal SIGTERM on delete
11/20/2012 10:49:20;000d;PBS_Server.1832;Job;524.csg.bcmd.bcm.edu;Not sending email: User does not want mail of this type.
11/20/2012 10:49:20;0010;PBS_Server.1832;Job;524.csg.bcmd.bcm.edu;Exit_status=271 resources_used.cput=00:13:47 resources_used.mem=5956kb resources_used.vmem=74860kb resources_used.walltime=00:31:56
11/20/2012 10:49:20;0008;PBS_Server.1835;Job;524.csg.bcmd.bcm.edu;on_job_exit valid pjob: 524.csg.bcmd.bcm.edu (substate=50)
11/20/2012 10:49:22;0040;PBS_Server.18130;Svr;csg.bcmd.bcm.edu;Scheduler was sent the command term
11/20/2012 10:49:30;0080;PBS_Server.1832;Job;524.csg.bcmd.bcm.edu;Request invalid for state of job COMPLETE
11/20/2012 10:49:30;0080;PBS_Server.1832;Req;req_reject;Reject reply code=15018(Request invalid for state of job MSG=invalid state for job - COMPLETE), aux=0, type=DeleteJob, from lacuesta@csg.bcmd.bcm.edu
11/20/2012 10:52:12;0002;PBS_Server.1834;Svr;PBS_Server;Torque Server Version = 4.1.2, loglevel = 0
11/20/2012 10:54:27;0008;PBS_Server.1831;Job;524.csg.bcmd.bcm.edu;on_job_exit valid pjob: 524.csg.bcmd.bcm.edu (substate=59)
11/20/2012 10:54:27;0100;PBS_Server.1831;Job;524.csg.bcmd.bcm.edu;dequeuing from high, state COMPLETE
11/20/2012 10:54:32;0040;PBS_Server.18220;Svr;csg.bcmd.bcm.edu;Scheduler was sent the command term
11/20/2012 10:57:23;0002;PBS_Server.1837;Svr;PBS_Server;Torque Server Version = 4.1.2, loglevel = 0
11/20/2012 10:57:49;0100;PBS_Server.1832;Job;525.csg.bcmd.bcm.edu;enqueuing into batch, state 1 hop 1
11/20/2012 10:57:49;0008;PBS_Server.1832;Job;525.csg.bcmd.bcm.edu;Job Queued at request of lacuesta@csg.bcmd.bcm.edu, owner = lacuesta@csg.bcmd.bcm.edu, job name = kbjob_AA_HDL_SNV_rs142953140.txt, queue = batch
11/20/2012 10:57:53;0040;PBS_Server.18273;Svr;csg.bcmd.bcm.edu;Scheduler was sent the command new
11/20/2012 10:57:54;0008;PBS_Server.1829;Job;525.csg.bcmd.bcm.edu;Job Run at request of root@csg.bcmd.bcm.edu
11/20/2012 10:57:54;000d;PBS_Server.1829;Job;525.csg.bcmd.bcm.edu;Not sending email: User does not want mail of this type.
11/20/2012 11:02:23;0002;PBS_Server.1830;Svr;PBS_Server;Torque Server Version = 4.1.2, loglevel = 0
11/20/2012 11:07:34;0002;PBS_Server.1826;Svr;PBS_Server;Torque Server Version = 4.1.2, loglevel = 0
11/20/2012 11:08:08;0040;PBS_Server.18333;Svr;csg.bcmd.bcm.edu;Scheduler was sent the command time
11/20/2012 11:12:42;0002;PBS_Server.1830;Svr;PBS_Server;Torque Server Version = 4.1.2, loglevel = 0
11/20/2012 11:17:47;0002;PBS_Server.1830;Svr;PBS_Server;Torque Server Version = 4.1.2, loglevel = 0
11/20/2012 11:18:18;0040;PBS_Server.18348;Svr;csg.bcmd.bcm.edu;Scheduler was sent the command time
11/20/2012 11:22:52;0002;PBS_Server.1835;Svr;PBS_Server;Torque Server Version = 4.1.2, loglevel = 0
11/20/2012 11:27:57;0002;PBS_Server.1825;Svr;PBS_Server;Torque Server Version = 4.1.2, loglevel = 0
11/20/2012 11:28:28;0040;PBS_Server.18365;Svr;csg.bcmd.bcm.edu;Scheduler was sent the command time
11/20/2012 11:33:02;0002;PBS_Server.1834;Svr;PBS_Server;Torque Server Version = 4.1.2, loglevel = 0
11/20/2012 11:38:07;0002;PBS_Server.1827;Svr;PBS_Server;Torque Server Version = 4.1.2, loglevel = 0
11/20/2012 11:38:38;0040;PBS_Server.18385;Svr;csg.bcmd.bcm.edu;Scheduler was sent the command time
11/20/2012 11:43:12;0002;PBS_Server.1831;Svr;PBS_Server;Torque Server Version = 4.1.2, loglevel = 0
11/20/2012 11:48:17;0002;PBS_Server.1836;Svr;PBS_Server;Torque Server Version = 4.1.2, loglevel = 0
11/20/2012 11:48:48;0040;PBS_Server.18430;Svr;csg.bcmd.bcm.edu;Scheduler was sent the command time
11/20/2012 11:53:22;0002;PBS_Server.1833;Svr;PBS_Server;Torque Server Version = 4.1.2, loglevel = 0
11/20/2012 11:58:27;0002;PBS_Server.1834;Svr;PBS_Server;Torque Server Version = 4.1.2, loglevel = 0
11/20/2012 11:58:58;0040;PBS_Server.18446;Svr;csg.bcmd.bcm.edu;Scheduler was sent the command time
11/20/2012 11:59:16;000d;PBS_Server.1828;Job;525.csg.bcmd.bcm.edu;Not sending email: User does not want mail of this type.
11/20/2012 11:59:16;0010;PBS_Server.1828;Job;525.csg.bcmd.bcm.edu;Exit_status=0 resources_used.cput=00:22:19 resources_used.mem=144132kb resources_used.vmem=1105428kb resources_used.walltime=01:01:22
11/20/2012 11:59:16;0008;PBS_Server.1825;Job;525.csg.bcmd.bcm.edu;on_job_exit valid pjob: 525.csg.bcmd.bcm.edu (substate=50)
11/20/2012 11:59:19;0040;PBS_Server.18455;Svr;csg.bcmd.bcm.edu;Scheduler was sent the command term
11/20/2012 12:03:28;0002;PBS_Server.1832;Svr;PBS_Server;Torque Server Version = 4.1.2, loglevel = 0
11/20/2012 12:04:24;0008;PBS_Server.1837;Job;525.csg.bcmd.bcm.edu;on_job_exit valid pjob: 525.csg.bcmd.bcm.edu (substate=59)
11/20/2012 12:04:24;0100;PBS_Server.1837;Job;525.csg.bcmd.bcm.edu;dequeuing from batch, state COMPLETE
11/20/2012 12:04:29;0040;PBS_Server.18582;Svr;csg.bcmd.bcm.edu;Scheduler was sent the command term
11/20/2012 12:08:37;0002;PBS_Server.1831;Svr;PBS_Server;Torque Server Version = 4.1.2, loglevel = 0
11/20/2012 12:13:46;0002;PBS_Server.1834;Svr;PBS_Server;Torque Server Version = 4.1.2, loglevel = 0
11/20/2012 12:14:43;0040;PBS_Server.18730;Svr;csg.bcmd.bcm.edu;Scheduler was sent the command time
11/20/2012 12:18:51;0002;PBS_Server.1825;Svr;PBS_Server;Torque Server Version = 4.1.2, loglevel = 0
11/20/2012 12:23:56;0002;PBS_Server.1826;Svr;PBS_Server;Torque Server Version = 4.1.2, loglevel = 0
11/20/2012 12:24:53;0040;PBS_Server.20164;Svr;csg.bcmd.bcm.edu;Scheduler was sent the command time
11/20/2012 12:29:01;0002;PBS_Server.1829;Svr;PBS_Server;Torque Server Version = 4.1.2, loglevel = 0
11/20/2012 12:34:06;0002;PBS_Server.1835;Svr;PBS_Server;Torque Server Version = 4.1.2, loglevel = 0
11/20/2012 12:35:03;0040;PBS_Server.20294;Svr;csg.bcmd.bcm.edu;Scheduler was sent the command time
11/20/2012 12:39:11;0002;PBS_Server.1835;Svr;PBS_Server;Torque Server Version = 4.1.2, loglevel = 0
11/20/2012 12:44:16;0002;PBS_Server.1829;Svr;PBS_Server;Torque Server Version = 4.1.2, loglevel = 0
11/20/2012 12:45:13;0040;PBS_Server.20390;Svr;csg.bcmd.bcm.edu;Scheduler was sent the command time
11/20/2012 12:49:21;0002;PBS_Server.1830;Svr;PBS_Server;Torque Server Version = 4.1.2, loglevel = 0
11/20/2012 12:54:26;0002;PBS_Server.1837;Svr;PBS_Server;Torque Server Version = 4.1.2, loglevel = 0
11/20/2012 12:55:23;0040;PBS_Server.20487;Svr;csg.bcmd.bcm.edu;Scheduler was sent the command time
11/20/2012 12:59:31;0002;PBS_Server.1835;Svr;PBS_Server;Torque Server Version = 4.1.2, loglevel = 0
11/20/2012 13:04:36;0002;PBS_Server.1835;Svr;PBS_Server;Torque Server Version = 4.1.2, loglevel = 0
11/20/2012 13:05:33;0040;PBS_Server.20561;Svr;csg.bcmd.bcm.edu;Scheduler was sent the command time
11/20/2012 13:09:41;0002;PBS_Server.1830;Svr;PBS_Server;Torque Server Version = 4.1.2, loglevel = 0
11/20/2012 13:14:46;0002;PBS_Server.1828;Svr;PBS_Server;Torque Server Version = 4.1.2, loglevel = 0
11/20/2012 13:15:43;0040;PBS_Server.20593;Svr;csg.bcmd.bcm.edu;Scheduler was sent the command time
11/20/2012 13:19:51;0002;PBS_Server.1830;Svr;PBS_Server;Torque Server Version = 4.1.2, loglevel = 0
11/20/2012 13:24:56;0002;PBS_Server.1837;Svr;PBS_Server;Torque Server Version = 4.1.2, loglevel = 0
11/20/2012 13:25:53;0040;PBS_Server.20611;Svr;csg.bcmd.bcm.edu;Scheduler was sent the command time
11/20/2012 13:30:01;0002;PBS_Server.1833;Svr;PBS_Server;Torque Server Version = 4.1.2, loglevel = 0
11/20/2012 13:35:06;0002;PBS_Server.1831;Svr;PBS_Server;Torque Server Version = 4.1.2, loglevel = 0
11/20/2012 13:36:03;0040;PBS_Server.20629;Svr;csg.bcmd.bcm.edu;Scheduler was sent the command time
11/20/2012 13:40:11;0002;PBS_Server.1837;Svr;PBS_Server;Torque Server Version = 4.1.2, loglevel = 0
11/20/2012 13:45:16;0002;PBS_Server.1830;Svr;PBS_Server;Torque Server Version = 4.1.2, loglevel = 0
11/20/2012 13:46:13;0040;PBS_Server.20651;Svr;csg.bcmd.bcm.edu;Scheduler was sent the command time
11/20/2012 13:50:21;0002;PBS_Server.1826;Svr;PBS_Server;Torque Server Version = 4.1.2, loglevel = 0
11/20/2012 13:55:26;0002;PBS_Server.1837;Svr;PBS_Server;Torque Server Version = 4.1.2, loglevel = 0
11/20/2012 13:56:23;0040;PBS_Server.20665;Svr;csg.bcmd.bcm.edu;Scheduler was sent the command time
11/20/2012 14:00:31;0002;PBS_Server.1825;Svr;PBS_Server;Torque Server Version = 4.1.2, loglevel = 0
11/20/2012 14:05:36;0002;PBS_Server.1829;Svr;PBS_Server;Torque Server Version = 4.1.2, loglevel = 0
11/20/2012 14:06:33;0040;PBS_Server.20841;Svr;csg.bcmd.bcm.edu;Scheduler was sent the command time
11/20/2012 14:10:41;0002;PBS_Server.1829;Svr;PBS_Server;Torque Server Version = 4.1.2, loglevel = 0
11/20/2012 14:15:46;0002;PBS_Server.1828;Svr;PBS_Server;Torque Server Version = 4.1.2, loglevel = 0
11/20/2012 14:16:43;0040;PBS_Server.20936;Svr;csg.bcmd.bcm.edu;Scheduler was sent the command time
11/20/2012 14:20:51;0002;PBS_Server.1825;Svr;PBS_Server;Torque Server Version = 4.1.2, loglevel = 0
11/20/2012 14:25:56;0002;PBS_Server.1827;Svr;PBS_Server;Torque Server Version = 4.1.2, loglevel = 0
11/20/2012 14:26:53;0040;PBS_Server.21080;Svr;csg.bcmd.bcm.edu;Scheduler was sent the command time
11/20/2012 14:31:01;0002;PBS_Server.1837;Svr;PBS_Server;Torque Server Version = 4.1.2, loglevel = 0
11/20/2012 14:36:06;0002;PBS_Server.1830;Svr;PBS_Server;Torque Server Version = 4.1.2, loglevel = 0
11/20/2012 14:37:03;0040;PBS_Server.21244;Svr;csg.bcmd.bcm.edu;Scheduler was sent the command time
11/20/2012 14:41:11;0002;PBS_Server.1830;Svr;PBS_Server;Torque Server Version = 4.1.2, loglevel = 0
11/20/2012 14:46:16;0002;PBS_Server.1837;Svr;PBS_Server;Torque Server Version = 4.1.2, loglevel = 0
11/20/2012 14:47:13;0040;PBS_Server.21351;Svr;csg.bcmd.bcm.edu;Scheduler was sent the command time
11/20/2012 14:51:21;0002;PBS_Server.1836;Svr;PBS_Server;Torque Server Version = 4.1.2, loglevel = 0
11/20/2012 14:56:26;0002;PBS_Server.1829;Svr;PBS_Server;Torque Server Version = 4.1.2, loglevel = 0
11/20/2012 14:57:23;0040;PBS_Server.21446;Svr;csg.bcmd.bcm.edu;Scheduler was sent the command time
11/20/2012 15:01:31;0002;PBS_Server.1830;Svr;PBS_Server;Torque Server Version = 4.1.2, loglevel = 0
11/20/2012 15:06:36;0002;PBS_Server.1835;Svr;PBS_Server;Torque Server Version = 4.1.2, loglevel = 0
11/20/2012 15:07:33;0040;PBS_Server.21496;Svr;csg.bcmd.bcm.edu;Scheduler was sent the command time
11/20/2012 15:11:41;0002;PBS_Server.1827;Svr;PBS_Server;Torque Server Version = 4.1.2, loglevel = 0
11/20/2012 15:16:46;0002;PBS_Server.1830;Svr;PBS_Server;Torque Server Version = 4.1.2, loglevel = 0
11/20/2012 15:17:43;0040;PBS_Server.21524;Svr;csg.bcmd.bcm.edu;Scheduler was sent the command time
11/20/2012 15:21:51;0002;PBS_Server.1835;Svr;PBS_Server;Torque Server Version = 4.1.2, loglevel = 0
11/20/2012 15:26:56;0002;PBS_Server.1831;Svr;PBS_Server;Torque Server Version = 4.1.2, loglevel = 0
11/20/2012 15:27:53;0040;PBS_Server.21560;Svr;csg.bcmd.bcm.edu;Scheduler was sent the command time
11/20/2012 15:32:01;0002;PBS_Server.1827;Svr;PBS_Server;Torque Server Version = 4.1.2, loglevel = 0
11/20/2012 15:37:06;0002;PBS_Server.1826;Svr;PBS_Server;Torque Server Version = 4.1.2, loglevel = 0
11/20/2012 15:38:03;0040;PBS_Server.21639;Svr;csg.bcmd.bcm.edu;Scheduler was sent the command time
11/20/2012 15:42:11;0002;PBS_Server.1837;Svr;PBS_Server;Torque Server Version = 4.1.2, loglevel = 0
11/20/2012 15:47:16;0002;PBS_Server.1828;Svr;PBS_Server;Torque Server Version = 4.1.2, loglevel = 0
11/20/2012 15:48:13;0040;PBS_Server.21687;Svr;csg.bcmd.bcm.edu;Scheduler was sent the command time
11/20/2012 15:52:21;0002;PBS_Server.1827;Svr;PBS_Server;Torque Server Version = 4.1.2, loglevel = 0
11/20/2012 15:57:26;0002;PBS_Server.1826;Svr;PBS_Server;Torque Server Version = 4.1.2, loglevel = 0
11/20/2012 15:58:23;0040;PBS_Server.21717;Svr;csg.bcmd.bcm.edu;Scheduler was sent the command time
11/20/2012 16:02:31;0002;PBS_Server.1825;Svr;PBS_Server;Torque Server Version = 4.1.2, loglevel = 0
11/20/2012 16:07:36;0002;PBS_Server.1829;Svr;PBS_Server;Torque Server Version = 4.1.2, loglevel = 0
11/20/2012 16:08:33;0040;PBS_Server.21948;Svr;csg.bcmd.bcm.edu;Scheduler was sent the command time
11/20/2012 16:12:41;0002;PBS_Server.1829;Svr;PBS_Server;Torque Server Version = 4.1.2, loglevel = 0
11/20/2012 16:17:46;0002;PBS_Server.1834;Svr;PBS_Server;Torque Server Version = 4.1.2, loglevel = 0
11/20/2012 16:18:43;0040;PBS_Server.22098;Svr;csg.bcmd.bcm.edu;Scheduler was sent the command time
11/20/2012 16:22:51;0002;PBS_Server.1828;Svr;PBS_Server;Torque Server Version = 4.1.2, loglevel = 0
11/20/2012 16:27:56;0002;PBS_Server.1826;Svr;PBS_Server;Torque Server Version = 4.1.2, loglevel = 0
11/20/2012 16:28:53;0040;PBS_Server.22221;Svr;csg.bcmd.bcm.edu;Scheduler was sent the command time
11/20/2012 16:33:01;0002;PBS_Server.1836;Svr;PBS_Server;Torque Server Version = 4.1.2, loglevel = 0
11/20/2012 16:38:06;0002;PBS_Server.1833;Svr;PBS_Server;Torque Server Version = 4.1.2, loglevel = 0
11/20/2012 16:39:03;0040;PBS_Server.22376;Svr;csg.bcmd.bcm.edu;Scheduler was sent the command time
11/20/2012 16:43:11;0002;PBS_Server.1826;Svr;PBS_Server;Torque Server Version = 4.1.2, loglevel = 0
11/20/2012 16:48:16;0002;PBS_Server.1831;Svr;PBS_Server;Torque Server Version = 4.1.2, loglevel = 0
11/20/2012 16:49:13;0040;PBS_Server.22487;Svr;csg.bcmd.bcm.edu;Scheduler was sent the command time
11/20/2012 16:53:21;0002;PBS_Server.1832;Svr;PBS_Server;Torque Server Version = 4.1.2, loglevel = 0
11/20/2012 16:58:26;0002;PBS_Server.1827;Svr;PBS_Server;Torque Server Version = 4.1.2, loglevel = 0
11/20/2012 16:59:23;0040;PBS_Server.22596;Svr;csg.bcmd.bcm.edu;Scheduler was sent the command time
11/20/2012 17:03:31;0002;PBS_Server.1828;Svr;PBS_Server;Torque Server Version = 4.1.2, loglevel = 0
11/20/2012 17:08:36;0002;PBS_Server.1827;Svr;PBS_Server;Torque Server Version = 4.1.2, loglevel = 0
11/20/2012 17:09:33;0040;PBS_Server.22618;Svr;csg.bcmd.bcm.edu;Scheduler was sent the command time
11/20/2012 17:13:41;0002;PBS_Server.1826;Svr;PBS_Server;Torque Server Version = 4.1.2, loglevel = 0
11/20/2012 17:18:46;0002;PBS_Server.1832;Svr;PBS_Server;Torque Server Version = 4.1.2, loglevel = 0
11/20/2012 17:19:43;0040;PBS_Server.22761;Svr;csg.bcmd.bcm.edu;Scheduler was sent the command time
11/20/2012 17:23:51;0002;PBS_Server.1834;Svr;PBS_Server;Torque Server Version = 4.1.2, loglevel = 0
11/20/2012 17:28:56;0002;PBS_Server.1835;Svr;PBS_Server;Torque Server Version = 4.1.2, loglevel = 0
11/20/2012 17:29:53;0040;PBS_Server.22872;Svr;csg.bcmd.bcm.edu;Scheduler was sent the command time
11/20/2012 17:34:01;0002;PBS_Server.1828;Svr;PBS_Server;Torque Server Version = 4.1.2, loglevel = 0
11/20/2012 17:38:56;0100;PBS_Server.1834;Job;526.csg.bcmd.bcm.edu;enqueuing into high, state 1 hop 1
11/20/2012 17:38:56;0008;PBS_Server.1834;Job;526.csg.bcmd.bcm.edu;Job Queued at request of lacuesta@csg.bcmd.bcm.edu, owner = lacuesta@csg.bcmd.bcm.edu, job name = kbjob_AA_TRIGS_SID_kb, queue = high
11/20/2012 17:39:01;0040;PBS_Server.23081;Svr;csg.bcmd.bcm.edu;Scheduler was sent the command new
11/20/2012 17:39:02;0002;PBS_Server.1828;Svr;PBS_Server;Torque Server Version = 4.1.2, loglevel = 0
11/20/2012 17:39:02;0008;PBS_Server.1829;Job;526.csg.bcmd.bcm.edu;Job Run at request of root@csg.bcmd.bcm.edu
11/20/2012 17:39:02;000d;PBS_Server.1829;Job;526.csg.bcmd.bcm.edu;Not sending email: User does not want mail of this type.
11/20/2012 17:40:12;000d;PBS_Server.1827;Job;526.csg.bcmd.bcm.edu;Not sending email: User does not want mail of this type.
11/20/2012 17:40:12;0010;PBS_Server.1827;Job;526.csg.bcmd.bcm.edu;Exit_status=0 resources_used.cput=00:00:37 resources_used.mem=5924kb resources_used.vmem=74064kb resources_used.walltime=00:01:10
11/20/2012 17:40:12;0008;PBS_Server.1835;Job;526.csg.bcmd.bcm.edu;on_job_exit valid pjob: 526.csg.bcmd.bcm.edu (substate=50)
11/20/2012 17:40:17;0040;PBS_Server.23108;Svr;csg.bcmd.bcm.edu;Scheduler was sent the command term
11/20/2012 17:43:58;0100;PBS_Server.1837;Job;527.csg.bcmd.bcm.edu;enqueuing into high, state 1 hop 1
11/20/2012 17:43:58;0008;PBS_Server.1837;Job;527.csg.bcmd.bcm.edu;Job Queued at request of lacuesta@csg.bcmd.bcm.edu, owner = lacuesta@csg.bcmd.bcm.edu, job name = kbjob_EA_TRIGS_SID, queue = high
11/20/2012 17:44:02;0002;PBS_Server.1833;Svr;PBS_Server;Torque Server Version = 4.1.2, loglevel = 0
11/20/2012 17:44:02;0040;PBS_Server.23119;Svr;csg.bcmd.bcm.edu;Scheduler was sent the command new
11/20/2012 17:44:03;0008;PBS_Server.1829;Job;527.csg.bcmd.bcm.edu;Job Run at request of root@csg.bcmd.bcm.edu
11/20/2012 17:44:03;000d;PBS_Server.1829;Job;527.csg.bcmd.bcm.edu;Not sending email: User does not want mail of this type.
11/20/2012 17:44:04;000d;PBS_Server.1830;Job;527.csg.bcmd.bcm.edu;Not sending email: User does not want mail of this type.
11/20/2012 17:44:04;0010;PBS_Server.1830;Job;527.csg.bcmd.bcm.edu;Exit_status=0 resources_used.cput=00:00:00 resources_used.mem=0kb resources_used.vmem=0kb resources_used.walltime=00:00:01
11/20/2012 17:44:04;0008;PBS_Server.1835;Job;527.csg.bcmd.bcm.edu;on_job_exit valid pjob: 527.csg.bcmd.bcm.edu (substate=50)
11/20/2012 17:44:07;0040;PBS_Server.23128;Svr;csg.bcmd.bcm.edu;Scheduler was sent the command term
11/20/2012 17:45:17;0008;PBS_Server.1836;Job;526.csg.bcmd.bcm.edu;on_job_exit valid pjob: 526.csg.bcmd.bcm.edu (substate=59)
11/20/2012 17:45:17;0100;PBS_Server.1836;Job;526.csg.bcmd.bcm.edu;dequeuing from high, state COMPLETE
11/20/2012 17:45:20;0100;PBS_Server.1828;Job;528.csg.bcmd.bcm.edu;enqueuing into high, state 1 hop 1
11/20/2012 17:45:20;0008;PBS_Server.1828;Job;528.csg.bcmd.bcm.edu;Job Queued at request of lacuesta@csg.bcmd.bcm.edu, owner = lacuesta@csg.bcmd.bcm.edu, job name = kbjob_EA_TRIGS_SID, queue = high
11/20/2012 17:45:22;0040;PBS_Server.23153;Svr;csg.bcmd.bcm.edu;Scheduler was sent the command new
11/20/2012 17:45:23;0008;PBS_Server.1829;Job;528.csg.bcmd.bcm.edu;Job Run at request of root@csg.bcmd.bcm.edu
11/20/2012 17:45:23;000d;PBS_Server.1829;Job;528.csg.bcmd.bcm.edu;Not sending email: User does not want mail of this type.
11/20/2012 17:47:06;0100;PBS_Server.1825;Job;529.csg.bcmd.bcm.edu;enqueuing into high, state 1 hop 1
11/20/2012 17:47:06;0008;PBS_Server.1825;Job;529.csg.bcmd.bcm.edu;Job Queued at request of lacuesta@csg.bcmd.bcm.edu, owner = lacuesta@csg.bcmd.bcm.edu, job name = kbjob_AA_TRIGS_SID, queue = high
11/20/2012 17:47:07;0040;PBS_Server.23196;Svr;csg.bcmd.bcm.edu;Scheduler was sent the command new
11/20/2012 17:47:09;0008;PBS_Server.1829;Job;529.csg.bcmd.bcm.edu;Job Run at request of root@csg.bcmd.bcm.edu
11/20/2012 17:47:09;000d;PBS_Server.1829;Job;529.csg.bcmd.bcm.edu;Not sending email: User does not want mail of this type.
11/20/2012 17:49:13;0002;PBS_Server.1833;Svr;PBS_Server;Torque Server Version = 4.1.2, loglevel = 0
11/20/2012 17:49:13;0008;PBS_Server.1827;Job;527.csg.bcmd.bcm.edu;on_job_exit valid pjob: 527.csg.bcmd.bcm.edu (substate=59)
11/20/2012 17:49:13;0100;PBS_Server.1827;Job;527.csg.bcmd.bcm.edu;dequeuing from high, state COMPLETE
11/20/2012 17:49:18;0040;PBS_Server.23241;Svr;csg.bcmd.bcm.edu;Scheduler was sent the command term
11/20/2012 17:54:13;0002;PBS_Server.1836;Svr;PBS_Server;Torque Server Version = 4.1.2, loglevel = 0
11/20/2012 17:59:18;0002;PBS_Server.1832;Svr;PBS_Server;Torque Server Version = 4.1.2, loglevel = 0
11/20/2012 17:59:23;0040;PBS_Server.23433;Svr;csg.bcmd.bcm.edu;Scheduler was sent the command time
11/20/2012 18:04:23;0002;PBS_Server.1825;Svr;PBS_Server;Torque Server Version = 4.1.2, loglevel = 0
11/20/2012 18:09:28;0002;PBS_Server.1834;Svr;PBS_Server;Torque Server Version = 4.1.2, loglevel = 0
11/20/2012 18:09:33;0040;PBS_Server.23687;Svr;csg.bcmd.bcm.edu;Scheduler was sent the command time
11/20/2012 18:14:33;0002;PBS_Server.1829;Svr;PBS_Server;Torque Server Version = 4.1.2, loglevel = 0
11/20/2012 18:19:38;0002;PBS_Server.1825;Svr;PBS_Server;Torque Server Version = 4.1.2, loglevel = 0
11/20/2012 18:19:43;0040;PBS_Server.23799;Svr;csg.bcmd.bcm.edu;Scheduler was sent the command time
11/20/2012 18:24:43;0002;PBS_Server.1827;Svr;PBS_Server;Torque Server Version = 4.1.2, loglevel = 0
11/20/2012 18:29:48;0002;PBS_Server.1829;Svr;PBS_Server;Torque Server Version = 4.1.2, loglevel = 0
11/20/2012 18:29:53;0040;PBS_Server.23893;Svr;csg.bcmd.bcm.edu;Scheduler was sent the command time
11/20/2012 18:34:53;0002;PBS_Server.1833;Svr;PBS_Server;Torque Server Version = 4.1.2, loglevel = 0
11/20/2012 18:39:58;0002;PBS_Server.1834;Svr;PBS_Server;Torque Server Version = 4.1.2, loglevel = 0
11/20/2012 18:40:03;0040;PBS_Server.23999;Svr;csg.bcmd.bcm.edu;Scheduler was sent the command time
11/20/2012 18:45:08;0002;PBS_Server.1834;Svr;PBS_Server;Torque Server Version = 4.1.2, loglevel = 0
11/20/2012 18:50:13;0002;PBS_Server.1829;Svr;PBS_Server;Torque Server Version = 4.1.2, loglevel = 0
11/20/2012 18:50:18;0040;PBS_Server.24096;Svr;csg.bcmd.bcm.edu;Scheduler was sent the command time
11/20/2012 18:55:18;0002;PBS_Server.1825;Svr;PBS_Server;Torque Server Version = 4.1.2, loglevel = 0
11/20/2012 19:00:23;0002;PBS_Server.1830;Svr;PBS_Server;Torque Server Version = 4.1.2, loglevel = 0
11/20/2012 19:00:28;0040;PBS_Server.24183;Svr;csg.bcmd.bcm.edu;Scheduler was sent the command time
11/20/2012 19:05:28;0002;PBS_Server.1835;Svr;PBS_Server;Torque Server Version = 4.1.2, loglevel = 0
11/20/2012 19:10:33;0002;PBS_Server.1825;Svr;PBS_Server;Torque Server Version = 4.1.2, loglevel = 0
11/20/2012 19:10:38;0040;PBS_Server.24204;Svr;csg.bcmd.bcm.edu;Scheduler was sent the command time
11/20/2012 19:15:38;0002;PBS_Server.1828;Svr;PBS_Server;Torque Server Version = 4.1.2, loglevel = 0
11/20/2012 19:20:43;0002;PBS_Server.1835;Svr;PBS_Server;Torque Server Version = 4.1.2, loglevel = 0
11/20/2012 19:20:48;0040;PBS_Server.24223;Svr;csg.bcmd.bcm.edu;Scheduler was sent the command time
11/20/2012 19:25:48;0002;PBS_Server.1828;Svr;PBS_Server;Torque Server Version = 4.1.2, loglevel = 0
11/20/2012 19:30:53;0002;PBS_Server.1833;Svr;PBS_Server;Torque Server Version = 4.1.2, loglevel = 0
11/20/2012 19:30:58;0040;PBS_Server.24240;Svr;csg.bcmd.bcm.edu;Scheduler was sent the command time
11/20/2012 19:35:58;0002;PBS_Server.1829;Svr;PBS_Server;Torque Server Version = 4.1.2, loglevel = 0
11/20/2012 19:41:03;0002;PBS_Server.1830;Svr;PBS_Server;Torque Server Version = 4.1.2, loglevel = 0
11/20/2012 19:41:08;0040;PBS_Server.24259;Svr;csg.bcmd.bcm.edu;Scheduler was sent the command time
11/20/2012 19:46:08;0002;PBS_Server.1836;Svr;PBS_Server;Torque Server Version = 4.1.2, loglevel = 0
11/20/2012 19:51:13;0002;PBS_Server.1825;Svr;PBS_Server;Torque Server Version = 4.1.2, loglevel = 0
11/20/2012 19:51:18;0040;PBS_Server.24275;Svr;csg.bcmd.bcm.edu;Scheduler was sent the command time
11/20/2012 19:56:18;0002;PBS_Server.1832;Svr;PBS_Server;Torque Server Version = 4.1.2, loglevel = 0
11/20/2012 20:01:23;0002;PBS_Server.1826;Svr;PBS_Server;Torque Server Version = 4.1.2, loglevel = 0
11/20/2012 20:01:28;0040;PBS_Server.24373;Svr;csg.bcmd.bcm.edu;Scheduler was sent the command time
11/20/2012 20:06:28;0002;PBS_Server.1827;Svr;PBS_Server;Torque Server Version = 4.1.2, loglevel = 0
11/20/2012 20:09:39;0001;PBS_Server.1822;Svr;PBS_Server;LOG_ERROR::Bad file descriptor (9) in wait_request, Unable to select sockets to read requests
11/20/2012 20:09:39;0001;PBS_Server.1822;Svr;PBS_Server;LOG_ERROR::PBS_Server, wait_request failed
11/20/2012 20:11:33;0002;PBS_Server.1831;Svr;PBS_Server;Torque Server Version = 4.1.2, loglevel = 0
11/20/2012 20:11:38;0040;PBS_Server.24468;Svr;csg.bcmd.bcm.edu;Scheduler was sent the command time
11/20/2012 20:16:38;0002;PBS_Server.1825;Svr;PBS_Server;Torque Server Version = 4.1.2, loglevel = 0
11/20/2012 20:21:43;0002;PBS_Server.1834;Svr;PBS_Server;Torque Server Version = 4.1.2, loglevel = 0
11/20/2012 20:21:48;0040;PBS_Server.24563;Svr;csg.bcmd.bcm.edu;Scheduler was sent the command time
11/20/2012 20:26:48;0002;PBS_Server.1835;Svr;PBS_Server;Torque Server Version = 4.1.2, loglevel = 0
11/20/2012 20:31:53;0002;PBS_Server.1829;Svr;PBS_Server;Torque Server Version = 4.1.2, loglevel = 0
11/20/2012 20:31:58;0040;PBS_Server.24658;Svr;csg.bcmd.bcm.edu;Scheduler was sent the command time
11/20/2012 20:36:58;0002;PBS_Server.1837;Svr;PBS_Server;Torque Server Version = 4.1.2, loglevel = 0
11/20/2012 20:42:03;0002;PBS_Server.1837;Svr;PBS_Server;Torque Server Version = 4.1.2, loglevel = 0
11/20/2012 20:42:08;0040;PBS_Server.24761;Svr;csg.bcmd.bcm.edu;Scheduler was sent the command time
11/20/2012 20:43:51;000d;PBS_Server.1826;Job;529.csg.bcmd.bcm.edu;Not sending email: User does not want mail of this type.
11/20/2012 20:43:51;0010;PBS_Server.1826;Job;529.csg.bcmd.bcm.edu;Exit_status=0 resources_used.cput=32:59:26 resources_used.mem=1099072kb resources_used.vmem=5597876kb resources_used.walltime=02:56:42
11/20/2012 20:43:51;0008;PBS_Server.1832;Job;529.csg.bcmd.bcm.edu;on_job_exit valid pjob: 529.csg.bcmd.bcm.edu (substate=50)
11/20/2012 20:43:52;0040;PBS_Server.24779;Svr;csg.bcmd.bcm.edu;Scheduler was sent the command term
11/20/2012 20:47:04;0002;PBS_Server.1837;Svr;PBS_Server;Torque Server Version = 4.1.2, loglevel = 0
11/20/2012 20:48:52;0008;PBS_Server.1829;Job;529.csg.bcmd.bcm.edu;on_job_exit valid pjob: 529.csg.bcmd.bcm.edu (substate=59)
11/20/2012 20:48:52;0100;PBS_Server.1829;Job;529.csg.bcmd.bcm.edu;dequeuing from high, state COMPLETE
11/20/2012 20:48:57;0040;PBS_Server.24828;Svr;csg.bcmd.bcm.edu;Scheduler was sent the command term
11/20/2012 20:52:09;0002;PBS_Server.1837;Svr;PBS_Server;Torque Server Version = 4.1.2, loglevel = 0
11/20/2012 20:57:14;0002;PBS_Server.1828;Svr;PBS_Server;Torque Server Version = 4.1.2, loglevel = 0
11/20/2012 20:59:07;0040;PBS_Server.24929;Svr;csg.bcmd.bcm.edu;Scheduler was sent the command time
11/20/2012 21:02:19;0002;PBS_Server.1826;Svr;PBS_Server;Torque Server Version = 4.1.2, loglevel = 0
11/20/2012 21:07:24;0002;PBS_Server.1835;Svr;PBS_Server;Torque Server Version = 4.1.2, loglevel = 0
11/20/2012 21:09:17;0040;PBS_Server.24950;Svr;csg.bcmd.bcm.edu;Scheduler was sent the command time
11/20/2012 21:12:29;0002;PBS_Server.1830;Svr;PBS_Server;Torque Server Version = 4.1.2, loglevel = 0
11/20/2012 21:17:34;0002;PBS_Server.1835;Svr;PBS_Server;Torque Server Version = 4.1.2, loglevel = 0
11/20/2012 21:19:27;0040;PBS_Server.24964;Svr;csg.bcmd.bcm.edu;Scheduler was sent the command time
11/20/2012 21:22:39;0002;PBS_Server.1837;Svr;PBS_Server;Torque Server Version = 4.1.2, loglevel = 0
11/20/2012 21:27:44;0002;PBS_Server.1835;Svr;PBS_Server;Torque Server Version = 4.1.2, loglevel = 0
11/20/2012 21:29:37;0040;PBS_Server.24979;Svr;csg.bcmd.bcm.edu;Scheduler was sent the command time
11/20/2012 21:32:49;0002;PBS_Server.1829;Svr;PBS_Server;Torque Server Version = 4.1.2, loglevel = 0
11/20/2012 21:37:54;0002;PBS_Server.1827;Svr;PBS_Server;Torque Server Version = 4.1.2, loglevel = 0
11/20/2012 21:39:47;0040;PBS_Server.24992;Svr;csg.bcmd.bcm.edu;Scheduler was sent the command time
11/20/2012 21:42:59;0002;PBS_Server.1826;Svr;PBS_Server;Torque Server Version = 4.1.2, loglevel = 0
11/20/2012 21:48:04;0002;PBS_Server.1832;Svr;PBS_Server;Torque Server Version = 4.1.2, loglevel = 0
11/20/2012 21:49:57;0040;PBS_Server.25007;Svr;csg.bcmd.bcm.edu;Scheduler was sent the command time
11/20/2012 21:53:09;0002;PBS_Server.1825;Svr;PBS_Server;Torque Server Version = 4.1.2, loglevel = 0
11/20/2012 21:58:14;0002;PBS_Server.1829;Svr;PBS_Server;Torque Server Version = 4.1.2, loglevel = 0
11/20/2012 22:00:07;0040;PBS_Server.25033;Svr;csg.bcmd.bcm.edu;Scheduler was sent the command time
11/20/2012 22:03:19;0002;PBS_Server.1825;Svr;PBS_Server;Torque Server Version = 4.1.2, loglevel = 0
11/20/2012 22:08:24;0002;PBS_Server.1837;Svr;PBS_Server;Torque Server Version = 4.1.2, loglevel = 0
11/20/2012 22:10:17;0040;PBS_Server.25195;Svr;csg.bcmd.bcm.edu;Scheduler was sent the command time
11/20/2012 22:13:29;0002;PBS_Server.1832;Svr;PBS_Server;Torque Server Version = 4.1.2, loglevel = 0
11/20/2012 22:18:34;0002;PBS_Server.1832;Svr;PBS_Server;Torque Server Version = 4.1.2, loglevel = 0
11/20/2012 22:20:27;0040;PBS_Server.25289;Svr;csg.bcmd.bcm.edu;Scheduler was sent the command time
11/20/2012 22:23:39;0002;PBS_Server.1825;Svr;PBS_Server;Torque Server Version = 4.1.2, loglevel = 0
11/20/2012 22:28:44;0002;PBS_Server.1836;Svr;PBS_Server;Torque Server Version = 4.1.2, loglevel = 0
11/20/2012 22:30:37;0040;PBS_Server.25384;Svr;csg.bcmd.bcm.edu;Scheduler was sent the command time
11/20/2012 22:33:49;0002;PBS_Server.1828;Svr;PBS_Server;Torque Server Version = 4.1.2, loglevel = 0
11/20/2012 22:38:54;0002;PBS_Server.1834;Svr;PBS_Server;Torque Server Version = 4.1.2, loglevel = 0
11/20/2012 22:40:47;0040;PBS_Server.25477;Svr;csg.bcmd.bcm.edu;Scheduler was sent the command time
11/20/2012 22:42:13;000d;PBS_Server.1833;Job;528.csg.bcmd.bcm.edu;Not sending email: User does not want mail of this type.
11/20/2012 22:42:13;0010;PBS_Server.1833;Job;528.csg.bcmd.bcm.edu;Exit_status=0 resources_used.cput=52:18:17 resources_used.mem=1145760kb resources_used.vmem=5644388kb resources_used.walltime=04:56:50
11/20/2012 22:42:13;0008;PBS_Server.1826;Job;528.csg.bcmd.bcm.edu;on_job_exit valid pjob: 528.csg.bcmd.bcm.edu (substate=50)
11/20/2012 22:42:15;0040;PBS_Server.25503;Svr;csg.bcmd.bcm.edu;Scheduler was sent the command term
11/20/2012 22:43:59;0002;PBS_Server.1830;Svr;PBS_Server;Torque Server Version = 4.1.2, loglevel = 0
11/20/2012 22:47:20;0008;PBS_Server.1831;Job;528.csg.bcmd.bcm.edu;on_job_exit valid pjob: 528.csg.bcmd.bcm.edu (substate=59)
11/20/2012 22:47:20;0100;PBS_Server.1831;Job;528.csg.bcmd.bcm.edu;dequeuing from high, state COMPLETE
11/20/2012 22:47:25;0040;PBS_Server.25553;Svr;csg.bcmd.bcm.edu;Scheduler was sent the command term
11/20/2012 22:49:08;0002;PBS_Server.1837;Svr;PBS_Server;Torque Server Version = 4.1.2, loglevel = 0
11/20/2012 22:54:13;0002;PBS_Server.1836;Svr;PBS_Server;Torque Server Version = 4.1.2, loglevel = 0
11/20/2012 22:57:39;0040;PBS_Server.25648;Svr;csg.bcmd.bcm.edu;Scheduler was sent the command time
11/20/2012 22:59:18;0002;PBS_Server.1830;Svr;PBS_Server;Torque Server Version = 4.1.2, loglevel = 0
11/20/2012 23:04:23;0002;PBS_Server.1834;Svr;PBS_Server;Torque Server Version = 4.1.2, loglevel = 0
11/20/2012 23:07:49;0040;PBS_Server.25685;Svr;csg.bcmd.bcm.edu;Scheduler was sent the command time
11/20/2012 23:09:28;0002;PBS_Server.1831;Svr;PBS_Server;Torque Server Version = 4.1.2, loglevel = 0
11/20/2012 23:14:33;0002;PBS_Server.1830;Svr;PBS_Server;Torque Server Version = 4.1.2, loglevel = 0
11/20/2012 23:17:59;0040;PBS_Server.25698;Svr;csg.bcmd.bcm.edu;Scheduler was sent the command time
11/20/2012 23:19:38;0002;PBS_Server.1830;Svr;PBS_Server;Torque Server Version = 4.1.2, loglevel = 0
11/20/2012 23:24:43;0002;PBS_Server.1827;Svr;PBS_Server;Torque Server Version = 4.1.2, loglevel = 0
11/20/2012 23:28:09;0040;PBS_Server.25713;Svr;csg.bcmd.bcm.edu;Scheduler was sent the command time
11/20/2012 23:29:48;0002;PBS_Server.1825;Svr;PBS_Server;Torque Server Version = 4.1.2, loglevel = 0
11/20/2012 23:34:53;0002;PBS_Server.1833;Svr;PBS_Server;Torque Server Version = 4.1.2, loglevel = 0
11/20/2012 23:38:19;0040;PBS_Server.25727;Svr;csg.bcmd.bcm.edu;Scheduler was sent the command time
11/20/2012 23:39:58;0002;PBS_Server.1830;Svr;PBS_Server;Torque Server Version = 4.1.2, loglevel = 0
11/20/2012 23:45:03;0002;PBS_Server.1835;Svr;PBS_Server;Torque Server Version = 4.1.2, loglevel = 0
11/20/2012 23:48:29;0040;PBS_Server.25743;Svr;csg.bcmd.bcm.edu;Scheduler was sent the command time
11/20/2012 23:50:08;0002;PBS_Server.1835;Svr;PBS_Server;Torque Server Version = 4.1.2, loglevel = 0
11/20/2012 23:55:13;0002;PBS_Server.1832;Svr;PBS_Server;Torque Server Version = 4.1.2, loglevel = 0
11/20/2012 23:58:39;0040;PBS_Server.25757;Svr;csg.bcmd.bcm.edu;Scheduler was sent the command time
11/21/2012 00:00:18;0002;PBS_Server.1835;Svr;Log;Log closed
