11/02/2012 00:00:26;0002;PBS_Server.1827;Svr;Log;Log opened
11/02/2012 00:00:26;0002;PBS_Server.1827;Svr;PBS_Server;Torque Server Version = 4.1.2, loglevel = 0
11/02/2012 00:05:31;0002;PBS_Server.1833;Svr;PBS_Server;Torque Server Version = 4.1.2, loglevel = 0
11/02/2012 00:09:23;0040;PBS_Server.8089;Svr;csg.bcmd.bcm.edu;Scheduler was sent the command time
11/02/2012 00:10:36;0002;PBS_Server.1831;Svr;PBS_Server;Torque Server Version = 4.1.2, loglevel = 0
11/02/2012 00:15:41;0002;PBS_Server.1836;Svr;PBS_Server;Torque Server Version = 4.1.2, loglevel = 0
11/02/2012 00:19:33;0040;PBS_Server.8184;Svr;csg.bcmd.bcm.edu;Scheduler was sent the command time
11/02/2012 00:20:46;0002;PBS_Server.1837;Svr;PBS_Server;Torque Server Version = 4.1.2, loglevel = 0
11/02/2012 00:25:51;0002;PBS_Server.1836;Svr;PBS_Server;Torque Server Version = 4.1.2, loglevel = 0
11/02/2012 00:29:43;0040;PBS_Server.8279;Svr;csg.bcmd.bcm.edu;Scheduler was sent the command time
11/02/2012 00:30:56;0002;PBS_Server.1832;Svr;PBS_Server;Torque Server Version = 4.1.2, loglevel = 0
11/02/2012 00:36:01;0002;PBS_Server.1826;Svr;PBS_Server;Torque Server Version = 4.1.2, loglevel = 0
11/02/2012 00:39:53;0040;PBS_Server.8373;Svr;csg.bcmd.bcm.edu;Scheduler was sent the command time
11/02/2012 00:41:06;0002;PBS_Server.1827;Svr;PBS_Server;Torque Server Version = 4.1.2, loglevel = 0
11/02/2012 00:46:11;0002;PBS_Server.1835;Svr;PBS_Server;Torque Server Version = 4.1.2, loglevel = 0
11/02/2012 00:50:03;0040;PBS_Server.8478;Svr;csg.bcmd.bcm.edu;Scheduler was sent the command time
11/02/2012 00:51:16;0002;PBS_Server.1835;Svr;PBS_Server;Torque Server Version = 4.1.2, loglevel = 0
11/02/2012 00:56:21;0002;PBS_Server.1836;Svr;PBS_Server;Torque Server Version = 4.1.2, loglevel = 0
11/02/2012 01:00:13;0040;PBS_Server.8566;Svr;csg.bcmd.bcm.edu;Scheduler was sent the command time
11/02/2012 01:01:26;0002;PBS_Server.1827;Svr;PBS_Server;Torque Server Version = 4.1.2, loglevel = 0
11/02/2012 01:06:31;0002;PBS_Server.1832;Svr;PBS_Server;Torque Server Version = 4.1.2, loglevel = 0
11/02/2012 01:10:23;0040;PBS_Server.8587;Svr;csg.bcmd.bcm.edu;Scheduler was sent the command time
11/02/2012 01:11:36;0002;PBS_Server.1836;Svr;PBS_Server;Torque Server Version = 4.1.2, loglevel = 0
11/02/2012 01:16:41;0002;PBS_Server.1825;Svr;PBS_Server;Torque Server Version = 4.1.2, loglevel = 0
11/02/2012 01:20:33;0040;PBS_Server.8602;Svr;csg.bcmd.bcm.edu;Scheduler was sent the command time
11/02/2012 01:21:46;0002;PBS_Server.1825;Svr;PBS_Server;Torque Server Version = 4.1.2, loglevel = 0
11/02/2012 01:26:51;0002;PBS_Server.1825;Svr;PBS_Server;Torque Server Version = 4.1.2, loglevel = 0
11/02/2012 01:30:31;000d;PBS_Server.1828;Job;291.csg.bcmd.bcm.edu;Not sending email: User does not want mail of this type.
11/02/2012 01:30:31;0002;PBS_Server.1828;Svr;Act;Account file /var/spool/torque/server_priv/accounting/20121102 opened
11/02/2012 01:30:31;0010;PBS_Server.1828;Job;291.csg.bcmd.bcm.edu;Exit_status=1 resources_used.cput=20:46:31 resources_used.mem=1151568kb resources_used.vmem=5541668kb resources_used.walltime=08:21:18
11/02/2012 01:30:31;0008;PBS_Server.1826;Job;291.csg.bcmd.bcm.edu;on_job_exit valid pjob: 291.csg.bcmd.bcm.edu (substate=50)
11/02/2012 01:30:39;000d;PBS_Server.1826;Job;291.csg.bcmd.bcm.edu;Post job file processing error; job 291.csg.bcmd.bcm.edu on host csg14/15+csg14/14+csg14/13+csg14/12+csg14/11+csg14/10+csg14/9+csg14/8+csg14/7+csg14/6+csg14/5+csg14/4+csg14/3+csg14/2+csg14/1+csg14/0
11/02/2012 01:30:39;000d;PBS_Server.1828;Job;291.csg.bcmd.bcm.edu;Email 'o' to gaow@csg.bcmd.bcm.edu failed: Child process 'sendmail -f adm gaow@csg.bcmd.bcm.edu' returned 127 (errno 0:Success)
11/02/2012 01:30:39;0040;PBS_Server.8629;Svr;csg.bcmd.bcm.edu;Scheduler was sent the command time
11/02/2012 01:30:39;0040;PBS_Server.8630;Svr;csg.bcmd.bcm.edu;Scheduler was sent the command term
11/02/2012 01:31:56;0002;PBS_Server.1835;Svr;PBS_Server;Torque Server Version = 4.1.2, loglevel = 0
11/02/2012 01:35:43;0008;PBS_Server.1829;Job;291.csg.bcmd.bcm.edu;on_job_exit valid pjob: 291.csg.bcmd.bcm.edu (substate=59)
11/02/2012 01:35:43;0100;PBS_Server.1829;Job;291.csg.bcmd.bcm.edu;dequeuing from high, state COMPLETE
11/02/2012 01:35:48;0040;PBS_Server.8637;Svr;csg.bcmd.bcm.edu;Scheduler was sent the command term
11/02/2012 01:37:05;0002;PBS_Server.1833;Svr;PBS_Server;Torque Server Version = 4.1.2, loglevel = 0
11/02/2012 01:42:10;0002;PBS_Server.1837;Svr;PBS_Server;Torque Server Version = 4.1.2, loglevel = 0
11/02/2012 01:46:02;0040;PBS_Server.8651;Svr;csg.bcmd.bcm.edu;Scheduler was sent the command time
11/02/2012 01:47:15;0002;PBS_Server.1828;Svr;PBS_Server;Torque Server Version = 4.1.2, loglevel = 0
11/02/2012 01:52:20;0002;PBS_Server.1833;Svr;PBS_Server;Torque Server Version = 4.1.2, loglevel = 0
11/02/2012 01:56:12;0040;PBS_Server.8667;Svr;csg.bcmd.bcm.edu;Scheduler was sent the command time
11/02/2012 01:57:25;0002;PBS_Server.1837;Svr;PBS_Server;Torque Server Version = 4.1.2, loglevel = 0
11/02/2012 02:02:30;0002;PBS_Server.1830;Svr;PBS_Server;Torque Server Version = 4.1.2, loglevel = 0
11/02/2012 02:06:22;0040;PBS_Server.8745;Svr;csg.bcmd.bcm.edu;Scheduler was sent the command time
11/02/2012 02:07:35;0002;PBS_Server.1827;Svr;PBS_Server;Torque Server Version = 4.1.2, loglevel = 0
11/02/2012 02:12:40;0002;PBS_Server.1837;Svr;PBS_Server;Torque Server Version = 4.1.2, loglevel = 0
11/02/2012 02:16:32;0040;PBS_Server.8840;Svr;csg.bcmd.bcm.edu;Scheduler was sent the command time
11/02/2012 02:17:45;0002;PBS_Server.1833;Svr;PBS_Server;Torque Server Version = 4.1.2, loglevel = 0
11/02/2012 02:22:50;0002;PBS_Server.1825;Svr;PBS_Server;Torque Server Version = 4.1.2, loglevel = 0
11/02/2012 02:26:42;0040;PBS_Server.8934;Svr;csg.bcmd.bcm.edu;Scheduler was sent the command time
11/02/2012 02:27:55;0002;PBS_Server.1826;Svr;PBS_Server;Torque Server Version = 4.1.2, loglevel = 0
11/02/2012 02:33:00;0002;PBS_Server.1829;Svr;PBS_Server;Torque Server Version = 4.1.2, loglevel = 0
11/02/2012 02:36:52;0040;PBS_Server.9028;Svr;csg.bcmd.bcm.edu;Scheduler was sent the command time
11/02/2012 02:38:05;0002;PBS_Server.1835;Svr;PBS_Server;Torque Server Version = 4.1.2, loglevel = 0
11/02/2012 02:43:10;0002;PBS_Server.1833;Svr;PBS_Server;Torque Server Version = 4.1.2, loglevel = 0
11/02/2012 02:47:02;0040;PBS_Server.9129;Svr;csg.bcmd.bcm.edu;Scheduler was sent the command time
11/02/2012 02:48:15;0002;PBS_Server.1827;Svr;PBS_Server;Torque Server Version = 4.1.2, loglevel = 0
11/02/2012 02:53:20;0002;PBS_Server.1834;Svr;PBS_Server;Torque Server Version = 4.1.2, loglevel = 0
11/02/2012 02:57:12;0040;PBS_Server.9223;Svr;csg.bcmd.bcm.edu;Scheduler was sent the command time
11/02/2012 02:58:25;0002;PBS_Server.1834;Svr;PBS_Server;Torque Server Version = 4.1.2, loglevel = 0
11/02/2012 03:03:30;0002;PBS_Server.1825;Svr;PBS_Server;Torque Server Version = 4.1.2, loglevel = 0
11/02/2012 03:07:22;0040;PBS_Server.9262;Svr;csg.bcmd.bcm.edu;Scheduler was sent the command time
11/02/2012 03:08:35;0002;PBS_Server.1833;Svr;PBS_Server;Torque Server Version = 4.1.2, loglevel = 0
11/02/2012 03:13:40;0002;PBS_Server.1826;Svr;PBS_Server;Torque Server Version = 4.1.2, loglevel = 0
11/02/2012 03:17:32;0040;PBS_Server.9288;Svr;csg.bcmd.bcm.edu;Scheduler was sent the command time
11/02/2012 03:18:45;0002;PBS_Server.1830;Svr;PBS_Server;Torque Server Version = 4.1.2, loglevel = 0
11/02/2012 03:23:50;0002;PBS_Server.1825;Svr;PBS_Server;Torque Server Version = 4.1.2, loglevel = 0
11/02/2012 03:27:42;0040;PBS_Server.9302;Svr;csg.bcmd.bcm.edu;Scheduler was sent the command time
11/02/2012 03:28:55;0002;PBS_Server.1828;Svr;PBS_Server;Torque Server Version = 4.1.2, loglevel = 0
11/02/2012 03:34:00;0002;PBS_Server.1829;Svr;PBS_Server;Torque Server Version = 4.1.2, loglevel = 0
11/02/2012 03:37:52;0040;PBS_Server.9316;Svr;csg.bcmd.bcm.edu;Scheduler was sent the command time
11/02/2012 03:39:05;0002;PBS_Server.1835;Svr;PBS_Server;Torque Server Version = 4.1.2, loglevel = 0
11/02/2012 03:44:10;0002;PBS_Server.1834;Svr;PBS_Server;Torque Server Version = 4.1.2, loglevel = 0
11/02/2012 03:48:02;0040;PBS_Server.9330;Svr;csg.bcmd.bcm.edu;Scheduler was sent the command time
11/02/2012 03:49:15;0002;PBS_Server.1828;Svr;PBS_Server;Torque Server Version = 4.1.2, loglevel = 0
11/02/2012 03:54:20;0002;PBS_Server.1835;Svr;PBS_Server;Torque Server Version = 4.1.2, loglevel = 0
11/02/2012 03:58:12;0040;PBS_Server.9345;Svr;csg.bcmd.bcm.edu;Scheduler was sent the command time
11/02/2012 03:59:25;0002;PBS_Server.1826;Svr;PBS_Server;Torque Server Version = 4.1.2, loglevel = 0
11/02/2012 04:04:30;0002;PBS_Server.1827;Svr;PBS_Server;Torque Server Version = 4.1.2, loglevel = 0
11/02/2012 04:08:22;0040;PBS_Server.9436;Svr;csg.bcmd.bcm.edu;Scheduler was sent the command time
11/02/2012 04:09:35;0002;PBS_Server.1832;Svr;PBS_Server;Torque Server Version = 4.1.2, loglevel = 0
11/02/2012 04:14:40;0002;PBS_Server.1833;Svr;PBS_Server;Torque Server Version = 4.1.2, loglevel = 0
11/02/2012 04:18:32;0040;PBS_Server.9530;Svr;csg.bcmd.bcm.edu;Scheduler was sent the command time
11/02/2012 04:19:45;0002;PBS_Server.1826;Svr;PBS_Server;Torque Server Version = 4.1.2, loglevel = 0
11/02/2012 04:24:50;0002;PBS_Server.1833;Svr;PBS_Server;Torque Server Version = 4.1.2, loglevel = 0
11/02/2012 04:28:42;0040;PBS_Server.9623;Svr;csg.bcmd.bcm.edu;Scheduler was sent the command time
11/02/2012 04:29:55;0002;PBS_Server.1826;Svr;PBS_Server;Torque Server Version = 4.1.2, loglevel = 0
11/02/2012 04:35:00;0002;PBS_Server.1825;Svr;PBS_Server;Torque Server Version = 4.1.2, loglevel = 0
11/02/2012 04:38:52;0040;PBS_Server.9717;Svr;csg.bcmd.bcm.edu;Scheduler was sent the command time
11/02/2012 04:40:05;0002;PBS_Server.1837;Svr;PBS_Server;Torque Server Version = 4.1.2, loglevel = 0
11/02/2012 04:45:10;0002;PBS_Server.1830;Svr;PBS_Server;Torque Server Version = 4.1.2, loglevel = 0
11/02/2012 04:49:02;0040;PBS_Server.9818;Svr;csg.bcmd.bcm.edu;Scheduler was sent the command time
11/02/2012 04:50:15;0002;PBS_Server.1836;Svr;PBS_Server;Torque Server Version = 4.1.2, loglevel = 0
11/02/2012 04:55:20;0002;PBS_Server.1827;Svr;PBS_Server;Torque Server Version = 4.1.2, loglevel = 0
11/02/2012 04:59:12;0040;PBS_Server.9912;Svr;csg.bcmd.bcm.edu;Scheduler was sent the command time
11/02/2012 05:00:25;0002;PBS_Server.1835;Svr;PBS_Server;Torque Server Version = 4.1.2, loglevel = 0
11/02/2012 05:05:30;0002;PBS_Server.1829;Svr;PBS_Server;Torque Server Version = 4.1.2, loglevel = 0
11/02/2012 05:09:22;0040;PBS_Server.9933;Svr;csg.bcmd.bcm.edu;Scheduler was sent the command time
11/02/2012 05:10:35;0002;PBS_Server.1832;Svr;PBS_Server;Torque Server Version = 4.1.2, loglevel = 0
11/02/2012 05:15:40;0002;PBS_Server.1832;Svr;PBS_Server;Torque Server Version = 4.1.2, loglevel = 0
11/02/2012 05:19:32;0040;PBS_Server.9947;Svr;csg.bcmd.bcm.edu;Scheduler was sent the command time
11/02/2012 05:20:45;0002;PBS_Server.1825;Svr;PBS_Server;Torque Server Version = 4.1.2, loglevel = 0
11/02/2012 05:25:50;0002;PBS_Server.1835;Svr;PBS_Server;Torque Server Version = 4.1.2, loglevel = 0
11/02/2012 05:29:42;0040;PBS_Server.10005;Svr;csg.bcmd.bcm.edu;Scheduler was sent the command time
11/02/2012 05:30:55;0002;PBS_Server.1832;Svr;PBS_Server;Torque Server Version = 4.1.2, loglevel = 0
11/02/2012 05:36:00;0002;PBS_Server.1828;Svr;PBS_Server;Torque Server Version = 4.1.2, loglevel = 0
11/02/2012 05:39:52;0040;PBS_Server.10189;Svr;csg.bcmd.bcm.edu;Scheduler was sent the command time
11/02/2012 05:41:05;0002;PBS_Server.1831;Svr;PBS_Server;Torque Server Version = 4.1.2, loglevel = 0
11/02/2012 05:41:58;0100;PBS_Server.1835;Job;293.csg.bcmd.bcm.edu;enqueuing into high, state 1 hop 1
11/02/2012 05:41:58;0008;PBS_Server.1835;Job;293.csg.bcmd.bcm.edu;Job Queued at request of lacuesta@csg.bcmd.bcm.edu, owner = lacuesta@csg.bcmd.bcm.edu, job name = kbjob_AA_Menarche_CMCm4p12, queue = high
11/02/2012 05:42:02;0040;PBS_Server.10215;Svr;csg.bcmd.bcm.edu;Scheduler was sent the command new
11/02/2012 05:42:03;0008;PBS_Server.1837;Job;293.csg.bcmd.bcm.edu;Job Run at request of root@csg.bcmd.bcm.edu
11/02/2012 05:42:03;000d;PBS_Server.1837;Job;293.csg.bcmd.bcm.edu;Not sending email: User does not want mail of this type.
11/02/2012 05:46:08;0002;PBS_Server.1834;Svr;PBS_Server;Torque Server Version = 4.1.2, loglevel = 0
11/02/2012 05:51:08;0002;PBS_Server.1827;Svr;PBS_Server;Torque Server Version = 4.1.2, loglevel = 0
11/02/2012 05:52:14;0040;PBS_Server.10283;Svr;csg.bcmd.bcm.edu;Scheduler was sent the command time
11/02/2012 05:55:58;0008;PBS_Server.1831;Job;290.csg.bcmd.bcm.edu;Job deleted at request of lacuesta@csg.bcmd.bcm.edu
11/02/2012 05:55:58;0008;PBS_Server.1831;Job;290.csg.bcmd.bcm.edu;Job sent signal SIGTERM on delete
11/02/2012 05:55:58;000d;PBS_Server.1825;Job;290.csg.bcmd.bcm.edu;Not sending email: User does not want mail of this type.
11/02/2012 05:55:58;0010;PBS_Server.1825;Job;290.csg.bcmd.bcm.edu;Exit_status=271 resources_used.cput=212:55:16 resources_used.mem=913424kb resources_used.vmem=5342304kb resources_used.walltime=14:54:07
11/02/2012 05:55:58;0008;PBS_Server.1830;Job;290.csg.bcmd.bcm.edu;on_job_exit valid pjob: 290.csg.bcmd.bcm.edu (substate=50)
11/02/2012 05:55:59;0040;PBS_Server.10336;Svr;csg.bcmd.bcm.edu;Scheduler was sent the command term
11/02/2012 05:56:09;0002;PBS_Server.1831;Svr;PBS_Server;Torque Server Version = 4.1.2, loglevel = 0
11/02/2012 06:00:27;0100;PBS_Server.1834;Job;294.csg.bcmd.bcm.edu;enqueuing into high, state 1 hop 1
11/02/2012 06:00:27;0008;PBS_Server.1834;Job;294.csg.bcmd.bcm.edu;Job Queued at request of lacuesta@csg.bcmd.bcm.edu, owner = lacuesta@csg.bcmd.bcm.edu, job name = kbjob_EA_Menarche_CMCm4p12, queue = high
11/02/2012 06:00:29;0040;PBS_Server.10395;Svr;csg.bcmd.bcm.edu;Scheduler was sent the command new
11/02/2012 06:00:31;0008;PBS_Server.1837;Job;294.csg.bcmd.bcm.edu;Job Run at request of root@csg.bcmd.bcm.edu
11/02/2012 06:00:31;000d;PBS_Server.1837;Job;294.csg.bcmd.bcm.edu;Not sending email: User does not want mail of this type.
11/02/2012 06:00:31;000d;PBS_Server.1829;Job;294.csg.bcmd.bcm.edu;Not sending email: User does not want mail of this type.
11/02/2012 06:00:31;0010;PBS_Server.1829;Job;294.csg.bcmd.bcm.edu;Exit_status=2 resources_used.cput=00:00:00 resources_used.mem=0kb resources_used.vmem=0kb resources_used.walltime=00:00:00
11/02/2012 06:00:31;0008;PBS_Server.1836;Job;294.csg.bcmd.bcm.edu;on_job_exit valid pjob: 294.csg.bcmd.bcm.edu (substate=50)
11/02/2012 06:00:34;0040;PBS_Server.10406;Svr;csg.bcmd.bcm.edu;Scheduler was sent the command term
11/02/2012 06:01:05;0008;PBS_Server.1827;Job;290.csg.bcmd.bcm.edu;on_job_exit valid pjob: 290.csg.bcmd.bcm.edu (substate=59)
11/02/2012 06:01:05;0100;PBS_Server.1827;Job;290.csg.bcmd.bcm.edu;dequeuing from high, state COMPLETE
11/02/2012 06:01:10;0040;PBS_Server.10446;Svr;csg.bcmd.bcm.edu;Scheduler was sent the command term
11/02/2012 06:01:20;0002;PBS_Server.1828;Svr;PBS_Server;Torque Server Version = 4.1.2, loglevel = 0
11/02/2012 06:01:45;0100;PBS_Server.1826;Job;295.csg.bcmd.bcm.edu;enqueuing into high, state 1 hop 1
11/02/2012 06:01:45;0008;PBS_Server.1826;Job;295.csg.bcmd.bcm.edu;Job Queued at request of lacuesta@csg.bcmd.bcm.edu, owner = lacuesta@csg.bcmd.bcm.edu, job name = kbjob_EA_Menarche_CMCm4p12, queue = high
11/02/2012 06:01:50;0040;PBS_Server.10463;Svr;csg.bcmd.bcm.edu;Scheduler was sent the command new
11/02/2012 06:01:51;0008;PBS_Server.1837;Job;295.csg.bcmd.bcm.edu;Job Run at request of root@csg.bcmd.bcm.edu
11/02/2012 06:01:51;000d;PBS_Server.1837;Job;295.csg.bcmd.bcm.edu;Not sending email: User does not want mail of this type.
11/02/2012 06:05:35;0008;PBS_Server.1834;Job;294.csg.bcmd.bcm.edu;on_job_exit valid pjob: 294.csg.bcmd.bcm.edu (substate=59)
11/02/2012 06:05:35;0100;PBS_Server.1834;Job;294.csg.bcmd.bcm.edu;dequeuing from high, state COMPLETE
11/02/2012 06:05:40;0040;PBS_Server.10520;Svr;csg.bcmd.bcm.edu;Scheduler was sent the command term
11/02/2012 06:06:20;0002;PBS_Server.1832;Svr;PBS_Server;Torque Server Version = 4.1.2, loglevel = 0
11/02/2012 06:11:31;0002;PBS_Server.1828;Svr;PBS_Server;Torque Server Version = 4.1.2, loglevel = 0
11/02/2012 06:15:51;0040;PBS_Server.10622;Svr;csg.bcmd.bcm.edu;Scheduler was sent the command time
11/02/2012 06:16:31;0002;PBS_Server.1829;Svr;PBS_Server;Torque Server Version = 4.1.2, loglevel = 0
11/02/2012 06:21:33;0002;PBS_Server.1826;Svr;PBS_Server;Torque Server Version = 4.1.2, loglevel = 0
11/02/2012 06:26:06;0040;PBS_Server.10753;Svr;csg.bcmd.bcm.edu;Scheduler was sent the command time
11/02/2012 06:26:38;0002;PBS_Server.1827;Svr;PBS_Server;Torque Server Version = 4.1.2, loglevel = 0
11/02/2012 06:31:47;0002;PBS_Server.1834;Svr;PBS_Server;Torque Server Version = 4.1.2, loglevel = 0
11/02/2012 06:36:16;0040;PBS_Server.10858;Svr;csg.bcmd.bcm.edu;Scheduler was sent the command time
11/02/2012 06:36:48;0002;PBS_Server.1827;Svr;PBS_Server;Torque Server Version = 4.1.2, loglevel = 0
11/02/2012 06:41:57;0002;PBS_Server.1828;Svr;PBS_Server;Torque Server Version = 4.1.2, loglevel = 0
11/02/2012 06:46:26;0040;PBS_Server.10962;Svr;csg.bcmd.bcm.edu;Scheduler was sent the command time
11/02/2012 06:46:58;0002;PBS_Server.1834;Svr;PBS_Server;Torque Server Version = 4.1.2, loglevel = 0
11/02/2012 06:52:07;0002;PBS_Server.1836;Svr;PBS_Server;Torque Server Version = 4.1.2, loglevel = 0
11/02/2012 06:56:36;0040;PBS_Server.11056;Svr;csg.bcmd.bcm.edu;Scheduler was sent the command time
11/02/2012 06:57:08;0002;PBS_Server.1832;Svr;PBS_Server;Torque Server Version = 4.1.2, loglevel = 0
11/02/2012 07:02:17;0002;PBS_Server.1828;Svr;PBS_Server;Torque Server Version = 4.1.2, loglevel = 0
11/02/2012 07:06:46;0040;PBS_Server.11102;Svr;csg.bcmd.bcm.edu;Scheduler was sent the command time
11/02/2012 07:07:18;0002;PBS_Server.1832;Svr;PBS_Server;Torque Server Version = 4.1.2, loglevel = 0
11/02/2012 07:12:27;0002;PBS_Server.1830;Svr;PBS_Server;Torque Server Version = 4.1.2, loglevel = 0
11/02/2012 07:16:56;0040;PBS_Server.11119;Svr;csg.bcmd.bcm.edu;Scheduler was sent the command time
11/02/2012 07:17:05;000d;PBS_Server.1829;Job;256.csg.bcmd.bcm.edu;Not sending email: User does not want mail of this type.
11/02/2012 07:17:05;0010;PBS_Server.1829;Job;256.csg.bcmd.bcm.edu;Exit_status=0 resources_used.cput=50:20:13 resources_used.mem=967840kb resources_used.vmem=4917132kb resources_used.walltime=45:03:35
11/02/2012 07:17:05;0008;PBS_Server.1828;Job;256.csg.bcmd.bcm.edu;on_job_exit valid pjob: 256.csg.bcmd.bcm.edu (substate=50)
11/02/2012 07:17:07;0040;PBS_Server.11128;Svr;csg.bcmd.bcm.edu;Scheduler was sent the command term
11/02/2012 07:17:28;0002;PBS_Server.1831;Svr;PBS_Server;Torque Server Version = 4.1.2, loglevel = 0
11/02/2012 07:22:07;0008;PBS_Server.1834;Job;256.csg.bcmd.bcm.edu;on_job_exit valid pjob: 256.csg.bcmd.bcm.edu (substate=59)
11/02/2012 07:22:07;0100;PBS_Server.1834;Job;256.csg.bcmd.bcm.edu;dequeuing from high, state COMPLETE
11/02/2012 07:22:12;0040;PBS_Server.11137;Svr;csg.bcmd.bcm.edu;Scheduler was sent the command term
11/02/2012 07:22:33;0002;PBS_Server.1828;Svr;PBS_Server;Torque Server Version = 4.1.2, loglevel = 0
11/02/2012 07:27:38;0002;PBS_Server.1834;Svr;PBS_Server;Torque Server Version = 4.1.2, loglevel = 0
11/02/2012 07:32:22;0040;PBS_Server.11151;Svr;csg.bcmd.bcm.edu;Scheduler was sent the command time
11/02/2012 07:32:43;0002;PBS_Server.1828;Svr;PBS_Server;Torque Server Version = 4.1.2, loglevel = 0
11/02/2012 07:37:48;0002;PBS_Server.1837;Svr;PBS_Server;Torque Server Version = 4.1.2, loglevel = 0
11/02/2012 07:42:32;0040;PBS_Server.11165;Svr;csg.bcmd.bcm.edu;Scheduler was sent the command time
11/02/2012 07:42:53;0002;PBS_Server.1836;Svr;PBS_Server;Torque Server Version = 4.1.2, loglevel = 0
11/02/2012 07:47:58;0002;PBS_Server.1836;Svr;PBS_Server;Torque Server Version = 4.1.2, loglevel = 0
11/02/2012 07:52:42;0040;PBS_Server.11179;Svr;csg.bcmd.bcm.edu;Scheduler was sent the command time
11/02/2012 07:53:03;0002;PBS_Server.1830;Svr;PBS_Server;Torque Server Version = 4.1.2, loglevel = 0
11/02/2012 07:58:08;0002;PBS_Server.1832;Svr;PBS_Server;Torque Server Version = 4.1.2, loglevel = 0
11/02/2012 08:02:52;0040;PBS_Server.11222;Svr;csg.bcmd.bcm.edu;Scheduler was sent the command time
11/02/2012 08:03:13;0002;PBS_Server.1833;Svr;PBS_Server;Torque Server Version = 4.1.2, loglevel = 0
11/02/2012 08:08:18;0002;PBS_Server.1832;Svr;PBS_Server;Torque Server Version = 4.1.2, loglevel = 0
11/02/2012 08:13:02;0040;PBS_Server.11323;Svr;csg.bcmd.bcm.edu;Scheduler was sent the command time
11/02/2012 08:13:23;0002;PBS_Server.1831;Svr;PBS_Server;Torque Server Version = 4.1.2, loglevel = 0
11/02/2012 08:16:22;000d;PBS_Server.1834;Job;295.csg.bcmd.bcm.edu;Not sending email: User does not want mail of this type.
11/02/2012 08:16:22;0010;PBS_Server.1834;Job;295.csg.bcmd.bcm.edu;Exit_status=0 resources_used.cput=08:57:19 resources_used.mem=956780kb resources_used.vmem=5384256kb resources_used.walltime=02:14:31
11/02/2012 08:16:22;0008;PBS_Server.1827;Job;295.csg.bcmd.bcm.edu;on_job_exit valid pjob: 295.csg.bcmd.bcm.edu (substate=50)
11/02/2012 08:16:24;0040;PBS_Server.11362;Svr;csg.bcmd.bcm.edu;Scheduler was sent the command term
11/02/2012 08:18:28;0002;PBS_Server.1831;Svr;PBS_Server;Torque Server Version = 4.1.2, loglevel = 0
11/02/2012 08:21:34;0008;PBS_Server.1826;Job;295.csg.bcmd.bcm.edu;on_job_exit valid pjob: 295.csg.bcmd.bcm.edu (substate=59)
11/02/2012 08:21:34;0100;PBS_Server.1826;Job;295.csg.bcmd.bcm.edu;dequeuing from high, state COMPLETE
11/02/2012 08:21:35;0040;PBS_Server.11413;Svr;csg.bcmd.bcm.edu;Scheduler was sent the command term
11/02/2012 08:23:34;0002;PBS_Server.1828;Svr;PBS_Server;Torque Server Version = 4.1.2, loglevel = 0
11/02/2012 08:28:39;0002;PBS_Server.1835;Svr;PBS_Server;Torque Server Version = 4.1.2, loglevel = 0
11/02/2012 08:31:50;0040;PBS_Server.11506;Svr;csg.bcmd.bcm.edu;Scheduler was sent the command time
11/02/2012 08:33:44;0002;PBS_Server.1832;Svr;PBS_Server;Torque Server Version = 4.1.2, loglevel = 0
11/02/2012 08:38:49;0002;PBS_Server.1826;Svr;PBS_Server;Torque Server Version = 4.1.2, loglevel = 0
11/02/2012 08:42:00;0040;PBS_Server.11610;Svr;csg.bcmd.bcm.edu;Scheduler was sent the command time
11/02/2012 08:43:54;0002;PBS_Server.1834;Svr;PBS_Server;Torque Server Version = 4.1.2, loglevel = 0
11/02/2012 08:48:59;0002;PBS_Server.1836;Svr;PBS_Server;Torque Server Version = 4.1.2, loglevel = 0
11/02/2012 08:52:10;0040;PBS_Server.11805;Svr;csg.bcmd.bcm.edu;Scheduler was sent the command time
11/02/2012 08:54:04;0002;PBS_Server.1826;Svr;PBS_Server;Torque Server Version = 4.1.2, loglevel = 0
11/02/2012 08:59:09;0002;PBS_Server.1833;Svr;PBS_Server;Torque Server Version = 4.1.2, loglevel = 0
11/02/2012 09:02:20;0040;PBS_Server.11910;Svr;csg.bcmd.bcm.edu;Scheduler was sent the command time
11/02/2012 09:04:14;0002;PBS_Server.1834;Svr;PBS_Server;Torque Server Version = 4.1.2, loglevel = 0
11/02/2012 09:09:19;0002;PBS_Server.1825;Svr;PBS_Server;Torque Server Version = 4.1.2, loglevel = 0
11/02/2012 09:12:28;0100;PBS_Server.1828;Job;296.csg.bcmd.bcm.edu;enqueuing into high, state 1 hop 1
11/02/2012 09:12:28;0008;PBS_Server.1828;Job;296.csg.bcmd.bcm.edu;Job Queued at request of lacuesta@csg.bcmd.bcm.edu, owner = lacuesta@csg.bcmd.bcm.edu, job name = EA_WHR_FEMALE_VT_01Sep2012, queue = high
11/02/2012 09:12:30;0040;PBS_Server.12096;Svr;csg.bcmd.bcm.edu;Scheduler was sent the command new
11/02/2012 09:12:31;0008;PBS_Server.1831;Job;296.csg.bcmd.bcm.edu;Job Run at request of root@csg.bcmd.bcm.edu
11/02/2012 09:12:31;000d;PBS_Server.1831;Job;296.csg.bcmd.bcm.edu;Not sending email: User does not want mail of this type.
11/02/2012 09:14:21;0002;PBS_Server.1829;Svr;PBS_Server;Torque Server Version = 4.1.2, loglevel = 0
11/02/2012 09:19:21;0002;PBS_Server.1829;Svr;PBS_Server;Torque Server Version = 4.1.2, loglevel = 0
11/02/2012 09:22:42;0040;PBS_Server.12290;Svr;csg.bcmd.bcm.edu;Scheduler was sent the command time
11/02/2012 09:24:13;0100;PBS_Server.1825;Job;297.csg.bcmd.bcm.edu;enqueuing into batch, state 1 hop 1
11/02/2012 09:24:13;0008;PBS_Server.1825;Job;297.csg.bcmd.bcm.edu;Job Queued at request of lacuesta@csg.bcmd.bcm.edu, owner = lacuesta@csg.bcmd.bcm.edu, job name = jobname1, queue = batch
11/02/2012 09:24:13;0100;PBS_Server.1837;Job;298.csg.bcmd.bcm.edu;enqueuing into batch, state 1 hop 1
11/02/2012 09:24:13;0008;PBS_Server.1837;Job;298.csg.bcmd.bcm.edu;Job Queued at request of lacuesta@csg.bcmd.bcm.edu, owner = lacuesta@csg.bcmd.bcm.edu, job name = jobname2, queue = batch
11/02/2012 09:24:16;0008;PBS_Server.1831;Job;297.csg.bcmd.bcm.edu;Job Run at request of root@csg.bcmd.bcm.edu
11/02/2012 09:24:16;000d;PBS_Server.1831;Job;297.csg.bcmd.bcm.edu;Not sending email: User does not want mail of this type.
11/02/2012 09:24:16;0008;PBS_Server.1831;Job;298.csg.bcmd.bcm.edu;Job Run at request of root@csg.bcmd.bcm.edu
11/02/2012 09:24:16;000d;PBS_Server.1831;Job;298.csg.bcmd.bcm.edu;Not sending email: User does not want mail of this type.
11/02/2012 09:24:16;000d;PBS_Server.1836;Job;297.csg.bcmd.bcm.edu;Not sending email: User does not want mail of this type.
11/02/2012 09:24:16;0010;PBS_Server.1836;Job;297.csg.bcmd.bcm.edu;Exit_status=1 resources_used.cput=00:00:00 resources_used.mem=0kb resources_used.vmem=0kb resources_used.walltime=00:00:00
11/02/2012 09:24:16;0008;PBS_Server.1829;Job;297.csg.bcmd.bcm.edu;on_job_exit valid pjob: 297.csg.bcmd.bcm.edu (substate=50)
11/02/2012 09:24:16;000d;PBS_Server.1830;Job;298.csg.bcmd.bcm.edu;Not sending email: User does not want mail of this type.
11/02/2012 09:24:16;0010;PBS_Server.1830;Job;298.csg.bcmd.bcm.edu;Exit_status=1 resources_used.cput=00:00:00 resources_used.mem=0kb resources_used.vmem=0kb resources_used.walltime=00:00:00
11/02/2012 09:24:16;0008;PBS_Server.1832;Job;298.csg.bcmd.bcm.edu;on_job_exit valid pjob: 298.csg.bcmd.bcm.edu (substate=50)
11/02/2012 09:24:17;0040;PBS_Server.12320;Svr;csg.bcmd.bcm.edu;Scheduler was sent the command term
11/02/2012 09:24:20;0100;PBS_Server.1825;Job;299.csg.bcmd.bcm.edu;enqueuing into batch, state 1 hop 1
11/02/2012 09:24:20;0008;PBS_Server.1825;Job;299.csg.bcmd.bcm.edu;Job Queued at request of lacuesta@csg.bcmd.bcm.edu, owner = lacuesta@csg.bcmd.bcm.edu, job name = jobname1, queue = batch
11/02/2012 09:24:21;0100;PBS_Server.1837;Job;300.csg.bcmd.bcm.edu;enqueuing into batch, state 1 hop 1
11/02/2012 09:24:21;0008;PBS_Server.1837;Job;300.csg.bcmd.bcm.edu;Job Queued at request of lacuesta@csg.bcmd.bcm.edu, owner = lacuesta@csg.bcmd.bcm.edu, job name = jobname2, queue = batch
11/02/2012 09:24:22;0002;PBS_Server.1827;Svr;PBS_Server;Torque Server Version = 4.1.2, loglevel = 0
11/02/2012 09:24:22;0040;PBS_Server.12330;Svr;csg.bcmd.bcm.edu;Scheduler was sent the command new
11/02/2012 09:24:23;0008;PBS_Server.1831;Job;299.csg.bcmd.bcm.edu;Job Run at request of root@csg.bcmd.bcm.edu
11/02/2012 09:24:23;000d;PBS_Server.1831;Job;299.csg.bcmd.bcm.edu;Not sending email: User does not want mail of this type.
11/02/2012 09:24:23;0008;PBS_Server.1831;Job;300.csg.bcmd.bcm.edu;Job Run at request of root@csg.bcmd.bcm.edu
11/02/2012 09:24:23;000d;PBS_Server.1831;Job;300.csg.bcmd.bcm.edu;Not sending email: User does not want mail of this type.
11/02/2012 09:24:23;000d;PBS_Server.1833;Job;299.csg.bcmd.bcm.edu;Not sending email: User does not want mail of this type.
11/02/2012 09:24:23;0010;PBS_Server.1833;Job;299.csg.bcmd.bcm.edu;Exit_status=1 resources_used.cput=00:00:00 resources_used.mem=0kb resources_used.vmem=0kb resources_used.walltime=00:00:00
11/02/2012 09:24:23;0008;PBS_Server.1828;Job;299.csg.bcmd.bcm.edu;on_job_exit valid pjob: 299.csg.bcmd.bcm.edu (substate=50)
11/02/2012 09:24:23;000d;PBS_Server.1825;Job;300.csg.bcmd.bcm.edu;Not sending email: User does not want mail of this type.
11/02/2012 09:24:23;0010;PBS_Server.1825;Job;300.csg.bcmd.bcm.edu;Exit_status=1 resources_used.cput=00:00:00 resources_used.mem=0kb resources_used.vmem=0kb resources_used.walltime=00:00:00
11/02/2012 09:24:23;0008;PBS_Server.1834;Job;300.csg.bcmd.bcm.edu;on_job_exit valid pjob: 300.csg.bcmd.bcm.edu (substate=50)
11/02/2012 09:24:27;0040;PBS_Server.12347;Svr;csg.bcmd.bcm.edu;Scheduler was sent the command term
11/02/2012 09:29:22;0008;PBS_Server.1830;Job;298.csg.bcmd.bcm.edu;on_job_exit valid pjob: 298.csg.bcmd.bcm.edu (substate=59)
11/02/2012 09:29:22;0002;PBS_Server.1835;Svr;PBS_Server;Torque Server Version = 4.1.2, loglevel = 0
11/02/2012 09:29:22;0008;PBS_Server.1837;Job;297.csg.bcmd.bcm.edu;on_job_exit valid pjob: 297.csg.bcmd.bcm.edu (substate=59)
11/02/2012 09:29:22;0100;PBS_Server.1830;Job;298.csg.bcmd.bcm.edu;dequeuing from batch, state COMPLETE
11/02/2012 09:29:22;0100;PBS_Server.1837;Job;297.csg.bcmd.bcm.edu;dequeuing from batch, state COMPLETE
11/02/2012 09:29:27;0040;PBS_Server.12376;Svr;csg.bcmd.bcm.edu;Scheduler was sent the command term
11/02/2012 09:29:37;0008;PBS_Server.1825;Job;299.csg.bcmd.bcm.edu;on_job_exit valid pjob: 299.csg.bcmd.bcm.edu (substate=59)
11/02/2012 09:29:37;0008;PBS_Server.1833;Job;300.csg.bcmd.bcm.edu;on_job_exit valid pjob: 300.csg.bcmd.bcm.edu (substate=59)
11/02/2012 09:29:37;0100;PBS_Server.1825;Job;299.csg.bcmd.bcm.edu;dequeuing from batch, state COMPLETE
11/02/2012 09:29:37;0100;PBS_Server.1833;Job;300.csg.bcmd.bcm.edu;dequeuing from batch, state COMPLETE
11/02/2012 09:29:42;0040;PBS_Server.12382;Svr;csg.bcmd.bcm.edu;Scheduler was sent the command term
11/02/2012 09:30:35;0100;PBS_Server.1829;Job;301.csg.bcmd.bcm.edu;enqueuing into batch, state 1 hop 1
11/02/2012 09:30:35;0008;PBS_Server.1829;Job;301.csg.bcmd.bcm.edu;Job Queued at request of lacuesta@csg.bcmd.bcm.edu, owner = lacuesta@csg.bcmd.bcm.edu, job name = jobname1, queue = batch
11/02/2012 09:30:35;0100;PBS_Server.1833;Job;302.csg.bcmd.bcm.edu;enqueuing into batch, state 1 hop 1
11/02/2012 09:30:35;0008;PBS_Server.1833;Job;302.csg.bcmd.bcm.edu;Job Queued at request of lacuesta@csg.bcmd.bcm.edu, owner = lacuesta@csg.bcmd.bcm.edu, job name = jobname2, queue = batch
11/02/2012 09:30:37;0040;PBS_Server.12407;Svr;csg.bcmd.bcm.edu;Scheduler was sent the command new
11/02/2012 09:30:39;0008;PBS_Server.1831;Job;301.csg.bcmd.bcm.edu;Job Run at request of root@csg.bcmd.bcm.edu
11/02/2012 09:30:39;000d;PBS_Server.1831;Job;301.csg.bcmd.bcm.edu;Not sending email: User does not want mail of this type.
11/02/2012 09:30:39;0008;PBS_Server.1831;Job;302.csg.bcmd.bcm.edu;Job Run at request of root@csg.bcmd.bcm.edu
11/02/2012 09:30:39;000d;PBS_Server.1831;Job;302.csg.bcmd.bcm.edu;Not sending email: User does not want mail of this type.
11/02/2012 09:30:42;0100;PBS_Server.1828;Job;303.csg.bcmd.bcm.edu;enqueuing into batch, state 1 hop 1
11/02/2012 09:30:42;0008;PBS_Server.1828;Job;303.csg.bcmd.bcm.edu;Job Queued at request of lacuesta@csg.bcmd.bcm.edu, owner = lacuesta@csg.bcmd.bcm.edu, job name = jobname1, queue = batch
11/02/2012 09:30:42;0100;PBS_Server.1832;Job;304.csg.bcmd.bcm.edu;enqueuing into batch, state 1 hop 1
11/02/2012 09:30:42;0008;PBS_Server.1832;Job;304.csg.bcmd.bcm.edu;Job Queued at request of lacuesta@csg.bcmd.bcm.edu, owner = lacuesta@csg.bcmd.bcm.edu, job name = jobname2, queue = batch
11/02/2012 09:30:42;0040;PBS_Server.12417;Svr;csg.bcmd.bcm.edu;Scheduler was sent the command new
11/02/2012 09:30:44;0008;PBS_Server.1831;Job;303.csg.bcmd.bcm.edu;Job Run at request of root@csg.bcmd.bcm.edu
11/02/2012 09:30:44;000d;PBS_Server.1831;Job;303.csg.bcmd.bcm.edu;Not sending email: User does not want mail of this type.
11/02/2012 09:30:44;0008;PBS_Server.1831;Job;304.csg.bcmd.bcm.edu;Job Run at request of root@csg.bcmd.bcm.edu
11/02/2012 09:30:44;000d;PBS_Server.1831;Job;304.csg.bcmd.bcm.edu;Not sending email: User does not want mail of this type.
11/02/2012 09:30:49;000d;PBS_Server.1825;Job;303.csg.bcmd.bcm.edu;Not sending email: User does not want mail of this type.
11/02/2012 09:30:49;0010;PBS_Server.1825;Job;303.csg.bcmd.bcm.edu;Exit_status=1 resources_used.cput=00:00:00 resources_used.mem=0kb resources_used.vmem=0kb resources_used.walltime=00:00:05
11/02/2012 09:30:49;0008;PBS_Server.1829;Job;303.csg.bcmd.bcm.edu;on_job_exit valid pjob: 303.csg.bcmd.bcm.edu (substate=50)
11/02/2012 09:30:50;000d;PBS_Server.1834;Job;304.csg.bcmd.bcm.edu;Not sending email: User does not want mail of this type.
11/02/2012 09:30:50;0010;PBS_Server.1834;Job;304.csg.bcmd.bcm.edu;Exit_status=1 resources_used.cput=00:00:00 resources_used.mem=6768kb resources_used.vmem=52668kb resources_used.walltime=00:00:06
11/02/2012 09:30:50;0008;PBS_Server.1827;Job;304.csg.bcmd.bcm.edu;on_job_exit valid pjob: 304.csg.bcmd.bcm.edu (substate=50)
11/02/2012 09:30:50;0100;PBS_Server.1830;Job;305.csg.bcmd.bcm.edu;enqueuing into batch, state 1 hop 1
11/02/2012 09:30:50;0008;PBS_Server.1830;Job;305.csg.bcmd.bcm.edu;Job Queued at request of lacuesta@csg.bcmd.bcm.edu, owner = lacuesta@csg.bcmd.bcm.edu, job name = jobname1, queue = batch
11/02/2012 09:30:51;000d;PBS_Server.1837;Job;301.csg.bcmd.bcm.edu;Not sending email: User does not want mail of this type.
11/02/2012 09:30:51;0010;PBS_Server.1837;Job;301.csg.bcmd.bcm.edu;Exit_status=1 resources_used.cput=00:00:00 resources_used.mem=1132kb resources_used.vmem=13560kb resources_used.walltime=00:00:11
11/02/2012 09:30:51;0008;PBS_Server.1825;Job;301.csg.bcmd.bcm.edu;on_job_exit valid pjob: 301.csg.bcmd.bcm.edu (substate=50)
11/02/2012 09:30:51;000d;PBS_Server.1826;Job;302.csg.bcmd.bcm.edu;Not sending email: User does not want mail of this type.
11/02/2012 09:30:51;0010;PBS_Server.1826;Job;302.csg.bcmd.bcm.edu;Exit_status=1 resources_used.cput=00:00:00 resources_used.mem=1132kb resources_used.vmem=13560kb resources_used.walltime=00:00:12
11/02/2012 09:30:51;0008;PBS_Server.1829;Job;302.csg.bcmd.bcm.edu;on_job_exit valid pjob: 302.csg.bcmd.bcm.edu (substate=50)
11/02/2012 09:30:51;0100;PBS_Server.1833;Job;306.csg.bcmd.bcm.edu;enqueuing into batch, state 1 hop 1
11/02/2012 09:30:51;0008;PBS_Server.1833;Job;306.csg.bcmd.bcm.edu;Job Queued at request of lacuesta@csg.bcmd.bcm.edu, owner = lacuesta@csg.bcmd.bcm.edu, job name = jobname2, queue = batch
11/02/2012 09:30:53;0040;PBS_Server.12459;Svr;csg.bcmd.bcm.edu;Scheduler was sent the command term
11/02/2012 09:30:54;0008;PBS_Server.1831;Job;305.csg.bcmd.bcm.edu;Job Run at request of root@csg.bcmd.bcm.edu
11/02/2012 09:30:54;000d;PBS_Server.1831;Job;305.csg.bcmd.bcm.edu;Not sending email: User does not want mail of this type.
11/02/2012 09:30:54;0008;PBS_Server.1831;Job;306.csg.bcmd.bcm.edu;Job Run at request of root@csg.bcmd.bcm.edu
11/02/2012 09:30:54;000d;PBS_Server.1831;Job;306.csg.bcmd.bcm.edu;Not sending email: User does not want mail of this type.
11/02/2012 09:30:54;000d;PBS_Server.1826;Job;305.csg.bcmd.bcm.edu;Not sending email: User does not want mail of this type.
11/02/2012 09:30:54;0010;PBS_Server.1826;Job;305.csg.bcmd.bcm.edu;Exit_status=1 resources_used.cput=00:00:00 resources_used.mem=0kb resources_used.vmem=0kb resources_used.walltime=00:00:00
11/02/2012 09:30:54;0008;PBS_Server.1834;Job;305.csg.bcmd.bcm.edu;on_job_exit valid pjob: 305.csg.bcmd.bcm.edu (substate=50)
11/02/2012 09:30:54;000d;PBS_Server.1833;Job;306.csg.bcmd.bcm.edu;Not sending email: User does not want mail of this type.
11/02/2012 09:30:54;0010;PBS_Server.1833;Job;306.csg.bcmd.bcm.edu;Exit_status=1 resources_used.cput=00:00:00 resources_used.mem=0kb resources_used.vmem=0kb resources_used.walltime=00:00:00
11/02/2012 09:30:54;0008;PBS_Server.1828;Job;306.csg.bcmd.bcm.edu;on_job_exit valid pjob: 306.csg.bcmd.bcm.edu (substate=50)
11/02/2012 09:30:58;0040;PBS_Server.12477;Svr;csg.bcmd.bcm.edu;Scheduler was sent the command term
11/02/2012 09:32:35;0100;PBS_Server.1833;Job;307.csg.bcmd.bcm.edu;enqueuing into batch, state 1 hop 1
11/02/2012 09:32:35;0008;PBS_Server.1833;Job;307.csg.bcmd.bcm.edu;Job Queued at request of lacuesta@csg.bcmd.bcm.edu, owner = lacuesta@csg.bcmd.bcm.edu, job name = jobname1, queue = batch
11/02/2012 09:32:36;0100;PBS_Server.1828;Job;308.csg.bcmd.bcm.edu;enqueuing into batch, state 1 hop 1
11/02/2012 09:32:36;0008;PBS_Server.1828;Job;308.csg.bcmd.bcm.edu;Job Queued at request of lacuesta@csg.bcmd.bcm.edu, owner = lacuesta@csg.bcmd.bcm.edu, job name = jobname2, queue = batch
11/02/2012 09:32:38;0040;PBS_Server.12521;Svr;csg.bcmd.bcm.edu;Scheduler was sent the command new
11/02/2012 09:32:39;0008;PBS_Server.1831;Job;307.csg.bcmd.bcm.edu;Job Run at request of root@csg.bcmd.bcm.edu
11/02/2012 09:32:39;000d;PBS_Server.1831;Job;307.csg.bcmd.bcm.edu;Not sending email: User does not want mail of this type.
11/02/2012 09:32:39;0008;PBS_Server.1831;Job;308.csg.bcmd.bcm.edu;Job Run at request of root@csg.bcmd.bcm.edu
11/02/2012 09:32:39;000d;PBS_Server.1831;Job;308.csg.bcmd.bcm.edu;Not sending email: User does not want mail of this type.
11/02/2012 09:32:42;0100;PBS_Server.1837;Job;309.csg.bcmd.bcm.edu;enqueuing into batch, state 1 hop 1
11/02/2012 09:32:42;0008;PBS_Server.1837;Job;309.csg.bcmd.bcm.edu;Job Queued at request of lacuesta@csg.bcmd.bcm.edu, owner = lacuesta@csg.bcmd.bcm.edu, job name = jobname1, queue = batch
11/02/2012 09:32:42;0100;PBS_Server.1825;Job;310.csg.bcmd.bcm.edu;enqueuing into batch, state 1 hop 1
11/02/2012 09:32:42;0008;PBS_Server.1825;Job;310.csg.bcmd.bcm.edu;Job Queued at request of lacuesta@csg.bcmd.bcm.edu, owner = lacuesta@csg.bcmd.bcm.edu, job name = jobname2, queue = batch
11/02/2012 09:32:43;0040;PBS_Server.12531;Svr;csg.bcmd.bcm.edu;Scheduler was sent the command new
11/02/2012 09:32:44;0008;PBS_Server.1831;Job;309.csg.bcmd.bcm.edu;Job Run at request of root@csg.bcmd.bcm.edu
11/02/2012 09:32:44;000d;PBS_Server.1831;Job;309.csg.bcmd.bcm.edu;Not sending email: User does not want mail of this type.
11/02/2012 09:32:44;0008;PBS_Server.1831;Job;310.csg.bcmd.bcm.edu;Job Run at request of root@csg.bcmd.bcm.edu
11/02/2012 09:32:44;000d;PBS_Server.1831;Job;310.csg.bcmd.bcm.edu;Not sending email: User does not want mail of this type.
11/02/2012 09:33:01;0100;PBS_Server.1829;Job;311.csg.bcmd.bcm.edu;enqueuing into batch, state 1 hop 1
11/02/2012 09:33:01;0008;PBS_Server.1829;Job;311.csg.bcmd.bcm.edu;Job Queued at request of lacuesta@csg.bcmd.bcm.edu, owner = lacuesta@csg.bcmd.bcm.edu, job name = jobname1, queue = batch
11/02/2012 09:33:02;0100;PBS_Server.1836;Job;312.csg.bcmd.bcm.edu;enqueuing into batch, state 1 hop 1
11/02/2012 09:33:02;0008;PBS_Server.1836;Job;312.csg.bcmd.bcm.edu;Job Queued at request of lacuesta@csg.bcmd.bcm.edu, owner = lacuesta@csg.bcmd.bcm.edu, job name = jobname2, queue = batch
11/02/2012 09:33:03;0040;PBS_Server.12541;Svr;csg.bcmd.bcm.edu;Scheduler was sent the command new
11/02/2012 09:33:04;0008;PBS_Server.1831;Job;311.csg.bcmd.bcm.edu;Job Run at request of root@csg.bcmd.bcm.edu
11/02/2012 09:33:04;000d;PBS_Server.1831;Job;311.csg.bcmd.bcm.edu;Not sending email: User does not want mail of this type.
11/02/2012 09:33:04;0008;PBS_Server.1831;Job;312.csg.bcmd.bcm.edu;Job Run at request of root@csg.bcmd.bcm.edu
11/02/2012 09:33:04;000d;PBS_Server.1831;Job;312.csg.bcmd.bcm.edu;Not sending email: User does not want mail of this type.
11/02/2012 09:33:35;000d;PBS_Server.1833;Job;307.csg.bcmd.bcm.edu;Not sending email: User does not want mail of this type.
11/02/2012 09:33:35;0010;PBS_Server.1833;Job;307.csg.bcmd.bcm.edu;Exit_status=1 resources_used.cput=00:00:54 resources_used.mem=201120kb resources_used.vmem=320960kb resources_used.walltime=00:00:56
11/02/2012 09:33:35;0008;PBS_Server.1828;Job;307.csg.bcmd.bcm.edu;on_job_exit valid pjob: 307.csg.bcmd.bcm.edu (substate=50)
11/02/2012 09:33:38;0040;PBS_Server.12568;Svr;csg.bcmd.bcm.edu;Scheduler was sent the command term
11/02/2012 09:34:10;000d;PBS_Server.1833;Job;309.csg.bcmd.bcm.edu;Not sending email: User does not want mail of this type.
11/02/2012 09:34:10;0010;PBS_Server.1833;Job;309.csg.bcmd.bcm.edu;Exit_status=0 resources_used.cput=00:01:25 resources_used.mem=319532kb resources_used.vmem=450016kb resources_used.walltime=00:01:26
11/02/2012 09:34:10;0008;PBS_Server.1829;Job;309.csg.bcmd.bcm.edu;on_job_exit valid pjob: 309.csg.bcmd.bcm.edu (substate=50)
11/02/2012 09:34:13;0040;PBS_Server.12584;Svr;csg.bcmd.bcm.edu;Scheduler was sent the command term
11/02/2012 09:34:21;0100;PBS_Server.1834;Job;313.csg.bcmd.bcm.edu;enqueuing into batch, state 1 hop 1
11/02/2012 09:34:21;0008;PBS_Server.1834;Job;313.csg.bcmd.bcm.edu;Job Queued at request of lacuesta@csg.bcmd.bcm.edu, owner = lacuesta@csg.bcmd.bcm.edu, job name = jobname1, queue = batch
11/02/2012 09:34:22;0100;PBS_Server.1836;Job;314.csg.bcmd.bcm.edu;enqueuing into batch, state 1 hop 1
11/02/2012 09:34:22;0008;PBS_Server.1836;Job;314.csg.bcmd.bcm.edu;Job Queued at request of lacuesta@csg.bcmd.bcm.edu, owner = lacuesta@csg.bcmd.bcm.edu, job name = jobname2, queue = batch
11/02/2012 09:34:23;0002;PBS_Server.1825;Svr;PBS_Server;Torque Server Version = 4.1.2, loglevel = 0
11/02/2012 09:34:23;0040;PBS_Server.12594;Svr;csg.bcmd.bcm.edu;Scheduler was sent the command new
11/02/2012 09:34:24;0008;PBS_Server.1831;Job;313.csg.bcmd.bcm.edu;Job Run at request of root@csg.bcmd.bcm.edu
11/02/2012 09:34:24;000d;PBS_Server.1831;Job;313.csg.bcmd.bcm.edu;Not sending email: User does not want mail of this type.
11/02/2012 09:34:24;0008;PBS_Server.1831;Job;314.csg.bcmd.bcm.edu;Job Run at request of root@csg.bcmd.bcm.edu
11/02/2012 09:34:24;000d;PBS_Server.1831;Job;314.csg.bcmd.bcm.edu;Not sending email: User does not want mail of this type.
11/02/2012 09:34:25;0100;PBS_Server.1835;Job;315.csg.bcmd.bcm.edu;enqueuing into batch, state 1 hop 1
11/02/2012 09:34:25;0008;PBS_Server.1835;Job;315.csg.bcmd.bcm.edu;Job Queued at request of lacuesta@csg.bcmd.bcm.edu, owner = lacuesta@csg.bcmd.bcm.edu, job name = jobname1, queue = batch
11/02/2012 09:34:25;0100;PBS_Server.1830;Job;316.csg.bcmd.bcm.edu;enqueuing into batch, state 1 hop 1
11/02/2012 09:34:25;0008;PBS_Server.1830;Job;316.csg.bcmd.bcm.edu;Job Queued at request of lacuesta@csg.bcmd.bcm.edu, owner = lacuesta@csg.bcmd.bcm.edu, job name = jobname2, queue = batch
11/02/2012 09:34:28;0040;PBS_Server.12604;Svr;csg.bcmd.bcm.edu;Scheduler was sent the command new
11/02/2012 09:34:29;0008;PBS_Server.1831;Job;315.csg.bcmd.bcm.edu;Job Run at request of root@csg.bcmd.bcm.edu
11/02/2012 09:34:29;000d;PBS_Server.1831;Job;315.csg.bcmd.bcm.edu;Not sending email: User does not want mail of this type.
11/02/2012 09:34:29;0008;PBS_Server.1831;Job;316.csg.bcmd.bcm.edu;Job Run at request of root@csg.bcmd.bcm.edu
11/02/2012 09:34:29;000d;PBS_Server.1831;Job;316.csg.bcmd.bcm.edu;Not sending email: User does not want mail of this type.
11/02/2012 09:34:34;0100;PBS_Server.1827;Job;317.csg.bcmd.bcm.edu;enqueuing into batch, state 1 hop 1
11/02/2012 09:34:34;0008;PBS_Server.1827;Job;317.csg.bcmd.bcm.edu;Job Queued at request of lacuesta@csg.bcmd.bcm.edu, owner = lacuesta@csg.bcmd.bcm.edu, job name = jobname1, queue = batch
11/02/2012 09:34:34;0100;PBS_Server.1832;Job;318.csg.bcmd.bcm.edu;enqueuing into batch, state 1 hop 1
11/02/2012 09:34:34;0008;PBS_Server.1832;Job;318.csg.bcmd.bcm.edu;Job Queued at request of lacuesta@csg.bcmd.bcm.edu, owner = lacuesta@csg.bcmd.bcm.edu, job name = jobname2, queue = batch
11/02/2012 09:34:34;000d;PBS_Server.1834;Job;313.csg.bcmd.bcm.edu;Not sending email: User does not want mail of this type.
11/02/2012 09:34:34;0010;PBS_Server.1834;Job;313.csg.bcmd.bcm.edu;Exit_status=0 resources_used.cput=00:00:09 resources_used.mem=0kb resources_used.vmem=0kb resources_used.walltime=00:00:10
11/02/2012 09:34:34;0008;PBS_Server.1826;Job;313.csg.bcmd.bcm.edu;on_job_exit valid pjob: 313.csg.bcmd.bcm.edu (substate=50)
11/02/2012 09:34:35;000d;PBS_Server.1825;Job;314.csg.bcmd.bcm.edu;Not sending email: User does not want mail of this type.
11/02/2012 09:34:35;0010;PBS_Server.1825;Job;314.csg.bcmd.bcm.edu;Exit_status=0 resources_used.cput=00:00:10 resources_used.mem=43988kb resources_used.vmem=293192kb resources_used.walltime=00:00:11
11/02/2012 09:34:35;0008;PBS_Server.1837;Job;314.csg.bcmd.bcm.edu;on_job_exit valid pjob: 314.csg.bcmd.bcm.edu (substate=50)
11/02/2012 09:34:38;0040;PBS_Server.12630;Svr;csg.bcmd.bcm.edu;Scheduler was sent the command term
11/02/2012 09:34:39;0008;PBS_Server.1831;Job;317.csg.bcmd.bcm.edu;Job Run at request of root@csg.bcmd.bcm.edu
11/02/2012 09:34:39;000d;PBS_Server.1831;Job;317.csg.bcmd.bcm.edu;Not sending email: User does not want mail of this type.
11/02/2012 09:34:39;0008;PBS_Server.1831;Job;318.csg.bcmd.bcm.edu;Job Run at request of root@csg.bcmd.bcm.edu
11/02/2012 09:34:39;000d;PBS_Server.1831;Job;318.csg.bcmd.bcm.edu;Not sending email: User does not want mail of this type.
11/02/2012 09:34:39;000d;PBS_Server.1834;Job;315.csg.bcmd.bcm.edu;Not sending email: User does not want mail of this type.
11/02/2012 09:34:39;0010;PBS_Server.1834;Job;315.csg.bcmd.bcm.edu;Exit_status=0 resources_used.cput=00:00:09 resources_used.mem=38692kb resources_used.vmem=287744kb resources_used.walltime=00:00:10
11/02/2012 09:34:39;0008;PBS_Server.1830;Job;315.csg.bcmd.bcm.edu;on_job_exit valid pjob: 315.csg.bcmd.bcm.edu (substate=50)
11/02/2012 09:34:41;000d;PBS_Server.1833;Job;316.csg.bcmd.bcm.edu;Not sending email: User does not want mail of this type.
11/02/2012 09:34:41;0010;PBS_Server.1833;Job;316.csg.bcmd.bcm.edu;Exit_status=0 resources_used.cput=00:00:11 resources_used.mem=111892kb resources_used.vmem=292084kb resources_used.walltime=00:00:12
11/02/2012 09:34:41;0008;PBS_Server.1837;Job;316.csg.bcmd.bcm.edu;on_job_exit valid pjob: 316.csg.bcmd.bcm.edu (substate=50)
11/02/2012 09:34:43;0040;PBS_Server.12647;Svr;csg.bcmd.bcm.edu;Scheduler was sent the command term
11/02/2012 09:34:49;000d;PBS_Server.1832;Job;317.csg.bcmd.bcm.edu;Not sending email: User does not want mail of this type.
11/02/2012 09:34:49;0010;PBS_Server.1832;Job;317.csg.bcmd.bcm.edu;Exit_status=0 resources_used.cput=00:00:10 resources_used.mem=91812kb resources_used.vmem=222628kb resources_used.walltime=00:00:10
11/02/2012 09:34:49;0008;PBS_Server.1835;Job;317.csg.bcmd.bcm.edu;on_job_exit valid pjob: 317.csg.bcmd.bcm.edu (substate=50)
11/02/2012 09:34:51;000d;PBS_Server.1830;Job;318.csg.bcmd.bcm.edu;Not sending email: User does not want mail of this type.
11/02/2012 09:34:51;0010;PBS_Server.1830;Job;318.csg.bcmd.bcm.edu;Exit_status=0 resources_used.cput=00:00:11 resources_used.mem=91256kb resources_used.vmem=293328kb resources_used.walltime=00:00:11
11/02/2012 09:34:51;0008;PBS_Server.1828;Job;318.csg.bcmd.bcm.edu;on_job_exit valid pjob: 318.csg.bcmd.bcm.edu (substate=50)
11/02/2012 09:34:53;0040;PBS_Server.12665;Svr;csg.bcmd.bcm.edu;Scheduler was sent the command term
11/02/2012 09:35:13;000d;PBS_Server.1835;Job;310.csg.bcmd.bcm.edu;Not sending email: User does not want mail of this type.
11/02/2012 09:35:13;0010;PBS_Server.1835;Job;310.csg.bcmd.bcm.edu;Exit_status=0 resources_used.cput=00:02:27 resources_used.mem=349568kb resources_used.vmem=480000kb resources_used.walltime=00:02:29
11/02/2012 09:35:13;0008;PBS_Server.1825;Job;310.csg.bcmd.bcm.edu;on_job_exit valid pjob: 310.csg.bcmd.bcm.edu (substate=50)
11/02/2012 09:35:13;0040;PBS_Server.12693;Svr;csg.bcmd.bcm.edu;Scheduler was sent the command term
11/02/2012 09:35:22;000d;PBS_Server.1829;Job;308.csg.bcmd.bcm.edu;Not sending email: User does not want mail of this type.
11/02/2012 09:35:22;0010;PBS_Server.1829;Job;308.csg.bcmd.bcm.edu;Exit_status=0 resources_used.cput=00:02:42 resources_used.mem=311196kb resources_used.vmem=431224kb resources_used.walltime=00:02:43
11/02/2012 09:35:22;0008;PBS_Server.1833;Job;308.csg.bcmd.bcm.edu;on_job_exit valid pjob: 308.csg.bcmd.bcm.edu (substate=50)
11/02/2012 09:35:23;0040;PBS_Server.12703;Svr;csg.bcmd.bcm.edu;Scheduler was sent the command term
11/02/2012 09:35:53;0008;PBS_Server.1829;Job;303.csg.bcmd.bcm.edu;on_job_exit valid pjob: 303.csg.bcmd.bcm.edu (substate=59)
11/02/2012 09:35:53;0100;PBS_Server.1829;Job;303.csg.bcmd.bcm.edu;dequeuing from batch, state COMPLETE
11/02/2012 09:35:53;0008;PBS_Server.1830;Job;304.csg.bcmd.bcm.edu;on_job_exit valid pjob: 304.csg.bcmd.bcm.edu (substate=59)
11/02/2012 09:35:53;0008;PBS_Server.1827;Job;302.csg.bcmd.bcm.edu;on_job_exit valid pjob: 302.csg.bcmd.bcm.edu (substate=59)
11/02/2012 09:35:53;0100;PBS_Server.1830;Job;304.csg.bcmd.bcm.edu;dequeuing from batch, state COMPLETE
11/02/2012 09:35:53;0100;PBS_Server.1827;Job;302.csg.bcmd.bcm.edu;dequeuing from batch, state COMPLETE
11/02/2012 09:35:53;0008;PBS_Server.1833;Job;301.csg.bcmd.bcm.edu;on_job_exit valid pjob: 301.csg.bcmd.bcm.edu (substate=59)
11/02/2012 09:35:53;0100;PBS_Server.1833;Job;301.csg.bcmd.bcm.edu;dequeuing from batch, state COMPLETE
11/02/2012 09:35:58;0040;PBS_Server.12715;Svr;csg.bcmd.bcm.edu;Scheduler was sent the command term
11/02/2012 09:36:08;0008;PBS_Server.1827;Job;306.csg.bcmd.bcm.edu;on_job_exit valid pjob: 306.csg.bcmd.bcm.edu (substate=59)
11/02/2012 09:36:08;0008;PBS_Server.1836;Job;305.csg.bcmd.bcm.edu;on_job_exit valid pjob: 305.csg.bcmd.bcm.edu (substate=59)
11/02/2012 09:36:08;0100;PBS_Server.1836;Job;305.csg.bcmd.bcm.edu;dequeuing from batch, state COMPLETE
11/02/2012 09:36:08;0100;PBS_Server.1827;Job;306.csg.bcmd.bcm.edu;dequeuing from batch, state COMPLETE
11/02/2012 09:36:13;0040;PBS_Server.12716;Svr;csg.bcmd.bcm.edu;Scheduler was sent the command term
11/02/2012 09:36:54;000d;PBS_Server.1827;Job;311.csg.bcmd.bcm.edu;Not sending email: User does not want mail of this type.
11/02/2012 09:36:54;0010;PBS_Server.1827;Job;311.csg.bcmd.bcm.edu;Exit_status=0 resources_used.cput=00:03:48 resources_used.mem=308616kb resources_used.vmem=428556kb resources_used.walltime=00:03:50
11/02/2012 09:36:54;0008;PBS_Server.1833;Job;311.csg.bcmd.bcm.edu;on_job_exit valid pjob: 311.csg.bcmd.bcm.edu (substate=50)
11/02/2012 09:36:58;0040;PBS_Server.12729;Svr;csg.bcmd.bcm.edu;Scheduler was sent the command term
11/02/2012 09:37:23;0100;PBS_Server.1830;Job;319.csg.bcmd.bcm.edu;enqueuing into batch, state 1 hop 1
11/02/2012 09:37:23;0008;PBS_Server.1830;Job;319.csg.bcmd.bcm.edu;Job Queued at request of lacuesta@csg.bcmd.bcm.edu, owner = lacuesta@csg.bcmd.bcm.edu, job name = jobname1, queue = batch
11/02/2012 09:37:23;0100;PBS_Server.1835;Job;320.csg.bcmd.bcm.edu;enqueuing into batch, state 1 hop 1
11/02/2012 09:37:23;0008;PBS_Server.1835;Job;320.csg.bcmd.bcm.edu;Job Queued at request of lacuesta@csg.bcmd.bcm.edu, owner = lacuesta@csg.bcmd.bcm.edu, job name = jobname2, queue = batch
11/02/2012 09:37:23;0040;PBS_Server.12747;Svr;csg.bcmd.bcm.edu;Scheduler was sent the command new
11/02/2012 09:37:24;0008;PBS_Server.1831;Job;319.csg.bcmd.bcm.edu;Job Run at request of root@csg.bcmd.bcm.edu
11/02/2012 09:37:24;000d;PBS_Server.1831;Job;319.csg.bcmd.bcm.edu;Not sending email: User does not want mail of this type.
11/02/2012 09:37:24;0008;PBS_Server.1831;Job;320.csg.bcmd.bcm.edu;Job Run at request of root@csg.bcmd.bcm.edu
11/02/2012 09:37:24;000d;PBS_Server.1831;Job;320.csg.bcmd.bcm.edu;Not sending email: User does not want mail of this type.
11/02/2012 09:37:52;0100;PBS_Server.1832;Job;321.csg.bcmd.bcm.edu;enqueuing into batch, state 1 hop 1
11/02/2012 09:37:52;0008;PBS_Server.1832;Job;321.csg.bcmd.bcm.edu;Job Queued at request of lacuesta@csg.bcmd.bcm.edu, owner = lacuesta@csg.bcmd.bcm.edu, job name = jobname1, queue = batch
11/02/2012 09:37:52;0100;PBS_Server.1836;Job;322.csg.bcmd.bcm.edu;enqueuing into batch, state 1 hop 1
11/02/2012 09:37:52;0008;PBS_Server.1836;Job;322.csg.bcmd.bcm.edu;Job Queued at request of lacuesta@csg.bcmd.bcm.edu, owner = lacuesta@csg.bcmd.bcm.edu, job name = jobname2, queue = batch
11/02/2012 09:37:53;0040;PBS_Server.12781;Svr;csg.bcmd.bcm.edu;Scheduler was sent the command new
11/02/2012 09:37:54;0008;PBS_Server.1831;Job;321.csg.bcmd.bcm.edu;Job Run at request of root@csg.bcmd.bcm.edu
11/02/2012 09:37:54;000d;PBS_Server.1831;Job;321.csg.bcmd.bcm.edu;Not sending email: User does not want mail of this type.
11/02/2012 09:37:54;0008;PBS_Server.1831;Job;322.csg.bcmd.bcm.edu;Job Run at request of root@csg.bcmd.bcm.edu
11/02/2012 09:37:54;000d;PBS_Server.1831;Job;322.csg.bcmd.bcm.edu;Not sending email: User does not want mail of this type.
11/02/2012 09:38:38;0008;PBS_Server.1836;Job;307.csg.bcmd.bcm.edu;on_job_exit valid pjob: 307.csg.bcmd.bcm.edu (substate=59)
11/02/2012 09:38:38;0100;PBS_Server.1836;Job;307.csg.bcmd.bcm.edu;dequeuing from batch, state COMPLETE
11/02/2012 09:38:43;0040;PBS_Server.12843;Svr;csg.bcmd.bcm.edu;Scheduler was sent the command term
11/02/2012 09:39:18;000d;PBS_Server.1827;Job;321.csg.bcmd.bcm.edu;Not sending email: User does not want mail of this type.
11/02/2012 09:39:18;0010;PBS_Server.1827;Job;321.csg.bcmd.bcm.edu;Exit_status=0 resources_used.cput=00:01:23 resources_used.mem=241140kb resources_used.vmem=361208kb resources_used.walltime=00:01:24
11/02/2012 09:39:18;0008;PBS_Server.1828;Job;321.csg.bcmd.bcm.edu;on_job_exit valid pjob: 321.csg.bcmd.bcm.edu (substate=50)
11/02/2012 09:39:18;0040;PBS_Server.12895;Svr;csg.bcmd.bcm.edu;Scheduler was sent the command term
11/02/2012 09:39:23;0008;PBS_Server.1832;Job;309.csg.bcmd.bcm.edu;on_job_exit valid pjob: 309.csg.bcmd.bcm.edu (substate=59)
11/02/2012 09:39:23;0002;PBS_Server.1837;Svr;PBS_Server;Torque Server Version = 4.1.2, loglevel = 0
11/02/2012 09:39:23;0100;PBS_Server.1832;Job;309.csg.bcmd.bcm.edu;dequeuing from batch, state COMPLETE
11/02/2012 09:39:28;0040;PBS_Server.12898;Svr;csg.bcmd.bcm.edu;Scheduler was sent the command term
11/02/2012 09:39:38;0008;PBS_Server.1832;Job;314.csg.bcmd.bcm.edu;on_job_exit valid pjob: 314.csg.bcmd.bcm.edu (substate=59)
11/02/2012 09:39:38;0008;PBS_Server.1835;Job;313.csg.bcmd.bcm.edu;on_job_exit valid pjob: 313.csg.bcmd.bcm.edu (substate=59)
11/02/2012 09:39:38;0100;PBS_Server.1832;Job;314.csg.bcmd.bcm.edu;dequeuing from batch, state COMPLETE
11/02/2012 09:39:38;0100;PBS_Server.1835;Job;313.csg.bcmd.bcm.edu;dequeuing from batch, state COMPLETE
11/02/2012 09:39:43;0040;PBS_Server.12899;Svr;csg.bcmd.bcm.edu;Scheduler was sent the command term
11/02/2012 09:39:53;0008;PBS_Server.1835;Job;317.csg.bcmd.bcm.edu;on_job_exit valid pjob: 317.csg.bcmd.bcm.edu (substate=59)
11/02/2012 09:39:53;0100;PBS_Server.1835;Job;317.csg.bcmd.bcm.edu;dequeuing from batch, state COMPLETE
11/02/2012 09:39:53;0008;PBS_Server.1834;Job;315.csg.bcmd.bcm.edu;on_job_exit valid pjob: 315.csg.bcmd.bcm.edu (substate=59)
11/02/2012 09:39:53;0100;PBS_Server.1834;Job;315.csg.bcmd.bcm.edu;dequeuing from batch, state COMPLETE
11/02/2012 09:39:53;0008;PBS_Server.1837;Job;316.csg.bcmd.bcm.edu;on_job_exit valid pjob: 316.csg.bcmd.bcm.edu (substate=59)
11/02/2012 09:39:53;0008;PBS_Server.1825;Job;318.csg.bcmd.bcm.edu;on_job_exit valid pjob: 318.csg.bcmd.bcm.edu (substate=59)
11/02/2012 09:39:53;0100;PBS_Server.1837;Job;316.csg.bcmd.bcm.edu;dequeuing from batch, state COMPLETE
11/02/2012 09:39:53;0100;PBS_Server.1825;Job;318.csg.bcmd.bcm.edu;dequeuing from batch, state COMPLETE
11/02/2012 09:39:59;0040;PBS_Server.12900;Svr;csg.bcmd.bcm.edu;Scheduler was sent the command term
11/02/2012 09:40:23;0008;PBS_Server.1828;Job;308.csg.bcmd.bcm.edu;on_job_exit valid pjob: 308.csg.bcmd.bcm.edu (substate=59)
11/02/2012 09:40:23;0008;PBS_Server.1833;Job;310.csg.bcmd.bcm.edu;on_job_exit valid pjob: 310.csg.bcmd.bcm.edu (substate=59)
11/02/2012 09:40:23;0100;PBS_Server.1828;Job;308.csg.bcmd.bcm.edu;dequeuing from batch, state COMPLETE
11/02/2012 09:40:23;0100;PBS_Server.1833;Job;310.csg.bcmd.bcm.edu;dequeuing from batch, state COMPLETE
11/02/2012 09:40:29;0040;PBS_Server.12907;Svr;csg.bcmd.bcm.edu;Scheduler was sent the command term
11/02/2012 09:40:30;000d;PBS_Server.1833;Job;322.csg.bcmd.bcm.edu;Not sending email: User does not want mail of this type.
11/02/2012 09:40:30;0010;PBS_Server.1833;Job;322.csg.bcmd.bcm.edu;Exit_status=0 resources_used.cput=00:02:35 resources_used.mem=347668kb resources_used.vmem=478424kb resources_used.walltime=00:02:36
11/02/2012 09:40:30;0008;PBS_Server.1828;Job;322.csg.bcmd.bcm.edu;on_job_exit valid pjob: 322.csg.bcmd.bcm.edu (substate=50)
11/02/2012 09:40:34;0040;PBS_Server.12916;Svr;csg.bcmd.bcm.edu;Scheduler was sent the command term
11/02/2012 09:40:41;000d;PBS_Server.1830;Job;312.csg.bcmd.bcm.edu;Not sending email: User does not want mail of this type.
11/02/2012 09:40:41;0010;PBS_Server.1830;Job;312.csg.bcmd.bcm.edu;Exit_status=0 resources_used.cput=00:07:35 resources_used.mem=564860kb resources_used.vmem=695232kb resources_used.walltime=00:07:37
11/02/2012 09:40:41;0008;PBS_Server.1833;Job;312.csg.bcmd.bcm.edu;on_job_exit valid pjob: 312.csg.bcmd.bcm.edu (substate=50)
11/02/2012 09:40:44;0040;PBS_Server.12925;Svr;csg.bcmd.bcm.edu;Scheduler was sent the command term
11/02/2012 09:42:02;0008;PBS_Server.1827;Job;311.csg.bcmd.bcm.edu;on_job_exit valid pjob: 311.csg.bcmd.bcm.edu (substate=59)
11/02/2012 09:42:02;0100;PBS_Server.1827;Job;311.csg.bcmd.bcm.edu;dequeuing from batch, state COMPLETE
11/02/2012 09:42:07;0040;PBS_Server.12938;Svr;csg.bcmd.bcm.edu;Scheduler was sent the command term
11/02/2012 09:43:39;000d;PBS_Server.1831;Job;319.csg.bcmd.bcm.edu;Not sending email: User does not want mail of this type.
11/02/2012 09:43:39;0010;PBS_Server.1831;Job;319.csg.bcmd.bcm.edu;Exit_status=0 resources_used.cput=00:04:21 resources_used.mem=532992kb resources_used.vmem=663436kb resources_used.walltime=00:06:15
11/02/2012 09:43:39;0008;PBS_Server.1834;Job;319.csg.bcmd.bcm.edu;on_job_exit valid pjob: 319.csg.bcmd.bcm.edu (substate=50)
11/02/2012 09:43:40;0040;PBS_Server.12949;Svr;csg.bcmd.bcm.edu;Scheduler was sent the command term
11/02/2012 09:44:31;0008;PBS_Server.1832;Job;321.csg.bcmd.bcm.edu;on_job_exit valid pjob: 321.csg.bcmd.bcm.edu (substate=59)
11/02/2012 09:44:31;0002;PBS_Server.1827;Svr;PBS_Server;Torque Server Version = 4.1.2, loglevel = 0
11/02/2012 09:44:31;0100;PBS_Server.1832;Job;321.csg.bcmd.bcm.edu;dequeuing from batch, state COMPLETE
11/02/2012 09:44:36;0040;PBS_Server.12950;Svr;csg.bcmd.bcm.edu;Scheduler was sent the command term
11/02/2012 09:45:38;0008;PBS_Server.1837;Job;322.csg.bcmd.bcm.edu;on_job_exit valid pjob: 322.csg.bcmd.bcm.edu (substate=59)
11/02/2012 09:45:38;0100;PBS_Server.1837;Job;322.csg.bcmd.bcm.edu;dequeuing from batch, state COMPLETE
11/02/2012 09:45:39;0040;PBS_Server.12957;Svr;csg.bcmd.bcm.edu;Scheduler was sent the command term
11/02/2012 09:45:50;0008;PBS_Server.1828;Job;312.csg.bcmd.bcm.edu;on_job_exit valid pjob: 312.csg.bcmd.bcm.edu (substate=59)
11/02/2012 09:45:50;0100;PBS_Server.1828;Job;312.csg.bcmd.bcm.edu;dequeuing from batch, state COMPLETE
11/02/2012 09:45:55;0040;PBS_Server.12958;Svr;csg.bcmd.bcm.edu;Scheduler was sent the command term
11/02/2012 09:48:17;000d;PBS_Server.1826;Job;320.csg.bcmd.bcm.edu;Not sending email: User does not want mail of this type.
11/02/2012 09:48:17;0010;PBS_Server.1826;Job;320.csg.bcmd.bcm.edu;Exit_status=0 resources_used.cput=00:08:49 resources_used.mem=643768kb resources_used.vmem=783880kb resources_used.walltime=00:10:53
11/02/2012 09:48:17;0008;PBS_Server.1825;Job;320.csg.bcmd.bcm.edu;on_job_exit valid pjob: 320.csg.bcmd.bcm.edu (substate=50)
11/02/2012 09:48:20;0040;PBS_Server.12968;Svr;csg.bcmd.bcm.edu;Scheduler was sent the command term
11/02/2012 09:48:41;0008;PBS_Server.1827;Job;319.csg.bcmd.bcm.edu;on_job_exit valid pjob: 319.csg.bcmd.bcm.edu (substate=59)
11/02/2012 09:48:41;0100;PBS_Server.1827;Job;319.csg.bcmd.bcm.edu;dequeuing from batch, state COMPLETE
11/02/2012 09:48:46;0040;PBS_Server.12969;Svr;csg.bcmd.bcm.edu;Scheduler was sent the command term
11/02/2012 09:49:33;0002;PBS_Server.1833;Svr;PBS_Server;Torque Server Version = 4.1.2, loglevel = 0
11/02/2012 09:53:20;0008;PBS_Server.1834;Job;320.csg.bcmd.bcm.edu;on_job_exit valid pjob: 320.csg.bcmd.bcm.edu (substate=59)
11/02/2012 09:53:20;0100;PBS_Server.1834;Job;320.csg.bcmd.bcm.edu;dequeuing from batch, state COMPLETE
11/02/2012 09:53:25;0040;PBS_Server.12978;Svr;csg.bcmd.bcm.edu;Scheduler was sent the command term
11/02/2012 09:54:42;0002;PBS_Server.1828;Svr;PBS_Server;Torque Server Version = 4.1.2, loglevel = 0
11/02/2012 09:58:25;0100;PBS_Server.1825;Job;323.csg.bcmd.bcm.edu;enqueuing into batch, state 1 hop 1
11/02/2012 09:58:25;0008;PBS_Server.1825;Job;323.csg.bcmd.bcm.edu;Job Queued at request of lacuesta@csg.bcmd.bcm.edu, owner = lacuesta@csg.bcmd.bcm.edu, job name = jobname1, queue = batch
11/02/2012 09:58:25;0100;PBS_Server.1833;Job;324.csg.bcmd.bcm.edu;enqueuing into batch, state 1 hop 1
11/02/2012 09:58:25;0008;PBS_Server.1833;Job;324.csg.bcmd.bcm.edu;Job Queued at request of lacuesta@csg.bcmd.bcm.edu, owner = lacuesta@csg.bcmd.bcm.edu, job name = jobname2, queue = batch
11/02/2012 09:58:29;0040;PBS_Server.13056;Svr;csg.bcmd.bcm.edu;Scheduler was sent the command new
11/02/2012 09:58:30;0008;PBS_Server.1836;Job;323.csg.bcmd.bcm.edu;Job Run at request of root@csg.bcmd.bcm.edu
11/02/2012 09:58:30;000d;PBS_Server.1836;Job;323.csg.bcmd.bcm.edu;Not sending email: User does not want mail of this type.
11/02/2012 09:58:30;0008;PBS_Server.1836;Job;324.csg.bcmd.bcm.edu;Job Run at request of root@csg.bcmd.bcm.edu
11/02/2012 09:58:30;000d;PBS_Server.1836;Job;324.csg.bcmd.bcm.edu;Not sending email: User does not want mail of this type.
11/02/2012 09:59:55;0002;PBS_Server.1827;Svr;PBS_Server;Torque Server Version = 4.1.2, loglevel = 0
11/02/2012 10:01:11;0100;PBS_Server.1835;Job;325.csg.bcmd.bcm.edu;enqueuing into batch, state 1 hop 1
11/02/2012 10:01:11;0008;PBS_Server.1835;Job;325.csg.bcmd.bcm.edu;Job Queued at request of lacuesta@csg.bcmd.bcm.edu, owner = lacuesta@csg.bcmd.bcm.edu, job name = jobname1, queue = batch
11/02/2012 10:01:11;0100;PBS_Server.1837;Job;326.csg.bcmd.bcm.edu;enqueuing into batch, state 1 hop 1
11/02/2012 10:01:11;0008;PBS_Server.1837;Job;326.csg.bcmd.bcm.edu;Job Queued at request of lacuesta@csg.bcmd.bcm.edu, owner = lacuesta@csg.bcmd.bcm.edu, job name = jobname2, queue = batch
11/02/2012 10:01:15;0040;PBS_Server.13120;Svr;csg.bcmd.bcm.edu;Scheduler was sent the command new
11/02/2012 10:01:16;0008;PBS_Server.1836;Job;325.csg.bcmd.bcm.edu;Job Run at request of root@csg.bcmd.bcm.edu
11/02/2012 10:01:16;000d;PBS_Server.1836;Job;325.csg.bcmd.bcm.edu;Not sending email: User does not want mail of this type.
11/02/2012 10:01:16;0008;PBS_Server.1836;Job;326.csg.bcmd.bcm.edu;Job Run at request of root@csg.bcmd.bcm.edu
11/02/2012 10:01:16;000d;PBS_Server.1836;Job;326.csg.bcmd.bcm.edu;Not sending email: User does not want mail of this type.
11/02/2012 10:04:42;000d;PBS_Server.1826;Job;323.csg.bcmd.bcm.edu;Not sending email: User does not want mail of this type.
11/02/2012 10:04:42;0010;PBS_Server.1826;Job;323.csg.bcmd.bcm.edu;Exit_status=0 resources_used.cput=00:04:13 resources_used.mem=326260kb resources_used.vmem=446188kb resources_used.walltime=00:06:12
11/02/2012 10:04:42;0008;PBS_Server.1830;Job;323.csg.bcmd.bcm.edu;on_job_exit valid pjob: 323.csg.bcmd.bcm.edu (substate=50)
11/02/2012 10:04:45;0040;PBS_Server.13186;Svr;csg.bcmd.bcm.edu;Scheduler was sent the command term
11/02/2012 10:04:47;000d;PBS_Server.1837;Job;326.csg.bcmd.bcm.edu;Not sending email: User does not want mail of this type.
11/02/2012 10:04:47;0010;PBS_Server.1837;Job;326.csg.bcmd.bcm.edu;Exit_status=0 resources_used.cput=00:02:28 resources_used.mem=361316kb resources_used.vmem=491352kb resources_used.walltime=00:03:31
11/02/2012 10:04:47;0008;PBS_Server.1825;Job;326.csg.bcmd.bcm.edu;on_job_exit valid pjob: 326.csg.bcmd.bcm.edu (substate=50)
11/02/2012 10:04:50;0040;PBS_Server.13196;Svr;csg.bcmd.bcm.edu;Scheduler was sent the command term
11/02/2012 10:04:55;0002;PBS_Server.1835;Svr;PBS_Server;Torque Server Version = 4.1.2, loglevel = 0
11/02/2012 10:04:56;000d;PBS_Server.1830;Job;325.csg.bcmd.bcm.edu;Not sending email: User does not want mail of this type.
11/02/2012 10:04:56;0010;PBS_Server.1830;Job;325.csg.bcmd.bcm.edu;Exit_status=0 resources_used.cput=00:01:25 resources_used.mem=342336kb resources_used.vmem=472432kb resources_used.walltime=00:03:40
11/02/2012 10:04:56;0008;PBS_Server.1828;Job;325.csg.bcmd.bcm.edu;on_job_exit valid pjob: 325.csg.bcmd.bcm.edu (substate=50)
11/02/2012 10:05:00;0040;PBS_Server.13210;Svr;csg.bcmd.bcm.edu;Scheduler was sent the command term
11/02/2012 10:07:27;000d;PBS_Server.1834;Job;324.csg.bcmd.bcm.edu;Not sending email: User does not want mail of this type.
11/02/2012 10:07:27;0010;PBS_Server.1834;Job;324.csg.bcmd.bcm.edu;Exit_status=0 resources_used.cput=00:07:40 resources_used.mem=402724kb resources_used.vmem=522632kb resources_used.walltime=00:08:57
11/02/2012 10:07:27;0008;PBS_Server.1833;Job;324.csg.bcmd.bcm.edu;on_job_exit valid pjob: 324.csg.bcmd.bcm.edu (substate=50)
11/02/2012 10:07:30;0040;PBS_Server.13308;Svr;csg.bcmd.bcm.edu;Scheduler was sent the command term
11/02/2012 10:09:51;0008;PBS_Server.1828;Job;323.csg.bcmd.bcm.edu;on_job_exit valid pjob: 323.csg.bcmd.bcm.edu (substate=59)
11/02/2012 10:09:51;0100;PBS_Server.1828;Job;323.csg.bcmd.bcm.edu;dequeuing from batch, state COMPLETE
11/02/2012 10:09:51;0008;PBS_Server.1825;Job;326.csg.bcmd.bcm.edu;on_job_exit valid pjob: 326.csg.bcmd.bcm.edu (substate=59)
11/02/2012 10:09:51;0100;PBS_Server.1825;Job;326.csg.bcmd.bcm.edu;dequeuing from batch, state COMPLETE
11/02/2012 10:09:56;0040;PBS_Server.13380;Svr;csg.bcmd.bcm.edu;Scheduler was sent the command term
11/02/2012 10:10:06;0002;PBS_Server.1830;Svr;PBS_Server;Torque Server Version = 4.1.2, loglevel = 0
11/02/2012 10:10:06;0008;PBS_Server.1826;Job;325.csg.bcmd.bcm.edu;on_job_exit valid pjob: 325.csg.bcmd.bcm.edu (substate=59)
11/02/2012 10:10:06;0100;PBS_Server.1826;Job;325.csg.bcmd.bcm.edu;dequeuing from batch, state COMPLETE
11/02/2012 10:10:11;0040;PBS_Server.13394;Svr;csg.bcmd.bcm.edu;Scheduler was sent the command term
11/02/2012 10:11:35;0100;PBS_Server.1833;Job;327.csg.bcmd.bcm.edu;enqueuing into batch, state 1 hop 1
11/02/2012 10:11:35;0008;PBS_Server.1833;Job;327.csg.bcmd.bcm.edu;Job Queued at request of lacuesta@csg.bcmd.bcm.edu, owner = lacuesta@csg.bcmd.bcm.edu, job name = jobname1, queue = batch
11/02/2012 10:11:36;0100;PBS_Server.1834;Job;328.csg.bcmd.bcm.edu;enqueuing into batch, state 1 hop 1
11/02/2012 10:11:36;0008;PBS_Server.1834;Job;328.csg.bcmd.bcm.edu;Job Queued at request of lacuesta@csg.bcmd.bcm.edu, owner = lacuesta@csg.bcmd.bcm.edu, job name = jobname2, queue = batch
11/02/2012 10:11:36;0040;PBS_Server.13421;Svr;csg.bcmd.bcm.edu;Scheduler was sent the command new
11/02/2012 10:11:37;0008;PBS_Server.1836;Job;327.csg.bcmd.bcm.edu;Job Run at request of root@csg.bcmd.bcm.edu
11/02/2012 10:11:37;000d;PBS_Server.1836;Job;327.csg.bcmd.bcm.edu;Not sending email: User does not want mail of this type.
11/02/2012 10:11:37;0008;PBS_Server.1836;Job;328.csg.bcmd.bcm.edu;Job Run at request of root@csg.bcmd.bcm.edu
11/02/2012 10:11:37;000d;PBS_Server.1836;Job;328.csg.bcmd.bcm.edu;Not sending email: User does not want mail of this type.
11/02/2012 10:11:41;0100;PBS_Server.1829;Job;329.csg.bcmd.bcm.edu;enqueuing into batch, state 1 hop 1
11/02/2012 10:11:41;0008;PBS_Server.1829;Job;329.csg.bcmd.bcm.edu;Job Queued at request of lacuesta@csg.bcmd.bcm.edu, owner = lacuesta@csg.bcmd.bcm.edu, job name = jobname1, queue = batch
11/02/2012 10:11:42;0100;PBS_Server.1830;Job;330.csg.bcmd.bcm.edu;enqueuing into batch, state 1 hop 1
11/02/2012 10:11:42;0008;PBS_Server.1830;Job;330.csg.bcmd.bcm.edu;Job Queued at request of lacuesta@csg.bcmd.bcm.edu, owner = lacuesta@csg.bcmd.bcm.edu, job name = jobname2, queue = batch
11/02/2012 10:11:46;0040;PBS_Server.13437;Svr;csg.bcmd.bcm.edu;Scheduler was sent the command new
11/02/2012 10:11:47;0008;PBS_Server.1836;Job;329.csg.bcmd.bcm.edu;Job Run at request of root@csg.bcmd.bcm.edu
11/02/2012 10:11:47;000d;PBS_Server.1836;Job;329.csg.bcmd.bcm.edu;Not sending email: User does not want mail of this type.
11/02/2012 10:11:47;0008;PBS_Server.1836;Job;330.csg.bcmd.bcm.edu;Job Run at request of root@csg.bcmd.bcm.edu
11/02/2012 10:11:47;000d;PBS_Server.1836;Job;330.csg.bcmd.bcm.edu;Not sending email: User does not want mail of this type.
11/02/2012 10:11:47;000d;PBS_Server.1833;Job;327.csg.bcmd.bcm.edu;Not sending email: User does not want mail of this type.
11/02/2012 10:11:47;0010;PBS_Server.1833;Job;327.csg.bcmd.bcm.edu;Exit_status=0 resources_used.cput=00:00:09 resources_used.mem=0kb resources_used.vmem=0kb resources_used.walltime=00:00:10
11/02/2012 10:11:47;0008;PBS_Server.1828;Job;327.csg.bcmd.bcm.edu;on_job_exit valid pjob: 327.csg.bcmd.bcm.edu (substate=50)
11/02/2012 10:11:49;000d;PBS_Server.1831;Job;328.csg.bcmd.bcm.edu;Not sending email: User does not want mail of this type.
11/02/2012 10:11:49;0010;PBS_Server.1831;Job;328.csg.bcmd.bcm.edu;Exit_status=0 resources_used.cput=00:00:10 resources_used.mem=43832kb resources_used.vmem=292996kb resources_used.walltime=00:00:12
11/02/2012 10:11:49;0008;PBS_Server.1827;Job;328.csg.bcmd.bcm.edu;on_job_exit valid pjob: 328.csg.bcmd.bcm.edu (substate=50)
11/02/2012 10:11:51;0040;PBS_Server.13456;Svr;csg.bcmd.bcm.edu;Scheduler was sent the command term
11/02/2012 10:11:57;000d;PBS_Server.1835;Job;329.csg.bcmd.bcm.edu;Not sending email: User does not want mail of this type.
11/02/2012 10:11:57;0010;PBS_Server.1835;Job;329.csg.bcmd.bcm.edu;Exit_status=0 resources_used.cput=00:00:09 resources_used.mem=79428kb resources_used.vmem=210064kb resources_used.walltime=00:00:10
11/02/2012 10:11:57;0008;PBS_Server.1826;Job;329.csg.bcmd.bcm.edu;on_job_exit valid pjob: 329.csg.bcmd.bcm.edu (substate=50)
11/02/2012 10:11:57;000d;PBS_Server.1832;Job;330.csg.bcmd.bcm.edu;Not sending email: User does not want mail of this type.
11/02/2012 10:11:57;0010;PBS_Server.1832;Job;330.csg.bcmd.bcm.edu;Exit_status=0 resources_used.cput=00:00:08 resources_used.mem=86796kb resources_used.vmem=206696kb resources_used.walltime=00:00:10
11/02/2012 10:11:57;0008;PBS_Server.1833;Job;330.csg.bcmd.bcm.edu;on_job_exit valid pjob: 330.csg.bcmd.bcm.edu (substate=50)
11/02/2012 10:12:01;0040;PBS_Server.13475;Svr;csg.bcmd.bcm.edu;Scheduler was sent the command term
11/02/2012 10:12:36;0008;PBS_Server.1825;Job;324.csg.bcmd.bcm.edu;on_job_exit valid pjob: 324.csg.bcmd.bcm.edu (substate=59)
11/02/2012 10:12:36;0100;PBS_Server.1825;Job;324.csg.bcmd.bcm.edu;dequeuing from batch, state COMPLETE
11/02/2012 10:12:41;0040;PBS_Server.13490;Svr;csg.bcmd.bcm.edu;Scheduler was sent the command term
11/02/2012 10:15:06;0002;PBS_Server.1829;Svr;PBS_Server;Torque Server Version = 4.1.2, loglevel = 0
11/02/2012 10:16:51;0008;PBS_Server.1835;Job;327.csg.bcmd.bcm.edu;on_job_exit valid pjob: 327.csg.bcmd.bcm.edu (substate=59)
11/02/2012 10:16:51;0008;PBS_Server.1832;Job;328.csg.bcmd.bcm.edu;on_job_exit valid pjob: 328.csg.bcmd.bcm.edu (substate=59)
11/02/2012 10:16:51;0100;PBS_Server.1835;Job;327.csg.bcmd.bcm.edu;dequeuing from batch, state COMPLETE
11/02/2012 10:16:51;0100;PBS_Server.1832;Job;328.csg.bcmd.bcm.edu;dequeuing from batch, state COMPLETE
11/02/2012 10:16:56;0040;PBS_Server.13600;Svr;csg.bcmd.bcm.edu;Scheduler was sent the command term
11/02/2012 10:17:06;0008;PBS_Server.1829;Job;329.csg.bcmd.bcm.edu;on_job_exit valid pjob: 329.csg.bcmd.bcm.edu (substate=59)
11/02/2012 10:17:06;0008;PBS_Server.1828;Job;330.csg.bcmd.bcm.edu;on_job_exit valid pjob: 330.csg.bcmd.bcm.edu (substate=59)
11/02/2012 10:17:06;0100;PBS_Server.1829;Job;329.csg.bcmd.bcm.edu;dequeuing from batch, state COMPLETE
11/02/2012 10:17:06;0100;PBS_Server.1828;Job;330.csg.bcmd.bcm.edu;dequeuing from batch, state COMPLETE
11/02/2012 10:17:11;0040;PBS_Server.13622;Svr;csg.bcmd.bcm.edu;Scheduler was sent the command term
11/02/2012 10:20:17;0002;PBS_Server.1833;Svr;PBS_Server;Torque Server Version = 4.1.2, loglevel = 0
11/02/2012 10:23:58;0100;PBS_Server.1831;Job;331.csg.bcmd.bcm.edu;enqueuing into batch, state 1 hop 1
11/02/2012 10:23:58;0008;PBS_Server.1831;Job;331.csg.bcmd.bcm.edu;Job Queued at request of lacuesta@csg.bcmd.bcm.edu, owner = lacuesta@csg.bcmd.bcm.edu, job name = jobname1, queue = batch
11/02/2012 10:23:59;0100;PBS_Server.1830;Job;332.csg.bcmd.bcm.edu;enqueuing into batch, state 1 hop 1
11/02/2012 10:23:59;0008;PBS_Server.1830;Job;332.csg.bcmd.bcm.edu;Job Queued at request of lacuesta@csg.bcmd.bcm.edu, owner = lacuesta@csg.bcmd.bcm.edu, job name = jobname2, queue = batch
11/02/2012 10:24:02;0040;PBS_Server.13764;Svr;csg.bcmd.bcm.edu;Scheduler was sent the command new
11/02/2012 10:24:03;0008;PBS_Server.1836;Job;331.csg.bcmd.bcm.edu;Job Run at request of root@csg.bcmd.bcm.edu
11/02/2012 10:24:03;000d;PBS_Server.1836;Job;331.csg.bcmd.bcm.edu;Not sending email: User does not want mail of this type.
11/02/2012 10:24:03;0008;PBS_Server.1836;Job;332.csg.bcmd.bcm.edu;Job Run at request of root@csg.bcmd.bcm.edu
11/02/2012 10:24:03;000d;PBS_Server.1836;Job;332.csg.bcmd.bcm.edu;Not sending email: User does not want mail of this type.
11/02/2012 10:24:19;000d;PBS_Server.1831;Job;331.csg.bcmd.bcm.edu;Not sending email: User does not want mail of this type.
11/02/2012 10:24:19;0010;PBS_Server.1831;Job;331.csg.bcmd.bcm.edu;Exit_status=0 resources_used.cput=00:00:09 resources_used.mem=0kb resources_used.vmem=0kb resources_used.walltime=00:00:16
11/02/2012 10:24:19;0008;PBS_Server.1834;Job;331.csg.bcmd.bcm.edu;on_job_exit valid pjob: 331.csg.bcmd.bcm.edu (substate=50)
11/02/2012 10:24:19;0100;PBS_Server.1830;Job;333.csg.bcmd.bcm.edu;enqueuing into batch, state 1 hop 1
11/02/2012 10:24:19;0008;PBS_Server.1830;Job;333.csg.bcmd.bcm.edu;Job Queued at request of lacuesta@csg.bcmd.bcm.edu, owner = lacuesta@csg.bcmd.bcm.edu, job name = jobname1, queue = batch
11/02/2012 10:24:20;0100;PBS_Server.1832;Job;334.csg.bcmd.bcm.edu;enqueuing into batch, state 1 hop 1
11/02/2012 10:24:20;0008;PBS_Server.1832;Job;334.csg.bcmd.bcm.edu;Job Queued at request of lacuesta@csg.bcmd.bcm.edu, owner = lacuesta@csg.bcmd.bcm.edu, job name = jobname2, queue = batch
11/02/2012 10:24:20;000d;PBS_Server.1835;Job;332.csg.bcmd.bcm.edu;Not sending email: User does not want mail of this type.
11/02/2012 10:24:20;0010;PBS_Server.1835;Job;332.csg.bcmd.bcm.edu;Exit_status=0 resources_used.cput=00:00:10 resources_used.mem=43916kb resources_used.vmem=293192kb resources_used.walltime=00:00:17
11/02/2012 10:24:20;0008;PBS_Server.1829;Job;332.csg.bcmd.bcm.edu;on_job_exit valid pjob: 332.csg.bcmd.bcm.edu (substate=50)
11/02/2012 10:24:22;0040;PBS_Server.13801;Svr;csg.bcmd.bcm.edu;Scheduler was sent the command term
11/02/2012 10:24:23;0008;PBS_Server.1836;Job;333.csg.bcmd.bcm.edu;Job Run at request of root@csg.bcmd.bcm.edu
11/02/2012 10:24:23;000d;PBS_Server.1836;Job;333.csg.bcmd.bcm.edu;Not sending email: User does not want mail of this type.
11/02/2012 10:24:23;0008;PBS_Server.1836;Job;334.csg.bcmd.bcm.edu;Job Run at request of root@csg.bcmd.bcm.edu
11/02/2012 10:24:23;000d;PBS_Server.1836;Job;334.csg.bcmd.bcm.edu;Not sending email: User does not want mail of this type.
11/02/2012 10:24:32;000d;PBS_Server.1830;Job;333.csg.bcmd.bcm.edu;Not sending email: User does not want mail of this type.
11/02/2012 10:24:32;0010;PBS_Server.1830;Job;333.csg.bcmd.bcm.edu;Exit_status=0 resources_used.cput=00:00:08 resources_used.mem=0kb resources_used.vmem=0kb resources_used.walltime=00:00:09
11/02/2012 10:24:32;0008;PBS_Server.1837;Job;333.csg.bcmd.bcm.edu;on_job_exit valid pjob: 333.csg.bcmd.bcm.edu (substate=50)
11/02/2012 10:24:32;0040;PBS_Server.13810;Svr;csg.bcmd.bcm.edu;Scheduler was sent the command term
11/02/2012 10:24:33;000d;PBS_Server.1835;Job;334.csg.bcmd.bcm.edu;Not sending email: User does not want mail of this type.
11/02/2012 10:24:33;0010;PBS_Server.1835;Job;334.csg.bcmd.bcm.edu;Exit_status=0 resources_used.cput=00:00:09 resources_used.mem=43764kb resources_used.vmem=292996kb resources_used.walltime=00:00:10
11/02/2012 10:24:33;0008;PBS_Server.1827;Job;334.csg.bcmd.bcm.edu;on_job_exit valid pjob: 334.csg.bcmd.bcm.edu (substate=50)
11/02/2012 10:24:37;0040;PBS_Server.13820;Svr;csg.bcmd.bcm.edu;Scheduler was sent the command term
11/02/2012 10:25:17;0002;PBS_Server.1831;Svr;PBS_Server;Torque Server Version = 4.1.2, loglevel = 0
11/02/2012 10:29:28;0008;PBS_Server.1834;Job;331.csg.bcmd.bcm.edu;on_job_exit valid pjob: 331.csg.bcmd.bcm.edu (substate=59)
11/02/2012 10:29:28;0008;PBS_Server.1825;Job;332.csg.bcmd.bcm.edu;on_job_exit valid pjob: 332.csg.bcmd.bcm.edu (substate=59)
11/02/2012 10:29:28;0100;PBS_Server.1834;Job;331.csg.bcmd.bcm.edu;dequeuing from batch, state COMPLETE
11/02/2012 10:29:28;0100;PBS_Server.1825;Job;332.csg.bcmd.bcm.edu;dequeuing from batch, state COMPLETE
11/02/2012 10:29:33;0040;PBS_Server.13929;Svr;csg.bcmd.bcm.edu;Scheduler was sent the command term
11/02/2012 10:29:43;0008;PBS_Server.1837;Job;333.csg.bcmd.bcm.edu;on_job_exit valid pjob: 333.csg.bcmd.bcm.edu (substate=59)
11/02/2012 10:29:43;0008;PBS_Server.1835;Job;334.csg.bcmd.bcm.edu;on_job_exit valid pjob: 334.csg.bcmd.bcm.edu (substate=59)
11/02/2012 10:29:43;0100;PBS_Server.1837;Job;333.csg.bcmd.bcm.edu;dequeuing from batch, state COMPLETE
11/02/2012 10:29:43;0100;PBS_Server.1835;Job;334.csg.bcmd.bcm.edu;dequeuing from batch, state COMPLETE
11/02/2012 10:29:48;0040;PBS_Server.13932;Svr;csg.bcmd.bcm.edu;Scheduler was sent the command term
11/02/2012 10:30:28;0002;PBS_Server.1830;Svr;PBS_Server;Torque Server Version = 4.1.2, loglevel = 0
11/02/2012 10:35:30;0002;PBS_Server.1825;Svr;PBS_Server;Torque Server Version = 4.1.2, loglevel = 0
11/02/2012 10:36:41;0100;PBS_Server.1835;Job;335.csg.bcmd.bcm.edu;enqueuing into batch, state 1 hop 1
11/02/2012 10:36:41;0008;PBS_Server.1835;Job;335.csg.bcmd.bcm.edu;Job Queued at request of lacuesta@csg.bcmd.bcm.edu, owner = lacuesta@csg.bcmd.bcm.edu, job name = jobname1, queue = batch
11/02/2012 10:36:42;0040;PBS_Server.14057;Svr;csg.bcmd.bcm.edu;Scheduler was sent the command new
11/02/2012 10:36:42;0100;PBS_Server.1825;Job;336.csg.bcmd.bcm.edu;enqueuing into batch, state 1 hop 1
11/02/2012 10:36:42;0008;PBS_Server.1825;Job;336.csg.bcmd.bcm.edu;Job Queued at request of lacuesta@csg.bcmd.bcm.edu, owner = lacuesta@csg.bcmd.bcm.edu, job name = jobname2, queue = batch
11/02/2012 10:36:43;0008;PBS_Server.1828;Job;335.csg.bcmd.bcm.edu;Job Run at request of root@csg.bcmd.bcm.edu
11/02/2012 10:36:43;000d;PBS_Server.1828;Job;335.csg.bcmd.bcm.edu;Not sending email: User does not want mail of this type.
11/02/2012 10:36:43;0008;PBS_Server.1828;Job;336.csg.bcmd.bcm.edu;Job Run at request of root@csg.bcmd.bcm.edu
11/02/2012 10:36:43;000d;PBS_Server.1828;Job;336.csg.bcmd.bcm.edu;Not sending email: User does not want mail of this type.
11/02/2012 10:36:43;0040;PBS_Server.14062;Svr;csg.bcmd.bcm.edu;Scheduler was sent the command new
11/02/2012 10:37:05;000d;PBS_Server.1835;Job;335.csg.bcmd.bcm.edu;Not sending email: User does not want mail of this type.
11/02/2012 10:37:05;0010;PBS_Server.1835;Job;335.csg.bcmd.bcm.edu;Exit_status=0 resources_used.cput=00:00:08 resources_used.mem=0kb resources_used.vmem=0kb resources_used.walltime=00:00:22
11/02/2012 10:37:05;0008;PBS_Server.1826;Job;335.csg.bcmd.bcm.edu;on_job_exit valid pjob: 335.csg.bcmd.bcm.edu (substate=50)
11/02/2012 10:37:06;000d;PBS_Server.1834;Job;336.csg.bcmd.bcm.edu;Not sending email: User does not want mail of this type.
11/02/2012 10:37:06;0010;PBS_Server.1834;Job;336.csg.bcmd.bcm.edu;Exit_status=0 resources_used.cput=00:00:09 resources_used.mem=43452kb resources_used.vmem=292652kb resources_used.walltime=00:00:23
11/02/2012 10:37:06;0008;PBS_Server.1831;Job;336.csg.bcmd.bcm.edu;on_job_exit valid pjob: 336.csg.bcmd.bcm.edu (substate=50)
11/02/2012 10:37:08;0040;PBS_Server.14093;Svr;csg.bcmd.bcm.edu;Scheduler was sent the command term
11/02/2012 10:37:17;0100;PBS_Server.1830;Job;337.csg.bcmd.bcm.edu;enqueuing into batch, state 1 hop 1
11/02/2012 10:37:17;0008;PBS_Server.1830;Job;337.csg.bcmd.bcm.edu;Job Queued at request of lacuesta@csg.bcmd.bcm.edu, owner = lacuesta@csg.bcmd.bcm.edu, job name = jobname1, queue = batch
11/02/2012 10:37:17;0100;PBS_Server.1832;Job;338.csg.bcmd.bcm.edu;enqueuing into batch, state 1 hop 1
11/02/2012 10:37:17;0008;PBS_Server.1832;Job;338.csg.bcmd.bcm.edu;Job Queued at request of lacuesta@csg.bcmd.bcm.edu, owner = lacuesta@csg.bcmd.bcm.edu, job name = jobname2, queue = batch
11/02/2012 10:37:18;0040;PBS_Server.14105;Svr;csg.bcmd.bcm.edu;Scheduler was sent the command new
11/02/2012 10:37:19;0008;PBS_Server.1828;Job;337.csg.bcmd.bcm.edu;Job Run at request of root@csg.bcmd.bcm.edu
11/02/2012 10:37:19;000d;PBS_Server.1828;Job;337.csg.bcmd.bcm.edu;Not sending email: User does not want mail of this type.
11/02/2012 10:37:19;0008;PBS_Server.1828;Job;338.csg.bcmd.bcm.edu;Job Run at request of root@csg.bcmd.bcm.edu
11/02/2012 10:37:19;000d;PBS_Server.1828;Job;338.csg.bcmd.bcm.edu;Not sending email: User does not want mail of this type.
11/02/2012 10:37:29;000d;PBS_Server.1834;Job;337.csg.bcmd.bcm.edu;Not sending email: User does not want mail of this type.
11/02/2012 10:37:29;0010;PBS_Server.1834;Job;337.csg.bcmd.bcm.edu;Exit_status=0 resources_used.cput=00:00:09 resources_used.mem=0kb resources_used.vmem=0kb resources_used.walltime=00:00:10
11/02/2012 10:37:29;0008;PBS_Server.1836;Job;337.csg.bcmd.bcm.edu;on_job_exit valid pjob: 337.csg.bcmd.bcm.edu (substate=50)
11/02/2012 10:37:30;000d;PBS_Server.1829;Job;338.csg.bcmd.bcm.edu;Not sending email: User does not want mail of this type.
11/02/2012 10:37:30;0010;PBS_Server.1829;Job;338.csg.bcmd.bcm.edu;Exit_status=0 resources_used.cput=00:00:10 resources_used.mem=43492kb resources_used.vmem=292624kb resources_used.walltime=00:00:11
11/02/2012 10:37:30;0008;PBS_Server.1833;Job;338.csg.bcmd.bcm.edu;on_job_exit valid pjob: 338.csg.bcmd.bcm.edu (substate=50)
11/02/2012 10:37:33;0040;PBS_Server.14128;Svr;csg.bcmd.bcm.edu;Scheduler was sent the command term
11/02/2012 10:40:33;0002;PBS_Server.1829;Svr;PBS_Server;Torque Server Version = 4.1.2, loglevel = 0
11/02/2012 10:42:18;0008;PBS_Server.1825;Job;335.csg.bcmd.bcm.edu;on_job_exit valid pjob: 335.csg.bcmd.bcm.edu (substate=59)
11/02/2012 10:42:18;0008;PBS_Server.1835;Job;336.csg.bcmd.bcm.edu;on_job_exit valid pjob: 336.csg.bcmd.bcm.edu (substate=59)
11/02/2012 10:42:18;0100;PBS_Server.1825;Job;335.csg.bcmd.bcm.edu;dequeuing from batch, state COMPLETE
11/02/2012 10:42:18;0100;PBS_Server.1835;Job;336.csg.bcmd.bcm.edu;dequeuing from batch, state COMPLETE
11/02/2012 10:42:23;0040;PBS_Server.14194;Svr;csg.bcmd.bcm.edu;Scheduler was sent the command term
11/02/2012 10:42:33;0008;PBS_Server.1827;Job;337.csg.bcmd.bcm.edu;on_job_exit valid pjob: 337.csg.bcmd.bcm.edu (substate=59)
11/02/2012 10:42:33;0100;PBS_Server.1827;Job;337.csg.bcmd.bcm.edu;dequeuing from batch, state COMPLETE
11/02/2012 10:42:33;0008;PBS_Server.1829;Job;338.csg.bcmd.bcm.edu;on_job_exit valid pjob: 338.csg.bcmd.bcm.edu (substate=59)
11/02/2012 10:42:33;0100;PBS_Server.1829;Job;338.csg.bcmd.bcm.edu;dequeuing from batch, state COMPLETE
11/02/2012 10:42:38;0040;PBS_Server.14195;Svr;csg.bcmd.bcm.edu;Scheduler was sent the command term
11/02/2012 10:45:33;0002;PBS_Server.1832;Svr;PBS_Server;Torque Server Version = 4.1.2, loglevel = 0
11/02/2012 10:46:01;0100;PBS_Server.1830;Job;339.csg.bcmd.bcm.edu;enqueuing into high, state 1 hop 1
11/02/2012 10:46:01;0008;PBS_Server.1830;Job;339.csg.bcmd.bcm.edu;Job Queued at request of jiaweixu@csg.bcmd.bcm.edu, owner = jiaweixu@csg.bcmd.bcm.edu, job name = EA_pselectin_CMC_permutation_2Nov2012, queue = high
11/02/2012 10:46:04;0040;PBS_Server.14262;Svr;csg.bcmd.bcm.edu;Scheduler was sent the command new
11/02/2012 10:46:05;0008;PBS_Server.1828;Job;339.csg.bcmd.bcm.edu;Job Run at request of root@csg.bcmd.bcm.edu
11/02/2012 10:46:05;000d;PBS_Server.1828;Job;339.csg.bcmd.bcm.edu;Not sending email: User does not want mail of this type.
11/02/2012 10:48:02;0100;PBS_Server.1832;Job;340.csg.bcmd.bcm.edu;enqueuing into high, state 1 hop 1
11/02/2012 10:48:02;0008;PBS_Server.1832;Job;340.csg.bcmd.bcm.edu;Job Queued at request of jiaweixu@csg.bcmd.bcm.edu, owner = jiaweixu@csg.bcmd.bcm.edu, job name = EA_selectin_SNV_permutation_2Nov2012, queue = high
11/02/2012 10:48:04;0040;PBS_Server.14321;Svr;csg.bcmd.bcm.edu;Scheduler was sent the command new
11/02/2012 10:48:05;0008;PBS_Server.1828;Job;340.csg.bcmd.bcm.edu;Job Run at request of root@csg.bcmd.bcm.edu
11/02/2012 10:48:05;000d;PBS_Server.1828;Job;340.csg.bcmd.bcm.edu;Not sending email: User does not want mail of this type.
11/02/2012 10:50:44;0002;PBS_Server.1826;Svr;PBS_Server;Torque Server Version = 4.1.2, loglevel = 0
11/02/2012 10:54:26;0100;PBS_Server.1829;Job;341.csg.bcmd.bcm.edu;enqueuing into high, state 1 hop 1
11/02/2012 10:54:26;0008;PBS_Server.1829;Job;341.csg.bcmd.bcm.edu;Job Queued at request of jiaweixu@csg.bcmd.bcm.edu, owner = jiaweixu@csg.bcmd.bcm.edu, job name = EA_pselectin_VT_2Nov2012, queue = high
11/02/2012 10:54:29;0040;PBS_Server.14469;Svr;csg.bcmd.bcm.edu;Scheduler was sent the command new
11/02/2012 10:54:30;000d;PBS_Server.1830;Job;339.csg.bcmd.bcm.edu;Not sending email: User does not want mail of this type.
11/02/2012 10:54:30;0010;PBS_Server.1830;Job;339.csg.bcmd.bcm.edu;Exit_status=0 resources_used.cput=00:04:34 resources_used.mem=5464kb resources_used.vmem=64712kb resources_used.walltime=00:08:24
11/02/2012 10:54:30;0008;PBS_Server.1834;Job;339.csg.bcmd.bcm.edu;on_job_exit valid pjob: 339.csg.bcmd.bcm.edu (substate=50)
11/02/2012 10:54:31;0008;PBS_Server.1828;Job;341.csg.bcmd.bcm.edu;Job Run at request of root@csg.bcmd.bcm.edu
11/02/2012 10:54:31;000d;PBS_Server.1828;Job;341.csg.bcmd.bcm.edu;Not sending email: User does not want mail of this type.
11/02/2012 10:54:34;0040;PBS_Server.14478;Svr;csg.bcmd.bcm.edu;Scheduler was sent the command term
11/02/2012 10:54:38;0100;PBS_Server.1832;Job;342.csg.bcmd.bcm.edu;enqueuing into high, state 1 hop 1
11/02/2012 10:54:38;0008;PBS_Server.1832;Job;342.csg.bcmd.bcm.edu;Job Queued at request of jiaweixu@csg.bcmd.bcm.edu, owner = jiaweixu@csg.bcmd.bcm.edu, job name = EA_pselectin_VT_2Nov2012, queue = high
11/02/2012 10:54:40;0040;PBS_Server.14483;Svr;csg.bcmd.bcm.edu;Scheduler was sent the command new
11/02/2012 10:54:41;0008;PBS_Server.1828;Job;342.csg.bcmd.bcm.edu;Job Run at request of root@csg.bcmd.bcm.edu
11/02/2012 10:54:41;000d;PBS_Server.1828;Job;342.csg.bcmd.bcm.edu;Not sending email: User does not want mail of this type.
11/02/2012 10:55:55;0002;PBS_Server.1834;Svr;PBS_Server;Torque Server Version = 4.1.2, loglevel = 0
11/02/2012 10:56:13;000d;PBS_Server.1832;Job;293.csg.bcmd.bcm.edu;Not sending email: User does not want mail of this type.
11/02/2012 10:56:13;0010;PBS_Server.1832;Job;293.csg.bcmd.bcm.edu;Exit_status=0 resources_used.cput=07:24:24 resources_used.mem=910908kb resources_used.vmem=5339892kb resources_used.walltime=05:14:10
11/02/2012 10:56:13;0008;PBS_Server.1836;Job;293.csg.bcmd.bcm.edu;on_job_exit valid pjob: 293.csg.bcmd.bcm.edu (substate=50)
11/02/2012 10:56:15;0040;PBS_Server.14566;Svr;csg.bcmd.bcm.edu;Scheduler was sent the command term
11/02/2012 10:56:35;0008;PBS_Server.1833;Job;341.csg.bcmd.bcm.edu;Job deleted at request of jiaweixu@csg.bcmd.bcm.edu
11/02/2012 10:56:35;0008;PBS_Server.1833;Job;341.csg.bcmd.bcm.edu;Job sent signal SIGTERM on delete
11/02/2012 10:56:35;000d;PBS_Server.1837;Job;341.csg.bcmd.bcm.edu;Not sending email: User does not want mail of this type.
11/02/2012 10:56:35;0010;PBS_Server.1837;Job;341.csg.bcmd.bcm.edu;Exit_status=271 resources_used.cput=00:01:10 resources_used.mem=5460kb resources_used.vmem=64712kb resources_used.walltime=00:02:04
11/02/2012 10:56:35;0008;PBS_Server.1834;Job;341.csg.bcmd.bcm.edu;on_job_exit valid pjob: 341.csg.bcmd.bcm.edu (substate=50)
11/02/2012 10:56:40;0040;PBS_Server.14594;Svr;csg.bcmd.bcm.edu;Scheduler was sent the command term
11/02/2012 10:58:42;0100;PBS_Server.1836;Job;343.csg.bcmd.bcm.edu;enqueuing into high, state 1 hop 1
11/02/2012 10:58:42;0008;PBS_Server.1836;Job;343.csg.bcmd.bcm.edu;Job Queued at request of lacuesta@csg.bcmd.bcm.edu, owner = lacuesta@csg.bcmd.bcm.edu, job name = kbjob_AA_Menopause_SNV, queue = high
11/02/2012 10:58:45;0008;PBS_Server.1828;Job;343.csg.bcmd.bcm.edu;Job Run at request of root@csg.bcmd.bcm.edu
11/02/2012 10:58:45;000d;PBS_Server.1828;Job;343.csg.bcmd.bcm.edu;Not sending email: User does not want mail of this type.
11/02/2012 10:58:45;0040;PBS_Server.14674;Svr;csg.bcmd.bcm.edu;Scheduler was sent the command new
11/02/2012 10:59:40;0008;PBS_Server.1835;Job;339.csg.bcmd.bcm.edu;on_job_exit valid pjob: 339.csg.bcmd.bcm.edu (substate=59)
11/02/2012 10:59:40;0100;PBS_Server.1835;Job;339.csg.bcmd.bcm.edu;dequeuing from high, state COMPLETE
11/02/2012 10:59:45;0040;PBS_Server.14702;Svr;csg.bcmd.bcm.edu;Scheduler was sent the command term
11/02/2012 11:00:51;0100;PBS_Server.1836;Job;344.csg.bcmd.bcm.edu;enqueuing into high, state 1 hop 1
11/02/2012 11:00:51;0008;PBS_Server.1836;Job;344.csg.bcmd.bcm.edu;Job Queued at request of lacuesta@csg.bcmd.bcm.edu, owner = lacuesta@csg.bcmd.bcm.edu, job name = kbjob_EA_Menopause_SNV, queue = high
11/02/2012 11:00:55;0002;PBS_Server.1834;Svr;PBS_Server;Torque Server Version = 4.1.2, loglevel = 0
11/02/2012 11:00:56;0040;PBS_Server.14718;Svr;csg.bcmd.bcm.edu;Scheduler was sent the command new
11/02/2012 11:00:57;0008;PBS_Server.1828;Job;344.csg.bcmd.bcm.edu;Job Run at request of root@csg.bcmd.bcm.edu
11/02/2012 11:00:57;000d;PBS_Server.1828;Job;344.csg.bcmd.bcm.edu;Not sending email: User does not want mail of this type.
11/02/2012 11:01:21;0008;PBS_Server.1837;Job;293.csg.bcmd.bcm.edu;on_job_exit valid pjob: 293.csg.bcmd.bcm.edu (substate=59)
11/02/2012 11:01:21;0100;PBS_Server.1837;Job;293.csg.bcmd.bcm.edu;dequeuing from high, state COMPLETE
11/02/2012 11:01:26;0040;PBS_Server.14726;Svr;csg.bcmd.bcm.edu;Scheduler was sent the command term
11/02/2012 11:01:36;0008;PBS_Server.1832;Job;341.csg.bcmd.bcm.edu;on_job_exit valid pjob: 341.csg.bcmd.bcm.edu (substate=59)
11/02/2012 11:01:36;0100;PBS_Server.1832;Job;341.csg.bcmd.bcm.edu;dequeuing from high, state COMPLETE
11/02/2012 11:01:41;0040;PBS_Server.14736;Svr;csg.bcmd.bcm.edu;Scheduler was sent the command term
11/02/2012 11:03:55;000d;PBS_Server.1825;Job;342.csg.bcmd.bcm.edu;Not sending email: User does not want mail of this type.
11/02/2012 11:03:55;0010;PBS_Server.1825;Job;342.csg.bcmd.bcm.edu;Exit_status=0 resources_used.cput=00:04:32 resources_used.mem=5448kb resources_used.vmem=64712kb resources_used.walltime=00:09:14
11/02/2012 11:03:55;0008;PBS_Server.1832;Job;342.csg.bcmd.bcm.edu;on_job_exit valid pjob: 342.csg.bcmd.bcm.edu (substate=50)
11/02/2012 11:03:56;0040;PBS_Server.14779;Svr;csg.bcmd.bcm.edu;Scheduler was sent the command term
11/02/2012 11:06:06;0002;PBS_Server.1832;Svr;PBS_Server;Torque Server Version = 4.1.2, loglevel = 0
11/02/2012 11:08:15;0100;PBS_Server.1831;Job;345.csg.bcmd.bcm.edu;enqueuing into high, state 1 hop 1
11/02/2012 11:08:15;0008;PBS_Server.1831;Job;345.csg.bcmd.bcm.edu;Job Queued at request of jiaweixu@csg.bcmd.bcm.edu, owner = jiaweixu@csg.bcmd.bcm.edu, job name = EA_pselectin_CMC_permutation_2Nov2012, queue = high
11/02/2012 11:08:16;0040;PBS_Server.14820;Svr;csg.bcmd.bcm.edu;Scheduler was sent the command new
11/02/2012 11:08:17;0008;PBS_Server.1828;Job;345.csg.bcmd.bcm.edu;Job Run at request of root@csg.bcmd.bcm.edu
11/02/2012 11:08:17;000d;PBS_Server.1828;Job;345.csg.bcmd.bcm.edu;Not sending email: User does not want mail of this type.
11/02/2012 11:09:06;0008;PBS_Server.1835;Job;342.csg.bcmd.bcm.edu;on_job_exit valid pjob: 342.csg.bcmd.bcm.edu (substate=59)
11/02/2012 11:09:06;0100;PBS_Server.1835;Job;342.csg.bcmd.bcm.edu;dequeuing from high, state COMPLETE
11/02/2012 11:09:11;0040;PBS_Server.14855;Svr;csg.bcmd.bcm.edu;Scheduler was sent the command term
11/02/2012 11:11:07;0002;PBS_Server.1831;Svr;PBS_Server;Torque Server Version = 4.1.2, loglevel = 0
11/02/2012 11:13:22;0100;PBS_Server.1836;Job;346.csg.bcmd.bcm.edu;enqueuing into high, state 1 hop 1
11/02/2012 11:13:22;0008;PBS_Server.1836;Job;346.csg.bcmd.bcm.edu;Job Queued at request of jiaweixu@csg.bcmd.bcm.edu, owner = jiaweixu@csg.bcmd.bcm.edu, job name = EA_pselectin_VT_2Nov2012, queue = high
11/02/2012 11:13:22;0040;PBS_Server.14906;Svr;csg.bcmd.bcm.edu;Scheduler was sent the command new
11/02/2012 11:13:23;0008;PBS_Server.1828;Job;346.csg.bcmd.bcm.edu;Job Run at request of root@csg.bcmd.bcm.edu
11/02/2012 11:13:23;000d;PBS_Server.1828;Job;346.csg.bcmd.bcm.edu;Not sending email: User does not want mail of this type.
11/02/2012 11:16:07;0002;PBS_Server.1834;Svr;PBS_Server;Torque Server Version = 4.1.2, loglevel = 0
11/02/2012 11:21:08;0002;PBS_Server.1832;Svr;PBS_Server;Torque Server Version = 4.1.2, loglevel = 0
11/02/2012 11:23:32;0040;PBS_Server.15099;Svr;csg.bcmd.bcm.edu;Scheduler was sent the command time
11/02/2012 11:25:21;0100;PBS_Server.1826;Job;347.csg.bcmd.bcm.edu;enqueuing into high, state 1 hop 1
11/02/2012 11:25:21;0008;PBS_Server.1826;Job;347.csg.bcmd.bcm.edu;Job Queued at request of lacuesta@csg.bcmd.bcm.edu, owner = lacuesta@csg.bcmd.bcm.edu, job name = EA_totchol_CMC_permutation_02Nov2012, queue = high
11/02/2012 11:25:26;0040;PBS_Server.15119;Svr;csg.bcmd.bcm.edu;Scheduler was sent the command new
11/02/2012 11:25:27;0008;PBS_Server.1825;Job;347.csg.bcmd.bcm.edu;Job Run at request of root@csg.bcmd.bcm.edu
11/02/2012 11:25:27;000d;PBS_Server.1825;Job;347.csg.bcmd.bcm.edu;Not sending email: User does not want mail of this type.
11/02/2012 11:26:22;0002;PBS_Server.1830;Svr;PBS_Server;Torque Server Version = 4.1.2, loglevel = 0
11/02/2012 11:31:22;0002;PBS_Server.1827;Svr;PBS_Server;Torque Server Version = 4.1.2, loglevel = 0
11/02/2012 11:35:43;0040;PBS_Server.15221;Svr;csg.bcmd.bcm.edu;Scheduler was sent the command time
11/02/2012 11:36:23;0002;PBS_Server.1837;Svr;PBS_Server;Torque Server Version = 4.1.2, loglevel = 0
11/02/2012 11:38:12;0100;PBS_Server.1826;Job;348.csg.bcmd.bcm.edu;enqueuing into batch, state 1 hop 1
11/02/2012 11:38:12;0008;PBS_Server.1826;Job;348.csg.bcmd.bcm.edu;Job Queued at request of lacuesta@csg.bcmd.bcm.edu, owner = lacuesta@csg.bcmd.bcm.edu, job name = jobname1, queue = batch
11/02/2012 11:38:12;0100;PBS_Server.1833;Job;349.csg.bcmd.bcm.edu;enqueuing into batch, state 1 hop 1
11/02/2012 11:38:12;0008;PBS_Server.1833;Job;349.csg.bcmd.bcm.edu;Job Queued at request of lacuesta@csg.bcmd.bcm.edu, owner = lacuesta@csg.bcmd.bcm.edu, job name = jobname2, queue = batch
11/02/2012 11:38:13;0040;PBS_Server.15242;Svr;csg.bcmd.bcm.edu;Scheduler was sent the command new
11/02/2012 11:38:14;0008;PBS_Server.1825;Job;348.csg.bcmd.bcm.edu;Job Run at request of root@csg.bcmd.bcm.edu
11/02/2012 11:38:14;000d;PBS_Server.1825;Job;348.csg.bcmd.bcm.edu;Not sending email: User does not want mail of this type.
11/02/2012 11:38:14;0008;PBS_Server.1825;Job;349.csg.bcmd.bcm.edu;Job Run at request of root@csg.bcmd.bcm.edu
11/02/2012 11:38:14;000d;PBS_Server.1825;Job;349.csg.bcmd.bcm.edu;Not sending email: User does not want mail of this type.
11/02/2012 11:38:21;0100;PBS_Server.1828;Job;350.csg.bcmd.bcm.edu;enqueuing into batch, state 1 hop 1
11/02/2012 11:38:21;0008;PBS_Server.1828;Job;350.csg.bcmd.bcm.edu;Job Queued at request of lacuesta@csg.bcmd.bcm.edu, owner = lacuesta@csg.bcmd.bcm.edu, job name = jobname1, queue = batch
11/02/2012 11:38:21;0100;PBS_Server.1827;Job;351.csg.bcmd.bcm.edu;enqueuing into batch, state 1 hop 1
11/02/2012 11:38:21;0008;PBS_Server.1827;Job;351.csg.bcmd.bcm.edu;Job Queued at request of lacuesta@csg.bcmd.bcm.edu, owner = lacuesta@csg.bcmd.bcm.edu, job name = jobname2, queue = batch
11/02/2012 11:38:23;0040;PBS_Server.15252;Svr;csg.bcmd.bcm.edu;Scheduler was sent the command new
11/02/2012 11:38:24;0008;PBS_Server.1825;Job;350.csg.bcmd.bcm.edu;Job Run at request of root@csg.bcmd.bcm.edu
11/02/2012 11:38:24;000d;PBS_Server.1825;Job;350.csg.bcmd.bcm.edu;Not sending email: User does not want mail of this type.
11/02/2012 11:38:24;0008;PBS_Server.1825;Job;351.csg.bcmd.bcm.edu;Job Run at request of root@csg.bcmd.bcm.edu
11/02/2012 11:38:24;000d;PBS_Server.1825;Job;351.csg.bcmd.bcm.edu;Not sending email: User does not want mail of this type.
11/02/2012 11:38:36;0100;PBS_Server.1828;Job;352.csg.bcmd.bcm.edu;enqueuing into batch, state 1 hop 1
11/02/2012 11:38:36;0008;PBS_Server.1828;Job;352.csg.bcmd.bcm.edu;Job Queued at request of lacuesta@csg.bcmd.bcm.edu, owner = lacuesta@csg.bcmd.bcm.edu, job name = jobname1, queue = batch
11/02/2012 11:38:36;0100;PBS_Server.1827;Job;353.csg.bcmd.bcm.edu;enqueuing into batch, state 1 hop 1
11/02/2012 11:38:36;0008;PBS_Server.1827;Job;353.csg.bcmd.bcm.edu;Job Queued at request of lacuesta@csg.bcmd.bcm.edu, owner = lacuesta@csg.bcmd.bcm.edu, job name = jobname2, queue = batch
11/02/2012 11:38:38;000d;PBS_Server.1834;Job;350.csg.bcmd.bcm.edu;Not sending email: User does not want mail of this type.
11/02/2012 11:38:38;0010;PBS_Server.1834;Job;350.csg.bcmd.bcm.edu;Exit_status=0 resources_used.cput=00:00:09 resources_used.mem=38692kb resources_used.vmem=287744kb resources_used.walltime=00:00:14
11/02/2012 11:38:38;0008;PBS_Server.1826;Job;350.csg.bcmd.bcm.edu;on_job_exit valid pjob: 350.csg.bcmd.bcm.edu (substate=50)
11/02/2012 11:38:38;000d;PBS_Server.1832;Job;348.csg.bcmd.bcm.edu;Not sending email: User does not want mail of this type.
11/02/2012 11:38:38;0010;PBS_Server.1832;Job;348.csg.bcmd.bcm.edu;Exit_status=0 resources_used.cput=00:00:09 resources_used.mem=57532kb resources_used.vmem=287744kb resources_used.walltime=00:00:24
11/02/2012 11:38:38;0008;PBS_Server.1830;Job;348.csg.bcmd.bcm.edu;on_job_exit valid pjob: 348.csg.bcmd.bcm.edu (substate=50)
11/02/2012 11:38:38;0040;PBS_Server.15278;Svr;csg.bcmd.bcm.edu;Scheduler was sent the command term
11/02/2012 11:38:39;000d;PBS_Server.1827;Job;349.csg.bcmd.bcm.edu;Not sending email: User does not want mail of this type.
11/02/2012 11:38:39;0010;PBS_Server.1827;Job;349.csg.bcmd.bcm.edu;Exit_status=0 resources_used.cput=00:00:10 resources_used.mem=43828kb resources_used.vmem=292996kb resources_used.walltime=00:00:25
11/02/2012 11:38:39;0008;PBS_Server.1831;Job;349.csg.bcmd.bcm.edu;on_job_exit valid pjob: 349.csg.bcmd.bcm.edu (substate=50)
11/02/2012 11:38:39;0008;PBS_Server.1825;Job;352.csg.bcmd.bcm.edu;Job Run at request of root@csg.bcmd.bcm.edu
11/02/2012 11:38:39;000d;PBS_Server.1825;Job;352.csg.bcmd.bcm.edu;Not sending email: User does not want mail of this type.
11/02/2012 11:38:39;0008;PBS_Server.1825;Job;353.csg.bcmd.bcm.edu;Job Run at request of root@csg.bcmd.bcm.edu
11/02/2012 11:38:39;000d;PBS_Server.1825;Job;353.csg.bcmd.bcm.edu;Not sending email: User does not want mail of this type.
11/02/2012 11:38:39;000d;PBS_Server.1837;Job;351.csg.bcmd.bcm.edu;Not sending email: User does not want mail of this type.
11/02/2012 11:38:39;0010;PBS_Server.1837;Job;351.csg.bcmd.bcm.edu;Exit_status=0 resources_used.cput=00:00:10 resources_used.mem=53164kb resources_used.vmem=292948kb resources_used.walltime=00:00:15
11/02/2012 11:38:39;0008;PBS_Server.1832;Job;351.csg.bcmd.bcm.edu;on_job_exit valid pjob: 351.csg.bcmd.bcm.edu (substate=50)
11/02/2012 11:38:43;0040;PBS_Server.15295;Svr;csg.bcmd.bcm.edu;Scheduler was sent the command term
11/02/2012 11:38:45;0100;PBS_Server.1829;Job;354.csg.bcmd.bcm.edu;enqueuing into batch, state 1 hop 1
11/02/2012 11:38:45;0008;PBS_Server.1829;Job;354.csg.bcmd.bcm.edu;Job Queued at request of lacuesta@csg.bcmd.bcm.edu, owner = lacuesta@csg.bcmd.bcm.edu, job name = jobname1, queue = batch
11/02/2012 11:38:45;0100;PBS_Server.1836;Job;355.csg.bcmd.bcm.edu;enqueuing into batch, state 1 hop 1
11/02/2012 11:38:45;0008;PBS_Server.1836;Job;355.csg.bcmd.bcm.edu;Job Queued at request of lacuesta@csg.bcmd.bcm.edu, owner = lacuesta@csg.bcmd.bcm.edu, job name = jobname2, queue = batch
11/02/2012 11:38:48;0040;PBS_Server.15305;Svr;csg.bcmd.bcm.edu;Scheduler was sent the command new
11/02/2012 11:38:48;000d;PBS_Server.1833;Job;352.csg.bcmd.bcm.edu;Not sending email: User does not want mail of this type.
11/02/2012 11:38:48;0010;PBS_Server.1833;Job;352.csg.bcmd.bcm.edu;Exit_status=0 resources_used.cput=00:00:09 resources_used.mem=33524kb resources_used.vmem=107224kb resources_used.walltime=00:00:09
11/02/2012 11:38:48;0008;PBS_Server.1831;Job;352.csg.bcmd.bcm.edu;on_job_exit valid pjob: 352.csg.bcmd.bcm.edu (substate=50)
11/02/2012 11:38:49;0008;PBS_Server.1825;Job;354.csg.bcmd.bcm.edu;Job Run at request of root@csg.bcmd.bcm.edu
11/02/2012 11:38:49;000d;PBS_Server.1825;Job;354.csg.bcmd.bcm.edu;Not sending email: User does not want mail of this type.
11/02/2012 11:38:49;0008;PBS_Server.1825;Job;355.csg.bcmd.bcm.edu;Job Run at request of root@csg.bcmd.bcm.edu
11/02/2012 11:38:49;000d;PBS_Server.1825;Job;355.csg.bcmd.bcm.edu;Not sending email: User does not want mail of this type.
11/02/2012 11:38:50;000d;PBS_Server.1828;Job;353.csg.bcmd.bcm.edu;Not sending email: User does not want mail of this type.
11/02/2012 11:38:50;0010;PBS_Server.1828;Job;353.csg.bcmd.bcm.edu;Exit_status=0 resources_used.cput=00:00:10 resources_used.mem=43216kb resources_used.vmem=292084kb resources_used.walltime=00:00:11
11/02/2012 11:38:50;0008;PBS_Server.1829;Job;353.csg.bcmd.bcm.edu;on_job_exit valid pjob: 353.csg.bcmd.bcm.edu (substate=50)
11/02/2012 11:38:53;0040;PBS_Server.15324;Svr;csg.bcmd.bcm.edu;Scheduler was sent the command term
11/02/2012 11:38:59;000d;PBS_Server.1830;Job;354.csg.bcmd.bcm.edu;Not sending email: User does not want mail of this type.
11/02/2012 11:38:59;0010;PBS_Server.1830;Job;354.csg.bcmd.bcm.edu;Exit_status=0 resources_used.cput=00:00:09 resources_used.mem=76820kb resources_used.vmem=203080kb resources_used.walltime=00:00:10
11/02/2012 11:38:59;0008;PBS_Server.1837;Job;354.csg.bcmd.bcm.edu;on_job_exit valid pjob: 354.csg.bcmd.bcm.edu (substate=50)
11/02/2012 11:38:59;000d;PBS_Server.1835;Job;355.csg.bcmd.bcm.edu;Not sending email: User does not want mail of this type.
11/02/2012 11:38:59;0010;PBS_Server.1835;Job;355.csg.bcmd.bcm.edu;Exit_status=0 resources_used.cput=00:00:10 resources_used.mem=86396kb resources_used.vmem=292948kb resources_used.walltime=00:00:10
11/02/2012 11:38:59;0008;PBS_Server.1833;Job;355.csg.bcmd.bcm.edu;on_job_exit valid pjob: 355.csg.bcmd.bcm.edu (substate=50)
11/02/2012 11:39:00;0100;PBS_Server.1829;Job;356.csg.bcmd.bcm.edu;enqueuing into batch, state 1 hop 1
11/02/2012 11:39:00;0008;PBS_Server.1829;Job;356.csg.bcmd.bcm.edu;Job Queued at request of lacuesta@csg.bcmd.bcm.edu, owner = lacuesta@csg.bcmd.bcm.edu, job name = jobname1, queue = batch
11/02/2012 11:39:00;0100;PBS_Server.1834;Job;357.csg.bcmd.bcm.edu;enqueuing into batch, state 1 hop 1
11/02/2012 11:39:00;0008;PBS_Server.1834;Job;357.csg.bcmd.bcm.edu;Job Queued at request of lacuesta@csg.bcmd.bcm.edu, owner = lacuesta@csg.bcmd.bcm.edu, job name = jobname2, queue = batch
11/02/2012 11:39:03;0040;PBS_Server.15350;Svr;csg.bcmd.bcm.edu;Scheduler was sent the command new
11/02/2012 11:39:04;0008;PBS_Server.1825;Job;356.csg.bcmd.bcm.edu;Job Run at request of root@csg.bcmd.bcm.edu
11/02/2012 11:39:04;000d;PBS_Server.1825;Job;356.csg.bcmd.bcm.edu;Not sending email: User does not want mail of this type.
11/02/2012 11:39:04;0008;PBS_Server.1825;Job;357.csg.bcmd.bcm.edu;Job Run at request of root@csg.bcmd.bcm.edu
11/02/2012 11:39:04;000d;PBS_Server.1825;Job;357.csg.bcmd.bcm.edu;Not sending email: User does not want mail of this type.
11/02/2012 11:39:14;000d;PBS_Server.1830;Job;356.csg.bcmd.bcm.edu;Not sending email: User does not want mail of this type.
11/02/2012 11:39:14;0010;PBS_Server.1830;Job;356.csg.bcmd.bcm.edu;Exit_status=0 resources_used.cput=00:00:09 resources_used.mem=0kb resources_used.vmem=0kb resources_used.walltime=00:00:10
11/02/2012 11:39:14;0008;PBS_Server.1837;Job;356.csg.bcmd.bcm.edu;on_job_exit valid pjob: 356.csg.bcmd.bcm.edu (substate=50)
11/02/2012 11:39:14;000d;PBS_Server.1832;Job;357.csg.bcmd.bcm.edu;Not sending email: User does not want mail of this type.
11/02/2012 11:39:14;0010;PBS_Server.1832;Job;357.csg.bcmd.bcm.edu;Exit_status=0 resources_used.cput=00:00:09 resources_used.mem=60556kb resources_used.vmem=214776kb resources_used.walltime=00:00:10
11/02/2012 11:39:14;0008;PBS_Server.1836;Job;357.csg.bcmd.bcm.edu;on_job_exit valid pjob: 357.csg.bcmd.bcm.edu (substate=50)
11/02/2012 11:39:18;0040;PBS_Server.15367;Svr;csg.bcmd.bcm.edu;Scheduler was sent the command term
11/02/2012 11:39:18;0100;PBS_Server.1829;Job;358.csg.bcmd.bcm.edu;enqueuing into batch, state 1 hop 1
11/02/2012 11:39:18;0008;PBS_Server.1829;Job;358.csg.bcmd.bcm.edu;Job Queued at request of lacuesta@csg.bcmd.bcm.edu, owner = lacuesta@csg.bcmd.bcm.edu, job name = jobname1, queue = batch
11/02/2012 11:39:19;0100;PBS_Server.1834;Job;359.csg.bcmd.bcm.edu;enqueuing into batch, state 1 hop 1
11/02/2012 11:39:19;0008;PBS_Server.1834;Job;359.csg.bcmd.bcm.edu;Job Queued at request of lacuesta@csg.bcmd.bcm.edu, owner = lacuesta@csg.bcmd.bcm.edu, job name = jobname2, queue = batch
11/02/2012 11:39:19;0008;PBS_Server.1825;Job;358.csg.bcmd.bcm.edu;Job Run at request of root@csg.bcmd.bcm.edu
11/02/2012 11:39:19;000d;PBS_Server.1825;Job;358.csg.bcmd.bcm.edu;Not sending email: User does not want mail of this type.
11/02/2012 11:39:19;0008;PBS_Server.1825;Job;359.csg.bcmd.bcm.edu;Job Run at request of root@csg.bcmd.bcm.edu
11/02/2012 11:39:19;000d;PBS_Server.1825;Job;359.csg.bcmd.bcm.edu;Not sending email: User does not want mail of this type.
11/02/2012 11:39:23;0040;PBS_Server.15377;Svr;csg.bcmd.bcm.edu;Scheduler was sent the command new
11/02/2012 11:40:03;000d;PBS_Server.1829;Job;358.csg.bcmd.bcm.edu;Not sending email: User does not want mail of this type.
11/02/2012 11:40:03;0010;PBS_Server.1829;Job;358.csg.bcmd.bcm.edu;Exit_status=0 resources_used.cput=00:00:09 resources_used.mem=1124kb resources_used.vmem=13560kb resources_used.walltime=00:00:43
11/02/2012 11:40:03;0008;PBS_Server.1827;Job;358.csg.bcmd.bcm.edu;on_job_exit valid pjob: 358.csg.bcmd.bcm.edu (substate=50)
11/02/2012 11:40:03;0040;PBS_Server.15394;Svr;csg.bcmd.bcm.edu;Scheduler was sent the command term
11/02/2012 11:40:04;000d;PBS_Server.1836;Job;359.csg.bcmd.bcm.edu;Not sending email: User does not want mail of this type.
11/02/2012 11:40:04;0010;PBS_Server.1836;Job;359.csg.bcmd.bcm.edu;Exit_status=0 resources_used.cput=00:00:10 resources_used.mem=43556kb resources_used.vmem=292988kb resources_used.walltime=00:00:45
11/02/2012 11:40:04;0008;PBS_Server.1831;Job;359.csg.bcmd.bcm.edu;on_job_exit valid pjob: 359.csg.bcmd.bcm.edu (substate=50)
11/02/2012 11:40:08;0040;PBS_Server.15405;Svr;csg.bcmd.bcm.edu;Scheduler was sent the command term
11/02/2012 11:41:23;0002;PBS_Server.1834;Svr;PBS_Server;Torque Server Version = 4.1.2, loglevel = 0
11/02/2012 11:43:38;0008;PBS_Server.1836;Job;350.csg.bcmd.bcm.edu;on_job_exit valid pjob: 350.csg.bcmd.bcm.edu (substate=59)
11/02/2012 11:43:38;0008;PBS_Server.1833;Job;348.csg.bcmd.bcm.edu;on_job_exit valid pjob: 348.csg.bcmd.bcm.edu (substate=59)
11/02/2012 11:43:38;0100;PBS_Server.1833;Job;348.csg.bcmd.bcm.edu;dequeuing from batch, state COMPLETE
11/02/2012 11:43:38;0100;PBS_Server.1836;Job;350.csg.bcmd.bcm.edu;dequeuing from batch, state COMPLETE
11/02/2012 11:43:44;0040;PBS_Server.15440;Svr;csg.bcmd.bcm.edu;Scheduler was sent the command term
11/02/2012 11:43:53;0008;PBS_Server.1827;Job;353.csg.bcmd.bcm.edu;on_job_exit valid pjob: 353.csg.bcmd.bcm.edu (substate=59)
11/02/2012 11:43:53;0008;PBS_Server.1826;Job;351.csg.bcmd.bcm.edu;on_job_exit valid pjob: 351.csg.bcmd.bcm.edu (substate=59)
11/02/2012 11:43:53;0008;PBS_Server.1833;Job;349.csg.bcmd.bcm.edu;on_job_exit valid pjob: 349.csg.bcmd.bcm.edu (substate=59)
11/02/2012 11:43:53;0100;PBS_Server.1827;Job;353.csg.bcmd.bcm.edu;dequeuing from batch, state COMPLETE
11/02/2012 11:43:53;0100;PBS_Server.1833;Job;349.csg.bcmd.bcm.edu;dequeuing from batch, state COMPLETE
11/02/2012 11:43:53;0100;PBS_Server.1826;Job;351.csg.bcmd.bcm.edu;dequeuing from batch, state COMPLETE
11/02/2012 11:43:53;0008;PBS_Server.1836;Job;352.csg.bcmd.bcm.edu;on_job_exit valid pjob: 352.csg.bcmd.bcm.edu (substate=59)
11/02/2012 11:43:53;0100;PBS_Server.1836;Job;352.csg.bcmd.bcm.edu;dequeuing from batch, state COMPLETE
11/02/2012 11:43:59;0040;PBS_Server.15445;Svr;csg.bcmd.bcm.edu;Scheduler was sent the command term
11/02/2012 11:44:08;0008;PBS_Server.1828;Job;354.csg.bcmd.bcm.edu;on_job_exit valid pjob: 354.csg.bcmd.bcm.edu (substate=59)
11/02/2012 11:44:08;0008;PBS_Server.1829;Job;355.csg.bcmd.bcm.edu;on_job_exit valid pjob: 355.csg.bcmd.bcm.edu (substate=59)
11/02/2012 11:44:08;0100;PBS_Server.1828;Job;354.csg.bcmd.bcm.edu;dequeuing from batch, state COMPLETE
11/02/2012 11:44:08;0100;PBS_Server.1829;Job;355.csg.bcmd.bcm.edu;dequeuing from batch, state COMPLETE
11/02/2012 11:44:14;0040;PBS_Server.15448;Svr;csg.bcmd.bcm.edu;Scheduler was sent the command term
11/02/2012 11:44:19;0008;PBS_Server.1828;Job;356.csg.bcmd.bcm.edu;on_job_exit valid pjob: 356.csg.bcmd.bcm.edu (substate=59)
11/02/2012 11:44:19;0008;PBS_Server.1827;Job;357.csg.bcmd.bcm.edu;on_job_exit valid pjob: 357.csg.bcmd.bcm.edu (substate=59)
11/02/2012 11:44:19;0100;PBS_Server.1828;Job;356.csg.bcmd.bcm.edu;dequeuing from batch, state COMPLETE
11/02/2012 11:44:19;0100;PBS_Server.1827;Job;357.csg.bcmd.bcm.edu;dequeuing from batch, state COMPLETE
11/02/2012 11:44:24;0040;PBS_Server.15449;Svr;csg.bcmd.bcm.edu;Scheduler was sent the command term
11/02/2012 11:45:04;0008;PBS_Server.1833;Job;359.csg.bcmd.bcm.edu;on_job_exit valid pjob: 359.csg.bcmd.bcm.edu (substate=59)
11/02/2012 11:45:04;0008;PBS_Server.1827;Job;358.csg.bcmd.bcm.edu;on_job_exit valid pjob: 358.csg.bcmd.bcm.edu (substate=59)
11/02/2012 11:45:04;0100;PBS_Server.1833;Job;359.csg.bcmd.bcm.edu;dequeuing from batch, state COMPLETE
11/02/2012 11:45:04;0100;PBS_Server.1827;Job;358.csg.bcmd.bcm.edu;dequeuing from batch, state COMPLETE
11/02/2012 11:45:09;0040;PBS_Server.15455;Svr;csg.bcmd.bcm.edu;Scheduler was sent the command term
11/02/2012 11:46:34;0002;PBS_Server.1836;Svr;PBS_Server;Torque Server Version = 4.1.2, loglevel = 0
11/02/2012 11:51:34;0002;PBS_Server.1836;Svr;PBS_Server;Torque Server Version = 4.1.2, loglevel = 0
11/02/2012 11:55:20;0040;PBS_Server.15663;Svr;csg.bcmd.bcm.edu;Scheduler was sent the command time
11/02/2012 11:55:33;0100;PBS_Server.1837;Job;360.csg.bcmd.bcm.edu;enqueuing into batch, state 1 hop 1
11/02/2012 11:55:33;0008;PBS_Server.1837;Job;360.csg.bcmd.bcm.edu;Job Queued at request of lacuesta@csg.bcmd.bcm.edu, owner = lacuesta@csg.bcmd.bcm.edu, job name = jobname1, queue = batch
11/02/2012 11:55:33;0100;PBS_Server.1831;Job;361.csg.bcmd.bcm.edu;enqueuing into batch, state 1 hop 1
11/02/2012 11:55:33;0008;PBS_Server.1831;Job;361.csg.bcmd.bcm.edu;Job Queued at request of lacuesta@csg.bcmd.bcm.edu, owner = lacuesta@csg.bcmd.bcm.edu, job name = jobname2, queue = batch
11/02/2012 11:55:35;0040;PBS_Server.15673;Svr;csg.bcmd.bcm.edu;Scheduler was sent the command new
11/02/2012 11:55:36;0008;PBS_Server.1825;Job;360.csg.bcmd.bcm.edu;Job Run at request of root@csg.bcmd.bcm.edu
11/02/2012 11:55:36;000d;PBS_Server.1825;Job;360.csg.bcmd.bcm.edu;Not sending email: User does not want mail of this type.
11/02/2012 11:55:36;0008;PBS_Server.1825;Job;361.csg.bcmd.bcm.edu;Job Run at request of root@csg.bcmd.bcm.edu
11/02/2012 11:55:36;000d;PBS_Server.1825;Job;361.csg.bcmd.bcm.edu;Not sending email: User does not want mail of this type.
11/02/2012 11:55:48;000d;PBS_Server.1827;Job;361.csg.bcmd.bcm.edu;Not sending email: User does not want mail of this type.
11/02/2012 11:55:48;0010;PBS_Server.1827;Job;361.csg.bcmd.bcm.edu;Exit_status=1 resources_used.cput=00:00:00 resources_used.mem=0kb resources_used.vmem=0kb resources_used.walltime=00:00:12
11/02/2012 11:55:48;0008;PBS_Server.1826;Job;361.csg.bcmd.bcm.edu;on_job_exit valid pjob: 361.csg.bcmd.bcm.edu (substate=50)
11/02/2012 11:55:49;000d;PBS_Server.1835;Job;360.csg.bcmd.bcm.edu;Not sending email: User does not want mail of this type.
11/02/2012 11:55:49;0010;PBS_Server.1835;Job;360.csg.bcmd.bcm.edu;Exit_status=1 resources_used.cput=00:00:00 resources_used.mem=3444kb resources_used.vmem=37616kb resources_used.walltime=00:00:13
11/02/2012 11:55:49;0008;PBS_Server.1831;Job;360.csg.bcmd.bcm.edu;on_job_exit valid pjob: 360.csg.bcmd.bcm.edu (substate=50)
11/02/2012 11:55:50;0040;PBS_Server.15691;Svr;csg.bcmd.bcm.edu;Scheduler was sent the command term
11/02/2012 11:55:58;0100;PBS_Server.1829;Job;362.csg.bcmd.bcm.edu;enqueuing into batch, state 1 hop 1
11/02/2012 11:55:58;0008;PBS_Server.1829;Job;362.csg.bcmd.bcm.edu;Job Queued at request of lacuesta@csg.bcmd.bcm.edu, owner = lacuesta@csg.bcmd.bcm.edu, job name = jobname1, queue = batch
11/02/2012 11:55:59;0100;PBS_Server.1832;Job;363.csg.bcmd.bcm.edu;enqueuing into batch, state 1 hop 1
11/02/2012 11:55:59;0008;PBS_Server.1832;Job;363.csg.bcmd.bcm.edu;Job Queued at request of lacuesta@csg.bcmd.bcm.edu, owner = lacuesta@csg.bcmd.bcm.edu, job name = jobname2, queue = batch
11/02/2012 11:56:00;0040;PBS_Server.15702;Svr;csg.bcmd.bcm.edu;Scheduler was sent the command new
11/02/2012 11:56:01;0008;PBS_Server.1825;Job;362.csg.bcmd.bcm.edu;Job Run at request of root@csg.bcmd.bcm.edu
11/02/2012 11:56:01;000d;PBS_Server.1825;Job;362.csg.bcmd.bcm.edu;Not sending email: User does not want mail of this type.
11/02/2012 11:56:01;0008;PBS_Server.1825;Job;363.csg.bcmd.bcm.edu;Job Run at request of root@csg.bcmd.bcm.edu
11/02/2012 11:56:01;000d;PBS_Server.1825;Job;363.csg.bcmd.bcm.edu;Not sending email: User does not want mail of this type.
11/02/2012 11:56:01;000d;PBS_Server.1827;Job;362.csg.bcmd.bcm.edu;Not sending email: User does not want mail of this type.
11/02/2012 11:56:01;0010;PBS_Server.1827;Job;362.csg.bcmd.bcm.edu;Exit_status=1 resources_used.cput=00:00:00 resources_used.mem=0kb resources_used.vmem=0kb resources_used.walltime=00:00:00
11/02/2012 11:56:01;0008;PBS_Server.1832;Job;362.csg.bcmd.bcm.edu;on_job_exit valid pjob: 362.csg.bcmd.bcm.edu (substate=50)
11/02/2012 11:56:01;000d;PBS_Server.1826;Job;363.csg.bcmd.bcm.edu;Not sending email: User does not want mail of this type.
11/02/2012 11:56:01;0010;PBS_Server.1826;Job;363.csg.bcmd.bcm.edu;Exit_status=1 resources_used.cput=00:00:00 resources_used.mem=0kb resources_used.vmem=0kb resources_used.walltime=00:00:00
11/02/2012 11:56:01;0008;PBS_Server.1833;Job;363.csg.bcmd.bcm.edu;on_job_exit valid pjob: 363.csg.bcmd.bcm.edu (substate=50)
11/02/2012 11:56:05;0040;PBS_Server.15721;Svr;csg.bcmd.bcm.edu;Scheduler was sent the command term
11/02/2012 11:56:45;0002;PBS_Server.1835;Svr;PBS_Server;Torque Server Version = 4.1.2, loglevel = 0
11/02/2012 11:58:11;0100;PBS_Server.1837;Job;364.csg.bcmd.bcm.edu;enqueuing into batch, state 1 hop 1
11/02/2012 11:58:11;0008;PBS_Server.1837;Job;364.csg.bcmd.bcm.edu;Job Queued at request of lacuesta@csg.bcmd.bcm.edu, owner = lacuesta@csg.bcmd.bcm.edu, job name = jobname1, queue = batch
11/02/2012 11:58:11;0100;PBS_Server.1827;Job;365.csg.bcmd.bcm.edu;enqueuing into batch, state 1 hop 1
11/02/2012 11:58:11;0008;PBS_Server.1827;Job;365.csg.bcmd.bcm.edu;Job Queued at request of lacuesta@csg.bcmd.bcm.edu, owner = lacuesta@csg.bcmd.bcm.edu, job name = jobname2, queue = batch
11/02/2012 11:58:15;0040;PBS_Server.15752;Svr;csg.bcmd.bcm.edu;Scheduler was sent the command new
11/02/2012 11:58:15;0100;PBS_Server.1837;Job;366.csg.bcmd.bcm.edu;enqueuing into batch, state 1 hop 1
11/02/2012 11:58:15;0008;PBS_Server.1837;Job;366.csg.bcmd.bcm.edu;Job Queued at request of lacuesta@csg.bcmd.bcm.edu, owner = lacuesta@csg.bcmd.bcm.edu, job name = jobname1, queue = batch
11/02/2012 11:58:15;0100;PBS_Server.1827;Job;367.csg.bcmd.bcm.edu;enqueuing into batch, state 1 hop 1
11/02/2012 11:58:15;0008;PBS_Server.1827;Job;367.csg.bcmd.bcm.edu;Job Queued at request of lacuesta@csg.bcmd.bcm.edu, owner = lacuesta@csg.bcmd.bcm.edu, job name = jobname2, queue = batch
11/02/2012 11:58:16;0008;PBS_Server.1825;Job;364.csg.bcmd.bcm.edu;Job Run at request of root@csg.bcmd.bcm.edu
11/02/2012 11:58:16;000d;PBS_Server.1825;Job;364.csg.bcmd.bcm.edu;Not sending email: User does not want mail of this type.
11/02/2012 11:58:16;0008;PBS_Server.1825;Job;365.csg.bcmd.bcm.edu;Job Run at request of root@csg.bcmd.bcm.edu
11/02/2012 11:58:16;000d;PBS_Server.1825;Job;365.csg.bcmd.bcm.edu;Not sending email: User does not want mail of this type.
11/02/2012 11:58:16;0008;PBS_Server.1825;Job;366.csg.bcmd.bcm.edu;Job Run at request of root@csg.bcmd.bcm.edu
11/02/2012 11:58:16;000d;PBS_Server.1825;Job;366.csg.bcmd.bcm.edu;Not sending email: User does not want mail of this type.
11/02/2012 11:58:16;0008;PBS_Server.1825;Job;367.csg.bcmd.bcm.edu;Job Run at request of root@csg.bcmd.bcm.edu
11/02/2012 11:58:16;000d;PBS_Server.1825;Job;367.csg.bcmd.bcm.edu;Not sending email: User does not want mail of this type.
11/02/2012 11:58:20;0040;PBS_Server.15761;Svr;csg.bcmd.bcm.edu;Scheduler was sent the command new
11/02/2012 11:58:33;000d;PBS_Server.1833;Job;364.csg.bcmd.bcm.edu;Not sending email: User does not want mail of this type.
11/02/2012 11:58:33;0010;PBS_Server.1833;Job;364.csg.bcmd.bcm.edu;Exit_status=0 resources_used.cput=00:00:09 resources_used.mem=0kb resources_used.vmem=0kb resources_used.walltime=00:00:17
11/02/2012 11:58:33;0008;PBS_Server.1835;Job;364.csg.bcmd.bcm.edu;on_job_exit valid pjob: 364.csg.bcmd.bcm.edu (substate=50)
11/02/2012 11:58:33;000d;PBS_Server.1828;Job;366.csg.bcmd.bcm.edu;Not sending email: User does not want mail of this type.
11/02/2012 11:58:33;0010;PBS_Server.1828;Job;366.csg.bcmd.bcm.edu;Exit_status=0 resources_used.cput=00:00:09 resources_used.mem=56984kb resources_used.vmem=292572kb resources_used.walltime=00:00:17
11/02/2012 11:58:33;0008;PBS_Server.1836;Job;366.csg.bcmd.bcm.edu;on_job_exit valid pjob: 366.csg.bcmd.bcm.edu (substate=50)
11/02/2012 11:58:34;000d;PBS_Server.1837;Job;365.csg.bcmd.bcm.edu;Not sending email: User does not want mail of this type.
11/02/2012 11:58:34;0010;PBS_Server.1837;Job;365.csg.bcmd.bcm.edu;Exit_status=0 resources_used.cput=00:00:10 resources_used.mem=62072kb resources_used.vmem=293348kb resources_used.walltime=00:00:18
11/02/2012 11:58:34;0008;PBS_Server.1832;Job;365.csg.bcmd.bcm.edu;on_job_exit valid pjob: 365.csg.bcmd.bcm.edu (substate=50)
11/02/2012 11:58:34;000d;PBS_Server.1833;Job;367.csg.bcmd.bcm.edu;Not sending email: User does not want mail of this type.
11/02/2012 11:58:34;0010;PBS_Server.1833;Job;367.csg.bcmd.bcm.edu;Exit_status=0 resources_used.cput=00:00:10 resources_used.mem=70384kb resources_used.vmem=292624kb resources_used.walltime=00:00:18
11/02/2012 11:58:34;0008;PBS_Server.1831;Job;367.csg.bcmd.bcm.edu;on_job_exit valid pjob: 367.csg.bcmd.bcm.edu (substate=50)
11/02/2012 11:58:35;0040;PBS_Server.15801;Svr;csg.bcmd.bcm.edu;Scheduler was sent the command term
11/02/2012 12:01:00;0008;PBS_Server.1830;Job;361.csg.bcmd.bcm.edu;on_job_exit valid pjob: 361.csg.bcmd.bcm.edu (substate=59)
11/02/2012 12:01:00;0100;PBS_Server.1830;Job;361.csg.bcmd.bcm.edu;dequeuing from batch, state COMPLETE
11/02/2012 12:01:00;0008;PBS_Server.1827;Job;360.csg.bcmd.bcm.edu;on_job_exit valid pjob: 360.csg.bcmd.bcm.edu (substate=59)
11/02/2012 12:01:00;0100;PBS_Server.1827;Job;360.csg.bcmd.bcm.edu;dequeuing from batch, state COMPLETE
11/02/2012 12:01:05;0040;PBS_Server.15871;Svr;csg.bcmd.bcm.edu;Scheduler was sent the command term
11/02/2012 12:01:15;0008;PBS_Server.1826;Job;362.csg.bcmd.bcm.edu;on_job_exit valid pjob: 362.csg.bcmd.bcm.edu (substate=59)
11/02/2012 12:01:15;0100;PBS_Server.1826;Job;362.csg.bcmd.bcm.edu;dequeuing from batch, state COMPLETE
11/02/2012 12:01:15;0008;PBS_Server.1837;Job;363.csg.bcmd.bcm.edu;on_job_exit valid pjob: 363.csg.bcmd.bcm.edu (substate=59)
11/02/2012 12:01:15;0100;PBS_Server.1837;Job;363.csg.bcmd.bcm.edu;dequeuing from batch, state COMPLETE
11/02/2012 12:01:20;0040;PBS_Server.15882;Svr;csg.bcmd.bcm.edu;Scheduler was sent the command term
11/02/2012 12:01:45;0002;PBS_Server.1827;Svr;PBS_Server;Torque Server Version = 4.1.2, loglevel = 0
11/02/2012 12:02:33;000d;PBS_Server.1833;Job;345.csg.bcmd.bcm.edu;Not sending email: User does not want mail of this type.
11/02/2012 12:02:33;0010;PBS_Server.1833;Job;345.csg.bcmd.bcm.edu;Exit_status=0 resources_used.cput=04:46:53 resources_used.mem=834164kb resources_used.vmem=5227816kb resources_used.walltime=00:54:16
11/02/2012 12:02:33;0008;PBS_Server.1835;Job;345.csg.bcmd.bcm.edu;on_job_exit valid pjob: 345.csg.bcmd.bcm.edu (substate=50)
11/02/2012 12:02:35;0040;PBS_Server.15914;Svr;csg.bcmd.bcm.edu;Scheduler was sent the command term
11/02/2012 12:03:35;0100;PBS_Server.1830;Job;368.csg.bcmd.bcm.edu;enqueuing into batch, state 1 hop 1
11/02/2012 12:03:35;0008;PBS_Server.1830;Job;368.csg.bcmd.bcm.edu;Job Queued at request of lacuesta@csg.bcmd.bcm.edu, owner = lacuesta@csg.bcmd.bcm.edu, job name = jobname1, queue = batch
11/02/2012 12:03:35;0100;PBS_Server.1834;Job;369.csg.bcmd.bcm.edu;enqueuing into batch, state 1 hop 1
11/02/2012 12:03:35;0008;PBS_Server.1834;Job;369.csg.bcmd.bcm.edu;Job Queued at request of lacuesta@csg.bcmd.bcm.edu, owner = lacuesta@csg.bcmd.bcm.edu, job name = jobname2, queue = batch
11/02/2012 12:03:36;0040;PBS_Server.15945;Svr;csg.bcmd.bcm.edu;Scheduler was sent the command new
11/02/2012 12:03:37;0008;PBS_Server.1825;Job;368.csg.bcmd.bcm.edu;Job Run at request of root@csg.bcmd.bcm.edu
11/02/2012 12:03:37;000d;PBS_Server.1825;Job;368.csg.bcmd.bcm.edu;Not sending email: User does not want mail of this type.
11/02/2012 12:03:37;0008;PBS_Server.1825;Job;369.csg.bcmd.bcm.edu;Job Run at request of root@csg.bcmd.bcm.edu
11/02/2012 12:03:37;000d;PBS_Server.1825;Job;369.csg.bcmd.bcm.edu;Not sending email: User does not want mail of this type.
11/02/2012 12:03:41;0008;PBS_Server.1832;Job;365.csg.bcmd.bcm.edu;on_job_exit valid pjob: 365.csg.bcmd.bcm.edu (substate=59)
11/02/2012 12:03:41;0008;PBS_Server.1830;Job;364.csg.bcmd.bcm.edu;on_job_exit valid pjob: 364.csg.bcmd.bcm.edu (substate=59)
11/02/2012 12:03:41;0008;PBS_Server.1836;Job;367.csg.bcmd.bcm.edu;on_job_exit valid pjob: 367.csg.bcmd.bcm.edu (substate=59)
11/02/2012 12:03:41;0008;PBS_Server.1835;Job;366.csg.bcmd.bcm.edu;on_job_exit valid pjob: 366.csg.bcmd.bcm.edu (substate=59)
11/02/2012 12:03:41;0100;PBS_Server.1832;Job;365.csg.bcmd.bcm.edu;dequeuing from batch, state COMPLETE
11/02/2012 12:03:41;0100;PBS_Server.1830;Job;364.csg.bcmd.bcm.edu;dequeuing from batch, state COMPLETE
11/02/2012 12:03:41;0100;PBS_Server.1836;Job;367.csg.bcmd.bcm.edu;dequeuing from batch, state COMPLETE
11/02/2012 12:03:41;0100;PBS_Server.1835;Job;366.csg.bcmd.bcm.edu;dequeuing from batch, state COMPLETE
11/02/2012 12:03:41;0100;PBS_Server.1827;Job;370.csg.bcmd.bcm.edu;enqueuing into batch, state 1 hop 1
11/02/2012 12:03:41;0008;PBS_Server.1827;Job;370.csg.bcmd.bcm.edu;Job Queued at request of lacuesta@csg.bcmd.bcm.edu, owner = lacuesta@csg.bcmd.bcm.edu, job name = jobname1, queue = batch
11/02/2012 12:03:41;0100;PBS_Server.1831;Job;371.csg.bcmd.bcm.edu;enqueuing into batch, state 1 hop 1
11/02/2012 12:03:41;0008;PBS_Server.1831;Job;371.csg.bcmd.bcm.edu;Job Queued at request of lacuesta@csg.bcmd.bcm.edu, owner = lacuesta@csg.bcmd.bcm.edu, job name = jobname2, queue = batch
11/02/2012 12:03:46;0040;PBS_Server.15955;Svr;csg.bcmd.bcm.edu;Scheduler was sent the command new
11/02/2012 12:03:47;0008;PBS_Server.1825;Job;370.csg.bcmd.bcm.edu;Job Run at request of root@csg.bcmd.bcm.edu
11/02/2012 12:03:47;000d;PBS_Server.1825;Job;370.csg.bcmd.bcm.edu;Not sending email: User does not want mail of this type.
11/02/2012 12:03:47;0008;PBS_Server.1825;Job;371.csg.bcmd.bcm.edu;Job Run at request of root@csg.bcmd.bcm.edu
11/02/2012 12:03:47;000d;PBS_Server.1825;Job;371.csg.bcmd.bcm.edu;Not sending email: User does not want mail of this type.
11/02/2012 12:03:51;000d;PBS_Server.1836;Job;370.csg.bcmd.bcm.edu;Not sending email: User does not want mail of this type.
11/02/2012 12:03:51;0010;PBS_Server.1836;Job;370.csg.bcmd.bcm.edu;Exit_status=1 resources_used.cput=00:00:00 resources_used.mem=0kb resources_used.vmem=0kb resources_used.walltime=00:00:04
11/02/2012 12:03:51;0008;PBS_Server.1833;Job;370.csg.bcmd.bcm.edu;on_job_exit valid pjob: 370.csg.bcmd.bcm.edu (substate=50)
11/02/2012 12:03:51;000d;PBS_Server.1826;Job;371.csg.bcmd.bcm.edu;Not sending email: User does not want mail of this type.
11/02/2012 12:03:51;0010;PBS_Server.1826;Job;371.csg.bcmd.bcm.edu;Exit_status=1 resources_used.cput=00:00:00 resources_used.mem=0kb resources_used.vmem=0kb resources_used.walltime=00:00:04
11/02/2012 12:03:51;0008;PBS_Server.1829;Job;371.csg.bcmd.bcm.edu;on_job_exit valid pjob: 371.csg.bcmd.bcm.edu (substate=50)
11/02/2012 12:03:56;0040;PBS_Server.15976;Svr;csg.bcmd.bcm.edu;Scheduler was sent the command term
11/02/2012 12:04:01;000d;PBS_Server.1835;Job;368.csg.bcmd.bcm.edu;Not sending email: User does not want mail of this type.
11/02/2012 12:04:01;0010;PBS_Server.1835;Job;368.csg.bcmd.bcm.edu;Exit_status=0 resources_used.cput=00:00:09 resources_used.mem=69520kb resources_used.vmem=187112kb resources_used.walltime=00:00:24
11/02/2012 12:04:01;0008;PBS_Server.1830;Job;368.csg.bcmd.bcm.edu;on_job_exit valid pjob: 368.csg.bcmd.bcm.edu (substate=50)
11/02/2012 12:04:02;000d;PBS_Server.1827;Job;369.csg.bcmd.bcm.edu;Not sending email: User does not want mail of this type.
11/02/2012 12:04:02;0010;PBS_Server.1827;Job;369.csg.bcmd.bcm.edu;Exit_status=0 resources_used.cput=00:00:10 resources_used.mem=60048kb resources_used.vmem=292248kb resources_used.walltime=00:00:25
11/02/2012 12:04:02;0008;PBS_Server.1833;Job;369.csg.bcmd.bcm.edu;on_job_exit valid pjob: 369.csg.bcmd.bcm.edu (substate=50)
11/02/2012 12:04:06;0040;PBS_Server.16000;Svr;csg.bcmd.bcm.edu;Scheduler was sent the command term
11/02/2012 12:05:34;0100;PBS_Server.1829;Job;372.csg.bcmd.bcm.edu;enqueuing into batch, state 1 hop 1
11/02/2012 12:05:34;0008;PBS_Server.1829;Job;372.csg.bcmd.bcm.edu;Job Queued at request of lacuesta@csg.bcmd.bcm.edu, owner = lacuesta@csg.bcmd.bcm.edu, job name = jobname1, queue = batch
11/02/2012 12:05:34;0100;PBS_Server.1836;Job;373.csg.bcmd.bcm.edu;enqueuing into batch, state 1 hop 1
11/02/2012 12:05:34;0008;PBS_Server.1836;Job;373.csg.bcmd.bcm.edu;Job Queued at request of lacuesta@csg.bcmd.bcm.edu, owner = lacuesta@csg.bcmd.bcm.edu, job name = jobname2, queue = batch
11/02/2012 12:05:36;0040;PBS_Server.16047;Svr;csg.bcmd.bcm.edu;Scheduler was sent the command new
11/02/2012 12:05:37;0008;PBS_Server.1825;Job;372.csg.bcmd.bcm.edu;Job Run at request of root@csg.bcmd.bcm.edu
11/02/2012 12:05:37;000d;PBS_Server.1825;Job;372.csg.bcmd.bcm.edu;Not sending email: User does not want mail of this type.
11/02/2012 12:05:37;0008;PBS_Server.1825;Job;373.csg.bcmd.bcm.edu;Job Run at request of root@csg.bcmd.bcm.edu
11/02/2012 12:05:37;000d;PBS_Server.1825;Job;373.csg.bcmd.bcm.edu;Not sending email: User does not want mail of this type.
11/02/2012 12:05:50;000d;PBS_Server.1832;Job;372.csg.bcmd.bcm.edu;Not sending email: User does not want mail of this type.
11/02/2012 12:05:50;0010;PBS_Server.1832;Job;372.csg.bcmd.bcm.edu;Exit_status=1 resources_used.cput=00:00:00 resources_used.mem=0kb resources_used.vmem=0kb resources_used.walltime=00:00:13
11/02/2012 12:05:50;0008;PBS_Server.1834;Job;372.csg.bcmd.bcm.edu;on_job_exit valid pjob: 372.csg.bcmd.bcm.edu (substate=50)
11/02/2012 12:05:50;000d;PBS_Server.1829;Job;373.csg.bcmd.bcm.edu;Not sending email: User does not want mail of this type.
11/02/2012 12:05:50;0010;PBS_Server.1829;Job;373.csg.bcmd.bcm.edu;Exit_status=1 resources_used.cput=00:00:00 resources_used.mem=11960kb resources_used.vmem=81400kb resources_used.walltime=00:00:13
11/02/2012 12:05:50;0008;PBS_Server.1833;Job;373.csg.bcmd.bcm.edu;on_job_exit valid pjob: 373.csg.bcmd.bcm.edu (substate=50)
11/02/2012 12:05:51;0040;PBS_Server.16062;Svr;csg.bcmd.bcm.edu;Scheduler was sent the command term
11/02/2012 12:05:51;0040;PBS_Server.16067;Svr;csg.bcmd.bcm.edu;Scheduler was sent the command term
11/02/2012 12:06:56;0002;PBS_Server.1834;Svr;PBS_Server;Torque Server Version = 4.1.2, loglevel = 0
11/02/2012 12:07:41;0008;PBS_Server.1829;Job;345.csg.bcmd.bcm.edu;on_job_exit valid pjob: 345.csg.bcmd.bcm.edu (substate=59)
11/02/2012 12:07:41;0100;PBS_Server.1829;Job;345.csg.bcmd.bcm.edu;dequeuing from high, state COMPLETE
11/02/2012 12:07:46;0040;PBS_Server.16098;Svr;csg.bcmd.bcm.edu;Scheduler was sent the command term
11/02/2012 12:08:40;0100;PBS_Server.1834;Job;374.csg.bcmd.bcm.edu;enqueuing into batch, state 1 hop 1
11/02/2012 12:08:40;0008;PBS_Server.1834;Job;374.csg.bcmd.bcm.edu;Job Queued at request of lacuesta@csg.bcmd.bcm.edu, owner = lacuesta@csg.bcmd.bcm.edu, job name = jobname1, queue = batch
11/02/2012 12:08:40;0100;PBS_Server.1831;Job;375.csg.bcmd.bcm.edu;enqueuing into batch, state 1 hop 1
11/02/2012 12:08:40;0008;PBS_Server.1831;Job;375.csg.bcmd.bcm.edu;Job Queued at request of lacuesta@csg.bcmd.bcm.edu, owner = lacuesta@csg.bcmd.bcm.edu, job name = jobname2, queue = batch
11/02/2012 12:08:41;0040;PBS_Server.16128;Svr;csg.bcmd.bcm.edu;Scheduler was sent the command new
11/02/2012 12:08:42;0008;PBS_Server.1825;Job;374.csg.bcmd.bcm.edu;Job Run at request of root@csg.bcmd.bcm.edu
11/02/2012 12:08:42;000d;PBS_Server.1825;Job;374.csg.bcmd.bcm.edu;Not sending email: User does not want mail of this type.
11/02/2012 12:08:42;0008;PBS_Server.1825;Job;375.csg.bcmd.bcm.edu;Job Run at request of root@csg.bcmd.bcm.edu
11/02/2012 12:08:42;000d;PBS_Server.1825;Job;375.csg.bcmd.bcm.edu;Not sending email: User does not want mail of this type.
11/02/2012 12:08:42;000d;PBS_Server.1837;Job;374.csg.bcmd.bcm.edu;Not sending email: User does not want mail of this type.
11/02/2012 12:08:42;0010;PBS_Server.1837;Job;374.csg.bcmd.bcm.edu;Exit_status=1 resources_used.cput=00:00:00 resources_used.mem=0kb resources_used.vmem=0kb resources_used.walltime=00:00:00
11/02/2012 12:08:42;0008;PBS_Server.1826;Job;374.csg.bcmd.bcm.edu;on_job_exit valid pjob: 374.csg.bcmd.bcm.edu (substate=50)
11/02/2012 12:08:42;000d;PBS_Server.1836;Job;375.csg.bcmd.bcm.edu;Not sending email: User does not want mail of this type.
11/02/2012 12:08:42;0010;PBS_Server.1836;Job;375.csg.bcmd.bcm.edu;Exit_status=1 resources_used.cput=00:00:00 resources_used.mem=0kb resources_used.vmem=0kb resources_used.walltime=00:00:00
11/02/2012 12:08:42;0008;PBS_Server.1834;Job;375.csg.bcmd.bcm.edu;on_job_exit valid pjob: 375.csg.bcmd.bcm.edu (substate=50)
11/02/2012 12:08:46;0040;PBS_Server.16145;Svr;csg.bcmd.bcm.edu;Scheduler was sent the command term
11/02/2012 12:08:56;0008;PBS_Server.1826;Job;370.csg.bcmd.bcm.edu;on_job_exit valid pjob: 370.csg.bcmd.bcm.edu (substate=59)
11/02/2012 12:08:56;0100;PBS_Server.1826;Job;370.csg.bcmd.bcm.edu;dequeuing from batch, state COMPLETE
11/02/2012 12:08:56;0008;PBS_Server.1832;Job;371.csg.bcmd.bcm.edu;on_job_exit valid pjob: 371.csg.bcmd.bcm.edu (substate=59)
11/02/2012 12:08:56;0100;PBS_Server.1832;Job;371.csg.bcmd.bcm.edu;dequeuing from batch, state COMPLETE
11/02/2012 12:09:01;0040;PBS_Server.16161;Svr;csg.bcmd.bcm.edu;Scheduler was sent the command term
11/02/2012 12:09:11;0008;PBS_Server.1826;Job;369.csg.bcmd.bcm.edu;on_job_exit valid pjob: 369.csg.bcmd.bcm.edu (substate=59)
11/02/2012 12:09:11;0008;PBS_Server.1832;Job;368.csg.bcmd.bcm.edu;on_job_exit valid pjob: 368.csg.bcmd.bcm.edu (substate=59)
11/02/2012 12:09:11;0100;PBS_Server.1826;Job;369.csg.bcmd.bcm.edu;dequeuing from batch, state COMPLETE
11/02/2012 12:09:11;0100;PBS_Server.1832;Job;368.csg.bcmd.bcm.edu;dequeuing from batch, state COMPLETE
11/02/2012 12:09:16;0040;PBS_Server.16170;Svr;csg.bcmd.bcm.edu;Scheduler was sent the command term
11/02/2012 12:10:19;0100;PBS_Server.1830;Job;376.csg.bcmd.bcm.edu;enqueuing into batch, state 1 hop 1
11/02/2012 12:10:19;0008;PBS_Server.1830;Job;376.csg.bcmd.bcm.edu;Job Queued at request of lacuesta@csg.bcmd.bcm.edu, owner = lacuesta@csg.bcmd.bcm.edu, job name = jobname1, queue = batch
11/02/2012 12:10:20;0100;PBS_Server.1837;Job;377.csg.bcmd.bcm.edu;enqueuing into batch, state 1 hop 1
11/02/2012 12:10:20;0008;PBS_Server.1837;Job;377.csg.bcmd.bcm.edu;Job Queued at request of lacuesta@csg.bcmd.bcm.edu, owner = lacuesta@csg.bcmd.bcm.edu, job name = jobname2, queue = batch
11/02/2012 12:10:21;0040;PBS_Server.16233;Svr;csg.bcmd.bcm.edu;Scheduler was sent the command new
11/02/2012 12:10:23;0008;PBS_Server.1825;Job;376.csg.bcmd.bcm.edu;Job Run at request of root@csg.bcmd.bcm.edu
11/02/2012 12:10:23;000d;PBS_Server.1825;Job;376.csg.bcmd.bcm.edu;Not sending email: User does not want mail of this type.
11/02/2012 12:10:23;0008;PBS_Server.1825;Job;377.csg.bcmd.bcm.edu;Job Run at request of root@csg.bcmd.bcm.edu
11/02/2012 12:10:23;000d;PBS_Server.1825;Job;377.csg.bcmd.bcm.edu;Not sending email: User does not want mail of this type.
11/02/2012 12:10:33;000d;PBS_Server.1827;Job;376.csg.bcmd.bcm.edu;Not sending email: User does not want mail of this type.
11/02/2012 12:10:33;0010;PBS_Server.1827;Job;376.csg.bcmd.bcm.edu;Exit_status=0 resources_used.cput=00:00:09 resources_used.mem=0kb resources_used.vmem=0kb resources_used.walltime=00:00:10
11/02/2012 12:10:33;0008;PBS_Server.1828;Job;376.csg.bcmd.bcm.edu;on_job_exit valid pjob: 376.csg.bcmd.bcm.edu (substate=50)
11/02/2012 12:10:34;000d;PBS_Server.1832;Job;377.csg.bcmd.bcm.edu;Not sending email: User does not want mail of this type.
11/02/2012 12:10:34;0010;PBS_Server.1832;Job;377.csg.bcmd.bcm.edu;Exit_status=0 resources_used.cput=00:00:10 resources_used.mem=67208kb resources_used.vmem=293348kb resources_used.walltime=00:00:11
11/02/2012 12:10:34;0008;PBS_Server.1830;Job;377.csg.bcmd.bcm.edu;on_job_exit valid pjob: 377.csg.bcmd.bcm.edu (substate=50)
11/02/2012 12:10:37;0040;PBS_Server.16255;Svr;csg.bcmd.bcm.edu;Scheduler was sent the command term
11/02/2012 12:10:56;0008;PBS_Server.1836;Job;373.csg.bcmd.bcm.edu;on_job_exit valid pjob: 373.csg.bcmd.bcm.edu (substate=59)
11/02/2012 12:10:56;0008;PBS_Server.1827;Job;372.csg.bcmd.bcm.edu;on_job_exit valid pjob: 372.csg.bcmd.bcm.edu (substate=59)
11/02/2012 12:10:56;0100;PBS_Server.1836;Job;373.csg.bcmd.bcm.edu;dequeuing from batch, state COMPLETE
11/02/2012 12:10:56;0100;PBS_Server.1827;Job;372.csg.bcmd.bcm.edu;dequeuing from batch, state COMPLETE
11/02/2012 12:11:02;0040;PBS_Server.16270;Svr;csg.bcmd.bcm.edu;Scheduler was sent the command term
11/02/2012 12:11:57;0002;PBS_Server.1826;Svr;PBS_Server;Torque Server Version = 4.1.2, loglevel = 0
11/02/2012 12:13:48;0008;PBS_Server.1835;Job;375.csg.bcmd.bcm.edu;on_job_exit valid pjob: 375.csg.bcmd.bcm.edu (substate=59)
11/02/2012 12:13:48;0008;PBS_Server.1830;Job;374.csg.bcmd.bcm.edu;on_job_exit valid pjob: 374.csg.bcmd.bcm.edu (substate=59)
11/02/2012 12:13:48;0100;PBS_Server.1835;Job;375.csg.bcmd.bcm.edu;dequeuing from batch, state COMPLETE
11/02/2012 12:13:48;0100;PBS_Server.1830;Job;374.csg.bcmd.bcm.edu;dequeuing from batch, state COMPLETE
11/02/2012 12:13:53;0040;PBS_Server.16332;Svr;csg.bcmd.bcm.edu;Scheduler was sent the command term
11/02/2012 12:15:47;0008;PBS_Server.1830;Job;377.csg.bcmd.bcm.edu;on_job_exit valid pjob: 377.csg.bcmd.bcm.edu (substate=59)
11/02/2012 12:15:47;0008;PBS_Server.1828;Job;376.csg.bcmd.bcm.edu;on_job_exit valid pjob: 376.csg.bcmd.bcm.edu (substate=59)
11/02/2012 12:15:47;0100;PBS_Server.1830;Job;377.csg.bcmd.bcm.edu;dequeuing from batch, state COMPLETE
11/02/2012 12:15:47;0100;PBS_Server.1828;Job;376.csg.bcmd.bcm.edu;dequeuing from batch, state COMPLETE
11/02/2012 12:15:52;0040;PBS_Server.16380;Svr;csg.bcmd.bcm.edu;Scheduler was sent the command term
11/02/2012 12:17:05;0002;PBS_Server.1834;Svr;PBS_Server;Torque Server Version = 4.1.2, loglevel = 0
11/02/2012 12:20:03;0100;PBS_Server.1832;Job;378.csg.bcmd.bcm.edu;enqueuing into batch, state 1 hop 1
11/02/2012 12:20:03;0008;PBS_Server.1832;Job;378.csg.bcmd.bcm.edu;Job Queued at request of lacuesta@csg.bcmd.bcm.edu, owner = lacuesta@csg.bcmd.bcm.edu, job name = jobname1, queue = batch
11/02/2012 12:20:03;0100;PBS_Server.1825;Job;379.csg.bcmd.bcm.edu;enqueuing into batch, state 1 hop 1
11/02/2012 12:20:03;0008;PBS_Server.1825;Job;379.csg.bcmd.bcm.edu;Job Queued at request of lacuesta@csg.bcmd.bcm.edu, owner = lacuesta@csg.bcmd.bcm.edu, job name = jobname2, queue = batch
11/02/2012 12:20:06;0040;PBS_Server.16494;Svr;csg.bcmd.bcm.edu;Scheduler was sent the command new
11/02/2012 12:20:07;0008;PBS_Server.1837;Job;378.csg.bcmd.bcm.edu;Job Run at request of root@csg.bcmd.bcm.edu
11/02/2012 12:20:07;000d;PBS_Server.1837;Job;378.csg.bcmd.bcm.edu;Not sending email: User does not want mail of this type.
11/02/2012 12:20:07;0008;PBS_Server.1837;Job;379.csg.bcmd.bcm.edu;Job Run at request of root@csg.bcmd.bcm.edu
11/02/2012 12:20:07;000d;PBS_Server.1837;Job;379.csg.bcmd.bcm.edu;Not sending email: User does not want mail of this type.
11/02/2012 12:20:08;0100;PBS_Server.1829;Job;380.csg.bcmd.bcm.edu;enqueuing into batch, state 1 hop 1
11/02/2012 12:20:08;0008;PBS_Server.1829;Job;380.csg.bcmd.bcm.edu;Job Queued at request of lacuesta@csg.bcmd.bcm.edu, owner = lacuesta@csg.bcmd.bcm.edu, job name = jobname1, queue = batch
11/02/2012 12:20:08;0100;PBS_Server.1827;Job;381.csg.bcmd.bcm.edu;enqueuing into batch, state 1 hop 1
11/02/2012 12:20:08;0008;PBS_Server.1827;Job;381.csg.bcmd.bcm.edu;Job Queued at request of lacuesta@csg.bcmd.bcm.edu, owner = lacuesta@csg.bcmd.bcm.edu, job name = jobname2, queue = batch
11/02/2012 12:20:12;0040;PBS_Server.16505;Svr;csg.bcmd.bcm.edu;Scheduler was sent the command new
11/02/2012 12:20:13;0008;PBS_Server.1837;Job;380.csg.bcmd.bcm.edu;Job Run at request of root@csg.bcmd.bcm.edu
11/02/2012 12:20:13;000d;PBS_Server.1837;Job;380.csg.bcmd.bcm.edu;Not sending email: User does not want mail of this type.
11/02/2012 12:20:13;0008;PBS_Server.1837;Job;381.csg.bcmd.bcm.edu;Job Run at request of root@csg.bcmd.bcm.edu
11/02/2012 12:20:13;000d;PBS_Server.1837;Job;381.csg.bcmd.bcm.edu;Not sending email: User does not want mail of this type.
11/02/2012 12:22:12;0002;PBS_Server.1835;Svr;PBS_Server;Torque Server Version = 4.1.2, loglevel = 0
11/02/2012 12:22:17;000d;PBS_Server.1825;Job;379.csg.bcmd.bcm.edu;Not sending email: User does not want mail of this type.
11/02/2012 12:22:17;0010;PBS_Server.1825;Job;379.csg.bcmd.bcm.edu;Exit_status=0 resources_used.cput=00:00:09 resources_used.mem=108584kb resources_used.vmem=238840kb resources_used.walltime=00:02:10
11/02/2012 12:22:17;0008;PBS_Server.1828;Job;379.csg.bcmd.bcm.edu;on_job_exit valid pjob: 379.csg.bcmd.bcm.edu (substate=50)
11/02/2012 12:22:17;0040;PBS_Server.16538;Svr;csg.bcmd.bcm.edu;Scheduler was sent the command term
11/02/2012 12:22:18;000d;PBS_Server.1826;Job;381.csg.bcmd.bcm.edu;Not sending email: User does not want mail of this type.
11/02/2012 12:22:18;0010;PBS_Server.1826;Job;381.csg.bcmd.bcm.edu;Exit_status=0 resources_used.cput=00:00:10 resources_used.mem=102736kb resources_used.vmem=232800kb resources_used.walltime=00:02:05
11/02/2012 12:22:18;0008;PBS_Server.1834;Job;381.csg.bcmd.bcm.edu;on_job_exit valid pjob: 381.csg.bcmd.bcm.edu (substate=50)
11/02/2012 12:22:22;0040;PBS_Server.16547;Svr;csg.bcmd.bcm.edu;Scheduler was sent the command term
11/02/2012 12:22:23;000d;PBS_Server.1828;Job;380.csg.bcmd.bcm.edu;Not sending email: User does not want mail of this type.
11/02/2012 12:22:23;0010;PBS_Server.1828;Job;380.csg.bcmd.bcm.edu;Exit_status=0 resources_used.cput=00:00:08 resources_used.mem=41728kb resources_used.vmem=290876kb resources_used.walltime=00:02:10
11/02/2012 12:22:23;0008;PBS_Server.1831;Job;380.csg.bcmd.bcm.edu;on_job_exit valid pjob: 380.csg.bcmd.bcm.edu (substate=50)
11/02/2012 12:22:27;000d;PBS_Server.1833;Job;378.csg.bcmd.bcm.edu;Not sending email: User does not want mail of this type.
11/02/2012 12:22:27;0010;PBS_Server.1833;Job;378.csg.bcmd.bcm.edu;Exit_status=0 resources_used.cput=00:00:08 resources_used.mem=93392kb resources_used.vmem=287744kb resources_used.walltime=00:02:20
11/02/2012 12:22:27;0008;PBS_Server.1836;Job;378.csg.bcmd.bcm.edu;on_job_exit valid pjob: 378.csg.bcmd.bcm.edu (substate=50)
11/02/2012 12:22:27;0040;PBS_Server.16565;Svr;csg.bcmd.bcm.edu;Scheduler was sent the command term
11/02/2012 12:22:28;0040;PBS_Server.16566;Svr;csg.bcmd.bcm.edu;Scheduler was sent the command term
11/02/2012 12:27:23;0002;PBS_Server.1836;Svr;PBS_Server;Torque Server Version = 4.1.2, loglevel = 0
11/02/2012 12:27:23;0008;PBS_Server.1826;Job;381.csg.bcmd.bcm.edu;on_job_exit valid pjob: 381.csg.bcmd.bcm.edu (substate=59)
11/02/2012 12:27:23;0008;PBS_Server.1835;Job;380.csg.bcmd.bcm.edu;on_job_exit valid pjob: 380.csg.bcmd.bcm.edu (substate=59)
11/02/2012 12:27:23;0100;PBS_Server.1826;Job;381.csg.bcmd.bcm.edu;dequeuing from batch, state COMPLETE
11/02/2012 12:27:23;0100;PBS_Server.1835;Job;380.csg.bcmd.bcm.edu;dequeuing from batch, state COMPLETE
11/02/2012 12:27:23;0008;PBS_Server.1834;Job;379.csg.bcmd.bcm.edu;on_job_exit valid pjob: 379.csg.bcmd.bcm.edu (substate=59)
11/02/2012 12:27:23;0100;PBS_Server.1834;Job;379.csg.bcmd.bcm.edu;dequeuing from batch, state COMPLETE
11/02/2012 12:27:28;0040;PBS_Server.16652;Svr;csg.bcmd.bcm.edu;Scheduler was sent the command term
11/02/2012 12:27:38;0008;PBS_Server.1833;Job;378.csg.bcmd.bcm.edu;on_job_exit valid pjob: 378.csg.bcmd.bcm.edu (substate=59)
11/02/2012 12:27:38;0100;PBS_Server.1833;Job;378.csg.bcmd.bcm.edu;dequeuing from batch, state COMPLETE
11/02/2012 12:27:43;0040;PBS_Server.16655;Svr;csg.bcmd.bcm.edu;Scheduler was sent the command term
11/02/2012 12:32:34;0002;PBS_Server.1834;Svr;PBS_Server;Torque Server Version = 4.1.2, loglevel = 0
11/02/2012 12:37:34;0002;PBS_Server.1834;Svr;PBS_Server;Torque Server Version = 4.1.2, loglevel = 0
11/02/2012 12:37:54;0040;PBS_Server.16896;Svr;csg.bcmd.bcm.edu;Scheduler was sent the command time
11/02/2012 12:42:45;0002;PBS_Server.1829;Svr;PBS_Server;Torque Server Version = 4.1.2, loglevel = 0
11/02/2012 12:47:45;0002;PBS_Server.1836;Svr;PBS_Server;Torque Server Version = 4.1.2, loglevel = 0
11/02/2012 12:48:05;0040;PBS_Server.19756;Svr;csg.bcmd.bcm.edu;Scheduler was sent the command time
11/02/2012 12:48:33;000d;PBS_Server.1835;Job;346.csg.bcmd.bcm.edu;Not sending email: User does not want mail of this type.
11/02/2012 12:48:33;0010;PBS_Server.1835;Job;346.csg.bcmd.bcm.edu;Exit_status=0 resources_used.cput=09:51:50 resources_used.mem=847520kb resources_used.vmem=5240444kb resources_used.walltime=01:35:10
11/02/2012 12:48:33;0008;PBS_Server.1826;Job;346.csg.bcmd.bcm.edu;on_job_exit valid pjob: 346.csg.bcmd.bcm.edu (substate=50)
11/02/2012 12:48:35;0040;PBS_Server.19766;Svr;csg.bcmd.bcm.edu;Scheduler was sent the command term
11/02/2012 12:52:46;0002;PBS_Server.1832;Svr;PBS_Server;Torque Server Version = 4.1.2, loglevel = 0
11/02/2012 12:53:46;0008;PBS_Server.1835;Job;346.csg.bcmd.bcm.edu;on_job_exit valid pjob: 346.csg.bcmd.bcm.edu (substate=59)
11/02/2012 12:53:46;0100;PBS_Server.1835;Job;346.csg.bcmd.bcm.edu;dequeuing from high, state COMPLETE
11/02/2012 12:53:51;0040;PBS_Server.19820;Svr;csg.bcmd.bcm.edu;Scheduler was sent the command term
11/02/2012 12:57:46;0002;PBS_Server.1825;Svr;PBS_Server;Torque Server Version = 4.1.2, loglevel = 0
11/02/2012 13:02:54;0002;PBS_Server.1836;Svr;PBS_Server;Torque Server Version = 4.1.2, loglevel = 0
11/02/2012 13:04:06;0040;PBS_Server.19943;Svr;csg.bcmd.bcm.edu;Scheduler was sent the command time
11/02/2012 13:07:59;0002;PBS_Server.1837;Svr;PBS_Server;Torque Server Version = 4.1.2, loglevel = 0
11/02/2012 13:13:04;0002;PBS_Server.1832;Svr;PBS_Server;Torque Server Version = 4.1.2, loglevel = 0
11/02/2012 13:14:16;0040;PBS_Server.19994;Svr;csg.bcmd.bcm.edu;Scheduler was sent the command time
11/02/2012 13:18:09;0002;PBS_Server.1826;Svr;PBS_Server;Torque Server Version = 4.1.2, loglevel = 0
11/02/2012 13:23:14;0002;PBS_Server.1829;Svr;PBS_Server;Torque Server Version = 4.1.2, loglevel = 0
11/02/2012 13:24:26;0040;PBS_Server.20070;Svr;csg.bcmd.bcm.edu;Scheduler was sent the command time
11/02/2012 13:28:19;0002;PBS_Server.1825;Svr;PBS_Server;Torque Server Version = 4.1.2, loglevel = 0
11/02/2012 13:33:24;0002;PBS_Server.1834;Svr;PBS_Server;Torque Server Version = 4.1.2, loglevel = 0
11/02/2012 13:34:36;0040;PBS_Server.20101;Svr;csg.bcmd.bcm.edu;Scheduler was sent the command time
11/02/2012 13:37:27;0008;PBS_Server.1829;Job;347.csg.bcmd.bcm.edu;Job deleted at request of lacuesta@csg.bcmd.bcm.edu
11/02/2012 13:37:27;0008;PBS_Server.1829;Job;347.csg.bcmd.bcm.edu;Job sent signal SIGTERM on delete
11/02/2012 13:37:27;000d;PBS_Server.1828;Job;347.csg.bcmd.bcm.edu;Not sending email: User does not want mail of this type.
11/02/2012 13:37:27;0010;PBS_Server.1828;Job;347.csg.bcmd.bcm.edu;Exit_status=271 resources_used.cput=06:38:09 resources_used.mem=665584kb resources_used.vmem=1607472kb resources_used.walltime=02:12:00
11/02/2012 13:37:27;0008;PBS_Server.1836;Job;347.csg.bcmd.bcm.edu;on_job_exit valid pjob: 347.csg.bcmd.bcm.edu (substate=50)
11/02/2012 13:37:32;0040;PBS_Server.20149;Svr;csg.bcmd.bcm.edu;Scheduler was sent the command term
11/02/2012 13:38:29;0002;PBS_Server.1827;Svr;PBS_Server;Torque Server Version = 4.1.2, loglevel = 0
11/02/2012 13:39:58;0100;PBS_Server.1835;Job;382.csg.bcmd.bcm.edu;enqueuing into high, state 1 hop 1
11/02/2012 13:39:58;0008;PBS_Server.1835;Job;382.csg.bcmd.bcm.edu;Job Queued at request of lacuesta@csg.bcmd.bcm.edu, owner = lacuesta@csg.bcmd.bcm.edu, job name = EA_totchol_CMC_permutation_02Nov2012, queue = high
11/02/2012 13:40:02;0040;PBS_Server.20184;Svr;csg.bcmd.bcm.edu;Scheduler was sent the command new
11/02/2012 13:40:03;0008;PBS_Server.1830;Job;382.csg.bcmd.bcm.edu;Job Run at request of root@csg.bcmd.bcm.edu
11/02/2012 13:40:03;000d;PBS_Server.1830;Job;382.csg.bcmd.bcm.edu;Not sending email: User does not want mail of this type.
11/02/2012 13:41:51;0100;PBS_Server.1825;Job;383.csg.bcmd.bcm.edu;enqueuing into high, state 1 hop 1
11/02/2012 13:41:51;0008;PBS_Server.1825;Job;383.csg.bcmd.bcm.edu;Job Queued at request of lacuesta@csg.bcmd.bcm.edu, owner = lacuesta@csg.bcmd.bcm.edu, job name = EA_totchol_SNV_permutation_02Nov2012, queue = high
11/02/2012 13:41:53;0040;PBS_Server.20258;Svr;csg.bcmd.bcm.edu;Scheduler was sent the command new
11/02/2012 13:41:54;0008;PBS_Server.1830;Job;383.csg.bcmd.bcm.edu;Job Run at request of root@csg.bcmd.bcm.edu
11/02/2012 13:41:54;000d;PBS_Server.1830;Job;383.csg.bcmd.bcm.edu;Not sending email: User does not want mail of this type.
11/02/2012 13:42:28;0008;PBS_Server.1836;Job;347.csg.bcmd.bcm.edu;on_job_exit valid pjob: 347.csg.bcmd.bcm.edu (substate=59)
11/02/2012 13:42:28;0100;PBS_Server.1836;Job;347.csg.bcmd.bcm.edu;dequeuing from high, state COMPLETE
11/02/2012 13:42:33;0040;PBS_Server.20265;Svr;csg.bcmd.bcm.edu;Scheduler was sent the command term
11/02/2012 13:43:43;0002;PBS_Server.1833;Svr;PBS_Server;Torque Server Version = 4.1.2, loglevel = 0
11/02/2012 13:45:47;000d;PBS_Server.1837;Job;343.csg.bcmd.bcm.edu;Not sending email: User does not want mail of this type.
11/02/2012 13:45:47;0010;PBS_Server.1837;Job;343.csg.bcmd.bcm.edu;Exit_status=0 resources_used.cput=25:59:04 resources_used.mem=1220224kb resources_used.vmem=5613148kb resources_used.walltime=02:47:02
11/02/2012 13:45:47;0008;PBS_Server.1827;Job;343.csg.bcmd.bcm.edu;on_job_exit valid pjob: 343.csg.bcmd.bcm.edu (substate=50)
11/02/2012 13:45:48;0040;PBS_Server.20326;Svr;csg.bcmd.bcm.edu;Scheduler was sent the command term
11/02/2012 13:48:43;0002;PBS_Server.1834;Svr;PBS_Server;Torque Server Version = 4.1.2, loglevel = 0
11/02/2012 13:50:54;0008;PBS_Server.1829;Job;343.csg.bcmd.bcm.edu;on_job_exit valid pjob: 343.csg.bcmd.bcm.edu (substate=59)
11/02/2012 13:50:54;0100;PBS_Server.1829;Job;343.csg.bcmd.bcm.edu;dequeuing from high, state COMPLETE
11/02/2012 13:50:59;0040;PBS_Server.20370;Svr;csg.bcmd.bcm.edu;Scheduler was sent the command term
11/02/2012 13:53:50;0002;PBS_Server.1835;Svr;PBS_Server;Torque Server Version = 4.1.2, loglevel = 0
11/02/2012 13:58:55;0002;PBS_Server.1832;Svr;PBS_Server;Torque Server Version = 4.1.2, loglevel = 0
11/02/2012 14:01:14;0040;PBS_Server.20406;Svr;csg.bcmd.bcm.edu;Scheduler was sent the command time
11/02/2012 14:03:11;0100;PBS_Server.1830;Job;384.csg.bcmd.bcm.edu;enqueuing into batch, state 1 hop 1
11/02/2012 14:03:11;0008;PBS_Server.1830;Job;384.csg.bcmd.bcm.edu;Job Queued at request of jiaweixu@csg.bcmd.bcm.edu, owner = jiaweixu@csg.bcmd.bcm.edu, job name = jobname1, queue = batch
11/02/2012 14:03:11;0100;PBS_Server.1836;Job;385.csg.bcmd.bcm.edu;enqueuing into batch, state 1 hop 1
11/02/2012 14:03:11;0008;PBS_Server.1836;Job;385.csg.bcmd.bcm.edu;Job Queued at request of jiaweixu@csg.bcmd.bcm.edu, owner = jiaweixu@csg.bcmd.bcm.edu, job name = jobname2, queue = batch
11/02/2012 14:03:13;0040;PBS_Server.20449;Svr;csg.bcmd.bcm.edu;Scheduler was sent the command new
11/02/2012 14:03:14;0008;PBS_Server.1833;Job;384.csg.bcmd.bcm.edu;Job Run at request of root@csg.bcmd.bcm.edu
11/02/2012 14:03:14;000d;PBS_Server.1833;Job;384.csg.bcmd.bcm.edu;Not sending email: User does not want mail of this type.
11/02/2012 14:03:14;0008;PBS_Server.1833;Job;385.csg.bcmd.bcm.edu;Job Run at request of root@csg.bcmd.bcm.edu
11/02/2012 14:03:14;000d;PBS_Server.1833;Job;385.csg.bcmd.bcm.edu;Not sending email: User does not want mail of this type.
11/02/2012 14:03:23;000d;PBS_Server.1837;Job;384.csg.bcmd.bcm.edu;Not sending email: User does not want mail of this type.
11/02/2012 14:03:23;0010;PBS_Server.1837;Job;384.csg.bcmd.bcm.edu;Exit_status=0 resources_used.cput=00:00:08 resources_used.mem=38172kb resources_used.vmem=280228kb resources_used.walltime=00:00:09
11/02/2012 14:03:23;0008;PBS_Server.1825;Job;384.csg.bcmd.bcm.edu;on_job_exit valid pjob: 384.csg.bcmd.bcm.edu (substate=50)
11/02/2012 14:03:23;000d;PBS_Server.1828;Job;385.csg.bcmd.bcm.edu;Not sending email: User does not want mail of this type.
11/02/2012 14:03:23;0010;PBS_Server.1828;Job;385.csg.bcmd.bcm.edu;Exit_status=0 resources_used.cput=00:00:08 resources_used.mem=62664kb resources_used.vmem=284568kb resources_used.walltime=00:00:09
11/02/2012 14:03:23;0008;PBS_Server.1832;Job;385.csg.bcmd.bcm.edu;on_job_exit valid pjob: 385.csg.bcmd.bcm.edu (substate=50)
11/02/2012 14:03:24;0040;PBS_Server.20476;Svr;csg.bcmd.bcm.edu;Scheduler was sent the command term
11/02/2012 14:04:04;0002;PBS_Server.1836;Svr;PBS_Server;Torque Server Version = 4.1.2, loglevel = 0
11/02/2012 14:05:58;0100;PBS_Server.1826;Job;386.csg.bcmd.bcm.edu;enqueuing into high, state 1 hop 1
11/02/2012 14:05:58;0008;PBS_Server.1826;Job;386.csg.bcmd.bcm.edu;Job Queued at request of lacuesta@csg.bcmd.bcm.edu, owner = lacuesta@csg.bcmd.bcm.edu, job name = EA_totchol_VT_02Nov2012, queue = high
11/02/2012 14:05:59;0040;PBS_Server.20533;Svr;csg.bcmd.bcm.edu;Scheduler was sent the command new
11/02/2012 14:05:59;0008;PBS_Server.1833;Job;386.csg.bcmd.bcm.edu;Job Run at request of root@csg.bcmd.bcm.edu
11/02/2012 14:05:59;000d;PBS_Server.1833;Job;386.csg.bcmd.bcm.edu;Not sending email: User does not want mail of this type.
11/02/2012 14:08:34;0008;PBS_Server.1829;Job;384.csg.bcmd.bcm.edu;on_job_exit valid pjob: 384.csg.bcmd.bcm.edu (substate=59)
11/02/2012 14:08:34;0100;PBS_Server.1829;Job;384.csg.bcmd.bcm.edu;dequeuing from batch, state COMPLETE
11/02/2012 14:08:34;0008;PBS_Server.1837;Job;385.csg.bcmd.bcm.edu;on_job_exit valid pjob: 385.csg.bcmd.bcm.edu (substate=59)
11/02/2012 14:08:34;0100;PBS_Server.1837;Job;385.csg.bcmd.bcm.edu;dequeuing from batch, state COMPLETE
11/02/2012 14:08:39;0040;PBS_Server.20593;Svr;csg.bcmd.bcm.edu;Scheduler was sent the command term
11/02/2012 14:08:49;0100;PBS_Server.1832;Job;387.csg.bcmd.bcm.edu;enqueuing into batch, state 1 hop 1
11/02/2012 14:08:49;0008;PBS_Server.1832;Job;387.csg.bcmd.bcm.edu;Job Queued at request of jiaweixu@csg.bcmd.bcm.edu, owner = jiaweixu@csg.bcmd.bcm.edu, job name = jobname1, queue = batch
11/02/2012 14:08:49;0040;PBS_Server.20601;Svr;csg.bcmd.bcm.edu;Scheduler was sent the command new
11/02/2012 14:08:49;0100;PBS_Server.1827;Job;388.csg.bcmd.bcm.edu;enqueuing into batch, state 1 hop 1
11/02/2012 14:08:49;0008;PBS_Server.1827;Job;388.csg.bcmd.bcm.edu;Job Queued at request of jiaweixu@csg.bcmd.bcm.edu, owner = jiaweixu@csg.bcmd.bcm.edu, job name = jobname2, queue = batch
11/02/2012 14:08:50;0008;PBS_Server.1833;Job;387.csg.bcmd.bcm.edu;Job Run at request of root@csg.bcmd.bcm.edu
11/02/2012 14:08:50;000d;PBS_Server.1833;Job;387.csg.bcmd.bcm.edu;Not sending email: User does not want mail of this type.
11/02/2012 14:08:50;0008;PBS_Server.1833;Job;388.csg.bcmd.bcm.edu;Job Run at request of root@csg.bcmd.bcm.edu
11/02/2012 14:08:50;000d;PBS_Server.1833;Job;388.csg.bcmd.bcm.edu;Not sending email: User does not want mail of this type.
11/02/2012 14:08:54;0040;PBS_Server.20605;Svr;csg.bcmd.bcm.edu;Scheduler was sent the command new
11/02/2012 14:08:59;000d;PBS_Server.1830;Job;387.csg.bcmd.bcm.edu;Not sending email: User does not want mail of this type.
11/02/2012 14:08:59;0010;PBS_Server.1830;Job;387.csg.bcmd.bcm.edu;Exit_status=0 resources_used.cput=00:00:08 resources_used.mem=0kb resources_used.vmem=0kb resources_used.walltime=00:00:09
11/02/2012 14:08:59;0008;PBS_Server.1834;Job;387.csg.bcmd.bcm.edu;on_job_exit valid pjob: 387.csg.bcmd.bcm.edu (substate=50)
11/02/2012 14:08:59;0040;PBS_Server.20618;Svr;csg.bcmd.bcm.edu;Scheduler was sent the command term
11/02/2012 14:09:01;000d;PBS_Server.1826;Job;388.csg.bcmd.bcm.edu;Not sending email: User does not want mail of this type.
11/02/2012 14:09:01;0010;PBS_Server.1826;Job;388.csg.bcmd.bcm.edu;Exit_status=0 resources_used.cput=00:00:08 resources_used.mem=42688kb resources_used.vmem=284568kb resources_used.walltime=00:00:11
11/02/2012 14:09:01;0008;PBS_Server.1825;Job;388.csg.bcmd.bcm.edu;on_job_exit valid pjob: 388.csg.bcmd.bcm.edu (substate=50)
11/02/2012 14:09:04;0002;PBS_Server.1830;Svr;PBS_Server;Torque Server Version = 4.1.2, loglevel = 0
11/02/2012 14:09:04;0040;PBS_Server.20635;Svr;csg.bcmd.bcm.edu;Scheduler was sent the command term
11/02/2012 14:12:43;0100;PBS_Server.1825;Job;389.csg.bcmd.bcm.edu;enqueuing into batch, state 1 hop 1
11/02/2012 14:12:43;0008;PBS_Server.1825;Job;389.csg.bcmd.bcm.edu;Job Queued at request of jiaweixu@csg.bcmd.bcm.edu, owner = jiaweixu@csg.bcmd.bcm.edu, job name = jobname1, queue = batch
11/02/2012 14:12:43;0100;PBS_Server.1827;Job;390.csg.bcmd.bcm.edu;enqueuing into batch, state 1 hop 1
11/02/2012 14:12:43;0008;PBS_Server.1827;Job;390.csg.bcmd.bcm.edu;Job Queued at request of jiaweixu@csg.bcmd.bcm.edu, owner = jiaweixu@csg.bcmd.bcm.edu, job name = jobname2, queue = batch
11/02/2012 14:12:45;0040;PBS_Server.20789;Svr;csg.bcmd.bcm.edu;Scheduler was sent the command new
11/02/2012 14:12:46;0008;PBS_Server.1833;Job;389.csg.bcmd.bcm.edu;Job Run at request of root@csg.bcmd.bcm.edu
11/02/2012 14:12:46;000d;PBS_Server.1833;Job;389.csg.bcmd.bcm.edu;Not sending email: User does not want mail of this type.
11/02/2012 14:12:46;0008;PBS_Server.1833;Job;390.csg.bcmd.bcm.edu;Job Run at request of root@csg.bcmd.bcm.edu
11/02/2012 14:12:46;000d;PBS_Server.1833;Job;390.csg.bcmd.bcm.edu;Not sending email: User does not want mail of this type.
11/02/2012 14:12:55;000d;PBS_Server.1832;Job;389.csg.bcmd.bcm.edu;Not sending email: User does not want mail of this type.
11/02/2012 14:12:55;0010;PBS_Server.1832;Job;389.csg.bcmd.bcm.edu;Exit_status=0 resources_used.cput=00:00:08 resources_used.mem=0kb resources_used.vmem=0kb resources_used.walltime=00:00:09
11/02/2012 14:12:55;0008;PBS_Server.1831;Job;389.csg.bcmd.bcm.edu;on_job_exit valid pjob: 389.csg.bcmd.bcm.edu (substate=50)
11/02/2012 14:12:55;000d;PBS_Server.1826;Job;390.csg.bcmd.bcm.edu;Not sending email: User does not want mail of this type.
11/02/2012 14:12:55;0010;PBS_Server.1826;Job;390.csg.bcmd.bcm.edu;Exit_status=0 resources_used.cput=00:00:08 resources_used.mem=61940kb resources_used.vmem=312660kb resources_used.walltime=00:00:09
11/02/2012 14:12:55;0008;PBS_Server.1825;Job;390.csg.bcmd.bcm.edu;on_job_exit valid pjob: 390.csg.bcmd.bcm.edu (substate=50)
11/02/2012 14:13:00;0040;PBS_Server.20815;Svr;csg.bcmd.bcm.edu;Scheduler was sent the command term
11/02/2012 14:14:05;0008;PBS_Server.1835;Job;387.csg.bcmd.bcm.edu;on_job_exit valid pjob: 387.csg.bcmd.bcm.edu (substate=59)
11/02/2012 14:14:05;0002;PBS_Server.1827;Svr;PBS_Server;Torque Server Version = 4.1.2, loglevel = 0
11/02/2012 14:14:05;0008;PBS_Server.1831;Job;388.csg.bcmd.bcm.edu;on_job_exit valid pjob: 388.csg.bcmd.bcm.edu (substate=59)
11/02/2012 14:14:05;0100;PBS_Server.1831;Job;388.csg.bcmd.bcm.edu;dequeuing from batch, state COMPLETE
11/02/2012 14:14:05;0100;PBS_Server.1835;Job;387.csg.bcmd.bcm.edu;dequeuing from batch, state COMPLETE
11/02/2012 14:14:10;0040;PBS_Server.20848;Svr;csg.bcmd.bcm.edu;Scheduler was sent the command term
11/02/2012 14:15:20;0100;PBS_Server.1832;Job;391.csg.bcmd.bcm.edu;enqueuing into batch, state 1 hop 1
11/02/2012 14:15:20;0008;PBS_Server.1832;Job;391.csg.bcmd.bcm.edu;Job Queued at request of jiaweixu@csg.bcmd.bcm.edu, owner = jiaweixu@csg.bcmd.bcm.edu, job name = jobname1, queue = batch
11/02/2012 14:15:20;0100;PBS_Server.1835;Job;392.csg.bcmd.bcm.edu;enqueuing into batch, state 1 hop 1
11/02/2012 14:15:20;0008;PBS_Server.1835;Job;392.csg.bcmd.bcm.edu;Job Queued at request of jiaweixu@csg.bcmd.bcm.edu, owner = jiaweixu@csg.bcmd.bcm.edu, job name = jobname2, queue = batch
11/02/2012 14:15:25;0040;PBS_Server.20932;Svr;csg.bcmd.bcm.edu;Scheduler was sent the command new
11/02/2012 14:15:26;0008;PBS_Server.1833;Job;391.csg.bcmd.bcm.edu;Job Run at request of root@csg.bcmd.bcm.edu
11/02/2012 14:15:26;000d;PBS_Server.1833;Job;391.csg.bcmd.bcm.edu;Not sending email: User does not want mail of this type.
11/02/2012 14:15:26;0008;PBS_Server.1833;Job;392.csg.bcmd.bcm.edu;Job Run at request of root@csg.bcmd.bcm.edu
11/02/2012 14:15:26;000d;PBS_Server.1833;Job;392.csg.bcmd.bcm.edu;Not sending email: User does not want mail of this type.
11/02/2012 14:15:48;000d;PBS_Server.1825;Job;391.csg.bcmd.bcm.edu;Not sending email: User does not want mail of this type.
11/02/2012 14:15:48;0010;PBS_Server.1825;Job;391.csg.bcmd.bcm.edu;Exit_status=0 resources_used.cput=00:00:08 resources_used.mem=0kb resources_used.vmem=0kb resources_used.walltime=00:00:22
11/02/2012 14:15:48;0008;PBS_Server.1831;Job;391.csg.bcmd.bcm.edu;on_job_exit valid pjob: 391.csg.bcmd.bcm.edu (substate=50)
11/02/2012 14:15:48;000d;PBS_Server.1827;Job;392.csg.bcmd.bcm.edu;Not sending email: User does not want mail of this type.
11/02/2012 14:15:48;0010;PBS_Server.1827;Job;392.csg.bcmd.bcm.edu;Exit_status=0 resources_used.cput=00:00:08 resources_used.mem=52560kb resources_used.vmem=192152kb resources_used.walltime=00:00:22
11/02/2012 14:15:48;0008;PBS_Server.1836;Job;392.csg.bcmd.bcm.edu;on_job_exit valid pjob: 392.csg.bcmd.bcm.edu (substate=50)
11/02/2012 14:15:50;0040;PBS_Server.20961;Svr;csg.bcmd.bcm.edu;Scheduler was sent the command term
11/02/2012 14:18:05;0008;PBS_Server.1828;Job;389.csg.bcmd.bcm.edu;on_job_exit valid pjob: 389.csg.bcmd.bcm.edu (substate=59)
11/02/2012 14:18:05;0100;PBS_Server.1828;Job;389.csg.bcmd.bcm.edu;dequeuing from batch, state COMPLETE
11/02/2012 14:18:05;0008;PBS_Server.1831;Job;390.csg.bcmd.bcm.edu;on_job_exit valid pjob: 390.csg.bcmd.bcm.edu (substate=59)
11/02/2012 14:18:05;0100;PBS_Server.1831;Job;390.csg.bcmd.bcm.edu;dequeuing from batch, state COMPLETE
11/02/2012 14:18:10;0040;PBS_Server.21023;Svr;csg.bcmd.bcm.edu;Scheduler was sent the command term
11/02/2012 14:19:05;0002;PBS_Server.1837;Svr;PBS_Server;Torque Server Version = 4.1.2, loglevel = 0
11/02/2012 14:20:50;0008;PBS_Server.1829;Job;391.csg.bcmd.bcm.edu;on_job_exit valid pjob: 391.csg.bcmd.bcm.edu (substate=59)
11/02/2012 14:20:50;0008;PBS_Server.1836;Job;392.csg.bcmd.bcm.edu;on_job_exit valid pjob: 392.csg.bcmd.bcm.edu (substate=59)
11/02/2012 14:20:50;0100;PBS_Server.1829;Job;391.csg.bcmd.bcm.edu;dequeuing from batch, state COMPLETE
11/02/2012 14:20:50;0100;PBS_Server.1836;Job;392.csg.bcmd.bcm.edu;dequeuing from batch, state COMPLETE
11/02/2012 14:20:55;0040;PBS_Server.21063;Svr;csg.bcmd.bcm.edu;Scheduler was sent the command term
11/02/2012 14:24:16;0002;PBS_Server.1832;Svr;PBS_Server;Torque Server Version = 4.1.2, loglevel = 0
11/02/2012 14:29:16;0002;PBS_Server.1827;Svr;PBS_Server;Torque Server Version = 4.1.2, loglevel = 0
11/02/2012 14:30:31;000d;PBS_Server.1836;Job;340.csg.bcmd.bcm.edu;Not sending email: User does not want mail of this type.
11/02/2012 14:30:31;0010;PBS_Server.1836;Job;340.csg.bcmd.bcm.edu;Exit_status=0 resources_used.cput=22:46:35 resources_used.mem=959816kb resources_used.vmem=5351888kb resources_used.walltime=03:42:26
11/02/2012 14:30:31;0008;PBS_Server.1827;Job;340.csg.bcmd.bcm.edu;on_job_exit valid pjob: 340.csg.bcmd.bcm.edu (substate=50)
11/02/2012 14:30:37;0040;PBS_Server.21185;Svr;csg.bcmd.bcm.edu;Scheduler was sent the command term
11/02/2012 14:34:27;0002;PBS_Server.1834;Svr;PBS_Server;Torque Server Version = 4.1.2, loglevel = 0
11/02/2012 14:35:42;0008;PBS_Server.1829;Job;340.csg.bcmd.bcm.edu;on_job_exit valid pjob: 340.csg.bcmd.bcm.edu (substate=59)
11/02/2012 14:35:42;0100;PBS_Server.1829;Job;340.csg.bcmd.bcm.edu;dequeuing from high, state COMPLETE
11/02/2012 14:35:47;0040;PBS_Server.21233;Svr;csg.bcmd.bcm.edu;Scheduler was sent the command term
11/02/2012 14:39:38;0002;PBS_Server.1828;Svr;PBS_Server;Torque Server Version = 4.1.2, loglevel = 0
11/02/2012 14:42:49;0100;PBS_Server.1836;Job;393.csg.bcmd.bcm.edu;enqueuing into batch, state 1 hop 1
11/02/2012 14:42:49;0008;PBS_Server.1836;Job;393.csg.bcmd.bcm.edu;Job Queued at request of jiaweixu@csg.bcmd.bcm.edu, owner = jiaweixu@csg.bcmd.bcm.edu, job name = jobname1, queue = batch
11/02/2012 14:42:49;0100;PBS_Server.1826;Job;394.csg.bcmd.bcm.edu;enqueuing into batch, state 1 hop 1
11/02/2012 14:42:49;0008;PBS_Server.1826;Job;394.csg.bcmd.bcm.edu;Job Queued at request of jiaweixu@csg.bcmd.bcm.edu, owner = jiaweixu@csg.bcmd.bcm.edu, job name = jobname2, queue = batch
11/02/2012 14:42:53;0040;PBS_Server.21402;Svr;csg.bcmd.bcm.edu;Scheduler was sent the command new
11/02/2012 14:42:54;0008;PBS_Server.1827;Job;393.csg.bcmd.bcm.edu;Job Run at request of root@csg.bcmd.bcm.edu
11/02/2012 14:42:54;000d;PBS_Server.1827;Job;393.csg.bcmd.bcm.edu;Not sending email: User does not want mail of this type.
11/02/2012 14:42:54;0008;PBS_Server.1827;Job;394.csg.bcmd.bcm.edu;Job Run at request of root@csg.bcmd.bcm.edu
11/02/2012 14:42:54;000d;PBS_Server.1827;Job;394.csg.bcmd.bcm.edu;Not sending email: User does not want mail of this type.
11/02/2012 14:42:54;000d;PBS_Server.1836;Job;393.csg.bcmd.bcm.edu;Not sending email: User does not want mail of this type.
11/02/2012 14:42:54;0010;PBS_Server.1836;Job;393.csg.bcmd.bcm.edu;Exit_status=1 resources_used.cput=00:00:00 resources_used.mem=0kb resources_used.vmem=0kb resources_used.walltime=00:00:00
11/02/2012 14:42:54;0008;PBS_Server.1832;Job;393.csg.bcmd.bcm.edu;on_job_exit valid pjob: 393.csg.bcmd.bcm.edu (substate=50)
11/02/2012 14:42:54;000d;PBS_Server.1826;Job;394.csg.bcmd.bcm.edu;Not sending email: User does not want mail of this type.
11/02/2012 14:42:54;0010;PBS_Server.1826;Job;394.csg.bcmd.bcm.edu;Exit_status=1 resources_used.cput=00:00:00 resources_used.mem=0kb resources_used.vmem=0kb resources_used.walltime=00:00:00
11/02/2012 14:42:54;0008;PBS_Server.1837;Job;394.csg.bcmd.bcm.edu;on_job_exit valid pjob: 394.csg.bcmd.bcm.edu (substate=50)
11/02/2012 14:42:58;0040;PBS_Server.21422;Svr;csg.bcmd.bcm.edu;Scheduler was sent the command term
11/02/2012 14:44:38;0002;PBS_Server.1833;Svr;PBS_Server;Torque Server Version = 4.1.2, loglevel = 0
11/02/2012 14:47:35;0100;PBS_Server.1828;Job;395.csg.bcmd.bcm.edu;enqueuing into batch, state 1 hop 1
11/02/2012 14:47:35;0008;PBS_Server.1828;Job;395.csg.bcmd.bcm.edu;Job Queued at request of jiaweixu@csg.bcmd.bcm.edu, owner = jiaweixu@csg.bcmd.bcm.edu, job name = jobname1, queue = batch
11/02/2012 14:47:35;0100;PBS_Server.1826;Job;396.csg.bcmd.bcm.edu;enqueuing into batch, state 1 hop 1
11/02/2012 14:47:35;0008;PBS_Server.1826;Job;396.csg.bcmd.bcm.edu;Job Queued at request of jiaweixu@csg.bcmd.bcm.edu, owner = jiaweixu@csg.bcmd.bcm.edu, job name = jobname2, queue = batch
11/02/2012 14:47:38;0008;PBS_Server.1827;Job;395.csg.bcmd.bcm.edu;Job Run at request of root@csg.bcmd.bcm.edu
11/02/2012 14:47:38;000d;PBS_Server.1827;Job;395.csg.bcmd.bcm.edu;Not sending email: User does not want mail of this type.
11/02/2012 14:47:38;0008;PBS_Server.1827;Job;396.csg.bcmd.bcm.edu;Job Run at request of root@csg.bcmd.bcm.edu
11/02/2012 14:47:38;000d;PBS_Server.1827;Job;396.csg.bcmd.bcm.edu;Not sending email: User does not want mail of this type.
11/02/2012 14:47:39;0040;PBS_Server.21560;Svr;csg.bcmd.bcm.edu;Scheduler was sent the command new
11/02/2012 14:47:39;000d;PBS_Server.1825;Job;395.csg.bcmd.bcm.edu;Not sending email: User does not want mail of this type.
11/02/2012 14:47:39;0010;PBS_Server.1825;Job;395.csg.bcmd.bcm.edu;Exit_status=1 resources_used.cput=00:00:00 resources_used.mem=0kb resources_used.vmem=0kb resources_used.walltime=00:00:01
11/02/2012 14:47:39;0008;PBS_Server.1834;Job;395.csg.bcmd.bcm.edu;on_job_exit valid pjob: 395.csg.bcmd.bcm.edu (substate=50)
11/02/2012 14:47:39;000d;PBS_Server.1833;Job;396.csg.bcmd.bcm.edu;Not sending email: User does not want mail of this type.
11/02/2012 14:47:39;0010;PBS_Server.1833;Job;396.csg.bcmd.bcm.edu;Exit_status=1 resources_used.cput=00:00:00 resources_used.mem=0kb resources_used.vmem=0kb resources_used.walltime=00:00:01
11/02/2012 14:47:39;0008;PBS_Server.1832;Job;396.csg.bcmd.bcm.edu;on_job_exit valid pjob: 396.csg.bcmd.bcm.edu (substate=50)
11/02/2012 14:47:44;0040;PBS_Server.21579;Svr;csg.bcmd.bcm.edu;Scheduler was sent the command term
11/02/2012 14:48:04;0008;PBS_Server.1825;Job;393.csg.bcmd.bcm.edu;on_job_exit valid pjob: 393.csg.bcmd.bcm.edu (substate=59)
11/02/2012 14:48:04;0100;PBS_Server.1825;Job;393.csg.bcmd.bcm.edu;dequeuing from batch, state COMPLETE
11/02/2012 14:48:04;0008;PBS_Server.1833;Job;394.csg.bcmd.bcm.edu;on_job_exit valid pjob: 394.csg.bcmd.bcm.edu (substate=59)
11/02/2012 14:48:04;0100;PBS_Server.1833;Job;394.csg.bcmd.bcm.edu;dequeuing from batch, state COMPLETE
11/02/2012 14:48:09;0040;PBS_Server.21597;Svr;csg.bcmd.bcm.edu;Scheduler was sent the command term
11/02/2012 14:49:49;0002;PBS_Server.1828;Svr;PBS_Server;Torque Server Version = 4.1.2, loglevel = 0
11/02/2012 14:50:09;0100;PBS_Server.1830;Job;397.csg.bcmd.bcm.edu;enqueuing into batch, state 1 hop 1
11/02/2012 14:50:09;0008;PBS_Server.1830;Job;397.csg.bcmd.bcm.edu;Job Queued at request of jiaweixu@csg.bcmd.bcm.edu, owner = jiaweixu@csg.bcmd.bcm.edu, job name = jobname1, queue = batch
11/02/2012 14:50:09;0040;PBS_Server.21675;Svr;csg.bcmd.bcm.edu;Scheduler was sent the command new
11/02/2012 14:50:09;0100;PBS_Server.1826;Job;398.csg.bcmd.bcm.edu;enqueuing into batch, state 1 hop 1
11/02/2012 14:50:09;0008;PBS_Server.1826;Job;398.csg.bcmd.bcm.edu;Job Queued at request of jiaweixu@csg.bcmd.bcm.edu, owner = jiaweixu@csg.bcmd.bcm.edu, job name = jobname2, queue = batch
11/02/2012 14:50:10;0008;PBS_Server.1827;Job;397.csg.bcmd.bcm.edu;Job Run at request of root@csg.bcmd.bcm.edu
11/02/2012 14:50:10;000d;PBS_Server.1827;Job;397.csg.bcmd.bcm.edu;Not sending email: User does not want mail of this type.
11/02/2012 14:50:10;0008;PBS_Server.1827;Job;398.csg.bcmd.bcm.edu;Job Run at request of root@csg.bcmd.bcm.edu
11/02/2012 14:50:10;000d;PBS_Server.1827;Job;398.csg.bcmd.bcm.edu;Not sending email: User does not want mail of this type.
11/02/2012 14:50:14;0040;PBS_Server.21678;Svr;csg.bcmd.bcm.edu;Scheduler was sent the command new
11/02/2012 14:51:45;000d;PBS_Server.1834;Job;397.csg.bcmd.bcm.edu;Not sending email: User does not want mail of this type.
11/02/2012 14:51:45;0010;PBS_Server.1834;Job;397.csg.bcmd.bcm.edu;Exit_status=0 resources_used.cput=00:01:20 resources_used.mem=196220kb resources_used.vmem=309072kb resources_used.walltime=00:01:35
11/02/2012 14:51:45;0008;PBS_Server.1835;Job;397.csg.bcmd.bcm.edu;on_job_exit valid pjob: 397.csg.bcmd.bcm.edu (substate=50)
11/02/2012 14:51:49;0040;PBS_Server.21699;Svr;csg.bcmd.bcm.edu;Scheduler was sent the command term
11/02/2012 14:52:39;000d;PBS_Server.1826;Job;398.csg.bcmd.bcm.edu;Not sending email: User does not want mail of this type.
11/02/2012 14:52:39;0010;PBS_Server.1826;Job;398.csg.bcmd.bcm.edu;Exit_status=0 resources_used.cput=00:02:14 resources_used.mem=238964kb resources_used.vmem=352060kb resources_used.walltime=00:02:29
11/02/2012 14:52:39;0008;PBS_Server.1830;Job;398.csg.bcmd.bcm.edu;on_job_exit valid pjob: 398.csg.bcmd.bcm.edu (substate=50)
11/02/2012 14:52:44;0040;PBS_Server.21716;Svr;csg.bcmd.bcm.edu;Scheduler was sent the command term
11/02/2012 14:52:49;0008;PBS_Server.1825;Job;395.csg.bcmd.bcm.edu;on_job_exit valid pjob: 395.csg.bcmd.bcm.edu (substate=59)
11/02/2012 14:52:49;0008;PBS_Server.1835;Job;396.csg.bcmd.bcm.edu;on_job_exit valid pjob: 396.csg.bcmd.bcm.edu (substate=59)
11/02/2012 14:52:49;0100;PBS_Server.1825;Job;395.csg.bcmd.bcm.edu;dequeuing from batch, state COMPLETE
11/02/2012 14:52:49;0100;PBS_Server.1835;Job;396.csg.bcmd.bcm.edu;dequeuing from batch, state COMPLETE
11/02/2012 14:52:54;0040;PBS_Server.21717;Svr;csg.bcmd.bcm.edu;Scheduler was sent the command term
11/02/2012 14:54:49;0002;PBS_Server.1826;Svr;PBS_Server;Torque Server Version = 4.1.2, loglevel = 0
11/02/2012 14:56:45;0008;PBS_Server.1828;Job;397.csg.bcmd.bcm.edu;on_job_exit valid pjob: 397.csg.bcmd.bcm.edu (substate=59)
11/02/2012 14:56:45;0100;PBS_Server.1828;Job;397.csg.bcmd.bcm.edu;dequeuing from batch, state COMPLETE
11/02/2012 14:56:50;0040;PBS_Server.21789;Svr;csg.bcmd.bcm.edu;Scheduler was sent the command term
11/02/2012 14:57:45;0008;PBS_Server.1837;Job;398.csg.bcmd.bcm.edu;on_job_exit valid pjob: 398.csg.bcmd.bcm.edu (substate=59)
11/02/2012 14:57:45;0100;PBS_Server.1837;Job;398.csg.bcmd.bcm.edu;dequeuing from batch, state COMPLETE
11/02/2012 14:57:50;0040;PBS_Server.21805;Svr;csg.bcmd.bcm.edu;Scheduler was sent the command term
11/02/2012 15:00:00;0002;PBS_Server.1828;Svr;PBS_Server;Torque Server Version = 4.1.2, loglevel = 0
11/02/2012 15:05:00;0002;PBS_Server.1834;Svr;PBS_Server;Torque Server Version = 4.1.2, loglevel = 0
11/02/2012 15:08:01;0040;PBS_Server.21851;Svr;csg.bcmd.bcm.edu;Scheduler was sent the command time
11/02/2012 15:10:11;0002;PBS_Server.1829;Svr;PBS_Server;Torque Server Version = 4.1.2, loglevel = 0
11/02/2012 15:15:11;0002;PBS_Server.1826;Svr;PBS_Server;Torque Server Version = 4.1.2, loglevel = 0
11/02/2012 15:18:12;0040;PBS_Server.21865;Svr;csg.bcmd.bcm.edu;Scheduler was sent the command time
11/02/2012 15:20:22;0002;PBS_Server.1836;Svr;PBS_Server;Torque Server Version = 4.1.2, loglevel = 0
11/02/2012 15:25:33;0002;PBS_Server.1825;Svr;PBS_Server;Torque Server Version = 4.1.2, loglevel = 0
11/02/2012 15:27:02;000d;PBS_Server.1828;Job;296.csg.bcmd.bcm.edu;Not sending email: User does not want mail of this type.
11/02/2012 15:27:02;0010;PBS_Server.1828;Job;296.csg.bcmd.bcm.edu;Exit_status=1 resources_used.cput=28:41:24 resources_used.mem=1082256kb resources_used.vmem=5510312kb resources_used.walltime=06:14:31
11/02/2012 15:27:02;0008;PBS_Server.1833;Job;296.csg.bcmd.bcm.edu;on_job_exit valid pjob: 296.csg.bcmd.bcm.edu (substate=50)
11/02/2012 15:27:03;0040;PBS_Server.21915;Svr;csg.bcmd.bcm.edu;Scheduler was sent the command term
11/02/2012 15:30:44;0002;PBS_Server.1831;Svr;PBS_Server;Torque Server Version = 4.1.2, loglevel = 0
11/02/2012 15:32:14;0008;PBS_Server.1835;Job;296.csg.bcmd.bcm.edu;on_job_exit valid pjob: 296.csg.bcmd.bcm.edu (substate=59)
11/02/2012 15:32:14;0100;PBS_Server.1835;Job;296.csg.bcmd.bcm.edu;dequeuing from high, state COMPLETE
11/02/2012 15:32:19;0040;PBS_Server.21951;Svr;csg.bcmd.bcm.edu;Scheduler was sent the command term
11/02/2012 15:35:46;0002;PBS_Server.1826;Svr;PBS_Server;Torque Server Version = 4.1.2, loglevel = 0
11/02/2012 15:40:51;0002;PBS_Server.1836;Svr;PBS_Server;Torque Server Version = 4.1.2, loglevel = 0
11/02/2012 15:42:29;0040;PBS_Server.21980;Svr;csg.bcmd.bcm.edu;Scheduler was sent the command time
11/02/2012 15:45:56;0002;PBS_Server.1831;Svr;PBS_Server;Torque Server Version = 4.1.2, loglevel = 0
11/02/2012 15:51:01;0002;PBS_Server.1825;Svr;PBS_Server;Torque Server Version = 4.1.2, loglevel = 0
11/02/2012 15:52:39;0040;PBS_Server.21994;Svr;csg.bcmd.bcm.edu;Scheduler was sent the command time
11/02/2012 15:56:06;0002;PBS_Server.1830;Svr;PBS_Server;Torque Server Version = 4.1.2, loglevel = 0
11/02/2012 16:01:11;0002;PBS_Server.1834;Svr;PBS_Server;Torque Server Version = 4.1.2, loglevel = 0
11/02/2012 16:02:49;0040;PBS_Server.22039;Svr;csg.bcmd.bcm.edu;Scheduler was sent the command time
11/02/2012 16:06:16;0002;PBS_Server.1836;Svr;PBS_Server;Torque Server Version = 4.1.2, loglevel = 0
11/02/2012 16:11:21;0002;PBS_Server.1828;Svr;PBS_Server;Torque Server Version = 4.1.2, loglevel = 0
11/02/2012 16:12:59;0040;PBS_Server.22141;Svr;csg.bcmd.bcm.edu;Scheduler was sent the command time
11/02/2012 16:16:26;0002;PBS_Server.1835;Svr;PBS_Server;Torque Server Version = 4.1.2, loglevel = 0
11/02/2012 16:21:31;0002;PBS_Server.1836;Svr;PBS_Server;Torque Server Version = 4.1.2, loglevel = 0
11/02/2012 16:23:09;0040;PBS_Server.22242;Svr;csg.bcmd.bcm.edu;Scheduler was sent the command time
11/02/2012 16:26:36;0002;PBS_Server.1826;Svr;PBS_Server;Torque Server Version = 4.1.2, loglevel = 0
11/02/2012 16:31:41;0002;PBS_Server.1825;Svr;PBS_Server;Torque Server Version = 4.1.2, loglevel = 0
11/02/2012 16:33:19;0040;PBS_Server.22340;Svr;csg.bcmd.bcm.edu;Scheduler was sent the command time
11/02/2012 16:36:46;0002;PBS_Server.1834;Svr;PBS_Server;Torque Server Version = 4.1.2, loglevel = 0
11/02/2012 16:41:51;0002;PBS_Server.1832;Svr;PBS_Server;Torque Server Version = 4.1.2, loglevel = 0
11/02/2012 16:43:29;0040;PBS_Server.22436;Svr;csg.bcmd.bcm.edu;Scheduler was sent the command time
11/02/2012 16:46:56;0002;PBS_Server.1830;Svr;PBS_Server;Torque Server Version = 4.1.2, loglevel = 0
11/02/2012 16:52:01;0002;PBS_Server.1827;Svr;PBS_Server;Torque Server Version = 4.1.2, loglevel = 0
11/02/2012 16:53:39;0040;PBS_Server.22531;Svr;csg.bcmd.bcm.edu;Scheduler was sent the command time
11/02/2012 16:57:06;0002;PBS_Server.1835;Svr;PBS_Server;Torque Server Version = 4.1.2, loglevel = 0
11/02/2012 17:02:11;0002;PBS_Server.1829;Svr;PBS_Server;Torque Server Version = 4.1.2, loglevel = 0
11/02/2012 17:03:49;0040;PBS_Server.22598;Svr;csg.bcmd.bcm.edu;Scheduler was sent the command time
11/02/2012 17:07:16;0002;PBS_Server.1833;Svr;PBS_Server;Torque Server Version = 4.1.2, loglevel = 0
11/02/2012 17:12:21;0002;PBS_Server.1834;Svr;PBS_Server;Torque Server Version = 4.1.2, loglevel = 0
11/02/2012 17:13:59;0040;PBS_Server.22613;Svr;csg.bcmd.bcm.edu;Scheduler was sent the command time
11/02/2012 17:17:26;0002;PBS_Server.1837;Svr;PBS_Server;Torque Server Version = 4.1.2, loglevel = 0
11/02/2012 17:22:31;0002;PBS_Server.1830;Svr;PBS_Server;Torque Server Version = 4.1.2, loglevel = 0
11/02/2012 17:24:09;0040;PBS_Server.22629;Svr;csg.bcmd.bcm.edu;Scheduler was sent the command time
11/02/2012 17:27:36;0002;PBS_Server.1828;Svr;PBS_Server;Torque Server Version = 4.1.2, loglevel = 0
11/02/2012 17:32:41;0002;PBS_Server.1829;Svr;PBS_Server;Torque Server Version = 4.1.2, loglevel = 0
11/02/2012 17:34:19;0040;PBS_Server.22663;Svr;csg.bcmd.bcm.edu;Scheduler was sent the command time
11/02/2012 17:37:46;0002;PBS_Server.1827;Svr;PBS_Server;Torque Server Version = 4.1.2, loglevel = 0
11/02/2012 17:42:51;0002;PBS_Server.1830;Svr;PBS_Server;Torque Server Version = 4.1.2, loglevel = 0
11/02/2012 17:44:29;0040;PBS_Server.22677;Svr;csg.bcmd.bcm.edu;Scheduler was sent the command time
11/02/2012 17:46:43;000d;PBS_Server.1825;Job;382.csg.bcmd.bcm.edu;Not sending email: User does not want mail of this type.
11/02/2012 17:46:43;0010;PBS_Server.1825;Job;382.csg.bcmd.bcm.edu;Exit_status=1 resources_used.cput=21:13:14 resources_used.mem=1169948kb resources_used.vmem=5596976kb resources_used.walltime=04:06:40
11/02/2012 17:46:43;0008;PBS_Server.1830;Job;382.csg.bcmd.bcm.edu;on_job_exit valid pjob: 382.csg.bcmd.bcm.edu (substate=50)
11/02/2012 17:46:47;0040;PBS_Server.22692;Svr;csg.bcmd.bcm.edu;Scheduler was sent the command term
11/02/2012 17:48:05;0002;PBS_Server.1830;Svr;PBS_Server;Torque Server Version = 4.1.2, loglevel = 0
11/02/2012 17:51:52;0008;PBS_Server.1832;Job;382.csg.bcmd.bcm.edu;on_job_exit valid pjob: 382.csg.bcmd.bcm.edu (substate=59)
11/02/2012 17:51:52;0100;PBS_Server.1832;Job;382.csg.bcmd.bcm.edu;dequeuing from high, state COMPLETE
11/02/2012 17:51:57;0040;PBS_Server.22712;Svr;csg.bcmd.bcm.edu;Scheduler was sent the command term
11/02/2012 17:53:14;0002;PBS_Server.1831;Svr;PBS_Server;Torque Server Version = 4.1.2, loglevel = 0
11/02/2012 17:58:19;0002;PBS_Server.1825;Svr;PBS_Server;Torque Server Version = 4.1.2, loglevel = 0
11/02/2012 18:02:11;0040;PBS_Server.22755;Svr;csg.bcmd.bcm.edu;Scheduler was sent the command time
11/02/2012 18:03:24;0002;PBS_Server.1832;Svr;PBS_Server;Torque Server Version = 4.1.2, loglevel = 0
11/02/2012 18:08:29;0002;PBS_Server.1827;Svr;PBS_Server;Torque Server Version = 4.1.2, loglevel = 0
11/02/2012 18:12:21;0040;PBS_Server.22850;Svr;csg.bcmd.bcm.edu;Scheduler was sent the command time
11/02/2012 18:13:34;0002;PBS_Server.1835;Svr;PBS_Server;Torque Server Version = 4.1.2, loglevel = 0
11/02/2012 18:18:39;0002;PBS_Server.1831;Svr;PBS_Server;Torque Server Version = 4.1.2, loglevel = 0
11/02/2012 18:22:31;0040;PBS_Server.22967;Svr;csg.bcmd.bcm.edu;Scheduler was sent the command time
11/02/2012 18:23:44;0002;PBS_Server.1828;Svr;PBS_Server;Torque Server Version = 4.1.2, loglevel = 0
11/02/2012 18:28:49;0002;PBS_Server.1835;Svr;PBS_Server;Torque Server Version = 4.1.2, loglevel = 0
11/02/2012 18:32:41;0040;PBS_Server.23240;Svr;csg.bcmd.bcm.edu;Scheduler was sent the command time
11/02/2012 18:33:54;0002;PBS_Server.1827;Svr;PBS_Server;Torque Server Version = 4.1.2, loglevel = 0
11/02/2012 18:38:59;0002;PBS_Server.1836;Svr;PBS_Server;Torque Server Version = 4.1.2, loglevel = 0
11/02/2012 18:42:51;0040;PBS_Server.23335;Svr;csg.bcmd.bcm.edu;Scheduler was sent the command time
11/02/2012 18:44:04;0002;PBS_Server.1826;Svr;PBS_Server;Torque Server Version = 4.1.2, loglevel = 0
11/02/2012 18:49:09;0002;PBS_Server.1828;Svr;PBS_Server;Torque Server Version = 4.1.2, loglevel = 0
11/02/2012 18:53:01;0040;PBS_Server.23428;Svr;csg.bcmd.bcm.edu;Scheduler was sent the command time
11/02/2012 18:54:14;0002;PBS_Server.1829;Svr;PBS_Server;Torque Server Version = 4.1.2, loglevel = 0
11/02/2012 18:59:19;0002;PBS_Server.1837;Svr;PBS_Server;Torque Server Version = 4.1.2, loglevel = 0
11/02/2012 19:03:11;0040;PBS_Server.23528;Svr;csg.bcmd.bcm.edu;Scheduler was sent the command time
11/02/2012 19:04:24;0002;PBS_Server.1833;Svr;PBS_Server;Torque Server Version = 4.1.2, loglevel = 0
11/02/2012 19:09:29;0002;PBS_Server.1827;Svr;PBS_Server;Torque Server Version = 4.1.2, loglevel = 0
11/02/2012 19:13:21;0040;PBS_Server.23566;Svr;csg.bcmd.bcm.edu;Scheduler was sent the command time
11/02/2012 19:14:34;0002;PBS_Server.1828;Svr;PBS_Server;Torque Server Version = 4.1.2, loglevel = 0
11/02/2012 19:19:39;0002;PBS_Server.1834;Svr;PBS_Server;Torque Server Version = 4.1.2, loglevel = 0
11/02/2012 19:23:31;0040;PBS_Server.23583;Svr;csg.bcmd.bcm.edu;Scheduler was sent the command time
11/02/2012 19:24:44;0002;PBS_Server.1837;Svr;PBS_Server;Torque Server Version = 4.1.2, loglevel = 0
11/02/2012 19:29:43;0100;PBS_Server.1833;Job;399.csg.bcmd.bcm.edu;enqueuing into batch, state 1 hop 1
11/02/2012 19:29:43;0008;PBS_Server.1833;Job;399.csg.bcmd.bcm.edu;Job Queued at request of lacuesta@csg.bcmd.bcm.edu, owner = lacuesta@csg.bcmd.bcm.edu, job name = jobname1, queue = batch
11/02/2012 19:29:44;0008;PBS_Server.1835;Job;399.csg.bcmd.bcm.edu;Job Run at request of root@csg.bcmd.bcm.edu
11/02/2012 19:29:44;0100;PBS_Server.1829;Job;400.csg.bcmd.bcm.edu;enqueuing into batch, state 1 hop 1
11/02/2012 19:29:44;0008;PBS_Server.1829;Job;400.csg.bcmd.bcm.edu;Job Queued at request of lacuesta@csg.bcmd.bcm.edu, owner = lacuesta@csg.bcmd.bcm.edu, job name = jobname2, queue = batch
11/02/2012 19:29:44;000d;PBS_Server.1835;Job;399.csg.bcmd.bcm.edu;Not sending email: User does not want mail of this type.
11/02/2012 19:29:44;0040;PBS_Server.23674;Svr;csg.bcmd.bcm.edu;Scheduler was sent the command new
11/02/2012 19:29:44;0040;PBS_Server.23676;Svr;csg.bcmd.bcm.edu;Scheduler was sent the command new
11/02/2012 19:29:45;0008;PBS_Server.1835;Job;400.csg.bcmd.bcm.edu;Job Run at request of root@csg.bcmd.bcm.edu
11/02/2012 19:29:45;000d;PBS_Server.1835;Job;400.csg.bcmd.bcm.edu;Not sending email: User does not want mail of this type.
11/02/2012 19:29:49;0002;PBS_Server.1834;Svr;PBS_Server;Torque Server Version = 4.1.2, loglevel = 0
11/02/2012 19:29:56;000d;PBS_Server.1831;Job;399.csg.bcmd.bcm.edu;Not sending email: User does not want mail of this type.
11/02/2012 19:29:56;0010;PBS_Server.1831;Job;399.csg.bcmd.bcm.edu;Exit_status=0 resources_used.cput=00:00:10 resources_used.mem=0kb resources_used.vmem=0kb resources_used.walltime=00:00:12
11/02/2012 19:29:56;0008;PBS_Server.1830;Job;399.csg.bcmd.bcm.edu;on_job_exit valid pjob: 399.csg.bcmd.bcm.edu (substate=50)
11/02/2012 19:29:59;0040;PBS_Server.23689;Svr;csg.bcmd.bcm.edu;Scheduler was sent the command term
11/02/2012 19:30:01;000d;PBS_Server.1837;Job;400.csg.bcmd.bcm.edu;Not sending email: User does not want mail of this type.
11/02/2012 19:30:01;0010;PBS_Server.1837;Job;400.csg.bcmd.bcm.edu;Exit_status=0 resources_used.cput=00:00:11 resources_used.mem=43220kb resources_used.vmem=292084kb resources_used.walltime=00:00:16
11/02/2012 19:30:01;0008;PBS_Server.1833;Job;400.csg.bcmd.bcm.edu;on_job_exit valid pjob: 400.csg.bcmd.bcm.edu (substate=50)
11/02/2012 19:30:04;0040;PBS_Server.23703;Svr;csg.bcmd.bcm.edu;Scheduler was sent the command term
11/02/2012 19:31:50;0100;PBS_Server.1834;Job;401.csg.bcmd.bcm.edu;enqueuing into batch, state 1 hop 1
11/02/2012 19:31:50;0008;PBS_Server.1834;Job;401.csg.bcmd.bcm.edu;Job Queued at request of lacuesta@csg.bcmd.bcm.edu, owner = lacuesta@csg.bcmd.bcm.edu, job name = jobname1, queue = batch
11/02/2012 19:31:50;0100;PBS_Server.1832;Job;402.csg.bcmd.bcm.edu;enqueuing into batch, state 1 hop 1
11/02/2012 19:31:50;0008;PBS_Server.1832;Job;402.csg.bcmd.bcm.edu;Job Queued at request of lacuesta@csg.bcmd.bcm.edu, owner = lacuesta@csg.bcmd.bcm.edu, job name = jobname2, queue = batch
11/02/2012 19:31:54;0040;PBS_Server.23756;Svr;csg.bcmd.bcm.edu;Scheduler was sent the command new
11/02/2012 19:31:55;0008;PBS_Server.1835;Job;401.csg.bcmd.bcm.edu;Job Run at request of root@csg.bcmd.bcm.edu
11/02/2012 19:31:55;000d;PBS_Server.1835;Job;401.csg.bcmd.bcm.edu;Not sending email: User does not want mail of this type.
11/02/2012 19:31:55;0008;PBS_Server.1835;Job;402.csg.bcmd.bcm.edu;Job Run at request of root@csg.bcmd.bcm.edu
11/02/2012 19:31:55;000d;PBS_Server.1835;Job;402.csg.bcmd.bcm.edu;Not sending email: User does not want mail of this type.
11/02/2012 19:31:55;000d;PBS_Server.1827;Job;401.csg.bcmd.bcm.edu;Not sending email: User does not want mail of this type.
11/02/2012 19:31:55;0010;PBS_Server.1827;Job;401.csg.bcmd.bcm.edu;Exit_status=1 resources_used.cput=00:00:00 resources_used.mem=0kb resources_used.vmem=0kb resources_used.walltime=00:00:00
11/02/2012 19:31:55;0008;PBS_Server.1830;Job;401.csg.bcmd.bcm.edu;on_job_exit valid pjob: 401.csg.bcmd.bcm.edu (substate=50)
11/02/2012 19:31:55;000d;PBS_Server.1836;Job;402.csg.bcmd.bcm.edu;Not sending email: User does not want mail of this type.
11/02/2012 19:31:55;0010;PBS_Server.1836;Job;402.csg.bcmd.bcm.edu;Exit_status=1 resources_used.cput=00:00:00 resources_used.mem=0kb resources_used.vmem=0kb resources_used.walltime=00:00:00
11/02/2012 19:31:55;0008;PBS_Server.1831;Job;402.csg.bcmd.bcm.edu;on_job_exit valid pjob: 402.csg.bcmd.bcm.edu (substate=50)
11/02/2012 19:31:59;0040;PBS_Server.23773;Svr;csg.bcmd.bcm.edu;Scheduler was sent the command term
11/02/2012 19:34:49;0002;PBS_Server.1836;Svr;PBS_Server;Torque Server Version = 4.1.2, loglevel = 0
11/02/2012 19:34:55;0100;PBS_Server.1834;Job;403.csg.bcmd.bcm.edu;enqueuing into batch, state 1 hop 1
11/02/2012 19:34:55;0008;PBS_Server.1834;Job;403.csg.bcmd.bcm.edu;Job Queued at request of lacuesta@csg.bcmd.bcm.edu, owner = lacuesta@csg.bcmd.bcm.edu, job name = jobname1, queue = batch
11/02/2012 19:34:56;0100;PBS_Server.1825;Job;404.csg.bcmd.bcm.edu;enqueuing into batch, state 1 hop 1
11/02/2012 19:34:56;0008;PBS_Server.1825;Job;404.csg.bcmd.bcm.edu;Job Queued at request of lacuesta@csg.bcmd.bcm.edu, owner = lacuesta@csg.bcmd.bcm.edu, job name = jobname2, queue = batch
11/02/2012 19:34:59;0040;PBS_Server.23973;Svr;csg.bcmd.bcm.edu;Scheduler was sent the command new
11/02/2012 19:35:00;0008;PBS_Server.1835;Job;403.csg.bcmd.bcm.edu;Job Run at request of root@csg.bcmd.bcm.edu
11/02/2012 19:35:00;000d;PBS_Server.1835;Job;403.csg.bcmd.bcm.edu;Not sending email: User does not want mail of this type.
11/02/2012 19:35:00;0008;PBS_Server.1835;Job;404.csg.bcmd.bcm.edu;Job Run at request of root@csg.bcmd.bcm.edu
11/02/2012 19:35:00;000d;PBS_Server.1835;Job;404.csg.bcmd.bcm.edu;Not sending email: User does not want mail of this type.
11/02/2012 19:35:00;000d;PBS_Server.1836;Job;403.csg.bcmd.bcm.edu;Not sending email: User does not want mail of this type.
11/02/2012 19:35:00;0010;PBS_Server.1836;Job;403.csg.bcmd.bcm.edu;Exit_status=1 resources_used.cput=00:00:00 resources_used.mem=0kb resources_used.vmem=0kb resources_used.walltime=00:00:00
11/02/2012 19:35:00;0008;PBS_Server.1829;Job;403.csg.bcmd.bcm.edu;on_job_exit valid pjob: 403.csg.bcmd.bcm.edu (substate=50)
11/02/2012 19:35:00;000d;PBS_Server.1833;Job;404.csg.bcmd.bcm.edu;Not sending email: User does not want mail of this type.
11/02/2012 19:35:00;0010;PBS_Server.1833;Job;404.csg.bcmd.bcm.edu;Exit_status=1 resources_used.cput=00:00:00 resources_used.mem=0kb resources_used.vmem=0kb resources_used.walltime=00:00:00
11/02/2012 19:35:00;0008;PBS_Server.1826;Job;404.csg.bcmd.bcm.edu;on_job_exit valid pjob: 404.csg.bcmd.bcm.edu (substate=50)
11/02/2012 19:35:04;0100;PBS_Server.1831;Job;405.csg.bcmd.bcm.edu;enqueuing into batch, state 1 hop 1
11/02/2012 19:35:04;0008;PBS_Server.1831;Job;405.csg.bcmd.bcm.edu;Job Queued at request of lacuesta@csg.bcmd.bcm.edu, owner = lacuesta@csg.bcmd.bcm.edu, job name = jobname1, queue = batch
11/02/2012 19:35:04;0100;PBS_Server.1832;Job;406.csg.bcmd.bcm.edu;enqueuing into batch, state 1 hop 1
11/02/2012 19:35:04;0008;PBS_Server.1832;Job;406.csg.bcmd.bcm.edu;Job Queued at request of lacuesta@csg.bcmd.bcm.edu, owner = lacuesta@csg.bcmd.bcm.edu, job name = jobname2, queue = batch
11/02/2012 19:35:04;0008;PBS_Server.1830;Job;400.csg.bcmd.bcm.edu;on_job_exit valid pjob: 400.csg.bcmd.bcm.edu (substate=59)
11/02/2012 19:35:04;0100;PBS_Server.1830;Job;400.csg.bcmd.bcm.edu;dequeuing from batch, state COMPLETE
11/02/2012 19:35:04;0008;PBS_Server.1828;Job;399.csg.bcmd.bcm.edu;on_job_exit valid pjob: 399.csg.bcmd.bcm.edu (substate=59)
11/02/2012 19:35:04;0100;PBS_Server.1828;Job;399.csg.bcmd.bcm.edu;dequeuing from batch, state COMPLETE
11/02/2012 19:35:04;0040;PBS_Server.24040;Svr;csg.bcmd.bcm.edu;Scheduler was sent the command new
11/02/2012 19:35:05;0008;PBS_Server.1835;Job;405.csg.bcmd.bcm.edu;Job Run at request of root@csg.bcmd.bcm.edu
11/02/2012 19:35:05;000d;PBS_Server.1835;Job;405.csg.bcmd.bcm.edu;Not sending email: User does not want mail of this type.
11/02/2012 19:35:05;0008;PBS_Server.1835;Job;406.csg.bcmd.bcm.edu;Job Run at request of root@csg.bcmd.bcm.edu
11/02/2012 19:35:05;000d;PBS_Server.1835;Job;406.csg.bcmd.bcm.edu;Not sending email: User does not want mail of this type.
11/02/2012 19:35:09;0040;PBS_Server.24042;Svr;csg.bcmd.bcm.edu;Scheduler was sent the command term
11/02/2012 19:35:16;000d;PBS_Server.1827;Job;405.csg.bcmd.bcm.edu;Not sending email: User does not want mail of this type.
11/02/2012 19:35:16;0010;PBS_Server.1827;Job;405.csg.bcmd.bcm.edu;Exit_status=0 resources_used.cput=00:00:10 resources_used.mem=0kb resources_used.vmem=0kb resources_used.walltime=00:00:11
11/02/2012 19:35:16;0008;PBS_Server.1829;Job;405.csg.bcmd.bcm.edu;on_job_exit valid pjob: 405.csg.bcmd.bcm.edu (substate=50)
11/02/2012 19:35:18;000d;PBS_Server.1825;Job;406.csg.bcmd.bcm.edu;Not sending email: User does not want mail of this type.
11/02/2012 19:35:18;0010;PBS_Server.1825;Job;406.csg.bcmd.bcm.edu;Exit_status=0 resources_used.cput=00:00:11 resources_used.mem=43220kb resources_used.vmem=292084kb resources_used.walltime=00:00:13
11/02/2012 19:35:18;0008;PBS_Server.1831;Job;406.csg.bcmd.bcm.edu;on_job_exit valid pjob: 406.csg.bcmd.bcm.edu (substate=50)
11/02/2012 19:35:19;0040;PBS_Server.24059;Svr;csg.bcmd.bcm.edu;Scheduler was sent the command term
11/02/2012 19:37:04;0008;PBS_Server.1828;Job;401.csg.bcmd.bcm.edu;on_job_exit valid pjob: 401.csg.bcmd.bcm.edu (substate=59)
11/02/2012 19:37:04;0008;PBS_Server.1830;Job;402.csg.bcmd.bcm.edu;on_job_exit valid pjob: 402.csg.bcmd.bcm.edu (substate=59)
11/02/2012 19:37:04;0100;PBS_Server.1828;Job;401.csg.bcmd.bcm.edu;dequeuing from batch, state COMPLETE
11/02/2012 19:37:04;0100;PBS_Server.1830;Job;402.csg.bcmd.bcm.edu;dequeuing from batch, state COMPLETE
11/02/2012 19:37:09;0040;PBS_Server.24183;Svr;csg.bcmd.bcm.edu;Scheduler was sent the command term
11/02/2012 19:39:50;0002;PBS_Server.1827;Svr;PBS_Server;Torque Server Version = 4.1.2, loglevel = 0
11/02/2012 19:40:05;0008;PBS_Server.1830;Job;403.csg.bcmd.bcm.edu;on_job_exit valid pjob: 403.csg.bcmd.bcm.edu (substate=59)
11/02/2012 19:40:05;0100;PBS_Server.1830;Job;403.csg.bcmd.bcm.edu;dequeuing from batch, state COMPLETE
11/02/2012 19:40:05;0008;PBS_Server.1836;Job;404.csg.bcmd.bcm.edu;on_job_exit valid pjob: 404.csg.bcmd.bcm.edu (substate=59)
11/02/2012 19:40:05;0100;PBS_Server.1836;Job;404.csg.bcmd.bcm.edu;dequeuing from batch, state COMPLETE
11/02/2012 19:40:10;0040;PBS_Server.24189;Svr;csg.bcmd.bcm.edu;Scheduler was sent the command term
11/02/2012 19:40:20;0008;PBS_Server.1831;Job;405.csg.bcmd.bcm.edu;on_job_exit valid pjob: 405.csg.bcmd.bcm.edu (substate=59)
11/02/2012 19:40:20;0008;PBS_Server.1827;Job;406.csg.bcmd.bcm.edu;on_job_exit valid pjob: 406.csg.bcmd.bcm.edu (substate=59)
11/02/2012 19:40:20;0100;PBS_Server.1831;Job;405.csg.bcmd.bcm.edu;dequeuing from batch, state COMPLETE
11/02/2012 19:40:20;0100;PBS_Server.1827;Job;406.csg.bcmd.bcm.edu;dequeuing from batch, state COMPLETE
11/02/2012 19:40:25;0040;PBS_Server.24190;Svr;csg.bcmd.bcm.edu;Scheduler was sent the command term
11/02/2012 19:44:50;0002;PBS_Server.1834;Svr;PBS_Server;Torque Server Version = 4.1.2, loglevel = 0
11/02/2012 19:47:39;0100;PBS_Server.1831;Job;407.csg.bcmd.bcm.edu;enqueuing into batch, state 1 hop 1
11/02/2012 19:47:39;0008;PBS_Server.1831;Job;407.csg.bcmd.bcm.edu;Job Queued at request of lacuesta@csg.bcmd.bcm.edu, owner = lacuesta@csg.bcmd.bcm.edu, job name = jobname1, queue = batch
11/02/2012 19:47:40;0008;PBS_Server.1834;Job;407.csg.bcmd.bcm.edu;Job Run at request of root@csg.bcmd.bcm.edu
11/02/2012 19:47:40;0100;PBS_Server.1827;Job;408.csg.bcmd.bcm.edu;enqueuing into batch, state 1 hop 1
11/02/2012 19:47:40;0008;PBS_Server.1827;Job;408.csg.bcmd.bcm.edu;Job Queued at request of lacuesta@csg.bcmd.bcm.edu, owner = lacuesta@csg.bcmd.bcm.edu, job name = jobname2, queue = batch
11/02/2012 19:47:40;000d;PBS_Server.1834;Job;407.csg.bcmd.bcm.edu;Not sending email: User does not want mail of this type.
11/02/2012 19:47:40;0040;PBS_Server.24330;Svr;csg.bcmd.bcm.edu;Scheduler was sent the command new
11/02/2012 19:47:40;0040;PBS_Server.24332;Svr;csg.bcmd.bcm.edu;Scheduler was sent the command new
11/02/2012 19:47:41;0008;PBS_Server.1834;Job;408.csg.bcmd.bcm.edu;Job Run at request of root@csg.bcmd.bcm.edu
11/02/2012 19:47:41;000d;PBS_Server.1834;Job;408.csg.bcmd.bcm.edu;Not sending email: User does not want mail of this type.
11/02/2012 19:47:59;000d;PBS_Server.1836;Job;408.csg.bcmd.bcm.edu;Not sending email: User does not want mail of this type.
11/02/2012 19:47:59;0010;PBS_Server.1836;Job;408.csg.bcmd.bcm.edu;Exit_status=1 resources_used.cput=00:00:00 resources_used.mem=0kb resources_used.vmem=0kb resources_used.walltime=00:00:18
11/02/2012 19:47:59;0008;PBS_Server.1827;Job;408.csg.bcmd.bcm.edu;on_job_exit valid pjob: 408.csg.bcmd.bcm.edu (substate=50)
11/02/2012 19:48:00;0040;PBS_Server.24352;Svr;csg.bcmd.bcm.edu;Scheduler was sent the command term
11/02/2012 19:48:07;000d;PBS_Server.1825;Job;407.csg.bcmd.bcm.edu;Not sending email: User does not want mail of this type.
11/02/2012 19:48:07;0010;PBS_Server.1825;Job;407.csg.bcmd.bcm.edu;Exit_status=1 resources_used.cput=00:00:00 resources_used.mem=1132kb resources_used.vmem=13560kb resources_used.walltime=00:00:27
11/02/2012 19:48:07;0008;PBS_Server.1833;Job;407.csg.bcmd.bcm.edu;on_job_exit valid pjob: 407.csg.bcmd.bcm.edu (substate=50)
11/02/2012 19:48:10;0040;PBS_Server.24361;Svr;csg.bcmd.bcm.edu;Scheduler was sent the command term
11/02/2012 19:50:00;0002;PBS_Server.1826;Svr;PBS_Server;Torque Server Version = 4.1.2, loglevel = 0
11/02/2012 19:51:33;000d;PBS_Server.1828;Job;386.csg.bcmd.bcm.edu;Not sending email: User does not want mail of this type.
11/02/2012 19:51:33;0010;PBS_Server.1828;Job;386.csg.bcmd.bcm.edu;Exit_status=1 resources_used.cput=57:26:02 resources_used.mem=1311976kb resources_used.vmem=5740752kb resources_used.walltime=05:45:34
11/02/2012 19:51:33;0008;PBS_Server.1827;Job;386.csg.bcmd.bcm.edu;on_job_exit valid pjob: 386.csg.bcmd.bcm.edu (substate=50)
11/02/2012 19:51:36;0040;PBS_Server.24449;Svr;csg.bcmd.bcm.edu;Scheduler was sent the command term
11/02/2012 19:53:11;0008;PBS_Server.1835;Job;408.csg.bcmd.bcm.edu;on_job_exit valid pjob: 408.csg.bcmd.bcm.edu (substate=59)
11/02/2012 19:53:11;0008;PBS_Server.1828;Job;407.csg.bcmd.bcm.edu;on_job_exit valid pjob: 407.csg.bcmd.bcm.edu (substate=59)
11/02/2012 19:53:11;0100;PBS_Server.1835;Job;408.csg.bcmd.bcm.edu;dequeuing from batch, state COMPLETE
11/02/2012 19:53:11;0100;PBS_Server.1828;Job;407.csg.bcmd.bcm.edu;dequeuing from batch, state COMPLETE
11/02/2012 19:53:16;0040;PBS_Server.24459;Svr;csg.bcmd.bcm.edu;Scheduler was sent the command term
11/02/2012 19:55:11;0002;PBS_Server.1827;Svr;PBS_Server;Torque Server Version = 4.1.2, loglevel = 0
11/02/2012 19:55:12;0100;PBS_Server.1829;Job;409.csg.bcmd.bcm.edu;enqueuing into batch, state 1 hop 1
11/02/2012 19:55:12;0008;PBS_Server.1829;Job;409.csg.bcmd.bcm.edu;Job Queued at request of lacuesta@csg.bcmd.bcm.edu, owner = lacuesta@csg.bcmd.bcm.edu, job name = jobname1, queue = batch
11/02/2012 19:55:12;0100;PBS_Server.1832;Job;410.csg.bcmd.bcm.edu;enqueuing into batch, state 1 hop 1
11/02/2012 19:55:12;0008;PBS_Server.1832;Job;410.csg.bcmd.bcm.edu;Job Queued at request of lacuesta@csg.bcmd.bcm.edu, owner = lacuesta@csg.bcmd.bcm.edu, job name = jobname2, queue = batch
11/02/2012 19:55:16;0040;PBS_Server.24501;Svr;csg.bcmd.bcm.edu;Scheduler was sent the command new
11/02/2012 19:55:17;0008;PBS_Server.1834;Job;409.csg.bcmd.bcm.edu;Job Run at request of root@csg.bcmd.bcm.edu
11/02/2012 19:55:17;000d;PBS_Server.1834;Job;409.csg.bcmd.bcm.edu;Not sending email: User does not want mail of this type.
11/02/2012 19:55:17;0008;PBS_Server.1834;Job;410.csg.bcmd.bcm.edu;Job Run at request of root@csg.bcmd.bcm.edu
11/02/2012 19:55:17;000d;PBS_Server.1834;Job;410.csg.bcmd.bcm.edu;Not sending email: User does not want mail of this type.
11/02/2012 19:56:41;0008;PBS_Server.1826;Job;386.csg.bcmd.bcm.edu;on_job_exit valid pjob: 386.csg.bcmd.bcm.edu (substate=59)
11/02/2012 19:56:41;0100;PBS_Server.1826;Job;386.csg.bcmd.bcm.edu;dequeuing from high, state COMPLETE
11/02/2012 19:56:46;0040;PBS_Server.24504;Svr;csg.bcmd.bcm.edu;Scheduler was sent the command term
11/02/2012 19:56:52;000d;PBS_Server.1832;Job;410.csg.bcmd.bcm.edu;Not sending email: User does not want mail of this type.
11/02/2012 19:56:52;0010;PBS_Server.1832;Job;410.csg.bcmd.bcm.edu;Exit_status=0 resources_used.cput=00:00:11 resources_used.mem=114212kb resources_used.vmem=256076kb resources_used.walltime=00:01:35
11/02/2012 19:56:52;0008;PBS_Server.1830;Job;410.csg.bcmd.bcm.edu;on_job_exit valid pjob: 410.csg.bcmd.bcm.edu (substate=50)
11/02/2012 19:56:56;0040;PBS_Server.24515;Svr;csg.bcmd.bcm.edu;Scheduler was sent the command term
11/02/2012 19:57:00;000d;PBS_Server.1832;Job;409.csg.bcmd.bcm.edu;Not sending email: User does not want mail of this type.
11/02/2012 19:57:00;0010;PBS_Server.1832;Job;409.csg.bcmd.bcm.edu;Exit_status=0 resources_used.cput=00:00:10 resources_used.mem=41740kb resources_used.vmem=290876kb resources_used.walltime=00:01:43
11/02/2012 19:57:00;0008;PBS_Server.1835;Job;409.csg.bcmd.bcm.edu;on_job_exit valid pjob: 409.csg.bcmd.bcm.edu (substate=50)
11/02/2012 19:57:01;0040;PBS_Server.24527;Svr;csg.bcmd.bcm.edu;Scheduler was sent the command term
11/02/2012 20:00:12;0002;PBS_Server.1835;Svr;PBS_Server;Torque Server Version = 4.1.2, loglevel = 0
11/02/2012 20:01:57;0008;PBS_Server.1837;Job;410.csg.bcmd.bcm.edu;on_job_exit valid pjob: 410.csg.bcmd.bcm.edu (substate=59)
11/02/2012 20:01:57;0100;PBS_Server.1837;Job;410.csg.bcmd.bcm.edu;dequeuing from batch, state COMPLETE
11/02/2012 20:02:02;0040;PBS_Server.24599;Svr;csg.bcmd.bcm.edu;Scheduler was sent the command term
11/02/2012 20:02:12;0008;PBS_Server.1832;Job;409.csg.bcmd.bcm.edu;on_job_exit valid pjob: 409.csg.bcmd.bcm.edu (substate=59)
11/02/2012 20:02:12;0100;PBS_Server.1832;Job;409.csg.bcmd.bcm.edu;dequeuing from batch, state COMPLETE
11/02/2012 20:02:17;0040;PBS_Server.24601;Svr;csg.bcmd.bcm.edu;Scheduler was sent the command term
11/02/2012 20:02:51;0100;PBS_Server.1837;Job;411.csg.bcmd.bcm.edu;enqueuing into batch, state 1 hop 1
11/02/2012 20:02:51;0008;PBS_Server.1837;Job;411.csg.bcmd.bcm.edu;Job Queued at request of lacuesta@csg.bcmd.bcm.edu, owner = lacuesta@csg.bcmd.bcm.edu, job name = jobname1, queue = batch
11/02/2012 20:02:51;0100;PBS_Server.1835;Job;412.csg.bcmd.bcm.edu;enqueuing into batch, state 1 hop 1
11/02/2012 20:02:51;0008;PBS_Server.1835;Job;412.csg.bcmd.bcm.edu;Job Queued at request of lacuesta@csg.bcmd.bcm.edu, owner = lacuesta@csg.bcmd.bcm.edu, job name = jobname2, queue = batch
11/02/2012 20:02:52;0040;PBS_Server.24642;Svr;csg.bcmd.bcm.edu;Scheduler was sent the command new
11/02/2012 20:02:53;0008;PBS_Server.1834;Job;411.csg.bcmd.bcm.edu;Job Run at request of root@csg.bcmd.bcm.edu
11/02/2012 20:02:53;000d;PBS_Server.1834;Job;411.csg.bcmd.bcm.edu;Not sending email: User does not want mail of this type.
11/02/2012 20:02:53;0008;PBS_Server.1834;Job;412.csg.bcmd.bcm.edu;Job Run at request of root@csg.bcmd.bcm.edu
11/02/2012 20:02:53;000d;PBS_Server.1834;Job;412.csg.bcmd.bcm.edu;Not sending email: User does not want mail of this type.
11/02/2012 20:03:04;000d;PBS_Server.1831;Job;411.csg.bcmd.bcm.edu;Not sending email: User does not want mail of this type.
11/02/2012 20:03:04;0010;PBS_Server.1831;Job;411.csg.bcmd.bcm.edu;Exit_status=0 resources_used.cput=00:00:10 resources_used.mem=0kb resources_used.vmem=0kb resources_used.walltime=00:00:11
11/02/2012 20:03:04;0008;PBS_Server.1836;Job;411.csg.bcmd.bcm.edu;on_job_exit valid pjob: 411.csg.bcmd.bcm.edu (substate=50)
11/02/2012 20:03:05;000d;PBS_Server.1832;Job;412.csg.bcmd.bcm.edu;Not sending email: User does not want mail of this type.
11/02/2012 20:03:05;0010;PBS_Server.1832;Job;412.csg.bcmd.bcm.edu;Exit_status=0 resources_used.cput=00:00:11 resources_used.mem=43216kb resources_used.vmem=292084kb resources_used.walltime=00:00:12
11/02/2012 20:03:05;0008;PBS_Server.1825;Job;412.csg.bcmd.bcm.edu;on_job_exit valid pjob: 412.csg.bcmd.bcm.edu (substate=50)
11/02/2012 20:03:07;0040;PBS_Server.24698;Svr;csg.bcmd.bcm.edu;Scheduler was sent the command term
11/02/2012 20:05:12;0002;PBS_Server.1826;Svr;PBS_Server;Torque Server Version = 4.1.2, loglevel = 0
11/02/2012 20:08:12;0008;PBS_Server.1831;Job;411.csg.bcmd.bcm.edu;on_job_exit valid pjob: 411.csg.bcmd.bcm.edu (substate=59)
11/02/2012 20:08:12;0008;PBS_Server.1825;Job;412.csg.bcmd.bcm.edu;on_job_exit valid pjob: 412.csg.bcmd.bcm.edu (substate=59)
11/02/2012 20:08:12;0100;PBS_Server.1831;Job;411.csg.bcmd.bcm.edu;dequeuing from batch, state COMPLETE
11/02/2012 20:08:12;0100;PBS_Server.1825;Job;412.csg.bcmd.bcm.edu;dequeuing from batch, state COMPLETE
11/02/2012 20:08:17;0040;PBS_Server.25671;Svr;csg.bcmd.bcm.edu;Scheduler was sent the command term
11/02/2012 20:10:23;0002;PBS_Server.1837;Svr;PBS_Server;Torque Server Version = 4.1.2, loglevel = 0
11/02/2012 20:15:23;0002;PBS_Server.1826;Svr;PBS_Server;Torque Server Version = 4.1.2, loglevel = 0
11/02/2012 20:16:53;0100;PBS_Server.1831;Job;413.csg.bcmd.bcm.edu;enqueuing into batch, state 1 hop 1
11/02/2012 20:16:53;0008;PBS_Server.1831;Job;413.csg.bcmd.bcm.edu;Job Queued at request of lacuesta@csg.bcmd.bcm.edu, owner = lacuesta@csg.bcmd.bcm.edu, job name = jobname1, queue = batch
11/02/2012 20:16:54;0100;PBS_Server.1833;Job;414.csg.bcmd.bcm.edu;enqueuing into batch, state 1 hop 1
11/02/2012 20:16:54;0008;PBS_Server.1833;Job;414.csg.bcmd.bcm.edu;Job Queued at request of lacuesta@csg.bcmd.bcm.edu, owner = lacuesta@csg.bcmd.bcm.edu, job name = jobname2, queue = batch
11/02/2012 20:16:58;0040;PBS_Server.25788;Svr;csg.bcmd.bcm.edu;Scheduler was sent the command new
11/02/2012 20:16:59;0008;PBS_Server.1834;Job;413.csg.bcmd.bcm.edu;Job Run at request of root@csg.bcmd.bcm.edu
11/02/2012 20:16:59;000d;PBS_Server.1834;Job;413.csg.bcmd.bcm.edu;Not sending email: User does not want mail of this type.
11/02/2012 20:16:59;0008;PBS_Server.1834;Job;414.csg.bcmd.bcm.edu;Job Run at request of root@csg.bcmd.bcm.edu
11/02/2012 20:16:59;000d;PBS_Server.1834;Job;414.csg.bcmd.bcm.edu;Not sending email: User does not want mail of this type.
11/02/2012 20:18:16;000d;PBS_Server.1825;Job;413.csg.bcmd.bcm.edu;Not sending email: User does not want mail of this type.
11/02/2012 20:18:16;0010;PBS_Server.1825;Job;413.csg.bcmd.bcm.edu;Exit_status=0 resources_used.cput=00:00:09 resources_used.mem=8396kb resources_used.vmem=153684kb resources_used.walltime=00:01:17
11/02/2012 20:18:16;0008;PBS_Server.1826;Job;413.csg.bcmd.bcm.edu;on_job_exit valid pjob: 413.csg.bcmd.bcm.edu (substate=50)
11/02/2012 20:18:18;0040;PBS_Server.25816;Svr;csg.bcmd.bcm.edu;Scheduler was sent the command term
11/02/2012 20:18:20;000d;PBS_Server.1837;Job;414.csg.bcmd.bcm.edu;Not sending email: User does not want mail of this type.
11/02/2012 20:18:20;0010;PBS_Server.1837;Job;414.csg.bcmd.bcm.edu;Exit_status=0 resources_used.cput=00:00:11 resources_used.mem=107440kb resources_used.vmem=291332kb resources_used.walltime=00:01:21
11/02/2012 20:18:20;0008;PBS_Server.1830;Job;414.csg.bcmd.bcm.edu;on_job_exit valid pjob: 414.csg.bcmd.bcm.edu (substate=50)
11/02/2012 20:18:23;0040;PBS_Server.25825;Svr;csg.bcmd.bcm.edu;Scheduler was sent the command term
11/02/2012 20:20:34;0002;PBS_Server.1830;Svr;PBS_Server;Torque Server Version = 4.1.2, loglevel = 0
11/02/2012 20:23:19;0008;PBS_Server.1835;Job;413.csg.bcmd.bcm.edu;on_job_exit valid pjob: 413.csg.bcmd.bcm.edu (substate=59)
11/02/2012 20:23:19;0100;PBS_Server.1835;Job;413.csg.bcmd.bcm.edu;dequeuing from batch, state COMPLETE
11/02/2012 20:23:24;0040;PBS_Server.25906;Svr;csg.bcmd.bcm.edu;Scheduler was sent the command term
11/02/2012 20:23:34;0008;PBS_Server.1828;Job;414.csg.bcmd.bcm.edu;on_job_exit valid pjob: 414.csg.bcmd.bcm.edu (substate=59)
11/02/2012 20:23:34;0100;PBS_Server.1828;Job;414.csg.bcmd.bcm.edu;dequeuing from batch, state COMPLETE
11/02/2012 20:23:39;0040;PBS_Server.25907;Svr;csg.bcmd.bcm.edu;Scheduler was sent the command term
11/02/2012 20:25:34;0002;PBS_Server.1829;Svr;PBS_Server;Torque Server Version = 4.1.2, loglevel = 0
11/02/2012 20:30:45;0002;PBS_Server.1831;Svr;PBS_Server;Torque Server Version = 4.1.2, loglevel = 0
11/02/2012 20:33:50;0040;PBS_Server.26152;Svr;csg.bcmd.bcm.edu;Scheduler was sent the command time
11/02/2012 20:35:45;0002;PBS_Server.1829;Svr;PBS_Server;Torque Server Version = 4.1.2, loglevel = 0
11/02/2012 20:36:19;0100;PBS_Server.1836;Job;415.csg.bcmd.bcm.edu;enqueuing into batch, state 1 hop 1
11/02/2012 20:36:19;0008;PBS_Server.1836;Job;415.csg.bcmd.bcm.edu;Job Queued at request of lacuesta@csg.bcmd.bcm.edu, owner = lacuesta@csg.bcmd.bcm.edu, job name = jobname1, queue = batch
11/02/2012 20:36:19;0100;PBS_Server.1837;Job;416.csg.bcmd.bcm.edu;enqueuing into batch, state 1 hop 1
11/02/2012 20:36:19;0008;PBS_Server.1837;Job;416.csg.bcmd.bcm.edu;Job Queued at request of lacuesta@csg.bcmd.bcm.edu, owner = lacuesta@csg.bcmd.bcm.edu, job name = jobname2, queue = batch
11/02/2012 20:36:20;0040;PBS_Server.26272;Svr;csg.bcmd.bcm.edu;Scheduler was sent the command new
11/02/2012 20:36:21;0008;PBS_Server.1832;Job;415.csg.bcmd.bcm.edu;Job Run at request of root@csg.bcmd.bcm.edu
11/02/2012 20:36:21;0001;PBS_Server.1822;Svr;PBS_Server;LOG_ERROR::wait_request, closed connections to fd 9 - num_connections=1 (select bad socket)
11/02/2012 20:36:21;000d;PBS_Server.1832;Job;415.csg.bcmd.bcm.edu;Not sending email: User does not want mail of this type.
11/02/2012 20:36:21;0008;PBS_Server.1832;Job;416.csg.bcmd.bcm.edu;Job Run at request of root@csg.bcmd.bcm.edu
11/02/2012 20:36:21;000d;PBS_Server.1832;Job;416.csg.bcmd.bcm.edu;Not sending email: User does not want mail of this type.
11/02/2012 20:37:19;000d;PBS_Server.1828;Job;415.csg.bcmd.bcm.edu;Not sending email: User does not want mail of this type.
11/02/2012 20:37:19;0010;PBS_Server.1828;Job;415.csg.bcmd.bcm.edu;Exit_status=0 resources_used.cput=00:00:09 resources_used.mem=8392kb resources_used.vmem=153684kb resources_used.walltime=00:00:58
11/02/2012 20:37:19;0008;PBS_Server.1827;Job;415.csg.bcmd.bcm.edu;on_job_exit valid pjob: 415.csg.bcmd.bcm.edu (substate=50)
11/02/2012 20:37:21;0040;PBS_Server.26291;Svr;csg.bcmd.bcm.edu;Scheduler was sent the command term
11/02/2012 20:37:27;000d;PBS_Server.1829;Job;416.csg.bcmd.bcm.edu;Not sending email: User does not want mail of this type.
11/02/2012 20:37:27;0010;PBS_Server.1829;Job;416.csg.bcmd.bcm.edu;Exit_status=0 resources_used.cput=00:00:11 resources_used.mem=100816kb resources_used.vmem=230944kb resources_used.walltime=00:01:06
11/02/2012 20:37:27;0008;PBS_Server.1827;Job;416.csg.bcmd.bcm.edu;on_job_exit valid pjob: 416.csg.bcmd.bcm.edu (substate=50)
11/02/2012 20:37:31;0040;PBS_Server.26300;Svr;csg.bcmd.bcm.edu;Scheduler was sent the command term
11/02/2012 20:38:08;000d;PBS_Server.1826;Job;269.csg.bcmd.bcm.edu;Not sending email: User does not want mail of this type.
11/02/2012 20:38:08;0010;PBS_Server.1826;Job;269.csg.bcmd.bcm.edu;Exit_status=1 resources_used.cput=42:47:42 resources_used.mem=156696kb resources_used.vmem=1089136kb resources_used.walltime=43:30:46
11/02/2012 20:38:08;0008;PBS_Server.1829;Job;269.csg.bcmd.bcm.edu;on_job_exit valid pjob: 269.csg.bcmd.bcm.edu (substate=50)
11/02/2012 20:38:11;0040;PBS_Server.26317;Svr;csg.bcmd.bcm.edu;Scheduler was sent the command term
11/02/2012 20:40:56;0002;PBS_Server.1833;Svr;PBS_Server;Torque Server Version = 4.1.2, loglevel = 0
11/02/2012 20:42:26;0008;PBS_Server.1828;Job;415.csg.bcmd.bcm.edu;on_job_exit valid pjob: 415.csg.bcmd.bcm.edu (substate=59)
11/02/2012 20:42:26;0100;PBS_Server.1828;Job;415.csg.bcmd.bcm.edu;dequeuing from batch, state COMPLETE
11/02/2012 20:42:31;0040;PBS_Server.26400;Svr;csg.bcmd.bcm.edu;Scheduler was sent the command term
11/02/2012 20:42:41;0008;PBS_Server.1829;Job;416.csg.bcmd.bcm.edu;on_job_exit valid pjob: 416.csg.bcmd.bcm.edu (substate=59)
11/02/2012 20:42:41;0100;PBS_Server.1829;Job;416.csg.bcmd.bcm.edu;dequeuing from batch, state COMPLETE
11/02/2012 20:42:46;0040;PBS_Server.26401;Svr;csg.bcmd.bcm.edu;Scheduler was sent the command term
11/02/2012 20:43:11;0008;PBS_Server.1830;Job;269.csg.bcmd.bcm.edu;on_job_exit valid pjob: 269.csg.bcmd.bcm.edu (substate=59)
11/02/2012 20:43:11;0100;PBS_Server.1830;Job;269.csg.bcmd.bcm.edu;dequeuing from high, state COMPLETE
11/02/2012 20:43:16;0040;PBS_Server.26410;Svr;csg.bcmd.bcm.edu;Scheduler was sent the command term
11/02/2012 20:45:57;0002;PBS_Server.1829;Svr;PBS_Server;Torque Server Version = 4.1.2, loglevel = 0
11/02/2012 20:50:57;0002;PBS_Server.1826;Svr;PBS_Server;Torque Server Version = 4.1.2, loglevel = 0
11/02/2012 20:53:32;0040;PBS_Server.26504;Svr;csg.bcmd.bcm.edu;Scheduler was sent the command time
11/02/2012 20:55:58;0002;PBS_Server.1825;Svr;PBS_Server;Torque Server Version = 4.1.2, loglevel = 0
11/02/2012 20:58:29;0100;PBS_Server.1831;Job;417.csg.bcmd.bcm.edu;enqueuing into batch, state 1 hop 1
11/02/2012 20:58:29;0008;PBS_Server.1831;Job;417.csg.bcmd.bcm.edu;Job Queued at request of lacuesta@csg.bcmd.bcm.edu, owner = lacuesta@csg.bcmd.bcm.edu, job name = jobname1, queue = batch
11/02/2012 20:58:29;0100;PBS_Server.1837;Job;418.csg.bcmd.bcm.edu;enqueuing into batch, state 1 hop 1
11/02/2012 20:58:29;0008;PBS_Server.1837;Job;418.csg.bcmd.bcm.edu;Job Queued at request of lacuesta@csg.bcmd.bcm.edu, owner = lacuesta@csg.bcmd.bcm.edu, job name = jobname2, queue = batch
11/02/2012 20:58:33;0040;PBS_Server.26564;Svr;csg.bcmd.bcm.edu;Scheduler was sent the command new
11/02/2012 20:58:34;0008;PBS_Server.1832;Job;417.csg.bcmd.bcm.edu;Job Run at request of root@csg.bcmd.bcm.edu
11/02/2012 20:58:34;000d;PBS_Server.1832;Job;417.csg.bcmd.bcm.edu;Not sending email: User does not want mail of this type.
11/02/2012 20:58:34;0008;PBS_Server.1832;Job;418.csg.bcmd.bcm.edu;Job Run at request of root@csg.bcmd.bcm.edu
11/02/2012 20:58:34;000d;PBS_Server.1832;Job;418.csg.bcmd.bcm.edu;Not sending email: User does not want mail of this type.
11/02/2012 20:59:15;000d;PBS_Server.1828;Job;418.csg.bcmd.bcm.edu;Not sending email: User does not want mail of this type.
11/02/2012 20:59:15;0010;PBS_Server.1828;Job;418.csg.bcmd.bcm.edu;Exit_status=0 resources_used.cput=00:00:13 resources_used.mem=85596kb resources_used.vmem=205640kb resources_used.walltime=00:00:41
11/02/2012 20:59:15;0008;PBS_Server.1831;Job;418.csg.bcmd.bcm.edu;on_job_exit valid pjob: 418.csg.bcmd.bcm.edu (substate=50)
11/02/2012 20:59:18;0040;PBS_Server.26581;Svr;csg.bcmd.bcm.edu;Scheduler was sent the command term
11/02/2012 20:59:21;000d;PBS_Server.1827;Job;417.csg.bcmd.bcm.edu;Not sending email: User does not want mail of this type.
11/02/2012 20:59:21;0010;PBS_Server.1827;Job;417.csg.bcmd.bcm.edu;Exit_status=0 resources_used.cput=00:00:13 resources_used.mem=96104kb resources_used.vmem=342016kb resources_used.walltime=00:00:47
11/02/2012 20:59:21;0008;PBS_Server.1835;Job;417.csg.bcmd.bcm.edu;on_job_exit valid pjob: 417.csg.bcmd.bcm.edu (substate=50)
11/02/2012 20:59:23;0040;PBS_Server.26590;Svr;csg.bcmd.bcm.edu;Scheduler was sent the command term
11/02/2012 21:00:58;0002;PBS_Server.1834;Svr;PBS_Server;Torque Server Version = 4.1.2, loglevel = 0
11/02/2012 21:03:56;0100;PBS_Server.1830;Job;419.csg.bcmd.bcm.edu;enqueuing into batch, state 1 hop 1
11/02/2012 21:03:56;0008;PBS_Server.1830;Job;419.csg.bcmd.bcm.edu;Job Queued at request of lacuesta@csg.bcmd.bcm.edu, owner = lacuesta@csg.bcmd.bcm.edu, job name = jobname1, queue = batch
11/02/2012 21:03:56;0100;PBS_Server.1835;Job;420.csg.bcmd.bcm.edu;enqueuing into batch, state 1 hop 1
11/02/2012 21:03:56;0008;PBS_Server.1835;Job;420.csg.bcmd.bcm.edu;Job Queued at request of lacuesta@csg.bcmd.bcm.edu, owner = lacuesta@csg.bcmd.bcm.edu, job name = jobname2, queue = batch
11/02/2012 21:03:59;0040;PBS_Server.26619;Svr;csg.bcmd.bcm.edu;Scheduler was sent the command new
11/02/2012 21:04:00;0008;PBS_Server.1832;Job;419.csg.bcmd.bcm.edu;Job Run at request of root@csg.bcmd.bcm.edu
11/02/2012 21:04:00;000d;PBS_Server.1832;Job;419.csg.bcmd.bcm.edu;Not sending email: User does not want mail of this type.
11/02/2012 21:04:00;0008;PBS_Server.1832;Job;420.csg.bcmd.bcm.edu;Job Run at request of root@csg.bcmd.bcm.edu
11/02/2012 21:04:00;000d;PBS_Server.1832;Job;420.csg.bcmd.bcm.edu;Not sending email: User does not want mail of this type.
11/02/2012 21:04:15;000d;PBS_Server.1829;Job;419.csg.bcmd.bcm.edu;Not sending email: User does not want mail of this type.
11/02/2012 21:04:15;0010;PBS_Server.1829;Job;419.csg.bcmd.bcm.edu;Exit_status=0 resources_used.cput=00:00:13 resources_used.mem=93240kb resources_used.vmem=341880kb resources_used.walltime=00:00:15
11/02/2012 21:04:15;0008;PBS_Server.1830;Job;419.csg.bcmd.bcm.edu;on_job_exit valid pjob: 419.csg.bcmd.bcm.edu (substate=50)
11/02/2012 21:04:15;000d;PBS_Server.1837;Job;420.csg.bcmd.bcm.edu;Not sending email: User does not want mail of this type.
11/02/2012 21:04:15;0010;PBS_Server.1837;Job;420.csg.bcmd.bcm.edu;Exit_status=0 resources_used.cput=00:00:14 resources_used.mem=136552kb resources_used.vmem=294692kb resources_used.walltime=00:00:15
11/02/2012 21:04:15;0008;PBS_Server.1831;Job;420.csg.bcmd.bcm.edu;on_job_exit valid pjob: 420.csg.bcmd.bcm.edu (substate=50)
11/02/2012 21:04:19;0040;PBS_Server.26636;Svr;csg.bcmd.bcm.edu;Scheduler was sent the command term
11/02/2012 21:04:29;0008;PBS_Server.1830;Job;418.csg.bcmd.bcm.edu;on_job_exit valid pjob: 418.csg.bcmd.bcm.edu (substate=59)
11/02/2012 21:04:29;0008;PBS_Server.1837;Job;417.csg.bcmd.bcm.edu;on_job_exit valid pjob: 417.csg.bcmd.bcm.edu (substate=59)
11/02/2012 21:04:29;0100;PBS_Server.1830;Job;418.csg.bcmd.bcm.edu;dequeuing from batch, state COMPLETE
11/02/2012 21:04:29;0100;PBS_Server.1837;Job;417.csg.bcmd.bcm.edu;dequeuing from batch, state COMPLETE
11/02/2012 21:04:34;0040;PBS_Server.26637;Svr;csg.bcmd.bcm.edu;Scheduler was sent the command term
11/02/2012 21:05:59;0002;PBS_Server.1825;Svr;PBS_Server;Torque Server Version = 4.1.2, loglevel = 0
11/02/2012 21:09:29;0008;PBS_Server.1835;Job;419.csg.bcmd.bcm.edu;on_job_exit valid pjob: 419.csg.bcmd.bcm.edu (substate=59)
11/02/2012 21:09:29;0008;PBS_Server.1826;Job;420.csg.bcmd.bcm.edu;on_job_exit valid pjob: 420.csg.bcmd.bcm.edu (substate=59)
11/02/2012 21:09:29;0100;PBS_Server.1835;Job;419.csg.bcmd.bcm.edu;dequeuing from batch, state COMPLETE
11/02/2012 21:09:29;0100;PBS_Server.1826;Job;420.csg.bcmd.bcm.edu;dequeuing from batch, state COMPLETE
11/02/2012 21:09:34;0040;PBS_Server.26649;Svr;csg.bcmd.bcm.edu;Scheduler was sent the command term
11/02/2012 21:10:59;0002;PBS_Server.1830;Svr;PBS_Server;Torque Server Version = 4.1.2, loglevel = 0
11/02/2012 21:13:00;0100;PBS_Server.1826;Job;421.csg.bcmd.bcm.edu;enqueuing into batch, state 1 hop 1
11/02/2012 21:13:00;0008;PBS_Server.1826;Job;421.csg.bcmd.bcm.edu;Job Queued at request of lacuesta@csg.bcmd.bcm.edu, owner = lacuesta@csg.bcmd.bcm.edu, job name = jobname1, queue = batch
11/02/2012 21:13:00;0100;PBS_Server.1829;Job;422.csg.bcmd.bcm.edu;enqueuing into batch, state 1 hop 1
11/02/2012 21:13:00;0008;PBS_Server.1829;Job;422.csg.bcmd.bcm.edu;Job Queued at request of lacuesta@csg.bcmd.bcm.edu, owner = lacuesta@csg.bcmd.bcm.edu, job name = jobname2, queue = batch
11/02/2012 21:13:04;0040;PBS_Server.26668;Svr;csg.bcmd.bcm.edu;Scheduler was sent the command new
11/02/2012 21:13:05;0100;PBS_Server.1828;Job;423.csg.bcmd.bcm.edu;enqueuing into batch, state 1 hop 1
11/02/2012 21:13:05;0008;PBS_Server.1828;Job;423.csg.bcmd.bcm.edu;Job Queued at request of lacuesta@csg.bcmd.bcm.edu, owner = lacuesta@csg.bcmd.bcm.edu, job name = jobname1, queue = batch
11/02/2012 21:13:05;0100;PBS_Server.1827;Job;424.csg.bcmd.bcm.edu;enqueuing into batch, state 1 hop 1
11/02/2012 21:13:05;0008;PBS_Server.1827;Job;424.csg.bcmd.bcm.edu;Job Queued at request of lacuesta@csg.bcmd.bcm.edu, owner = lacuesta@csg.bcmd.bcm.edu, job name = jobname2, queue = batch
11/02/2012 21:13:06;0008;PBS_Server.1832;Job;421.csg.bcmd.bcm.edu;Job Run at request of root@csg.bcmd.bcm.edu
11/02/2012 21:13:06;000d;PBS_Server.1832;Job;421.csg.bcmd.bcm.edu;Not sending email: User does not want mail of this type.
11/02/2012 21:13:06;0008;PBS_Server.1832;Job;422.csg.bcmd.bcm.edu;Job Run at request of root@csg.bcmd.bcm.edu
11/02/2012 21:13:06;000d;PBS_Server.1832;Job;422.csg.bcmd.bcm.edu;Not sending email: User does not want mail of this type.
11/02/2012 21:13:06;0008;PBS_Server.1832;Job;423.csg.bcmd.bcm.edu;Job Run at request of root@csg.bcmd.bcm.edu
11/02/2012 21:13:06;000d;PBS_Server.1832;Job;423.csg.bcmd.bcm.edu;Not sending email: User does not want mail of this type.
11/02/2012 21:13:06;0008;PBS_Server.1832;Job;424.csg.bcmd.bcm.edu;Job Run at request of root@csg.bcmd.bcm.edu
11/02/2012 21:13:06;000d;PBS_Server.1832;Job;424.csg.bcmd.bcm.edu;Not sending email: User does not want mail of this type.
11/02/2012 21:13:09;0040;PBS_Server.26678;Svr;csg.bcmd.bcm.edu;Scheduler was sent the command new
11/02/2012 21:13:18;0100;PBS_Server.1826;Job;425.csg.bcmd.bcm.edu;enqueuing into batch, state 1 hop 1
11/02/2012 21:13:18;0008;PBS_Server.1826;Job;425.csg.bcmd.bcm.edu;Job Queued at request of lacuesta@csg.bcmd.bcm.edu, owner = lacuesta@csg.bcmd.bcm.edu, job name = jobname1, queue = batch
11/02/2012 21:13:18;0100;PBS_Server.1829;Job;426.csg.bcmd.bcm.edu;enqueuing into batch, state 1 hop 1
11/02/2012 21:13:18;0008;PBS_Server.1829;Job;426.csg.bcmd.bcm.edu;Job Queued at request of lacuesta@csg.bcmd.bcm.edu, owner = lacuesta@csg.bcmd.bcm.edu, job name = jobname2, queue = batch
11/02/2012 21:13:20;0040;PBS_Server.26690;Svr;csg.bcmd.bcm.edu;Scheduler was sent the command new
11/02/2012 21:13:21;0008;PBS_Server.1832;Job;425.csg.bcmd.bcm.edu;Job Run at request of root@csg.bcmd.bcm.edu
11/02/2012 21:13:21;000d;PBS_Server.1832;Job;425.csg.bcmd.bcm.edu;Not sending email: User does not want mail of this type.
11/02/2012 21:13:21;0008;PBS_Server.1832;Job;426.csg.bcmd.bcm.edu;Job Run at request of root@csg.bcmd.bcm.edu
11/02/2012 21:13:21;000d;PBS_Server.1832;Job;426.csg.bcmd.bcm.edu;Not sending email: User does not want mail of this type.
11/02/2012 21:14:29;000d;PBS_Server.1831;Job;421.csg.bcmd.bcm.edu;Not sending email: User does not want mail of this type.
11/02/2012 21:14:29;0010;PBS_Server.1831;Job;421.csg.bcmd.bcm.edu;Exit_status=0 resources_used.cput=00:00:13 resources_used.mem=105364kb resources_used.vmem=236572kb resources_used.walltime=00:01:23
11/02/2012 21:14:29;0008;PBS_Server.1828;Job;421.csg.bcmd.bcm.edu;on_job_exit valid pjob: 421.csg.bcmd.bcm.edu (substate=50)
11/02/2012 21:14:30;0040;PBS_Server.26699;Svr;csg.bcmd.bcm.edu;Scheduler was sent the command term
11/02/2012 21:14:34;000d;PBS_Server.1826;Job;423.csg.bcmd.bcm.edu;Not sending email: User does not want mail of this type.
11/02/2012 21:14:34;0010;PBS_Server.1826;Job;423.csg.bcmd.bcm.edu;Exit_status=0 resources_used.cput=00:00:13 resources_used.mem=93236kb resources_used.vmem=342016kb resources_used.walltime=00:01:28
11/02/2012 21:14:34;0008;PBS_Server.1829;Job;423.csg.bcmd.bcm.edu;on_job_exit valid pjob: 423.csg.bcmd.bcm.edu (substate=50)
11/02/2012 21:14:35;000d;PBS_Server.1827;Job;425.csg.bcmd.bcm.edu;Not sending email: User does not want mail of this type.
11/02/2012 21:14:35;0010;PBS_Server.1827;Job;425.csg.bcmd.bcm.edu;Exit_status=0 resources_used.cput=00:00:13 resources_used.mem=188584kb resources_used.vmem=347648kb resources_used.walltime=00:01:14
11/02/2012 21:14:35;0008;PBS_Server.1831;Job;425.csg.bcmd.bcm.edu;on_job_exit valid pjob: 425.csg.bcmd.bcm.edu (substate=50)
11/02/2012 21:14:35;0040;PBS_Server.26712;Svr;csg.bcmd.bcm.edu;Scheduler was sent the command term
11/02/2012 21:14:35;0040;PBS_Server.26717;Svr;csg.bcmd.bcm.edu;Scheduler was sent the command term
11/02/2012 21:16:00;0002;PBS_Server.1828;Svr;PBS_Server;Torque Server Version = 4.1.2, loglevel = 0
11/02/2012 21:17:11;000d;PBS_Server.1826;Job;422.csg.bcmd.bcm.edu;Not sending email: User does not want mail of this type.
11/02/2012 21:17:11;0010;PBS_Server.1826;Job;422.csg.bcmd.bcm.edu;Exit_status=0 resources_used.cput=00:00:15 resources_used.mem=108088kb resources_used.vmem=237968kb resources_used.walltime=00:04:05
11/02/2012 21:17:11;0008;PBS_Server.1837;Job;422.csg.bcmd.bcm.edu;on_job_exit valid pjob: 422.csg.bcmd.bcm.edu (substate=50)
11/02/2012 21:17:11;000d;PBS_Server.1833;Job;424.csg.bcmd.bcm.edu;Not sending email: User does not want mail of this type.
11/02/2012 21:17:11;0010;PBS_Server.1833;Job;424.csg.bcmd.bcm.edu;Exit_status=0 resources_used.cput=00:00:14 resources_used.mem=107440kb resources_used.vmem=237332kb resources_used.walltime=00:04:05
11/02/2012 21:17:11;0008;PBS_Server.1825;Job;424.csg.bcmd.bcm.edu;on_job_exit valid pjob: 424.csg.bcmd.bcm.edu (substate=50)
11/02/2012 21:17:15;0040;PBS_Server.26751;Svr;csg.bcmd.bcm.edu;Scheduler was sent the command term
11/02/2012 21:17:15;000d;PBS_Server.1830;Job;426.csg.bcmd.bcm.edu;Not sending email: User does not want mail of this type.
11/02/2012 21:17:15;0010;PBS_Server.1830;Job;426.csg.bcmd.bcm.edu;Exit_status=0 resources_used.cput=00:00:13 resources_used.mem=117252kb resources_used.vmem=342040kb resources_used.walltime=00:03:54
11/02/2012 21:17:15;0008;PBS_Server.1836;Job;426.csg.bcmd.bcm.edu;on_job_exit valid pjob: 426.csg.bcmd.bcm.edu (substate=50)
11/02/2012 21:17:20;0040;PBS_Server.26760;Svr;csg.bcmd.bcm.edu;Scheduler was sent the command term
11/02/2012 21:19:30;0008;PBS_Server.1825;Job;421.csg.bcmd.bcm.edu;on_job_exit valid pjob: 421.csg.bcmd.bcm.edu (substate=59)
11/02/2012 21:19:30;0100;PBS_Server.1825;Job;421.csg.bcmd.bcm.edu;dequeuing from batch, state COMPLETE
11/02/2012 21:19:35;0040;PBS_Server.26762;Svr;csg.bcmd.bcm.edu;Scheduler was sent the command term
11/02/2012 21:19:45;0008;PBS_Server.1834;Job;423.csg.bcmd.bcm.edu;on_job_exit valid pjob: 423.csg.bcmd.bcm.edu (substate=59)
11/02/2012 21:19:45;0008;PBS_Server.1828;Job;425.csg.bcmd.bcm.edu;on_job_exit valid pjob: 425.csg.bcmd.bcm.edu (substate=59)
11/02/2012 21:19:45;0100;PBS_Server.1834;Job;423.csg.bcmd.bcm.edu;dequeuing from batch, state COMPLETE
11/02/2012 21:19:45;0100;PBS_Server.1828;Job;425.csg.bcmd.bcm.edu;dequeuing from batch, state COMPLETE
11/02/2012 21:19:50;0040;PBS_Server.26763;Svr;csg.bcmd.bcm.edu;Scheduler was sent the command term
11/02/2012 21:21:00;0002;PBS_Server.1828;Svr;PBS_Server;Torque Server Version = 4.1.2, loglevel = 0
11/02/2012 21:22:11;0008;PBS_Server.1833;Job;424.csg.bcmd.bcm.edu;on_job_exit valid pjob: 424.csg.bcmd.bcm.edu (substate=59)
11/02/2012 21:22:11;0008;PBS_Server.1837;Job;422.csg.bcmd.bcm.edu;on_job_exit valid pjob: 422.csg.bcmd.bcm.edu (substate=59)
11/02/2012 21:22:11;0100;PBS_Server.1833;Job;424.csg.bcmd.bcm.edu;dequeuing from batch, state COMPLETE
11/02/2012 21:22:11;0100;PBS_Server.1837;Job;422.csg.bcmd.bcm.edu;dequeuing from batch, state COMPLETE
11/02/2012 21:22:16;0040;PBS_Server.26770;Svr;csg.bcmd.bcm.edu;Scheduler was sent the command term
11/02/2012 21:22:26;0008;PBS_Server.1827;Job;426.csg.bcmd.bcm.edu;on_job_exit valid pjob: 426.csg.bcmd.bcm.edu (substate=59)
11/02/2012 21:22:26;0100;PBS_Server.1827;Job;426.csg.bcmd.bcm.edu;dequeuing from batch, state COMPLETE
11/02/2012 21:22:31;0040;PBS_Server.26771;Svr;csg.bcmd.bcm.edu;Scheduler was sent the command term
11/02/2012 21:26:09;0002;PBS_Server.1837;Svr;PBS_Server;Torque Server Version = 4.1.2, loglevel = 0
11/02/2012 21:29:19;000d;PBS_Server.1831;Job;383.csg.bcmd.bcm.edu;Not sending email: User does not want mail of this type.
11/02/2012 21:29:19;0010;PBS_Server.1831;Job;383.csg.bcmd.bcm.edu;Exit_status=1 resources_used.cput=79:38:17 resources_used.mem=1131340kb resources_used.vmem=5562632kb resources_used.walltime=07:47:25
11/02/2012 21:29:19;0008;PBS_Server.1837;Job;383.csg.bcmd.bcm.edu;on_job_exit valid pjob: 383.csg.bcmd.bcm.edu (substate=50)
11/02/2012 21:29:20;0040;PBS_Server.26829;Svr;csg.bcmd.bcm.edu;Scheduler was sent the command term
11/02/2012 21:31:14;0002;PBS_Server.1837;Svr;PBS_Server;Torque Server Version = 4.1.2, loglevel = 0
11/02/2012 21:34:20;0008;PBS_Server.1835;Job;383.csg.bcmd.bcm.edu;on_job_exit valid pjob: 383.csg.bcmd.bcm.edu (substate=59)
11/02/2012 21:34:20;0100;PBS_Server.1835;Job;383.csg.bcmd.bcm.edu;dequeuing from high, state COMPLETE
11/02/2012 21:34:25;0040;PBS_Server.26838;Svr;csg.bcmd.bcm.edu;Scheduler was sent the command term
11/02/2012 21:36:19;0002;PBS_Server.1826;Svr;PBS_Server;Torque Server Version = 4.1.2, loglevel = 0
11/02/2012 21:41:24;0002;PBS_Server.1836;Svr;PBS_Server;Torque Server Version = 4.1.2, loglevel = 0
11/02/2012 21:44:35;0040;PBS_Server.26851;Svr;csg.bcmd.bcm.edu;Scheduler was sent the command time
11/02/2012 21:46:29;0002;PBS_Server.1827;Svr;PBS_Server;Torque Server Version = 4.1.2, loglevel = 0
11/02/2012 21:51:34;0002;PBS_Server.1827;Svr;PBS_Server;Torque Server Version = 4.1.2, loglevel = 0
11/02/2012 21:54:45;0040;PBS_Server.26872;Svr;csg.bcmd.bcm.edu;Scheduler was sent the command time
11/02/2012 21:56:39;0002;PBS_Server.1826;Svr;PBS_Server;Torque Server Version = 4.1.2, loglevel = 0
11/02/2012 22:01:44;0002;PBS_Server.1827;Svr;PBS_Server;Torque Server Version = 4.1.2, loglevel = 0
11/02/2012 22:04:55;0040;PBS_Server.26954;Svr;csg.bcmd.bcm.edu;Scheduler was sent the command time
11/02/2012 22:06:49;0002;PBS_Server.1837;Svr;PBS_Server;Torque Server Version = 4.1.2, loglevel = 0
11/02/2012 22:11:54;0002;PBS_Server.1828;Svr;PBS_Server;Torque Server Version = 4.1.2, loglevel = 0
11/02/2012 22:15:05;0040;PBS_Server.27150;Svr;csg.bcmd.bcm.edu;Scheduler was sent the command time
11/02/2012 22:16:59;0002;PBS_Server.1827;Svr;PBS_Server;Torque Server Version = 4.1.2, loglevel = 0
11/02/2012 22:22:04;0002;PBS_Server.1836;Svr;PBS_Server;Torque Server Version = 4.1.2, loglevel = 0
11/02/2012 22:25:15;0040;PBS_Server.27353;Svr;csg.bcmd.bcm.edu;Scheduler was sent the command time
11/02/2012 22:27:09;0002;PBS_Server.1837;Svr;PBS_Server;Torque Server Version = 4.1.2, loglevel = 0
11/02/2012 22:32:14;0002;PBS_Server.1828;Svr;PBS_Server;Torque Server Version = 4.1.2, loglevel = 0
11/02/2012 22:35:25;0040;PBS_Server.27447;Svr;csg.bcmd.bcm.edu;Scheduler was sent the command time
11/02/2012 22:37:19;0002;PBS_Server.1826;Svr;PBS_Server;Torque Server Version = 4.1.2, loglevel = 0
11/02/2012 22:38:25;000d;PBS_Server.1828;Job;344.csg.bcmd.bcm.edu;Not sending email: User does not want mail of this type.
11/02/2012 22:38:25;0010;PBS_Server.1828;Job;344.csg.bcmd.bcm.edu;Exit_status=1 resources_used.cput=83:03:54 resources_used.mem=983348kb resources_used.vmem=5414432kb resources_used.walltime=11:37:28
11/02/2012 22:38:25;0008;PBS_Server.1830;Job;344.csg.bcmd.bcm.edu;on_job_exit valid pjob: 344.csg.bcmd.bcm.edu (substate=50)
11/02/2012 22:38:26;0040;PBS_Server.27481;Svr;csg.bcmd.bcm.edu;Scheduler was sent the command term
11/02/2012 22:42:24;0002;PBS_Server.1832;Svr;PBS_Server;Torque Server Version = 4.1.2, loglevel = 0
11/02/2012 22:43:31;0008;PBS_Server.1829;Job;344.csg.bcmd.bcm.edu;on_job_exit valid pjob: 344.csg.bcmd.bcm.edu (substate=59)
11/02/2012 22:43:31;0100;PBS_Server.1829;Job;344.csg.bcmd.bcm.edu;dequeuing from high, state COMPLETE
11/02/2012 22:43:36;0040;PBS_Server.27530;Svr;csg.bcmd.bcm.edu;Scheduler was sent the command term
11/02/2012 22:47:33;0002;PBS_Server.1834;Svr;PBS_Server;Torque Server Version = 4.1.2, loglevel = 0
11/02/2012 22:52:38;0002;PBS_Server.1837;Svr;PBS_Server;Torque Server Version = 4.1.2, loglevel = 0
11/02/2012 22:53:50;0040;PBS_Server.27624;Svr;csg.bcmd.bcm.edu;Scheduler was sent the command time
11/02/2012 22:57:43;0002;PBS_Server.1825;Svr;PBS_Server;Torque Server Version = 4.1.2, loglevel = 0
11/02/2012 23:02:48;0002;PBS_Server.1836;Svr;PBS_Server;Torque Server Version = 4.1.2, loglevel = 0
11/02/2012 23:04:00;0040;PBS_Server.27692;Svr;csg.bcmd.bcm.edu;Scheduler was sent the command time
11/02/2012 23:07:53;0002;PBS_Server.1837;Svr;PBS_Server;Torque Server Version = 4.1.2, loglevel = 0
11/02/2012 23:12:58;0002;PBS_Server.1833;Svr;PBS_Server;Torque Server Version = 4.1.2, loglevel = 0
11/02/2012 23:14:10;0040;PBS_Server.27710;Svr;csg.bcmd.bcm.edu;Scheduler was sent the command time
11/02/2012 23:18:03;0002;PBS_Server.1831;Svr;PBS_Server;Torque Server Version = 4.1.2, loglevel = 0
11/02/2012 23:23:08;0002;PBS_Server.1828;Svr;PBS_Server;Torque Server Version = 4.1.2, loglevel = 0
11/02/2012 23:24:20;0040;PBS_Server.27725;Svr;csg.bcmd.bcm.edu;Scheduler was sent the command time
11/02/2012 23:28:13;0002;PBS_Server.1826;Svr;PBS_Server;Torque Server Version = 4.1.2, loglevel = 0
11/02/2012 23:33:18;0002;PBS_Server.1837;Svr;PBS_Server;Torque Server Version = 4.1.2, loglevel = 0
11/02/2012 23:34:30;0040;PBS_Server.27739;Svr;csg.bcmd.bcm.edu;Scheduler was sent the command time
11/02/2012 23:38:23;0002;PBS_Server.1826;Svr;PBS_Server;Torque Server Version = 4.1.2, loglevel = 0
11/02/2012 23:43:28;0002;PBS_Server.1831;Svr;PBS_Server;Torque Server Version = 4.1.2, loglevel = 0
11/02/2012 23:44:40;0040;PBS_Server.27760;Svr;csg.bcmd.bcm.edu;Scheduler was sent the command time
11/02/2012 23:48:33;0002;PBS_Server.1837;Svr;PBS_Server;Torque Server Version = 4.1.2, loglevel = 0
11/02/2012 23:53:38;0002;PBS_Server.1836;Svr;PBS_Server;Torque Server Version = 4.1.2, loglevel = 0
11/02/2012 23:54:50;0040;PBS_Server.27786;Svr;csg.bcmd.bcm.edu;Scheduler was sent the command time
11/02/2012 23:58:43;0002;PBS_Server.1833;Svr;PBS_Server;Torque Server Version = 4.1.2, loglevel = 0
11/03/2012 00:03:48;0002;PBS_Server.1828;Svr;Log;Log closed
