11/16/2012 00:02:24;0002;PBS_Server.1827;Svr;Log;Log opened
11/16/2012 00:02:24;0002;PBS_Server.1827;Svr;PBS_Server;Torque Server Version = 4.1.2, loglevel = 0
11/16/2012 00:05:09;0040;PBS_Server.5266;Svr;csg.bcmd.bcm.edu;Scheduler was sent the command time
11/16/2012 00:07:29;0002;PBS_Server.1837;Svr;PBS_Server;Torque Server Version = 4.1.2, loglevel = 0
11/16/2012 00:12:34;0002;PBS_Server.1825;Svr;PBS_Server;Torque Server Version = 4.1.2, loglevel = 0
11/16/2012 00:15:19;0040;PBS_Server.5361;Svr;csg.bcmd.bcm.edu;Scheduler was sent the command time
11/16/2012 00:17:39;0002;PBS_Server.1834;Svr;PBS_Server;Torque Server Version = 4.1.2, loglevel = 0
11/16/2012 00:22:44;0002;PBS_Server.1825;Svr;PBS_Server;Torque Server Version = 4.1.2, loglevel = 0
11/16/2012 00:25:29;0040;PBS_Server.5456;Svr;csg.bcmd.bcm.edu;Scheduler was sent the command time
11/16/2012 00:27:49;0002;PBS_Server.1834;Svr;PBS_Server;Torque Server Version = 4.1.2, loglevel = 0
11/16/2012 00:32:54;0002;PBS_Server.1833;Svr;PBS_Server;Torque Server Version = 4.1.2, loglevel = 0
11/16/2012 00:35:39;0040;PBS_Server.5549;Svr;csg.bcmd.bcm.edu;Scheduler was sent the command time
11/16/2012 00:37:59;0002;PBS_Server.1833;Svr;PBS_Server;Torque Server Version = 4.1.2, loglevel = 0
11/16/2012 00:43:04;0002;PBS_Server.1830;Svr;PBS_Server;Torque Server Version = 4.1.2, loglevel = 0
11/16/2012 00:45:49;0040;PBS_Server.5645;Svr;csg.bcmd.bcm.edu;Scheduler was sent the command time
11/16/2012 00:48:09;0002;PBS_Server.1828;Svr;PBS_Server;Torque Server Version = 4.1.2, loglevel = 0
11/16/2012 00:53:14;0002;PBS_Server.1833;Svr;PBS_Server;Torque Server Version = 4.1.2, loglevel = 0
11/16/2012 00:55:59;0040;PBS_Server.5738;Svr;csg.bcmd.bcm.edu;Scheduler was sent the command time
11/16/2012 00:58:19;0002;PBS_Server.1827;Svr;PBS_Server;Torque Server Version = 4.1.2, loglevel = 0
11/16/2012 01:03:24;0002;PBS_Server.1836;Svr;PBS_Server;Torque Server Version = 4.1.2, loglevel = 0
11/16/2012 01:06:09;0040;PBS_Server.5793;Svr;csg.bcmd.bcm.edu;Scheduler was sent the command time
11/16/2012 01:08:29;0002;PBS_Server.1835;Svr;PBS_Server;Torque Server Version = 4.1.2, loglevel = 0
11/16/2012 01:13:34;0002;PBS_Server.1826;Svr;PBS_Server;Torque Server Version = 4.1.2, loglevel = 0
11/16/2012 01:16:19;0040;PBS_Server.5807;Svr;csg.bcmd.bcm.edu;Scheduler was sent the command time
11/16/2012 01:18:39;0002;PBS_Server.1826;Svr;PBS_Server;Torque Server Version = 4.1.2, loglevel = 0
11/16/2012 01:23:44;0002;PBS_Server.1825;Svr;PBS_Server;Torque Server Version = 4.1.2, loglevel = 0
11/16/2012 01:26:29;0040;PBS_Server.5823;Svr;csg.bcmd.bcm.edu;Scheduler was sent the command time
11/16/2012 01:28:49;0002;PBS_Server.1829;Svr;PBS_Server;Torque Server Version = 4.1.2, loglevel = 0
11/16/2012 01:33:54;0002;PBS_Server.1825;Svr;PBS_Server;Torque Server Version = 4.1.2, loglevel = 0
11/16/2012 01:36:39;0040;PBS_Server.5836;Svr;csg.bcmd.bcm.edu;Scheduler was sent the command time
11/16/2012 01:38:59;0002;PBS_Server.1831;Svr;PBS_Server;Torque Server Version = 4.1.2, loglevel = 0
11/16/2012 01:44:04;0002;PBS_Server.1832;Svr;PBS_Server;Torque Server Version = 4.1.2, loglevel = 0
11/16/2012 01:46:49;0040;PBS_Server.5851;Svr;csg.bcmd.bcm.edu;Scheduler was sent the command time
11/16/2012 01:49:09;0002;PBS_Server.1827;Svr;PBS_Server;Torque Server Version = 4.1.2, loglevel = 0
11/16/2012 01:54:14;0002;PBS_Server.1831;Svr;PBS_Server;Torque Server Version = 4.1.2, loglevel = 0
11/16/2012 01:56:59;0040;PBS_Server.5865;Svr;csg.bcmd.bcm.edu;Scheduler was sent the command time
11/16/2012 01:59:19;0002;PBS_Server.1835;Svr;PBS_Server;Torque Server Version = 4.1.2, loglevel = 0
11/16/2012 02:04:24;0002;PBS_Server.1834;Svr;PBS_Server;Torque Server Version = 4.1.2, loglevel = 0
11/16/2012 02:07:09;0040;PBS_Server.5953;Svr;csg.bcmd.bcm.edu;Scheduler was sent the command time
11/16/2012 02:09:29;0002;PBS_Server.1834;Svr;PBS_Server;Torque Server Version = 4.1.2, loglevel = 0
11/16/2012 02:14:34;0002;PBS_Server.1831;Svr;PBS_Server;Torque Server Version = 4.1.2, loglevel = 0
11/16/2012 02:17:19;0040;PBS_Server.6051;Svr;csg.bcmd.bcm.edu;Scheduler was sent the command time
11/16/2012 02:19:39;0002;PBS_Server.1836;Svr;PBS_Server;Torque Server Version = 4.1.2, loglevel = 0
11/16/2012 02:24:44;0002;PBS_Server.1835;Svr;PBS_Server;Torque Server Version = 4.1.2, loglevel = 0
11/16/2012 02:27:29;0040;PBS_Server.6147;Svr;csg.bcmd.bcm.edu;Scheduler was sent the command time
11/16/2012 02:29:49;0002;PBS_Server.1828;Svr;PBS_Server;Torque Server Version = 4.1.2, loglevel = 0
11/16/2012 02:34:54;0002;PBS_Server.1825;Svr;PBS_Server;Torque Server Version = 4.1.2, loglevel = 0
11/16/2012 02:37:39;0040;PBS_Server.6241;Svr;csg.bcmd.bcm.edu;Scheduler was sent the command time
11/16/2012 02:39:59;0002;PBS_Server.1834;Svr;PBS_Server;Torque Server Version = 4.1.2, loglevel = 0
11/16/2012 02:45:04;0002;PBS_Server.1831;Svr;PBS_Server;Torque Server Version = 4.1.2, loglevel = 0
11/16/2012 02:47:49;0040;PBS_Server.6336;Svr;csg.bcmd.bcm.edu;Scheduler was sent the command time
11/16/2012 02:50:09;0002;PBS_Server.1831;Svr;PBS_Server;Torque Server Version = 4.1.2, loglevel = 0
11/16/2012 02:55:14;0002;PBS_Server.1835;Svr;PBS_Server;Torque Server Version = 4.1.2, loglevel = 0
11/16/2012 02:57:59;0040;PBS_Server.6430;Svr;csg.bcmd.bcm.edu;Scheduler was sent the command time
11/16/2012 03:00:19;0002;PBS_Server.1833;Svr;PBS_Server;Torque Server Version = 4.1.2, loglevel = 0
11/16/2012 03:05:24;0002;PBS_Server.1830;Svr;PBS_Server;Torque Server Version = 4.1.2, loglevel = 0
11/16/2012 03:08:09;0040;PBS_Server.6469;Svr;csg.bcmd.bcm.edu;Scheduler was sent the command time
11/16/2012 03:10:29;0002;PBS_Server.1837;Svr;PBS_Server;Torque Server Version = 4.1.2, loglevel = 0
11/16/2012 03:15:34;0002;PBS_Server.1826;Svr;PBS_Server;Torque Server Version = 4.1.2, loglevel = 0
11/16/2012 03:18:19;0040;PBS_Server.6482;Svr;csg.bcmd.bcm.edu;Scheduler was sent the command time
11/16/2012 03:20:39;0002;PBS_Server.1825;Svr;PBS_Server;Torque Server Version = 4.1.2, loglevel = 0
11/16/2012 03:25:44;0002;PBS_Server.1833;Svr;PBS_Server;Torque Server Version = 4.1.2, loglevel = 0
11/16/2012 03:28:29;0040;PBS_Server.6509;Svr;csg.bcmd.bcm.edu;Scheduler was sent the command time
11/16/2012 03:30:49;0002;PBS_Server.1826;Svr;PBS_Server;Torque Server Version = 4.1.2, loglevel = 0
11/16/2012 03:35:54;0002;PBS_Server.1836;Svr;PBS_Server;Torque Server Version = 4.1.2, loglevel = 0
11/16/2012 03:38:39;0040;PBS_Server.6523;Svr;csg.bcmd.bcm.edu;Scheduler was sent the command time
11/16/2012 03:40:59;0002;PBS_Server.1832;Svr;PBS_Server;Torque Server Version = 4.1.2, loglevel = 0
11/16/2012 03:46:04;0002;PBS_Server.1829;Svr;PBS_Server;Torque Server Version = 4.1.2, loglevel = 0
11/16/2012 03:48:49;0040;PBS_Server.6539;Svr;csg.bcmd.bcm.edu;Scheduler was sent the command time
11/16/2012 03:51:09;0002;PBS_Server.1830;Svr;PBS_Server;Torque Server Version = 4.1.2, loglevel = 0
11/16/2012 03:56:14;0002;PBS_Server.1831;Svr;PBS_Server;Torque Server Version = 4.1.2, loglevel = 0
11/16/2012 03:58:59;0040;PBS_Server.6554;Svr;csg.bcmd.bcm.edu;Scheduler was sent the command time
11/16/2012 04:01:19;0002;PBS_Server.1836;Svr;PBS_Server;Torque Server Version = 4.1.2, loglevel = 0
11/16/2012 04:06:24;0002;PBS_Server.1832;Svr;PBS_Server;Torque Server Version = 4.1.2, loglevel = 0
11/16/2012 04:09:09;0040;PBS_Server.6653;Svr;csg.bcmd.bcm.edu;Scheduler was sent the command time
11/16/2012 04:11:29;0002;PBS_Server.1828;Svr;PBS_Server;Torque Server Version = 4.1.2, loglevel = 0
11/16/2012 04:16:34;0002;PBS_Server.1831;Svr;PBS_Server;Torque Server Version = 4.1.2, loglevel = 0
11/16/2012 04:19:19;0040;PBS_Server.6747;Svr;csg.bcmd.bcm.edu;Scheduler was sent the command time
11/16/2012 04:21:39;0002;PBS_Server.1825;Svr;PBS_Server;Torque Server Version = 4.1.2, loglevel = 0
11/16/2012 04:26:44;0002;PBS_Server.1826;Svr;PBS_Server;Torque Server Version = 4.1.2, loglevel = 0
11/16/2012 04:29:29;0040;PBS_Server.6842;Svr;csg.bcmd.bcm.edu;Scheduler was sent the command time
11/16/2012 04:31:49;0002;PBS_Server.1832;Svr;PBS_Server;Torque Server Version = 4.1.2, loglevel = 0
11/16/2012 04:36:54;0002;PBS_Server.1833;Svr;PBS_Server;Torque Server Version = 4.1.2, loglevel = 0
11/16/2012 04:39:39;0040;PBS_Server.6935;Svr;csg.bcmd.bcm.edu;Scheduler was sent the command time
11/16/2012 04:41:59;0002;PBS_Server.1827;Svr;PBS_Server;Torque Server Version = 4.1.2, loglevel = 0
11/16/2012 04:47:04;0002;PBS_Server.1826;Svr;PBS_Server;Torque Server Version = 4.1.2, loglevel = 0
11/16/2012 04:49:49;0040;PBS_Server.7031;Svr;csg.bcmd.bcm.edu;Scheduler was sent the command time
11/16/2012 04:52:09;0002;PBS_Server.1825;Svr;PBS_Server;Torque Server Version = 4.1.2, loglevel = 0
11/16/2012 04:57:14;0002;PBS_Server.1836;Svr;PBS_Server;Torque Server Version = 4.1.2, loglevel = 0
11/16/2012 04:59:59;0040;PBS_Server.7124;Svr;csg.bcmd.bcm.edu;Scheduler was sent the command time
11/16/2012 05:02:19;0002;PBS_Server.1830;Svr;PBS_Server;Torque Server Version = 4.1.2, loglevel = 0
11/16/2012 05:07:24;0002;PBS_Server.1826;Svr;PBS_Server;Torque Server Version = 4.1.2, loglevel = 0
11/16/2012 05:10:09;0040;PBS_Server.7150;Svr;csg.bcmd.bcm.edu;Scheduler was sent the command time
11/16/2012 05:12:29;0002;PBS_Server.1826;Svr;PBS_Server;Torque Server Version = 4.1.2, loglevel = 0
11/16/2012 05:17:34;0002;PBS_Server.1836;Svr;PBS_Server;Torque Server Version = 4.1.2, loglevel = 0
11/16/2012 05:20:19;0040;PBS_Server.7164;Svr;csg.bcmd.bcm.edu;Scheduler was sent the command time
11/16/2012 05:22:39;0002;PBS_Server.1830;Svr;PBS_Server;Torque Server Version = 4.1.2, loglevel = 0
11/16/2012 05:27:44;0002;PBS_Server.1825;Svr;PBS_Server;Torque Server Version = 4.1.2, loglevel = 0
11/16/2012 05:30:29;0040;PBS_Server.7179;Svr;csg.bcmd.bcm.edu;Scheduler was sent the command time
11/16/2012 05:32:49;0002;PBS_Server.1835;Svr;PBS_Server;Torque Server Version = 4.1.2, loglevel = 0
11/16/2012 05:37:54;0002;PBS_Server.1827;Svr;PBS_Server;Torque Server Version = 4.1.2, loglevel = 0
11/16/2012 05:40:39;0040;PBS_Server.7194;Svr;csg.bcmd.bcm.edu;Scheduler was sent the command time
11/16/2012 05:42:59;0002;PBS_Server.1825;Svr;PBS_Server;Torque Server Version = 4.1.2, loglevel = 0
11/16/2012 05:48:04;0002;PBS_Server.1831;Svr;PBS_Server;Torque Server Version = 4.1.2, loglevel = 0
11/16/2012 05:50:49;0040;PBS_Server.7209;Svr;csg.bcmd.bcm.edu;Scheduler was sent the command time
11/16/2012 05:53:09;0002;PBS_Server.1829;Svr;PBS_Server;Torque Server Version = 4.1.2, loglevel = 0
11/16/2012 05:58:14;0002;PBS_Server.1837;Svr;PBS_Server;Torque Server Version = 4.1.2, loglevel = 0
11/16/2012 06:00:59;0040;PBS_Server.7230;Svr;csg.bcmd.bcm.edu;Scheduler was sent the command time
11/16/2012 06:03:19;0002;PBS_Server.1825;Svr;PBS_Server;Torque Server Version = 4.1.2, loglevel = 0
11/16/2012 06:08:24;0002;PBS_Server.1830;Svr;PBS_Server;Torque Server Version = 4.1.2, loglevel = 0
11/16/2012 06:11:09;0040;PBS_Server.7337;Svr;csg.bcmd.bcm.edu;Scheduler was sent the command time
11/16/2012 06:13:29;0002;PBS_Server.1831;Svr;PBS_Server;Torque Server Version = 4.1.2, loglevel = 0
11/16/2012 06:18:34;0002;PBS_Server.1833;Svr;PBS_Server;Torque Server Version = 4.1.2, loglevel = 0
11/16/2012 06:21:19;0040;PBS_Server.7432;Svr;csg.bcmd.bcm.edu;Scheduler was sent the command time
11/16/2012 06:23:39;0002;PBS_Server.1830;Svr;PBS_Server;Torque Server Version = 4.1.2, loglevel = 0
11/16/2012 06:28:44;0002;PBS_Server.1825;Svr;PBS_Server;Torque Server Version = 4.1.2, loglevel = 0
11/16/2012 06:31:29;0040;PBS_Server.7528;Svr;csg.bcmd.bcm.edu;Scheduler was sent the command time
11/16/2012 06:33:49;0002;PBS_Server.1829;Svr;PBS_Server;Torque Server Version = 4.1.2, loglevel = 0
11/16/2012 06:38:54;0002;PBS_Server.1827;Svr;PBS_Server;Torque Server Version = 4.1.2, loglevel = 0
11/16/2012 06:41:39;0040;PBS_Server.7621;Svr;csg.bcmd.bcm.edu;Scheduler was sent the command time
11/16/2012 06:43:59;0002;PBS_Server.1837;Svr;PBS_Server;Torque Server Version = 4.1.2, loglevel = 0
11/16/2012 06:49:04;0002;PBS_Server.1825;Svr;PBS_Server;Torque Server Version = 4.1.2, loglevel = 0
11/16/2012 06:51:49;0040;PBS_Server.7718;Svr;csg.bcmd.bcm.edu;Scheduler was sent the command time
11/16/2012 06:54:09;0002;PBS_Server.1828;Svr;PBS_Server;Torque Server Version = 4.1.2, loglevel = 0
11/16/2012 06:59:14;0002;PBS_Server.1834;Svr;PBS_Server;Torque Server Version = 4.1.2, loglevel = 0
11/16/2012 07:01:59;0040;PBS_Server.7802;Svr;csg.bcmd.bcm.edu;Scheduler was sent the command time
11/16/2012 07:04:19;0002;PBS_Server.1827;Svr;PBS_Server;Torque Server Version = 4.1.2, loglevel = 0
11/16/2012 07:09:24;0002;PBS_Server.1831;Svr;PBS_Server;Torque Server Version = 4.1.2, loglevel = 0
11/16/2012 07:12:09;0040;PBS_Server.7817;Svr;csg.bcmd.bcm.edu;Scheduler was sent the command time
11/16/2012 07:14:29;0002;PBS_Server.1828;Svr;PBS_Server;Torque Server Version = 4.1.2, loglevel = 0
11/16/2012 07:19:34;0002;PBS_Server.1827;Svr;PBS_Server;Torque Server Version = 4.1.2, loglevel = 0
11/16/2012 07:22:19;0040;PBS_Server.7832;Svr;csg.bcmd.bcm.edu;Scheduler was sent the command time
11/16/2012 07:24:39;0002;PBS_Server.1828;Svr;PBS_Server;Torque Server Version = 4.1.2, loglevel = 0
11/16/2012 07:29:44;0002;PBS_Server.1831;Svr;PBS_Server;Torque Server Version = 4.1.2, loglevel = 0
11/16/2012 07:32:29;0040;PBS_Server.7846;Svr;csg.bcmd.bcm.edu;Scheduler was sent the command time
11/16/2012 07:34:49;0002;PBS_Server.1828;Svr;PBS_Server;Torque Server Version = 4.1.2, loglevel = 0
11/16/2012 07:39:54;0002;PBS_Server.1830;Svr;PBS_Server;Torque Server Version = 4.1.2, loglevel = 0
11/16/2012 07:42:39;0040;PBS_Server.7860;Svr;csg.bcmd.bcm.edu;Scheduler was sent the command time
11/16/2012 07:44:59;0002;PBS_Server.1836;Svr;PBS_Server;Torque Server Version = 4.1.2, loglevel = 0
11/16/2012 07:50:04;0002;PBS_Server.1834;Svr;PBS_Server;Torque Server Version = 4.1.2, loglevel = 0
11/16/2012 07:52:49;0040;PBS_Server.7874;Svr;csg.bcmd.bcm.edu;Scheduler was sent the command time
11/16/2012 07:55:09;0002;PBS_Server.1825;Svr;PBS_Server;Torque Server Version = 4.1.2, loglevel = 0
11/16/2012 08:00:14;0002;PBS_Server.1836;Svr;PBS_Server;Torque Server Version = 4.1.2, loglevel = 0
11/16/2012 08:02:59;0040;PBS_Server.7917;Svr;csg.bcmd.bcm.edu;Scheduler was sent the command time
11/16/2012 08:05:19;0002;PBS_Server.1836;Svr;PBS_Server;Torque Server Version = 4.1.2, loglevel = 0
11/16/2012 08:10:24;0002;PBS_Server.1836;Svr;PBS_Server;Torque Server Version = 4.1.2, loglevel = 0
11/16/2012 08:13:09;0040;PBS_Server.8019;Svr;csg.bcmd.bcm.edu;Scheduler was sent the command time
11/16/2012 08:15:29;0002;PBS_Server.1837;Svr;PBS_Server;Torque Server Version = 4.1.2, loglevel = 0
11/16/2012 08:20:34;0002;PBS_Server.1828;Svr;PBS_Server;Torque Server Version = 4.1.2, loglevel = 0
11/16/2012 08:23:19;0040;PBS_Server.8115;Svr;csg.bcmd.bcm.edu;Scheduler was sent the command time
11/16/2012 08:25:39;0002;PBS_Server.1832;Svr;PBS_Server;Torque Server Version = 4.1.2, loglevel = 0
11/16/2012 08:30:44;0002;PBS_Server.1834;Svr;PBS_Server;Torque Server Version = 4.1.2, loglevel = 0
11/16/2012 08:33:29;0040;PBS_Server.8212;Svr;csg.bcmd.bcm.edu;Scheduler was sent the command time
11/16/2012 08:35:49;0002;PBS_Server.1833;Svr;PBS_Server;Torque Server Version = 4.1.2, loglevel = 0
11/16/2012 08:40:54;0002;PBS_Server.1831;Svr;PBS_Server;Torque Server Version = 4.1.2, loglevel = 0
11/16/2012 08:43:39;0040;PBS_Server.8307;Svr;csg.bcmd.bcm.edu;Scheduler was sent the command time
11/16/2012 08:45:59;0002;PBS_Server.1826;Svr;PBS_Server;Torque Server Version = 4.1.2, loglevel = 0
11/16/2012 08:51:04;0002;PBS_Server.1830;Svr;PBS_Server;Torque Server Version = 4.1.2, loglevel = 0
11/16/2012 08:53:49;0040;PBS_Server.8402;Svr;csg.bcmd.bcm.edu;Scheduler was sent the command time
11/16/2012 08:56:09;0002;PBS_Server.1827;Svr;PBS_Server;Torque Server Version = 4.1.2, loglevel = 0
11/16/2012 09:01:14;0002;PBS_Server.1830;Svr;PBS_Server;Torque Server Version = 4.1.2, loglevel = 0
11/16/2012 09:03:59;0040;PBS_Server.8490;Svr;csg.bcmd.bcm.edu;Scheduler was sent the command time
11/16/2012 09:06:19;0002;PBS_Server.1832;Svr;PBS_Server;Torque Server Version = 4.1.2, loglevel = 0
11/16/2012 09:11:24;0002;PBS_Server.1828;Svr;PBS_Server;Torque Server Version = 4.1.2, loglevel = 0
11/16/2012 09:14:09;0040;PBS_Server.8542;Svr;csg.bcmd.bcm.edu;Scheduler was sent the command time
11/16/2012 09:16:29;0002;PBS_Server.1827;Svr;PBS_Server;Torque Server Version = 4.1.2, loglevel = 0
11/16/2012 09:21:34;0002;PBS_Server.1835;Svr;PBS_Server;Torque Server Version = 4.1.2, loglevel = 0
11/16/2012 09:24:19;0040;PBS_Server.8574;Svr;csg.bcmd.bcm.edu;Scheduler was sent the command time
11/16/2012 09:26:39;0002;PBS_Server.1831;Svr;PBS_Server;Torque Server Version = 4.1.2, loglevel = 0
11/16/2012 09:31:44;0002;PBS_Server.1832;Svr;PBS_Server;Torque Server Version = 4.1.2, loglevel = 0
11/16/2012 09:34:29;0040;PBS_Server.8588;Svr;csg.bcmd.bcm.edu;Scheduler was sent the command time
11/16/2012 09:36:49;0002;PBS_Server.1836;Svr;PBS_Server;Torque Server Version = 4.1.2, loglevel = 0
11/16/2012 09:41:54;0002;PBS_Server.1826;Svr;PBS_Server;Torque Server Version = 4.1.2, loglevel = 0
11/16/2012 09:44:39;0040;PBS_Server.8602;Svr;csg.bcmd.bcm.edu;Scheduler was sent the command time
11/16/2012 09:46:59;0002;PBS_Server.1827;Svr;PBS_Server;Torque Server Version = 4.1.2, loglevel = 0
11/16/2012 09:52:04;0002;PBS_Server.1830;Svr;PBS_Server;Torque Server Version = 4.1.2, loglevel = 0
11/16/2012 09:54:49;0040;PBS_Server.8638;Svr;csg.bcmd.bcm.edu;Scheduler was sent the command time
11/16/2012 09:57:09;0002;PBS_Server.1826;Svr;PBS_Server;Torque Server Version = 4.1.2, loglevel = 0
11/16/2012 10:02:14;0002;PBS_Server.1829;Svr;PBS_Server;Torque Server Version = 4.1.2, loglevel = 0
11/16/2012 10:04:59;0040;PBS_Server.8698;Svr;csg.bcmd.bcm.edu;Scheduler was sent the command time
11/16/2012 10:07:19;0002;PBS_Server.1831;Svr;PBS_Server;Torque Server Version = 4.1.2, loglevel = 0
11/16/2012 10:12:24;0002;PBS_Server.1827;Svr;PBS_Server;Torque Server Version = 4.1.2, loglevel = 0
11/16/2012 10:15:09;0040;PBS_Server.8837;Svr;csg.bcmd.bcm.edu;Scheduler was sent the command time
11/16/2012 10:17:29;0002;PBS_Server.1830;Svr;PBS_Server;Torque Server Version = 4.1.2, loglevel = 0
11/16/2012 10:22:34;0002;PBS_Server.1829;Svr;PBS_Server;Torque Server Version = 4.1.2, loglevel = 0
11/16/2012 10:25:19;0040;PBS_Server.8934;Svr;csg.bcmd.bcm.edu;Scheduler was sent the command time
11/16/2012 10:27:39;0002;PBS_Server.1829;Svr;PBS_Server;Torque Server Version = 4.1.2, loglevel = 0
11/16/2012 10:32:44;0002;PBS_Server.1833;Svr;PBS_Server;Torque Server Version = 4.1.2, loglevel = 0
11/16/2012 10:35:29;0040;PBS_Server.9028;Svr;csg.bcmd.bcm.edu;Scheduler was sent the command time
11/16/2012 10:37:49;0002;PBS_Server.1831;Svr;PBS_Server;Torque Server Version = 4.1.2, loglevel = 0
11/16/2012 10:42:54;0002;PBS_Server.1837;Svr;PBS_Server;Torque Server Version = 4.1.2, loglevel = 0
11/16/2012 10:45:39;0040;PBS_Server.9124;Svr;csg.bcmd.bcm.edu;Scheduler was sent the command time
11/16/2012 10:47:59;0002;PBS_Server.1836;Svr;PBS_Server;Torque Server Version = 4.1.2, loglevel = 0
11/16/2012 10:53:04;0002;PBS_Server.1828;Svr;PBS_Server;Torque Server Version = 4.1.2, loglevel = 0
11/16/2012 10:55:49;0040;PBS_Server.9218;Svr;csg.bcmd.bcm.edu;Scheduler was sent the command time
11/16/2012 10:58:09;0002;PBS_Server.1829;Svr;PBS_Server;Torque Server Version = 4.1.2, loglevel = 0
11/16/2012 11:03:14;0002;PBS_Server.1828;Svr;PBS_Server;Torque Server Version = 4.1.2, loglevel = 0
11/16/2012 11:05:59;0040;PBS_Server.9273;Svr;csg.bcmd.bcm.edu;Scheduler was sent the command time
11/16/2012 11:08:19;0002;PBS_Server.1828;Svr;PBS_Server;Torque Server Version = 4.1.2, loglevel = 0
11/16/2012 11:13:24;0002;PBS_Server.1829;Svr;PBS_Server;Torque Server Version = 4.1.2, loglevel = 0
11/16/2012 11:16:09;0040;PBS_Server.9300;Svr;csg.bcmd.bcm.edu;Scheduler was sent the command time
11/16/2012 11:18:29;0002;PBS_Server.1834;Svr;PBS_Server;Torque Server Version = 4.1.2, loglevel = 0
11/16/2012 11:23:34;0002;PBS_Server.1829;Svr;PBS_Server;Torque Server Version = 4.1.2, loglevel = 0
11/16/2012 11:25:47;0100;PBS_Server.1831;Job;489.csg.bcmd.bcm.edu;enqueuing into high, state 1 hop 1
11/16/2012 11:25:47;0002;PBS_Server.1831;Svr;Act;Account file /var/spool/torque/server_priv/accounting/20121116 opened
11/16/2012 11:25:47;0008;PBS_Server.1831;Job;489.csg.bcmd.bcm.edu;Job Queued at request of lacuesta@csg.bcmd.bcm.edu, owner = lacuesta@csg.bcmd.bcm.edu, job name = AA_WHR_FEMALE_CMC_permutation_impute_16Nov2012, queue = high
11/16/2012 11:25:48;0040;PBS_Server.9318;Svr;csg.bcmd.bcm.edu;Scheduler was sent the command new
11/16/2012 11:25:49;0008;PBS_Server.1827;Job;489.csg.bcmd.bcm.edu;Job Run at request of root@csg.bcmd.bcm.edu
11/16/2012 11:25:49;000d;PBS_Server.1827;Job;489.csg.bcmd.bcm.edu;Not sending email: User does not want mail of this type.
11/16/2012 11:28:44;0002;PBS_Server.1837;Svr;PBS_Server;Torque Server Version = 4.1.2, loglevel = 0
11/16/2012 11:33:49;0002;PBS_Server.1834;Svr;PBS_Server;Torque Server Version = 4.1.2, loglevel = 0
11/16/2012 11:35:53;0040;PBS_Server.9337;Svr;csg.bcmd.bcm.edu;Scheduler was sent the command time
11/16/2012 11:38:39;0100;PBS_Server.1832;Job;490.csg.bcmd.bcm.edu;enqueuing into high, state 1 hop 1
11/16/2012 11:38:39;0008;PBS_Server.1832;Job;490.csg.bcmd.bcm.edu;Job Queued at request of lacuesta@csg.bcmd.bcm.edu, owner = lacuesta@csg.bcmd.bcm.edu, job name = EA_WHR_FEMALE_CMC_permutation_16Nov2012, queue = high
11/16/2012 11:38:39;0040;PBS_Server.9345;Svr;csg.bcmd.bcm.edu;Scheduler was sent the command new
11/16/2012 11:38:40;0008;PBS_Server.1835;Job;490.csg.bcmd.bcm.edu;Job Run at request of root@csg.bcmd.bcm.edu
11/16/2012 11:38:40;000d;PBS_Server.1835;Job;490.csg.bcmd.bcm.edu;Not sending email: User does not want mail of this type.
11/16/2012 11:38:50;0002;PBS_Server.1836;Svr;PBS_Server;Torque Server Version = 4.1.2, loglevel = 0
11/16/2012 11:43:50;0002;PBS_Server.1832;Svr;PBS_Server;Torque Server Version = 4.1.2, loglevel = 0
11/16/2012 11:48:51;0040;PBS_Server.9370;Svr;csg.bcmd.bcm.edu;Scheduler was sent the command time
11/16/2012 11:49:01;0002;PBS_Server.1834;Svr;PBS_Server;Torque Server Version = 4.1.2, loglevel = 0
11/16/2012 11:54:01;0002;PBS_Server.1826;Svr;PBS_Server;Torque Server Version = 4.1.2, loglevel = 0
11/16/2012 11:59:02;0040;PBS_Server.9384;Svr;csg.bcmd.bcm.edu;Scheduler was sent the command time
11/16/2012 11:59:12;0002;PBS_Server.1832;Svr;PBS_Server;Torque Server Version = 4.1.2, loglevel = 0
11/16/2012 12:04:12;0002;PBS_Server.1827;Svr;PBS_Server;Torque Server Version = 4.1.2, loglevel = 0
11/16/2012 12:09:13;0040;PBS_Server.9489;Svr;csg.bcmd.bcm.edu;Scheduler was sent the command time
11/16/2012 12:09:23;0002;PBS_Server.1837;Svr;PBS_Server;Torque Server Version = 4.1.2, loglevel = 0
11/16/2012 12:14:23;0002;PBS_Server.1831;Svr;PBS_Server;Torque Server Version = 4.1.2, loglevel = 0
11/16/2012 12:19:24;0040;PBS_Server.9596;Svr;csg.bcmd.bcm.edu;Scheduler was sent the command time
11/16/2012 12:19:34;0002;PBS_Server.1833;Svr;PBS_Server;Torque Server Version = 4.1.2, loglevel = 0
11/16/2012 12:24:35;0002;PBS_Server.1837;Svr;PBS_Server;Torque Server Version = 4.1.2, loglevel = 0
11/16/2012 12:29:34;0040;PBS_Server.9691;Svr;csg.bcmd.bcm.edu;Scheduler was sent the command time
11/16/2012 12:29:40;0002;PBS_Server.1829;Svr;PBS_Server;Torque Server Version = 4.1.2, loglevel = 0
11/16/2012 12:34:45;0002;PBS_Server.1831;Svr;PBS_Server;Torque Server Version = 4.1.2, loglevel = 0
11/16/2012 12:39:44;0040;PBS_Server.9830;Svr;csg.bcmd.bcm.edu;Scheduler was sent the command time
11/16/2012 12:39:50;0002;PBS_Server.1837;Svr;PBS_Server;Torque Server Version = 4.1.2, loglevel = 0
11/16/2012 12:44:55;0002;PBS_Server.1826;Svr;PBS_Server;Torque Server Version = 4.1.2, loglevel = 0
11/16/2012 12:49:54;0040;PBS_Server.9989;Svr;csg.bcmd.bcm.edu;Scheduler was sent the command time
11/16/2012 12:50:00;0002;PBS_Server.1837;Svr;PBS_Server;Torque Server Version = 4.1.2, loglevel = 0
11/16/2012 12:55:05;0002;PBS_Server.1835;Svr;PBS_Server;Torque Server Version = 4.1.2, loglevel = 0
11/16/2012 13:00:04;0040;PBS_Server.10093;Svr;csg.bcmd.bcm.edu;Scheduler was sent the command time
11/16/2012 13:00:10;0002;PBS_Server.1827;Svr;PBS_Server;Torque Server Version = 4.1.2, loglevel = 0
11/16/2012 13:05:15;0002;PBS_Server.1837;Svr;PBS_Server;Torque Server Version = 4.1.2, loglevel = 0
11/16/2012 13:10:14;0040;PBS_Server.10114;Svr;csg.bcmd.bcm.edu;Scheduler was sent the command time
11/16/2012 13:10:20;0002;PBS_Server.1825;Svr;PBS_Server;Torque Server Version = 4.1.2, loglevel = 0
11/16/2012 13:15:25;0002;PBS_Server.1831;Svr;PBS_Server;Torque Server Version = 4.1.2, loglevel = 0
11/16/2012 13:20:24;0040;PBS_Server.10184;Svr;csg.bcmd.bcm.edu;Scheduler was sent the command time
11/16/2012 13:20:30;0002;PBS_Server.1828;Svr;PBS_Server;Torque Server Version = 4.1.2, loglevel = 0
11/16/2012 13:25:35;0002;PBS_Server.1835;Svr;PBS_Server;Torque Server Version = 4.1.2, loglevel = 0
11/16/2012 13:30:34;0040;PBS_Server.10226;Svr;csg.bcmd.bcm.edu;Scheduler was sent the command time
11/16/2012 13:30:40;0002;PBS_Server.1825;Svr;PBS_Server;Torque Server Version = 4.1.2, loglevel = 0
11/16/2012 13:35:45;0002;PBS_Server.1826;Svr;PBS_Server;Torque Server Version = 4.1.2, loglevel = 0
11/16/2012 13:40:44;0040;PBS_Server.10241;Svr;csg.bcmd.bcm.edu;Scheduler was sent the command time
11/16/2012 13:40:50;0002;PBS_Server.1831;Svr;PBS_Server;Torque Server Version = 4.1.2, loglevel = 0
11/16/2012 13:45:55;0002;PBS_Server.1830;Svr;PBS_Server;Torque Server Version = 4.1.2, loglevel = 0
11/16/2012 13:50:54;0040;PBS_Server.10264;Svr;csg.bcmd.bcm.edu;Scheduler was sent the command time
11/16/2012 13:51:00;0002;PBS_Server.1833;Svr;PBS_Server;Torque Server Version = 4.1.2, loglevel = 0
11/16/2012 13:56:05;0002;PBS_Server.1833;Svr;PBS_Server;Torque Server Version = 4.1.2, loglevel = 0
11/16/2012 14:01:04;0040;PBS_Server.10298;Svr;csg.bcmd.bcm.edu;Scheduler was sent the command time
11/16/2012 14:01:10;0002;PBS_Server.1826;Svr;PBS_Server;Torque Server Version = 4.1.2, loglevel = 0
11/16/2012 14:06:15;0002;PBS_Server.1826;Svr;PBS_Server;Torque Server Version = 4.1.2, loglevel = 0
11/16/2012 14:11:14;0040;PBS_Server.10404;Svr;csg.bcmd.bcm.edu;Scheduler was sent the command time
11/16/2012 14:11:20;0002;PBS_Server.1832;Svr;PBS_Server;Torque Server Version = 4.1.2, loglevel = 0
11/16/2012 14:16:25;0002;PBS_Server.1825;Svr;PBS_Server;Torque Server Version = 4.1.2, loglevel = 0
11/16/2012 14:21:24;0040;PBS_Server.10504;Svr;csg.bcmd.bcm.edu;Scheduler was sent the command time
11/16/2012 14:21:30;0002;PBS_Server.1827;Svr;PBS_Server;Torque Server Version = 4.1.2, loglevel = 0
11/16/2012 14:26:35;0002;PBS_Server.1828;Svr;PBS_Server;Torque Server Version = 4.1.2, loglevel = 0
11/16/2012 14:31:34;0040;PBS_Server.10610;Svr;csg.bcmd.bcm.edu;Scheduler was sent the command time
11/16/2012 14:31:40;0002;PBS_Server.1835;Svr;PBS_Server;Torque Server Version = 4.1.2, loglevel = 0
11/16/2012 14:36:45;0002;PBS_Server.1832;Svr;PBS_Server;Torque Server Version = 4.1.2, loglevel = 0
11/16/2012 14:41:44;0040;PBS_Server.10708;Svr;csg.bcmd.bcm.edu;Scheduler was sent the command time
11/16/2012 14:41:50;0002;PBS_Server.1828;Svr;PBS_Server;Torque Server Version = 4.1.2, loglevel = 0
11/16/2012 14:46:55;0002;PBS_Server.1837;Svr;PBS_Server;Torque Server Version = 4.1.2, loglevel = 0
11/16/2012 14:51:54;0040;PBS_Server.10804;Svr;csg.bcmd.bcm.edu;Scheduler was sent the command time
11/16/2012 14:52:00;0002;PBS_Server.1826;Svr;PBS_Server;Torque Server Version = 4.1.2, loglevel = 0
11/16/2012 14:57:05;0002;PBS_Server.1836;Svr;PBS_Server;Torque Server Version = 4.1.2, loglevel = 0
11/16/2012 15:02:04;0040;PBS_Server.10901;Svr;csg.bcmd.bcm.edu;Scheduler was sent the command time
11/16/2012 15:02:10;0002;PBS_Server.1837;Svr;PBS_Server;Torque Server Version = 4.1.2, loglevel = 0
11/16/2012 15:07:15;0002;PBS_Server.1828;Svr;PBS_Server;Torque Server Version = 4.1.2, loglevel = 0
11/16/2012 15:12:14;0040;PBS_Server.10965;Svr;csg.bcmd.bcm.edu;Scheduler was sent the command time
11/16/2012 15:12:20;0002;PBS_Server.1825;Svr;PBS_Server;Torque Server Version = 4.1.2, loglevel = 0
11/16/2012 15:17:25;0002;PBS_Server.1826;Svr;PBS_Server;Torque Server Version = 4.1.2, loglevel = 0
11/16/2012 15:21:42;000d;PBS_Server.1833;Job;489.csg.bcmd.bcm.edu;Not sending email: User does not want mail of this type.
11/16/2012 15:21:42;0010;PBS_Server.1833;Job;489.csg.bcmd.bcm.edu;Exit_status=1 resources_used.cput=10:35:25 resources_used.mem=940464kb resources_used.vmem=5438124kb resources_used.walltime=03:55:53
11/16/2012 15:21:42;0008;PBS_Server.1832;Job;489.csg.bcmd.bcm.edu;on_job_exit valid pjob: 489.csg.bcmd.bcm.edu (substate=50)
11/16/2012 15:21:43;0040;PBS_Server.11015;Svr;csg.bcmd.bcm.edu;Scheduler was sent the command term
11/16/2012 15:22:30;0002;PBS_Server.1828;Svr;PBS_Server;Torque Server Version = 4.1.2, loglevel = 0
11/16/2012 15:26:43;0008;PBS_Server.1836;Job;489.csg.bcmd.bcm.edu;on_job_exit valid pjob: 489.csg.bcmd.bcm.edu (substate=59)
11/16/2012 15:26:43;0100;PBS_Server.1836;Job;489.csg.bcmd.bcm.edu;dequeuing from high, state COMPLETE
11/16/2012 15:26:48;0040;PBS_Server.11063;Svr;csg.bcmd.bcm.edu;Scheduler was sent the command term
11/16/2012 15:27:35;0002;PBS_Server.1830;Svr;PBS_Server;Torque Server Version = 4.1.2, loglevel = 0
11/16/2012 15:32:40;0002;PBS_Server.1830;Svr;PBS_Server;Torque Server Version = 4.1.2, loglevel = 0
11/16/2012 15:34:13;0100;PBS_Server.1825;Job;491.csg.bcmd.bcm.edu;enqueuing into batch, state 1 hop 1
11/16/2012 15:34:13;0008;PBS_Server.1825;Job;491.csg.bcmd.bcm.edu;Job Queued at request of lacuesta@csg.bcmd.bcm.edu, owner = lacuesta@csg.bcmd.bcm.edu, job name = jobname1, queue = batch
11/16/2012 15:34:13;0100;PBS_Server.1832;Job;492.csg.bcmd.bcm.edu;enqueuing into batch, state 1 hop 1
11/16/2012 15:34:13;0008;PBS_Server.1832;Job;492.csg.bcmd.bcm.edu;Job Queued at request of lacuesta@csg.bcmd.bcm.edu, owner = lacuesta@csg.bcmd.bcm.edu, job name = jobname2, queue = batch
11/16/2012 15:34:16;0100;PBS_Server.1834;Job;493.csg.bcmd.bcm.edu;enqueuing into batch, state 1 hop 1
11/16/2012 15:34:16;0008;PBS_Server.1834;Job;493.csg.bcmd.bcm.edu;Job Queued at request of lacuesta@csg.bcmd.bcm.edu, owner = lacuesta@csg.bcmd.bcm.edu, job name = jobname1, queue = batch
11/16/2012 15:34:17;0100;PBS_Server.1830;Job;494.csg.bcmd.bcm.edu;enqueuing into batch, state 1 hop 1
11/16/2012 15:34:17;0008;PBS_Server.1830;Job;494.csg.bcmd.bcm.edu;Job Queued at request of lacuesta@csg.bcmd.bcm.edu, owner = lacuesta@csg.bcmd.bcm.edu, job name = jobname2, queue = batch
11/16/2012 15:34:18;0040;PBS_Server.11150;Svr;csg.bcmd.bcm.edu;Scheduler was sent the command new
11/16/2012 15:34:19;0008;PBS_Server.1835;Job;491.csg.bcmd.bcm.edu;Job Run at request of root@csg.bcmd.bcm.edu
11/16/2012 15:34:19;000d;PBS_Server.1835;Job;491.csg.bcmd.bcm.edu;Not sending email: User does not want mail of this type.
11/16/2012 15:34:19;0008;PBS_Server.1835;Job;492.csg.bcmd.bcm.edu;Job Run at request of root@csg.bcmd.bcm.edu
11/16/2012 15:34:19;000d;PBS_Server.1835;Job;492.csg.bcmd.bcm.edu;Not sending email: User does not want mail of this type.
11/16/2012 15:34:19;0008;PBS_Server.1835;Job;493.csg.bcmd.bcm.edu;Job Run at request of root@csg.bcmd.bcm.edu
11/16/2012 15:34:19;000d;PBS_Server.1835;Job;493.csg.bcmd.bcm.edu;Not sending email: User does not want mail of this type.
11/16/2012 15:34:19;0008;PBS_Server.1835;Job;494.csg.bcmd.bcm.edu;Job Run at request of root@csg.bcmd.bcm.edu
11/16/2012 15:34:19;000d;PBS_Server.1835;Job;494.csg.bcmd.bcm.edu;Not sending email: User does not want mail of this type.
11/16/2012 15:34:36;000d;PBS_Server.1834;Job;493.csg.bcmd.bcm.edu;Not sending email: User does not want mail of this type.
11/16/2012 15:34:36;0010;PBS_Server.1834;Job;493.csg.bcmd.bcm.edu;Exit_status=1 resources_used.cput=00:00:00 resources_used.mem=1128kb resources_used.vmem=13560kb resources_used.walltime=00:00:17
11/16/2012 15:34:36;0008;PBS_Server.1833;Job;493.csg.bcmd.bcm.edu;on_job_exit valid pjob: 493.csg.bcmd.bcm.edu (substate=50)
11/16/2012 15:34:36;000d;PBS_Server.1830;Job;494.csg.bcmd.bcm.edu;Not sending email: User does not want mail of this type.
11/16/2012 15:34:36;0010;PBS_Server.1830;Job;494.csg.bcmd.bcm.edu;Exit_status=1 resources_used.cput=00:00:00 resources_used.mem=1132kb resources_used.vmem=13560kb resources_used.walltime=00:00:17
11/16/2012 15:34:36;0008;PBS_Server.1827;Job;494.csg.bcmd.bcm.edu;on_job_exit valid pjob: 494.csg.bcmd.bcm.edu (substate=50)
11/16/2012 15:34:39;0040;PBS_Server.11167;Svr;csg.bcmd.bcm.edu;Scheduler was sent the command term
11/16/2012 15:34:55;0100;PBS_Server.1826;Job;495.csg.bcmd.bcm.edu;enqueuing into batch, state 1 hop 1
11/16/2012 15:34:55;0008;PBS_Server.1826;Job;495.csg.bcmd.bcm.edu;Job Queued at request of lacuesta@csg.bcmd.bcm.edu, owner = lacuesta@csg.bcmd.bcm.edu, job name = jobname1, queue = batch
11/16/2012 15:34:55;0100;PBS_Server.1837;Job;496.csg.bcmd.bcm.edu;enqueuing into batch, state 1 hop 1
11/16/2012 15:34:55;0008;PBS_Server.1837;Job;496.csg.bcmd.bcm.edu;Job Queued at request of lacuesta@csg.bcmd.bcm.edu, owner = lacuesta@csg.bcmd.bcm.edu, job name = jobname2, queue = batch
11/16/2012 15:34:59;0040;PBS_Server.11178;Svr;csg.bcmd.bcm.edu;Scheduler was sent the command new
11/16/2012 15:35:00;0008;PBS_Server.1835;Job;495.csg.bcmd.bcm.edu;Job Run at request of root@csg.bcmd.bcm.edu
11/16/2012 15:35:00;000d;PBS_Server.1835;Job;495.csg.bcmd.bcm.edu;Not sending email: User does not want mail of this type.
11/16/2012 15:35:00;0008;PBS_Server.1835;Job;496.csg.bcmd.bcm.edu;Job Run at request of root@csg.bcmd.bcm.edu
11/16/2012 15:35:00;000d;PBS_Server.1835;Job;496.csg.bcmd.bcm.edu;Not sending email: User does not want mail of this type.
11/16/2012 15:35:02;0100;PBS_Server.1829;Job;497.csg.bcmd.bcm.edu;enqueuing into batch, state 1 hop 1
11/16/2012 15:35:02;0008;PBS_Server.1829;Job;497.csg.bcmd.bcm.edu;Job Queued at request of lacuesta@csg.bcmd.bcm.edu, owner = lacuesta@csg.bcmd.bcm.edu, job name = jobname1, queue = batch
11/16/2012 15:35:02;0100;PBS_Server.1836;Job;498.csg.bcmd.bcm.edu;enqueuing into batch, state 1 hop 1
11/16/2012 15:35:02;0008;PBS_Server.1836;Job;498.csg.bcmd.bcm.edu;Job Queued at request of lacuesta@csg.bcmd.bcm.edu, owner = lacuesta@csg.bcmd.bcm.edu, job name = jobname2, queue = batch
11/16/2012 15:35:04;000d;PBS_Server.1826;Job;495.csg.bcmd.bcm.edu;Not sending email: User does not want mail of this type.
11/16/2012 15:35:04;0010;PBS_Server.1826;Job;495.csg.bcmd.bcm.edu;Exit_status=1 resources_used.cput=00:00:01 resources_used.mem=0kb resources_used.vmem=0kb resources_used.walltime=00:00:04
11/16/2012 15:35:04;0008;PBS_Server.1831;Job;495.csg.bcmd.bcm.edu;on_job_exit valid pjob: 495.csg.bcmd.bcm.edu (substate=50)
11/16/2012 15:35:04;0040;PBS_Server.11195;Svr;csg.bcmd.bcm.edu;Scheduler was sent the command new
11/16/2012 15:35:04;0040;PBS_Server.11202;Svr;csg.bcmd.bcm.edu;Scheduler was sent the command term
11/16/2012 15:35:04;0008;PBS_Server.1835;Job;497.csg.bcmd.bcm.edu;Job Run at request of root@csg.bcmd.bcm.edu
11/16/2012 15:35:04;000d;PBS_Server.1835;Job;497.csg.bcmd.bcm.edu;Not sending email: User does not want mail of this type.
11/16/2012 15:35:04;0008;PBS_Server.1835;Job;498.csg.bcmd.bcm.edu;Job Run at request of root@csg.bcmd.bcm.edu
11/16/2012 15:35:04;000d;PBS_Server.1835;Job;498.csg.bcmd.bcm.edu;Not sending email: User does not want mail of this type.
11/16/2012 15:35:05;000d;PBS_Server.1829;Job;497.csg.bcmd.bcm.edu;Not sending email: User does not want mail of this type.
11/16/2012 15:35:05;0010;PBS_Server.1829;Job;497.csg.bcmd.bcm.edu;Exit_status=1 resources_used.cput=00:00:00 resources_used.mem=0kb resources_used.vmem=0kb resources_used.walltime=00:00:01
11/16/2012 15:35:05;0008;PBS_Server.1830;Job;497.csg.bcmd.bcm.edu;on_job_exit valid pjob: 497.csg.bcmd.bcm.edu (substate=50)
11/16/2012 15:35:05;000d;PBS_Server.1833;Job;498.csg.bcmd.bcm.edu;Not sending email: User does not want mail of this type.
11/16/2012 15:35:05;0010;PBS_Server.1833;Job;498.csg.bcmd.bcm.edu;Exit_status=1 resources_used.cput=00:00:00 resources_used.mem=0kb resources_used.vmem=0kb resources_used.walltime=00:00:01
11/16/2012 15:35:05;0008;PBS_Server.1836;Job;498.csg.bcmd.bcm.edu;on_job_exit valid pjob: 498.csg.bcmd.bcm.edu (substate=50)
11/16/2012 15:35:08;000d;PBS_Server.1831;Job;496.csg.bcmd.bcm.edu;Not sending email: User does not want mail of this type.
11/16/2012 15:35:08;0010;PBS_Server.1831;Job;496.csg.bcmd.bcm.edu;Exit_status=1 resources_used.cput=00:00:05 resources_used.mem=103460kb resources_used.vmem=233592kb resources_used.walltime=00:00:08
11/16/2012 15:35:08;0008;PBS_Server.1825;Job;496.csg.bcmd.bcm.edu;on_job_exit valid pjob: 496.csg.bcmd.bcm.edu (substate=50)
11/16/2012 15:35:09;0040;PBS_Server.11228;Svr;csg.bcmd.bcm.edu;Scheduler was sent the command term
11/16/2012 15:35:19;0100;PBS_Server.1831;Job;499.csg.bcmd.bcm.edu;enqueuing into batch, state 1 hop 1
11/16/2012 15:35:19;0008;PBS_Server.1831;Job;499.csg.bcmd.bcm.edu;Job Queued at request of lacuesta@csg.bcmd.bcm.edu, owner = lacuesta@csg.bcmd.bcm.edu, job name = jobname1, queue = batch
11/16/2012 15:35:19;0100;PBS_Server.1825;Job;500.csg.bcmd.bcm.edu;enqueuing into batch, state 1 hop 1
11/16/2012 15:35:19;0008;PBS_Server.1825;Job;500.csg.bcmd.bcm.edu;Job Queued at request of lacuesta@csg.bcmd.bcm.edu, owner = lacuesta@csg.bcmd.bcm.edu, job name = jobname2, queue = batch
11/16/2012 15:35:19;0040;PBS_Server.11239;Svr;csg.bcmd.bcm.edu;Scheduler was sent the command new
11/16/2012 15:35:20;0008;PBS_Server.1835;Job;499.csg.bcmd.bcm.edu;Job Run at request of root@csg.bcmd.bcm.edu
11/16/2012 15:35:20;000d;PBS_Server.1835;Job;499.csg.bcmd.bcm.edu;Not sending email: User does not want mail of this type.
11/16/2012 15:35:20;0008;PBS_Server.1835;Job;500.csg.bcmd.bcm.edu;Job Run at request of root@csg.bcmd.bcm.edu
11/16/2012 15:35:20;000d;PBS_Server.1835;Job;500.csg.bcmd.bcm.edu;Not sending email: User does not want mail of this type.
11/16/2012 15:35:25;0100;PBS_Server.1833;Job;501.csg.bcmd.bcm.edu;enqueuing into batch, state 1 hop 1
11/16/2012 15:35:25;0008;PBS_Server.1833;Job;501.csg.bcmd.bcm.edu;Job Queued at request of lacuesta@csg.bcmd.bcm.edu, owner = lacuesta@csg.bcmd.bcm.edu, job name = jobname1, queue = batch
11/16/2012 15:35:26;0100;PBS_Server.1836;Job;502.csg.bcmd.bcm.edu;enqueuing into batch, state 1 hop 1
11/16/2012 15:35:26;0008;PBS_Server.1836;Job;502.csg.bcmd.bcm.edu;Job Queued at request of lacuesta@csg.bcmd.bcm.edu, owner = lacuesta@csg.bcmd.bcm.edu, job name = jobname2, queue = batch
11/16/2012 15:35:29;0040;PBS_Server.11249;Svr;csg.bcmd.bcm.edu;Scheduler was sent the command new
11/16/2012 15:35:30;0008;PBS_Server.1835;Job;501.csg.bcmd.bcm.edu;Job Run at request of root@csg.bcmd.bcm.edu
11/16/2012 15:35:30;000d;PBS_Server.1835;Job;501.csg.bcmd.bcm.edu;Not sending email: User does not want mail of this type.
11/16/2012 15:35:30;0008;PBS_Server.1835;Job;502.csg.bcmd.bcm.edu;Job Run at request of root@csg.bcmd.bcm.edu
11/16/2012 15:35:30;000d;PBS_Server.1835;Job;502.csg.bcmd.bcm.edu;Not sending email: User does not want mail of this type.
11/16/2012 15:35:31;0100;PBS_Server.1828;Job;503.csg.bcmd.bcm.edu;enqueuing into batch, state 1 hop 1
11/16/2012 15:35:31;0008;PBS_Server.1828;Job;503.csg.bcmd.bcm.edu;Job Queued at request of lacuesta@csg.bcmd.bcm.edu, owner = lacuesta@csg.bcmd.bcm.edu, job name = jobname1, queue = batch
11/16/2012 15:35:31;0100;PBS_Server.1834;Job;504.csg.bcmd.bcm.edu;enqueuing into batch, state 1 hop 1
11/16/2012 15:35:31;0008;PBS_Server.1834;Job;504.csg.bcmd.bcm.edu;Job Queued at request of lacuesta@csg.bcmd.bcm.edu, owner = lacuesta@csg.bcmd.bcm.edu, job name = jobname2, queue = batch
11/16/2012 15:35:34;000d;PBS_Server.1833;Job;500.csg.bcmd.bcm.edu;Not sending email: User does not want mail of this type.
11/16/2012 15:35:34;0010;PBS_Server.1833;Job;500.csg.bcmd.bcm.edu;Exit_status=1 resources_used.cput=00:00:00 resources_used.mem=0kb resources_used.vmem=0kb resources_used.walltime=00:00:14
11/16/2012 15:35:34;0008;PBS_Server.1836;Job;500.csg.bcmd.bcm.edu;on_job_exit valid pjob: 500.csg.bcmd.bcm.edu (substate=50)
11/16/2012 15:35:34;000d;PBS_Server.1826;Job;501.csg.bcmd.bcm.edu;Not sending email: User does not want mail of this type.
11/16/2012 15:35:34;0010;PBS_Server.1826;Job;501.csg.bcmd.bcm.edu;Exit_status=1 resources_used.cput=00:00:00 resources_used.mem=0kb resources_used.vmem=0kb resources_used.walltime=00:00:04
11/16/2012 15:35:34;0008;PBS_Server.1827;Job;501.csg.bcmd.bcm.edu;on_job_exit valid pjob: 501.csg.bcmd.bcm.edu (substate=50)
11/16/2012 15:35:34;000d;PBS_Server.1828;Job;502.csg.bcmd.bcm.edu;Not sending email: User does not want mail of this type.
11/16/2012 15:35:34;0010;PBS_Server.1828;Job;502.csg.bcmd.bcm.edu;Exit_status=1 resources_used.cput=00:00:00 resources_used.mem=0kb resources_used.vmem=0kb resources_used.walltime=00:00:04
11/16/2012 15:35:34;0008;PBS_Server.1825;Job;502.csg.bcmd.bcm.edu;on_job_exit valid pjob: 502.csg.bcmd.bcm.edu (substate=50)
11/16/2012 15:35:34;000d;PBS_Server.1832;Job;499.csg.bcmd.bcm.edu;Not sending email: User does not want mail of this type.
11/16/2012 15:35:34;0010;PBS_Server.1832;Job;499.csg.bcmd.bcm.edu;Exit_status=1 resources_used.cput=00:00:00 resources_used.mem=10392kb resources_used.vmem=59880kb resources_used.walltime=00:00:14
11/16/2012 15:35:34;0008;PBS_Server.1829;Job;499.csg.bcmd.bcm.edu;on_job_exit valid pjob: 499.csg.bcmd.bcm.edu (substate=50)
11/16/2012 15:35:34;0040;PBS_Server.11291;Svr;csg.bcmd.bcm.edu;Scheduler was sent the command term
11/16/2012 15:35:35;0008;PBS_Server.1835;Job;503.csg.bcmd.bcm.edu;Job Run at request of root@csg.bcmd.bcm.edu
11/16/2012 15:35:35;000d;PBS_Server.1835;Job;503.csg.bcmd.bcm.edu;Not sending email: User does not want mail of this type.
11/16/2012 15:35:35;0008;PBS_Server.1835;Job;504.csg.bcmd.bcm.edu;Job Run at request of root@csg.bcmd.bcm.edu
11/16/2012 15:35:35;000d;PBS_Server.1835;Job;504.csg.bcmd.bcm.edu;Not sending email: User does not want mail of this type.
11/16/2012 15:35:37;000d;PBS_Server.1833;Job;503.csg.bcmd.bcm.edu;Not sending email: User does not want mail of this type.
11/16/2012 15:35:37;0010;PBS_Server.1833;Job;503.csg.bcmd.bcm.edu;Exit_status=1 resources_used.cput=00:00:01 resources_used.mem=0kb resources_used.vmem=0kb resources_used.walltime=00:00:02
11/16/2012 15:35:37;0008;PBS_Server.1836;Job;503.csg.bcmd.bcm.edu;on_job_exit valid pjob: 503.csg.bcmd.bcm.edu (substate=50)
11/16/2012 15:35:39;0040;PBS_Server.11300;Svr;csg.bcmd.bcm.edu;Scheduler was sent the command term
11/16/2012 15:35:41;000d;PBS_Server.1832;Job;504.csg.bcmd.bcm.edu;Not sending email: User does not want mail of this type.
11/16/2012 15:35:41;0010;PBS_Server.1832;Job;504.csg.bcmd.bcm.edu;Exit_status=1 resources_used.cput=00:00:05 resources_used.mem=88004kb resources_used.vmem=207752kb resources_used.walltime=00:00:06
11/16/2012 15:35:41;0008;PBS_Server.1833;Job;504.csg.bcmd.bcm.edu;on_job_exit valid pjob: 504.csg.bcmd.bcm.edu (substate=50)
11/16/2012 15:35:44;0040;PBS_Server.11309;Svr;csg.bcmd.bcm.edu;Scheduler was sent the command term
11/16/2012 15:36:18;000d;PBS_Server.1830;Job;491.csg.bcmd.bcm.edu;Not sending email: User does not want mail of this type.
11/16/2012 15:36:18;0010;PBS_Server.1830;Job;491.csg.bcmd.bcm.edu;Exit_status=1 resources_used.cput=00:00:00 resources_used.mem=1128kb resources_used.vmem=13560kb resources_used.walltime=00:01:59
11/16/2012 15:36:18;0008;PBS_Server.1832;Job;491.csg.bcmd.bcm.edu;on_job_exit valid pjob: 491.csg.bcmd.bcm.edu (substate=50)
11/16/2012 15:36:18;000d;PBS_Server.1825;Job;492.csg.bcmd.bcm.edu;Not sending email: User does not want mail of this type.
11/16/2012 15:36:18;0010;PBS_Server.1825;Job;492.csg.bcmd.bcm.edu;Exit_status=1 resources_used.cput=00:00:00 resources_used.mem=1132kb resources_used.vmem=13560kb resources_used.walltime=00:01:59
11/16/2012 15:36:18;0008;PBS_Server.1833;Job;492.csg.bcmd.bcm.edu;on_job_exit valid pjob: 492.csg.bcmd.bcm.edu (substate=50)
11/16/2012 15:36:19;0040;PBS_Server.11329;Svr;csg.bcmd.bcm.edu;Scheduler was sent the command term
11/16/2012 15:37:54;0002;PBS_Server.1831;Svr;PBS_Server;Torque Server Version = 4.1.2, loglevel = 0
11/16/2012 15:38:05;000d;PBS_Server.1826;Job;490.csg.bcmd.bcm.edu;Not sending email: User does not want mail of this type.
11/16/2012 15:38:05;0010;PBS_Server.1826;Job;490.csg.bcmd.bcm.edu;Exit_status=1 resources_used.cput=14:07:55 resources_used.mem=952808kb resources_used.vmem=5450588kb resources_used.walltime=03:59:25
11/16/2012 15:38:05;0008;PBS_Server.1836;Job;490.csg.bcmd.bcm.edu;on_job_exit valid pjob: 490.csg.bcmd.bcm.edu (substate=50)
11/16/2012 15:38:09;0040;PBS_Server.11345;Svr;csg.bcmd.bcm.edu;Scheduler was sent the command term
11/16/2012 15:39:50;0008;PBS_Server.1829;Job;493.csg.bcmd.bcm.edu;on_job_exit valid pjob: 493.csg.bcmd.bcm.edu (substate=59)
11/16/2012 15:39:50;0008;PBS_Server.1834;Job;494.csg.bcmd.bcm.edu;on_job_exit valid pjob: 494.csg.bcmd.bcm.edu (substate=59)
11/16/2012 15:39:50;0100;PBS_Server.1829;Job;493.csg.bcmd.bcm.edu;dequeuing from batch, state COMPLETE
11/16/2012 15:39:50;0100;PBS_Server.1834;Job;494.csg.bcmd.bcm.edu;dequeuing from batch, state COMPLETE
11/16/2012 15:39:55;0040;PBS_Server.11381;Svr;csg.bcmd.bcm.edu;Scheduler was sent the command term
11/16/2012 15:40:05;0008;PBS_Server.1830;Job;495.csg.bcmd.bcm.edu;on_job_exit valid pjob: 495.csg.bcmd.bcm.edu (substate=59)
11/16/2012 15:40:05;0008;PBS_Server.1827;Job;497.csg.bcmd.bcm.edu;on_job_exit valid pjob: 497.csg.bcmd.bcm.edu (substate=59)
11/16/2012 15:40:05;0008;PBS_Server.1832;Job;498.csg.bcmd.bcm.edu;on_job_exit valid pjob: 498.csg.bcmd.bcm.edu (substate=59)
11/16/2012 15:40:05;0100;PBS_Server.1830;Job;495.csg.bcmd.bcm.edu;dequeuing from batch, state COMPLETE
11/16/2012 15:40:05;0100;PBS_Server.1827;Job;497.csg.bcmd.bcm.edu;dequeuing from batch, state COMPLETE
11/16/2012 15:40:05;0100;PBS_Server.1832;Job;498.csg.bcmd.bcm.edu;dequeuing from batch, state COMPLETE
11/16/2012 15:40:10;0040;PBS_Server.11400;Svr;csg.bcmd.bcm.edu;Scheduler was sent the command term
11/16/2012 15:40:20;0008;PBS_Server.1837;Job;496.csg.bcmd.bcm.edu;on_job_exit valid pjob: 496.csg.bcmd.bcm.edu (substate=59)
11/16/2012 15:40:20;0100;PBS_Server.1837;Job;496.csg.bcmd.bcm.edu;dequeuing from batch, state COMPLETE
11/16/2012 15:40:25;0040;PBS_Server.11401;Svr;csg.bcmd.bcm.edu;Scheduler was sent the command term
11/16/2012 15:40:35;0008;PBS_Server.1833;Job;500.csg.bcmd.bcm.edu;on_job_exit valid pjob: 500.csg.bcmd.bcm.edu (substate=59)
11/16/2012 15:40:35;0008;PBS_Server.1829;Job;499.csg.bcmd.bcm.edu;on_job_exit valid pjob: 499.csg.bcmd.bcm.edu (substate=59)
11/16/2012 15:40:35;0008;PBS_Server.1831;Job;501.csg.bcmd.bcm.edu;on_job_exit valid pjob: 501.csg.bcmd.bcm.edu (substate=59)
11/16/2012 15:40:35;0100;PBS_Server.1833;Job;500.csg.bcmd.bcm.edu;dequeuing from batch, state COMPLETE
11/16/2012 15:40:35;0008;PBS_Server.1826;Job;502.csg.bcmd.bcm.edu;on_job_exit valid pjob: 502.csg.bcmd.bcm.edu (substate=59)
11/16/2012 15:40:35;0100;PBS_Server.1829;Job;499.csg.bcmd.bcm.edu;dequeuing from batch, state COMPLETE
11/16/2012 15:40:35;0100;PBS_Server.1831;Job;501.csg.bcmd.bcm.edu;dequeuing from batch, state COMPLETE
11/16/2012 15:40:35;0100;PBS_Server.1826;Job;502.csg.bcmd.bcm.edu;dequeuing from batch, state COMPLETE
11/16/2012 15:40:40;0040;PBS_Server.11402;Svr;csg.bcmd.bcm.edu;Scheduler was sent the command term
11/16/2012 15:40:50;0008;PBS_Server.1830;Job;503.csg.bcmd.bcm.edu;on_job_exit valid pjob: 503.csg.bcmd.bcm.edu (substate=59)
11/16/2012 15:40:50;0008;PBS_Server.1834;Job;504.csg.bcmd.bcm.edu;on_job_exit valid pjob: 504.csg.bcmd.bcm.edu (substate=59)
11/16/2012 15:40:50;0100;PBS_Server.1830;Job;503.csg.bcmd.bcm.edu;dequeuing from batch, state COMPLETE
11/16/2012 15:40:50;0100;PBS_Server.1834;Job;504.csg.bcmd.bcm.edu;dequeuing from batch, state COMPLETE
11/16/2012 15:40:55;0040;PBS_Server.11403;Svr;csg.bcmd.bcm.edu;Scheduler was sent the command term
11/16/2012 15:41:20;0008;PBS_Server.1830;Job;491.csg.bcmd.bcm.edu;on_job_exit valid pjob: 491.csg.bcmd.bcm.edu (substate=59)
11/16/2012 15:41:20;0008;PBS_Server.1834;Job;492.csg.bcmd.bcm.edu;on_job_exit valid pjob: 492.csg.bcmd.bcm.edu (substate=59)
11/16/2012 15:41:20;0100;PBS_Server.1830;Job;491.csg.bcmd.bcm.edu;dequeuing from batch, state COMPLETE
11/16/2012 15:41:20;0100;PBS_Server.1834;Job;492.csg.bcmd.bcm.edu;dequeuing from batch, state COMPLETE
11/16/2012 15:41:25;0040;PBS_Server.11405;Svr;csg.bcmd.bcm.edu;Scheduler was sent the command term
11/16/2012 15:42:59;0002;PBS_Server.1837;Svr;PBS_Server;Torque Server Version = 4.1.2, loglevel = 0
11/16/2012 15:43:14;0008;PBS_Server.1834;Job;490.csg.bcmd.bcm.edu;on_job_exit valid pjob: 490.csg.bcmd.bcm.edu (substate=59)
11/16/2012 15:43:14;0100;PBS_Server.1834;Job;490.csg.bcmd.bcm.edu;dequeuing from high, state COMPLETE
11/16/2012 15:43:19;0040;PBS_Server.11409;Svr;csg.bcmd.bcm.edu;Scheduler was sent the command term
11/16/2012 15:48:04;0002;PBS_Server.1834;Svr;PBS_Server;Torque Server Version = 4.1.2, loglevel = 0
11/16/2012 15:53:09;0002;PBS_Server.1825;Svr;PBS_Server;Torque Server Version = 4.1.2, loglevel = 0
11/16/2012 15:53:29;0040;PBS_Server.11526;Svr;csg.bcmd.bcm.edu;Scheduler was sent the command time
11/16/2012 15:54:00;0100;PBS_Server.1826;Job;505.csg.bcmd.bcm.edu;enqueuing into high, state 1 hop 1
11/16/2012 15:54:00;0008;PBS_Server.1826;Job;505.csg.bcmd.bcm.edu;Job Queued at request of lacuesta@csg.bcmd.bcm.edu, owner = lacuesta@csg.bcmd.bcm.edu, job name = kbjob_AA_Height_SNV, queue = high
11/16/2012 15:54:01;0008;PBS_Server.1832;Job;505.csg.bcmd.bcm.edu;Job Run at request of root@csg.bcmd.bcm.edu
11/16/2012 15:54:01;000d;PBS_Server.1832;Job;505.csg.bcmd.bcm.edu;Not sending email: User does not want mail of this type.
11/16/2012 15:54:01;0040;PBS_Server.11539;Svr;csg.bcmd.bcm.edu;Scheduler was sent the command new
11/16/2012 15:58:16;0002;PBS_Server.1830;Svr;PBS_Server;Torque Server Version = 4.1.2, loglevel = 0
11/16/2012 16:03:16;0002;PBS_Server.1825;Svr;PBS_Server;Torque Server Version = 4.1.2, loglevel = 0
11/16/2012 16:04:07;0040;PBS_Server.11620;Svr;csg.bcmd.bcm.edu;Scheduler was sent the command time
11/16/2012 16:08:17;0002;PBS_Server.1830;Svr;PBS_Server;Torque Server Version = 4.1.2, loglevel = 0
11/16/2012 16:13:28;0002;PBS_Server.1834;Svr;PBS_Server;Torque Server Version = 4.1.2, loglevel = 0
11/16/2012 16:14:18;0040;PBS_Server.11723;Svr;csg.bcmd.bcm.edu;Scheduler was sent the command time
11/16/2012 16:18:28;0002;PBS_Server.1828;Svr;PBS_Server;Torque Server Version = 4.1.2, loglevel = 0
11/16/2012 16:23:29;0002;PBS_Server.1833;Svr;PBS_Server;Torque Server Version = 4.1.2, loglevel = 0
11/16/2012 16:24:34;0040;PBS_Server.11823;Svr;csg.bcmd.bcm.edu;Scheduler was sent the command time
11/16/2012 16:28:29;0002;PBS_Server.1830;Svr;PBS_Server;Torque Server Version = 4.1.2, loglevel = 0
11/16/2012 16:33:32;0002;PBS_Server.1825;Svr;PBS_Server;Torque Server Version = 4.1.2, loglevel = 0
11/16/2012 16:34:44;0040;PBS_Server.11920;Svr;csg.bcmd.bcm.edu;Scheduler was sent the command time
11/16/2012 16:38:37;0002;PBS_Server.1825;Svr;PBS_Server;Torque Server Version = 4.1.2, loglevel = 0
11/16/2012 16:43:42;0002;PBS_Server.1825;Svr;PBS_Server;Torque Server Version = 4.1.2, loglevel = 0
11/16/2012 16:44:54;0040;PBS_Server.12015;Svr;csg.bcmd.bcm.edu;Scheduler was sent the command time
11/16/2012 16:48:47;0002;PBS_Server.1835;Svr;PBS_Server;Torque Server Version = 4.1.2, loglevel = 0
11/16/2012 16:53:52;0002;PBS_Server.1832;Svr;PBS_Server;Torque Server Version = 4.1.2, loglevel = 0
11/16/2012 16:55:04;0040;PBS_Server.12122;Svr;csg.bcmd.bcm.edu;Scheduler was sent the command time
11/16/2012 16:58:57;0002;PBS_Server.1836;Svr;PBS_Server;Torque Server Version = 4.1.2, loglevel = 0
11/16/2012 17:04:02;0002;PBS_Server.1827;Svr;PBS_Server;Torque Server Version = 4.1.2, loglevel = 0
11/16/2012 17:05:14;0040;PBS_Server.12175;Svr;csg.bcmd.bcm.edu;Scheduler was sent the command time
11/16/2012 17:09:07;0002;PBS_Server.1831;Svr;PBS_Server;Torque Server Version = 4.1.2, loglevel = 0
11/16/2012 17:14:12;0002;PBS_Server.1826;Svr;PBS_Server;Torque Server Version = 4.1.2, loglevel = 0
11/16/2012 17:15:24;0040;PBS_Server.12190;Svr;csg.bcmd.bcm.edu;Scheduler was sent the command time
11/16/2012 17:19:17;0002;PBS_Server.1835;Svr;PBS_Server;Torque Server Version = 4.1.2, loglevel = 0
11/16/2012 17:24:22;0002;PBS_Server.1830;Svr;PBS_Server;Torque Server Version = 4.1.2, loglevel = 0
11/16/2012 17:25:34;0040;PBS_Server.12205;Svr;csg.bcmd.bcm.edu;Scheduler was sent the command time
11/16/2012 17:29:27;0002;PBS_Server.1830;Svr;PBS_Server;Torque Server Version = 4.1.2, loglevel = 0
11/16/2012 17:34:32;0002;PBS_Server.1828;Svr;PBS_Server;Torque Server Version = 4.1.2, loglevel = 0
11/16/2012 17:35:44;0040;PBS_Server.12219;Svr;csg.bcmd.bcm.edu;Scheduler was sent the command time
11/16/2012 17:39:37;0002;PBS_Server.1835;Svr;PBS_Server;Torque Server Version = 4.1.2, loglevel = 0
11/16/2012 17:44:42;0002;PBS_Server.1834;Svr;PBS_Server;Torque Server Version = 4.1.2, loglevel = 0
11/16/2012 17:45:54;0040;PBS_Server.12233;Svr;csg.bcmd.bcm.edu;Scheduler was sent the command time
11/16/2012 17:49:47;0002;PBS_Server.1832;Svr;PBS_Server;Torque Server Version = 4.1.2, loglevel = 0
11/16/2012 17:54:52;0002;PBS_Server.1837;Svr;PBS_Server;Torque Server Version = 4.1.2, loglevel = 0
11/16/2012 17:56:04;0040;PBS_Server.12247;Svr;csg.bcmd.bcm.edu;Scheduler was sent the command time
11/16/2012 17:59:57;0002;PBS_Server.1832;Svr;PBS_Server;Torque Server Version = 4.1.2, loglevel = 0
11/16/2012 18:05:02;0002;PBS_Server.1836;Svr;PBS_Server;Torque Server Version = 4.1.2, loglevel = 0
11/16/2012 18:06:14;0040;PBS_Server.12382;Svr;csg.bcmd.bcm.edu;Scheduler was sent the command time
11/16/2012 18:10:07;0002;PBS_Server.1825;Svr;PBS_Server;Torque Server Version = 4.1.2, loglevel = 0
11/16/2012 18:15:12;0002;PBS_Server.1837;Svr;PBS_Server;Torque Server Version = 4.1.2, loglevel = 0
11/16/2012 18:16:24;0040;PBS_Server.12478;Svr;csg.bcmd.bcm.edu;Scheduler was sent the command time
11/16/2012 18:20:17;0002;PBS_Server.1827;Svr;PBS_Server;Torque Server Version = 4.1.2, loglevel = 0
11/16/2012 18:25:22;0002;PBS_Server.1836;Svr;PBS_Server;Torque Server Version = 4.1.2, loglevel = 0
11/16/2012 18:26:34;0040;PBS_Server.12574;Svr;csg.bcmd.bcm.edu;Scheduler was sent the command time
11/16/2012 18:30:27;0002;PBS_Server.1828;Svr;PBS_Server;Torque Server Version = 4.1.2, loglevel = 0
11/16/2012 18:35:32;0002;PBS_Server.1835;Svr;PBS_Server;Torque Server Version = 4.1.2, loglevel = 0
11/16/2012 18:36:44;0040;PBS_Server.12668;Svr;csg.bcmd.bcm.edu;Scheduler was sent the command time
11/16/2012 18:40:37;0002;PBS_Server.1833;Svr;PBS_Server;Torque Server Version = 4.1.2, loglevel = 0
11/16/2012 18:45:42;0002;PBS_Server.1832;Svr;PBS_Server;Torque Server Version = 4.1.2, loglevel = 0
11/16/2012 18:46:54;0040;PBS_Server.12763;Svr;csg.bcmd.bcm.edu;Scheduler was sent the command time
11/16/2012 18:50:47;0002;PBS_Server.1827;Svr;PBS_Server;Torque Server Version = 4.1.2, loglevel = 0
11/16/2012 18:55:52;0002;PBS_Server.1834;Svr;PBS_Server;Torque Server Version = 4.1.2, loglevel = 0
11/16/2012 18:57:04;0040;PBS_Server.12864;Svr;csg.bcmd.bcm.edu;Scheduler was sent the command time
11/16/2012 19:00:57;0002;PBS_Server.1827;Svr;PBS_Server;Torque Server Version = 4.1.2, loglevel = 0
11/16/2012 19:06:02;0002;PBS_Server.1829;Svr;PBS_Server;Torque Server Version = 4.1.2, loglevel = 0
11/16/2012 19:07:14;0040;PBS_Server.12903;Svr;csg.bcmd.bcm.edu;Scheduler was sent the command time
11/16/2012 19:11:07;0002;PBS_Server.1834;Svr;PBS_Server;Torque Server Version = 4.1.2, loglevel = 0
11/16/2012 19:16:12;0002;PBS_Server.1834;Svr;PBS_Server;Torque Server Version = 4.1.2, loglevel = 0
11/16/2012 19:17:24;0040;PBS_Server.12917;Svr;csg.bcmd.bcm.edu;Scheduler was sent the command time
11/16/2012 19:21:17;0002;PBS_Server.1837;Svr;PBS_Server;Torque Server Version = 4.1.2, loglevel = 0
11/16/2012 19:26:22;0002;PBS_Server.1828;Svr;PBS_Server;Torque Server Version = 4.1.2, loglevel = 0
11/16/2012 19:27:34;0040;PBS_Server.12932;Svr;csg.bcmd.bcm.edu;Scheduler was sent the command time
11/16/2012 19:31:27;0002;PBS_Server.1837;Svr;PBS_Server;Torque Server Version = 4.1.2, loglevel = 0
11/16/2012 19:36:32;0002;PBS_Server.1834;Svr;PBS_Server;Torque Server Version = 4.1.2, loglevel = 0
11/16/2012 19:37:44;0040;PBS_Server.12945;Svr;csg.bcmd.bcm.edu;Scheduler was sent the command time
11/16/2012 19:41:37;0002;PBS_Server.1834;Svr;PBS_Server;Torque Server Version = 4.1.2, loglevel = 0
11/16/2012 19:46:42;0002;PBS_Server.1830;Svr;PBS_Server;Torque Server Version = 4.1.2, loglevel = 0
11/16/2012 19:47:54;0040;PBS_Server.12960;Svr;csg.bcmd.bcm.edu;Scheduler was sent the command time
11/16/2012 19:51:47;0002;PBS_Server.1826;Svr;PBS_Server;Torque Server Version = 4.1.2, loglevel = 0
11/16/2012 19:56:52;0002;PBS_Server.1828;Svr;PBS_Server;Torque Server Version = 4.1.2, loglevel = 0
11/16/2012 19:58:04;0040;PBS_Server.12975;Svr;csg.bcmd.bcm.edu;Scheduler was sent the command time
11/16/2012 20:01:57;0002;PBS_Server.1825;Svr;PBS_Server;Torque Server Version = 4.1.2, loglevel = 0
11/16/2012 20:07:02;0002;PBS_Server.1825;Svr;PBS_Server;Torque Server Version = 4.1.2, loglevel = 0
11/16/2012 20:08:14;0040;PBS_Server.13128;Svr;csg.bcmd.bcm.edu;Scheduler was sent the command time
11/16/2012 20:12:07;0002;PBS_Server.1826;Svr;PBS_Server;Torque Server Version = 4.1.2, loglevel = 0
11/16/2012 20:17:12;0002;PBS_Server.1836;Svr;PBS_Server;Torque Server Version = 4.1.2, loglevel = 0
11/16/2012 20:18:24;0040;PBS_Server.13222;Svr;csg.bcmd.bcm.edu;Scheduler was sent the command time
11/16/2012 20:22:17;0002;PBS_Server.1829;Svr;PBS_Server;Torque Server Version = 4.1.2, loglevel = 0
11/16/2012 20:27:22;0002;PBS_Server.1826;Svr;PBS_Server;Torque Server Version = 4.1.2, loglevel = 0
11/16/2012 20:28:34;0040;PBS_Server.13318;Svr;csg.bcmd.bcm.edu;Scheduler was sent the command time
11/16/2012 20:32:27;0002;PBS_Server.1826;Svr;PBS_Server;Torque Server Version = 4.1.2, loglevel = 0
11/16/2012 20:37:32;0002;PBS_Server.1827;Svr;PBS_Server;Torque Server Version = 4.1.2, loglevel = 0
11/16/2012 20:38:44;0040;PBS_Server.13414;Svr;csg.bcmd.bcm.edu;Scheduler was sent the command time
11/16/2012 20:42:37;0002;PBS_Server.1825;Svr;PBS_Server;Torque Server Version = 4.1.2, loglevel = 0
11/16/2012 20:47:42;0002;PBS_Server.1833;Svr;PBS_Server;Torque Server Version = 4.1.2, loglevel = 0
11/16/2012 20:48:54;0040;PBS_Server.13512;Svr;csg.bcmd.bcm.edu;Scheduler was sent the command time
11/16/2012 20:52:47;0002;PBS_Server.1828;Svr;PBS_Server;Torque Server Version = 4.1.2, loglevel = 0
11/16/2012 20:57:52;0002;PBS_Server.1829;Svr;PBS_Server;Torque Server Version = 4.1.2, loglevel = 0
11/16/2012 20:59:04;0040;PBS_Server.13613;Svr;csg.bcmd.bcm.edu;Scheduler was sent the command time
11/16/2012 21:02:57;0002;PBS_Server.1835;Svr;PBS_Server;Torque Server Version = 4.1.2, loglevel = 0
11/16/2012 21:08:02;0002;PBS_Server.1835;Svr;PBS_Server;Torque Server Version = 4.1.2, loglevel = 0
11/16/2012 21:09:14;0040;PBS_Server.13635;Svr;csg.bcmd.bcm.edu;Scheduler was sent the command time
11/16/2012 21:13:07;0002;PBS_Server.1826;Svr;PBS_Server;Torque Server Version = 4.1.2, loglevel = 0
11/16/2012 21:18:12;0002;PBS_Server.1825;Svr;PBS_Server;Torque Server Version = 4.1.2, loglevel = 0
11/16/2012 21:19:24;0040;PBS_Server.13649;Svr;csg.bcmd.bcm.edu;Scheduler was sent the command time
11/16/2012 21:23:17;0002;PBS_Server.1829;Svr;PBS_Server;Torque Server Version = 4.1.2, loglevel = 0
11/16/2012 21:28:22;0002;PBS_Server.1827;Svr;PBS_Server;Torque Server Version = 4.1.2, loglevel = 0
11/16/2012 21:29:34;0040;PBS_Server.13664;Svr;csg.bcmd.bcm.edu;Scheduler was sent the command time
11/16/2012 21:33:27;0002;PBS_Server.1833;Svr;PBS_Server;Torque Server Version = 4.1.2, loglevel = 0
11/16/2012 21:38:32;0002;PBS_Server.1826;Svr;PBS_Server;Torque Server Version = 4.1.2, loglevel = 0
11/16/2012 21:39:44;0040;PBS_Server.13678;Svr;csg.bcmd.bcm.edu;Scheduler was sent the command time
11/16/2012 21:43:37;0002;PBS_Server.1827;Svr;PBS_Server;Torque Server Version = 4.1.2, loglevel = 0
11/16/2012 21:48:42;0002;PBS_Server.1837;Svr;PBS_Server;Torque Server Version = 4.1.2, loglevel = 0
11/16/2012 21:49:54;0040;PBS_Server.13695;Svr;csg.bcmd.bcm.edu;Scheduler was sent the command time
11/16/2012 21:53:47;0002;PBS_Server.1835;Svr;PBS_Server;Torque Server Version = 4.1.2, loglevel = 0
11/16/2012 21:58:52;0002;PBS_Server.1833;Svr;PBS_Server;Torque Server Version = 4.1.2, loglevel = 0
11/16/2012 22:00:04;0040;PBS_Server.13723;Svr;csg.bcmd.bcm.edu;Scheduler was sent the command time
11/16/2012 22:03:57;0002;PBS_Server.1835;Svr;PBS_Server;Torque Server Version = 4.1.2, loglevel = 0
11/16/2012 22:06:05;000d;PBS_Server.1828;Job;505.csg.bcmd.bcm.edu;Not sending email: User does not want mail of this type.
11/16/2012 22:06:05;0010;PBS_Server.1828;Job;505.csg.bcmd.bcm.edu;Exit_status=1 resources_used.cput=47:12:45 resources_used.mem=1278048kb resources_used.vmem=5777168kb resources_used.walltime=06:12:04
11/16/2012 22:06:05;0008;PBS_Server.1832;Job;505.csg.bcmd.bcm.edu;on_job_exit valid pjob: 505.csg.bcmd.bcm.edu (substate=50)
11/16/2012 22:06:07;0040;PBS_Server.13853;Svr;csg.bcmd.bcm.edu;Scheduler was sent the command term
11/16/2012 22:08:58;0002;PBS_Server.1832;Svr;PBS_Server;Torque Server Version = 4.1.2, loglevel = 0
11/16/2012 22:11:12;0008;PBS_Server.1828;Job;505.csg.bcmd.bcm.edu;on_job_exit valid pjob: 505.csg.bcmd.bcm.edu (substate=59)
11/16/2012 22:11:12;0100;PBS_Server.1828;Job;505.csg.bcmd.bcm.edu;dequeuing from high, state COMPLETE
11/16/2012 22:11:17;0040;PBS_Server.13903;Svr;csg.bcmd.bcm.edu;Scheduler was sent the command term
11/16/2012 22:14:07;0002;PBS_Server.1832;Svr;PBS_Server;Torque Server Version = 4.1.2, loglevel = 0
11/16/2012 22:19:12;0002;PBS_Server.1835;Svr;PBS_Server;Torque Server Version = 4.1.2, loglevel = 0
11/16/2012 22:21:31;0040;PBS_Server.13997;Svr;csg.bcmd.bcm.edu;Scheduler was sent the command time
11/16/2012 22:24:17;0002;PBS_Server.1829;Svr;PBS_Server;Torque Server Version = 4.1.2, loglevel = 0
11/16/2012 22:29:22;0002;PBS_Server.1833;Svr;PBS_Server;Torque Server Version = 4.1.2, loglevel = 0
11/16/2012 22:31:41;0040;PBS_Server.14093;Svr;csg.bcmd.bcm.edu;Scheduler was sent the command time
11/16/2012 22:34:27;0002;PBS_Server.1831;Svr;PBS_Server;Torque Server Version = 4.1.2, loglevel = 0
11/16/2012 22:39:32;0002;PBS_Server.1830;Svr;PBS_Server;Torque Server Version = 4.1.2, loglevel = 0
11/16/2012 22:41:51;0040;PBS_Server.14186;Svr;csg.bcmd.bcm.edu;Scheduler was sent the command time
11/16/2012 22:44:37;0002;PBS_Server.1833;Svr;PBS_Server;Torque Server Version = 4.1.2, loglevel = 0
11/16/2012 22:49:42;0002;PBS_Server.1831;Svr;PBS_Server;Torque Server Version = 4.1.2, loglevel = 0
11/16/2012 22:52:01;0040;PBS_Server.14281;Svr;csg.bcmd.bcm.edu;Scheduler was sent the command time
11/16/2012 22:54:47;0002;PBS_Server.1835;Svr;PBS_Server;Torque Server Version = 4.1.2, loglevel = 0
11/16/2012 22:59:52;0002;PBS_Server.1834;Svr;PBS_Server;Torque Server Version = 4.1.2, loglevel = 0
11/16/2012 23:02:11;0040;PBS_Server.14365;Svr;csg.bcmd.bcm.edu;Scheduler was sent the command time
11/16/2012 23:04:57;0002;PBS_Server.1829;Svr;PBS_Server;Torque Server Version = 4.1.2, loglevel = 0
11/16/2012 23:10:02;0002;PBS_Server.1831;Svr;PBS_Server;Torque Server Version = 4.1.2, loglevel = 0
11/16/2012 23:12:21;0040;PBS_Server.14380;Svr;csg.bcmd.bcm.edu;Scheduler was sent the command time
11/16/2012 23:15:07;0002;PBS_Server.1836;Svr;PBS_Server;Torque Server Version = 4.1.2, loglevel = 0
11/16/2012 23:20:12;0002;PBS_Server.1835;Svr;PBS_Server;Torque Server Version = 4.1.2, loglevel = 0
11/16/2012 23:22:31;0040;PBS_Server.14394;Svr;csg.bcmd.bcm.edu;Scheduler was sent the command time
11/16/2012 23:25:17;0002;PBS_Server.1825;Svr;PBS_Server;Torque Server Version = 4.1.2, loglevel = 0
11/16/2012 23:30:22;0002;PBS_Server.1831;Svr;PBS_Server;Torque Server Version = 4.1.2, loglevel = 0
11/16/2012 23:32:41;0040;PBS_Server.14409;Svr;csg.bcmd.bcm.edu;Scheduler was sent the command time
11/16/2012 23:35:27;0002;PBS_Server.1837;Svr;PBS_Server;Torque Server Version = 4.1.2, loglevel = 0
11/16/2012 23:40:32;0002;PBS_Server.1837;Svr;PBS_Server;Torque Server Version = 4.1.2, loglevel = 0
11/16/2012 23:42:51;0040;PBS_Server.14424;Svr;csg.bcmd.bcm.edu;Scheduler was sent the command time
11/16/2012 23:45:37;0002;PBS_Server.1827;Svr;PBS_Server;Torque Server Version = 4.1.2, loglevel = 0
11/16/2012 23:50:42;0002;PBS_Server.1831;Svr;PBS_Server;Torque Server Version = 4.1.2, loglevel = 0
11/16/2012 23:53:01;0040;PBS_Server.14439;Svr;csg.bcmd.bcm.edu;Scheduler was sent the command time
11/16/2012 23:55:47;0002;PBS_Server.1835;Svr;PBS_Server;Torque Server Version = 4.1.2, loglevel = 0
11/17/2012 00:00:52;0002;PBS_Server.1827;Svr;Log;Log closed
