01/14/2013 00:01:12;0002;PBS_Server.1881;Svr;Log;Log opened
01/14/2013 00:01:12;0002;PBS_Server.1881;Svr;PBS_Server;Torque Server Version = 4.1.2, loglevel = 0
01/14/2013 00:06:11;0040;PBS_Server.15635;Svr;csg.bcmd.bcm.edu;Scheduler was sent the command time
01/14/2013 00:06:17;0002;PBS_Server.1886;Svr;PBS_Server;Torque Server Version = 4.1.2, loglevel = 0
01/14/2013 00:11:22;0002;PBS_Server.1882;Svr;PBS_Server;Torque Server Version = 4.1.2, loglevel = 0
01/14/2013 00:16:21;0040;PBS_Server.15651;Svr;csg.bcmd.bcm.edu;Scheduler was sent the command time
01/14/2013 00:16:27;0002;PBS_Server.1884;Svr;PBS_Server;Torque Server Version = 4.1.2, loglevel = 0
01/14/2013 00:21:32;0002;PBS_Server.1874;Svr;PBS_Server;Torque Server Version = 4.1.2, loglevel = 0
01/14/2013 00:26:31;0040;PBS_Server.15667;Svr;csg.bcmd.bcm.edu;Scheduler was sent the command time
01/14/2013 00:26:37;0002;PBS_Server.1882;Svr;PBS_Server;Torque Server Version = 4.1.2, loglevel = 0
01/14/2013 00:31:42;0002;PBS_Server.1880;Svr;PBS_Server;Torque Server Version = 4.1.2, loglevel = 0
01/14/2013 00:36:41;0040;PBS_Server.15681;Svr;csg.bcmd.bcm.edu;Scheduler was sent the command time
01/14/2013 00:36:47;0002;PBS_Server.1874;Svr;PBS_Server;Torque Server Version = 4.1.2, loglevel = 0
01/14/2013 00:41:52;0002;PBS_Server.1878;Svr;PBS_Server;Torque Server Version = 4.1.2, loglevel = 0
01/14/2013 00:46:51;0040;PBS_Server.15697;Svr;csg.bcmd.bcm.edu;Scheduler was sent the command time
01/14/2013 00:46:57;0002;PBS_Server.1882;Svr;PBS_Server;Torque Server Version = 4.1.2, loglevel = 0
01/14/2013 00:52:02;0002;PBS_Server.1885;Svr;PBS_Server;Torque Server Version = 4.1.2, loglevel = 0
01/14/2013 00:57:01;0040;PBS_Server.15710;Svr;csg.bcmd.bcm.edu;Scheduler was sent the command time
01/14/2013 00:57:07;0002;PBS_Server.1882;Svr;PBS_Server;Torque Server Version = 4.1.2, loglevel = 0
01/14/2013 01:02:12;0002;PBS_Server.1879;Svr;PBS_Server;Torque Server Version = 4.1.2, loglevel = 0
01/14/2013 01:07:11;0040;PBS_Server.15804;Svr;csg.bcmd.bcm.edu;Scheduler was sent the command time
01/14/2013 01:07:17;0002;PBS_Server.1880;Svr;PBS_Server;Torque Server Version = 4.1.2, loglevel = 0
01/14/2013 01:12:22;0002;PBS_Server.1881;Svr;PBS_Server;Torque Server Version = 4.1.2, loglevel = 0
01/14/2013 01:17:21;0040;PBS_Server.15909;Svr;csg.bcmd.bcm.edu;Scheduler was sent the command time
01/14/2013 01:17:27;0002;PBS_Server.1880;Svr;PBS_Server;Torque Server Version = 4.1.2, loglevel = 0
01/14/2013 01:22:32;0002;PBS_Server.1874;Svr;PBS_Server;Torque Server Version = 4.1.2, loglevel = 0
01/14/2013 01:27:31;0040;PBS_Server.16015;Svr;csg.bcmd.bcm.edu;Scheduler was sent the command time
01/14/2013 01:27:37;0002;PBS_Server.1876;Svr;PBS_Server;Torque Server Version = 4.1.2, loglevel = 0
01/14/2013 01:32:42;0002;PBS_Server.1881;Svr;PBS_Server;Torque Server Version = 4.1.2, loglevel = 0
01/14/2013 01:37:41;0040;PBS_Server.16118;Svr;csg.bcmd.bcm.edu;Scheduler was sent the command time
01/14/2013 01:37:47;0002;PBS_Server.1885;Svr;PBS_Server;Torque Server Version = 4.1.2, loglevel = 0
01/14/2013 01:42:52;0002;PBS_Server.1877;Svr;PBS_Server;Torque Server Version = 4.1.2, loglevel = 0
01/14/2013 01:47:51;0040;PBS_Server.16223;Svr;csg.bcmd.bcm.edu;Scheduler was sent the command time
01/14/2013 01:47:57;0002;PBS_Server.1882;Svr;PBS_Server;Torque Server Version = 4.1.2, loglevel = 0
01/14/2013 01:53:02;0002;PBS_Server.1884;Svr;PBS_Server;Torque Server Version = 4.1.2, loglevel = 0
01/14/2013 01:58:01;0040;PBS_Server.16326;Svr;csg.bcmd.bcm.edu;Scheduler was sent the command time
01/14/2013 01:58:07;0002;PBS_Server.1882;Svr;PBS_Server;Torque Server Version = 4.1.2, loglevel = 0
01/14/2013 02:03:12;0002;PBS_Server.1880;Svr;PBS_Server;Torque Server Version = 4.1.2, loglevel = 0
01/14/2013 02:08:11;0040;PBS_Server.16368;Svr;csg.bcmd.bcm.edu;Scheduler was sent the command time
01/14/2013 02:08:17;0002;PBS_Server.1879;Svr;PBS_Server;Torque Server Version = 4.1.2, loglevel = 0
01/14/2013 02:13:22;0002;PBS_Server.1874;Svr;PBS_Server;Torque Server Version = 4.1.2, loglevel = 0
01/14/2013 02:18:21;0040;PBS_Server.16382;Svr;csg.bcmd.bcm.edu;Scheduler was sent the command time
01/14/2013 02:18:27;0002;PBS_Server.1885;Svr;PBS_Server;Torque Server Version = 4.1.2, loglevel = 0
01/14/2013 02:23:32;0002;PBS_Server.1878;Svr;PBS_Server;Torque Server Version = 4.1.2, loglevel = 0
01/14/2013 02:28:31;0040;PBS_Server.16397;Svr;csg.bcmd.bcm.edu;Scheduler was sent the command time
01/14/2013 02:28:37;0002;PBS_Server.1885;Svr;PBS_Server;Torque Server Version = 4.1.2, loglevel = 0
01/14/2013 02:33:42;0002;PBS_Server.1882;Svr;PBS_Server;Torque Server Version = 4.1.2, loglevel = 0
01/14/2013 02:38:41;0040;PBS_Server.16411;Svr;csg.bcmd.bcm.edu;Scheduler was sent the command time
01/14/2013 02:38:47;0002;PBS_Server.1880;Svr;PBS_Server;Torque Server Version = 4.1.2, loglevel = 0
01/14/2013 02:43:52;0002;PBS_Server.1882;Svr;PBS_Server;Torque Server Version = 4.1.2, loglevel = 0
01/14/2013 02:48:51;0040;PBS_Server.16426;Svr;csg.bcmd.bcm.edu;Scheduler was sent the command time
01/14/2013 02:48:57;0002;PBS_Server.1883;Svr;PBS_Server;Torque Server Version = 4.1.2, loglevel = 0
01/14/2013 02:54:02;0002;PBS_Server.1876;Svr;PBS_Server;Torque Server Version = 4.1.2, loglevel = 0
01/14/2013 02:59:01;0040;PBS_Server.16441;Svr;csg.bcmd.bcm.edu;Scheduler was sent the command time
01/14/2013 02:59:07;0002;PBS_Server.1881;Svr;PBS_Server;Torque Server Version = 4.1.2, loglevel = 0
01/14/2013 03:04:12;0002;PBS_Server.1882;Svr;PBS_Server;Torque Server Version = 4.1.2, loglevel = 0
01/14/2013 03:09:11;0040;PBS_Server.16463;Svr;csg.bcmd.bcm.edu;Scheduler was sent the command time
01/14/2013 03:09:17;0002;PBS_Server.1884;Svr;PBS_Server;Torque Server Version = 4.1.2, loglevel = 0
01/14/2013 03:14:22;0002;PBS_Server.1874;Svr;PBS_Server;Torque Server Version = 4.1.2, loglevel = 0
01/14/2013 03:19:21;0040;PBS_Server.16476;Svr;csg.bcmd.bcm.edu;Scheduler was sent the command time
01/14/2013 03:19:27;0002;PBS_Server.1886;Svr;PBS_Server;Torque Server Version = 4.1.2, loglevel = 0
01/14/2013 03:24:32;0002;PBS_Server.1875;Svr;PBS_Server;Torque Server Version = 4.1.2, loglevel = 0
01/14/2013 03:29:31;0040;PBS_Server.16491;Svr;csg.bcmd.bcm.edu;Scheduler was sent the command time
01/14/2013 03:29:37;0002;PBS_Server.1886;Svr;PBS_Server;Torque Server Version = 4.1.2, loglevel = 0
01/14/2013 03:34:42;0002;PBS_Server.1881;Svr;PBS_Server;Torque Server Version = 4.1.2, loglevel = 0
01/14/2013 03:39:41;0040;PBS_Server.16517;Svr;csg.bcmd.bcm.edu;Scheduler was sent the command time
01/14/2013 03:39:47;0002;PBS_Server.1880;Svr;PBS_Server;Torque Server Version = 4.1.2, loglevel = 0
01/14/2013 03:44:52;0002;PBS_Server.1879;Svr;PBS_Server;Torque Server Version = 4.1.2, loglevel = 0
01/14/2013 03:49:51;0040;PBS_Server.16533;Svr;csg.bcmd.bcm.edu;Scheduler was sent the command time
01/14/2013 03:49:57;0002;PBS_Server.1874;Svr;PBS_Server;Torque Server Version = 4.1.2, loglevel = 0
01/14/2013 03:55:02;0002;PBS_Server.1876;Svr;PBS_Server;Torque Server Version = 4.1.2, loglevel = 0
01/14/2013 04:00:01;0040;PBS_Server.16547;Svr;csg.bcmd.bcm.edu;Scheduler was sent the command time
01/14/2013 04:00:07;0002;PBS_Server.1886;Svr;PBS_Server;Torque Server Version = 4.1.2, loglevel = 0
01/14/2013 04:05:12;0002;PBS_Server.1884;Svr;PBS_Server;Torque Server Version = 4.1.2, loglevel = 0
01/14/2013 04:10:11;0040;PBS_Server.16572;Svr;csg.bcmd.bcm.edu;Scheduler was sent the command time
01/14/2013 04:10:17;0002;PBS_Server.1883;Svr;PBS_Server;Torque Server Version = 4.1.2, loglevel = 0
01/14/2013 04:15:22;0002;PBS_Server.1878;Svr;PBS_Server;Torque Server Version = 4.1.2, loglevel = 0
01/14/2013 04:20:21;0040;PBS_Server.16585;Svr;csg.bcmd.bcm.edu;Scheduler was sent the command time
01/14/2013 04:20:27;0002;PBS_Server.1875;Svr;PBS_Server;Torque Server Version = 4.1.2, loglevel = 0
01/14/2013 04:25:32;0002;PBS_Server.1880;Svr;PBS_Server;Torque Server Version = 4.1.2, loglevel = 0
01/14/2013 04:30:31;0040;PBS_Server.16600;Svr;csg.bcmd.bcm.edu;Scheduler was sent the command time
01/14/2013 04:30:37;0002;PBS_Server.1876;Svr;PBS_Server;Torque Server Version = 4.1.2, loglevel = 0
01/14/2013 04:35:42;0002;PBS_Server.1874;Svr;PBS_Server;Torque Server Version = 4.1.2, loglevel = 0
01/14/2013 04:40:41;0040;PBS_Server.16617;Svr;csg.bcmd.bcm.edu;Scheduler was sent the command time
01/14/2013 04:40:47;0002;PBS_Server.1881;Svr;PBS_Server;Torque Server Version = 4.1.2, loglevel = 0
01/14/2013 04:45:52;0002;PBS_Server.1879;Svr;PBS_Server;Torque Server Version = 4.1.2, loglevel = 0
01/14/2013 04:50:51;0040;PBS_Server.16632;Svr;csg.bcmd.bcm.edu;Scheduler was sent the command time
01/14/2013 04:50:57;0002;PBS_Server.1877;Svr;PBS_Server;Torque Server Version = 4.1.2, loglevel = 0
01/14/2013 04:56:02;0002;PBS_Server.1875;Svr;PBS_Server;Torque Server Version = 4.1.2, loglevel = 0
01/14/2013 05:01:01;0040;PBS_Server.16651;Svr;csg.bcmd.bcm.edu;Scheduler was sent the command time
01/14/2013 05:01:07;0002;PBS_Server.1877;Svr;PBS_Server;Torque Server Version = 4.1.2, loglevel = 0
01/14/2013 05:06:12;0002;PBS_Server.1883;Svr;PBS_Server;Torque Server Version = 4.1.2, loglevel = 0
01/14/2013 05:11:11;0040;PBS_Server.16667;Svr;csg.bcmd.bcm.edu;Scheduler was sent the command time
01/14/2013 05:11:17;0002;PBS_Server.1878;Svr;PBS_Server;Torque Server Version = 4.1.2, loglevel = 0
01/14/2013 05:16:22;0002;PBS_Server.1879;Svr;PBS_Server;Torque Server Version = 4.1.2, loglevel = 0
01/14/2013 05:21:21;0040;PBS_Server.16681;Svr;csg.bcmd.bcm.edu;Scheduler was sent the command time
01/14/2013 05:21:27;0002;PBS_Server.1884;Svr;PBS_Server;Torque Server Version = 4.1.2, loglevel = 0
01/14/2013 05:26:32;0002;PBS_Server.1881;Svr;PBS_Server;Torque Server Version = 4.1.2, loglevel = 0
01/14/2013 05:31:31;0040;PBS_Server.16697;Svr;csg.bcmd.bcm.edu;Scheduler was sent the command time
01/14/2013 05:31:37;0002;PBS_Server.1880;Svr;PBS_Server;Torque Server Version = 4.1.2, loglevel = 0
01/14/2013 05:36:42;0002;PBS_Server.1884;Svr;PBS_Server;Torque Server Version = 4.1.2, loglevel = 0
01/14/2013 05:41:41;0040;PBS_Server.16710;Svr;csg.bcmd.bcm.edu;Scheduler was sent the command time
01/14/2013 05:41:47;0002;PBS_Server.1883;Svr;PBS_Server;Torque Server Version = 4.1.2, loglevel = 0
01/14/2013 05:46:52;0002;PBS_Server.1881;Svr;PBS_Server;Torque Server Version = 4.1.2, loglevel = 0
01/14/2013 05:51:51;0040;PBS_Server.16725;Svr;csg.bcmd.bcm.edu;Scheduler was sent the command time
01/14/2013 05:51:57;0002;PBS_Server.1886;Svr;PBS_Server;Torque Server Version = 4.1.2, loglevel = 0
01/14/2013 05:57:02;0002;PBS_Server.1878;Svr;PBS_Server;Torque Server Version = 4.1.2, loglevel = 0
01/14/2013 06:02:01;0040;PBS_Server.16744;Svr;csg.bcmd.bcm.edu;Scheduler was sent the command time
01/14/2013 06:02:07;0002;PBS_Server.1885;Svr;PBS_Server;Torque Server Version = 4.1.2, loglevel = 0
01/14/2013 06:07:12;0002;PBS_Server.1883;Svr;PBS_Server;Torque Server Version = 4.1.2, loglevel = 0
01/14/2013 06:12:11;0040;PBS_Server.16759;Svr;csg.bcmd.bcm.edu;Scheduler was sent the command time
01/14/2013 06:12:17;0002;PBS_Server.1874;Svr;PBS_Server;Torque Server Version = 4.1.2, loglevel = 0
01/14/2013 06:17:22;0002;PBS_Server.1884;Svr;PBS_Server;Torque Server Version = 4.1.2, loglevel = 0
01/14/2013 06:22:21;0040;PBS_Server.16774;Svr;csg.bcmd.bcm.edu;Scheduler was sent the command time
01/14/2013 06:22:27;0002;PBS_Server.1884;Svr;PBS_Server;Torque Server Version = 4.1.2, loglevel = 0
01/14/2013 06:27:32;0002;PBS_Server.1877;Svr;PBS_Server;Torque Server Version = 4.1.2, loglevel = 0
01/14/2013 06:32:31;0040;PBS_Server.16789;Svr;csg.bcmd.bcm.edu;Scheduler was sent the command time
01/14/2013 06:32:37;0002;PBS_Server.1884;Svr;PBS_Server;Torque Server Version = 4.1.2, loglevel = 0
01/14/2013 06:37:42;0002;PBS_Server.1886;Svr;PBS_Server;Torque Server Version = 4.1.2, loglevel = 0
01/14/2013 06:42:41;0040;PBS_Server.16802;Svr;csg.bcmd.bcm.edu;Scheduler was sent the command time
01/14/2013 06:42:47;0002;PBS_Server.1885;Svr;PBS_Server;Torque Server Version = 4.1.2, loglevel = 0
01/14/2013 06:47:52;0002;PBS_Server.1875;Svr;PBS_Server;Torque Server Version = 4.1.2, loglevel = 0
01/14/2013 06:52:51;0040;PBS_Server.16817;Svr;csg.bcmd.bcm.edu;Scheduler was sent the command time
01/14/2013 06:52:57;0002;PBS_Server.1883;Svr;PBS_Server;Torque Server Version = 4.1.2, loglevel = 0
01/14/2013 06:58:02;0002;PBS_Server.1878;Svr;PBS_Server;Torque Server Version = 4.1.2, loglevel = 0
01/14/2013 07:03:01;0040;PBS_Server.16836;Svr;csg.bcmd.bcm.edu;Scheduler was sent the command time
01/14/2013 07:03:07;0002;PBS_Server.1882;Svr;PBS_Server;Torque Server Version = 4.1.2, loglevel = 0
01/14/2013 07:08:12;0002;PBS_Server.1877;Svr;PBS_Server;Torque Server Version = 4.1.2, loglevel = 0
01/14/2013 07:13:11;0040;PBS_Server.16852;Svr;csg.bcmd.bcm.edu;Scheduler was sent the command time
01/14/2013 07:13:17;0002;PBS_Server.1874;Svr;PBS_Server;Torque Server Version = 4.1.2, loglevel = 0
01/14/2013 07:18:22;0002;PBS_Server.1882;Svr;PBS_Server;Torque Server Version = 4.1.2, loglevel = 0
01/14/2013 07:23:21;0040;PBS_Server.16865;Svr;csg.bcmd.bcm.edu;Scheduler was sent the command time
01/14/2013 07:23:27;0002;PBS_Server.1879;Svr;PBS_Server;Torque Server Version = 4.1.2, loglevel = 0
01/14/2013 07:28:32;0002;PBS_Server.1885;Svr;PBS_Server;Torque Server Version = 4.1.2, loglevel = 0
01/14/2013 07:33:31;0040;PBS_Server.16880;Svr;csg.bcmd.bcm.edu;Scheduler was sent the command time
01/14/2013 07:33:37;0002;PBS_Server.1875;Svr;PBS_Server;Torque Server Version = 4.1.2, loglevel = 0
01/14/2013 07:38:42;0002;PBS_Server.1879;Svr;PBS_Server;Torque Server Version = 4.1.2, loglevel = 0
01/14/2013 07:43:41;0040;PBS_Server.16894;Svr;csg.bcmd.bcm.edu;Scheduler was sent the command time
01/14/2013 07:43:47;0002;PBS_Server.1878;Svr;PBS_Server;Torque Server Version = 4.1.2, loglevel = 0
01/14/2013 07:48:52;0002;PBS_Server.1880;Svr;PBS_Server;Torque Server Version = 4.1.2, loglevel = 0
01/14/2013 07:53:51;0040;PBS_Server.16909;Svr;csg.bcmd.bcm.edu;Scheduler was sent the command time
01/14/2013 07:53:57;0002;PBS_Server.1879;Svr;PBS_Server;Torque Server Version = 4.1.2, loglevel = 0
01/14/2013 07:59:02;0002;PBS_Server.1884;Svr;PBS_Server;Torque Server Version = 4.1.2, loglevel = 0
01/14/2013 08:04:01;0040;PBS_Server.16929;Svr;csg.bcmd.bcm.edu;Scheduler was sent the command time
01/14/2013 08:04:07;0002;PBS_Server.1883;Svr;PBS_Server;Torque Server Version = 4.1.2, loglevel = 0
01/14/2013 08:09:12;0002;PBS_Server.1877;Svr;PBS_Server;Torque Server Version = 4.1.2, loglevel = 0
01/14/2013 08:14:11;0040;PBS_Server.16944;Svr;csg.bcmd.bcm.edu;Scheduler was sent the command time
01/14/2013 08:14:17;0002;PBS_Server.1882;Svr;PBS_Server;Torque Server Version = 4.1.2, loglevel = 0
01/14/2013 08:19:22;0002;PBS_Server.1883;Svr;PBS_Server;Torque Server Version = 4.1.2, loglevel = 0
01/14/2013 08:24:21;0040;PBS_Server.16957;Svr;csg.bcmd.bcm.edu;Scheduler was sent the command time
01/14/2013 08:24:27;0002;PBS_Server.1879;Svr;PBS_Server;Torque Server Version = 4.1.2, loglevel = 0
01/14/2013 08:29:32;0002;PBS_Server.1880;Svr;PBS_Server;Torque Server Version = 4.1.2, loglevel = 0
01/14/2013 08:34:31;0040;PBS_Server.16972;Svr;csg.bcmd.bcm.edu;Scheduler was sent the command time
01/14/2013 08:34:37;0002;PBS_Server.1879;Svr;PBS_Server;Torque Server Version = 4.1.2, loglevel = 0
01/14/2013 08:39:42;0002;PBS_Server.1878;Svr;PBS_Server;Torque Server Version = 4.1.2, loglevel = 0
01/14/2013 08:44:41;0040;PBS_Server.16986;Svr;csg.bcmd.bcm.edu;Scheduler was sent the command time
01/14/2013 08:44:47;0002;PBS_Server.1886;Svr;PBS_Server;Torque Server Version = 4.1.2, loglevel = 0
01/14/2013 08:49:52;0002;PBS_Server.1880;Svr;PBS_Server;Torque Server Version = 4.1.2, loglevel = 0
01/14/2013 08:54:51;0040;PBS_Server.17002;Svr;csg.bcmd.bcm.edu;Scheduler was sent the command time
01/14/2013 08:54:57;0002;PBS_Server.1886;Svr;PBS_Server;Torque Server Version = 4.1.2, loglevel = 0
01/14/2013 09:00:02;0002;PBS_Server.1883;Svr;PBS_Server;Torque Server Version = 4.1.2, loglevel = 0
01/14/2013 09:05:01;0040;PBS_Server.17031;Svr;csg.bcmd.bcm.edu;Scheduler was sent the command time
01/14/2013 09:05:07;0002;PBS_Server.1877;Svr;PBS_Server;Torque Server Version = 4.1.2, loglevel = 0
01/14/2013 09:10:12;0002;PBS_Server.1880;Svr;PBS_Server;Torque Server Version = 4.1.2, loglevel = 0
01/14/2013 09:15:11;0040;PBS_Server.17051;Svr;csg.bcmd.bcm.edu;Scheduler was sent the command time
01/14/2013 09:15:17;0002;PBS_Server.1881;Svr;PBS_Server;Torque Server Version = 4.1.2, loglevel = 0
01/14/2013 09:20:22;0002;PBS_Server.1875;Svr;PBS_Server;Torque Server Version = 4.1.2, loglevel = 0
01/14/2013 09:25:21;0040;PBS_Server.17066;Svr;csg.bcmd.bcm.edu;Scheduler was sent the command time
01/14/2013 09:25:27;0002;PBS_Server.1883;Svr;PBS_Server;Torque Server Version = 4.1.2, loglevel = 0
01/14/2013 09:30:32;0002;PBS_Server.1886;Svr;PBS_Server;Torque Server Version = 4.1.2, loglevel = 0
01/14/2013 09:35:31;0040;PBS_Server.17098;Svr;csg.bcmd.bcm.edu;Scheduler was sent the command time
01/14/2013 09:35:37;0002;PBS_Server.1883;Svr;PBS_Server;Torque Server Version = 4.1.2, loglevel = 0
01/14/2013 09:40:42;0002;PBS_Server.1886;Svr;PBS_Server;Torque Server Version = 4.1.2, loglevel = 0
01/14/2013 09:45:41;0040;PBS_Server.17113;Svr;csg.bcmd.bcm.edu;Scheduler was sent the command time
01/14/2013 09:45:47;0002;PBS_Server.1879;Svr;PBS_Server;Torque Server Version = 4.1.2, loglevel = 0
01/14/2013 09:50:52;0002;PBS_Server.1877;Svr;PBS_Server;Torque Server Version = 4.1.2, loglevel = 0
01/14/2013 09:55:51;0040;PBS_Server.17128;Svr;csg.bcmd.bcm.edu;Scheduler was sent the command time
01/14/2013 09:55:57;0002;PBS_Server.1875;Svr;PBS_Server;Torque Server Version = 4.1.2, loglevel = 0
01/14/2013 10:01:02;0002;PBS_Server.1875;Svr;PBS_Server;Torque Server Version = 4.1.2, loglevel = 0
01/14/2013 10:06:01;0040;PBS_Server.17146;Svr;csg.bcmd.bcm.edu;Scheduler was sent the command time
01/14/2013 10:06:07;0002;PBS_Server.1874;Svr;PBS_Server;Torque Server Version = 4.1.2, loglevel = 0
01/14/2013 10:11:12;0002;PBS_Server.1881;Svr;PBS_Server;Torque Server Version = 4.1.2, loglevel = 0
01/14/2013 10:16:11;0040;PBS_Server.17161;Svr;csg.bcmd.bcm.edu;Scheduler was sent the command time
01/14/2013 10:16:17;0002;PBS_Server.1879;Svr;PBS_Server;Torque Server Version = 4.1.2, loglevel = 0
01/14/2013 10:21:22;0002;PBS_Server.1886;Svr;PBS_Server;Torque Server Version = 4.1.2, loglevel = 0
01/14/2013 10:26:21;0040;PBS_Server.17175;Svr;csg.bcmd.bcm.edu;Scheduler was sent the command time
01/14/2013 10:26:27;0002;PBS_Server.1880;Svr;PBS_Server;Torque Server Version = 4.1.2, loglevel = 0
01/14/2013 10:31:32;0002;PBS_Server.1877;Svr;PBS_Server;Torque Server Version = 4.1.2, loglevel = 0
01/14/2013 10:36:31;0040;PBS_Server.17191;Svr;csg.bcmd.bcm.edu;Scheduler was sent the command time
01/14/2013 10:36:37;0002;PBS_Server.1876;Svr;PBS_Server;Torque Server Version = 4.1.2, loglevel = 0
01/14/2013 10:41:42;0002;PBS_Server.1875;Svr;PBS_Server;Torque Server Version = 4.1.2, loglevel = 0
01/14/2013 10:46:41;0040;PBS_Server.17206;Svr;csg.bcmd.bcm.edu;Scheduler was sent the command time
01/14/2013 10:46:47;0002;PBS_Server.1882;Svr;PBS_Server;Torque Server Version = 4.1.2, loglevel = 0
01/14/2013 10:51:52;0002;PBS_Server.1886;Svr;PBS_Server;Torque Server Version = 4.1.2, loglevel = 0
01/14/2013 10:56:51;0040;PBS_Server.17222;Svr;csg.bcmd.bcm.edu;Scheduler was sent the command time
01/14/2013 10:56:57;0002;PBS_Server.1875;Svr;PBS_Server;Torque Server Version = 4.1.2, loglevel = 0
01/14/2013 11:02:02;0002;PBS_Server.1874;Svr;PBS_Server;Torque Server Version = 4.1.2, loglevel = 0
01/14/2013 11:07:01;0040;PBS_Server.17241;Svr;csg.bcmd.bcm.edu;Scheduler was sent the command time
01/14/2013 11:07:07;0002;PBS_Server.1875;Svr;PBS_Server;Torque Server Version = 4.1.2, loglevel = 0
01/14/2013 11:12:12;0002;PBS_Server.1876;Svr;PBS_Server;Torque Server Version = 4.1.2, loglevel = 0
01/14/2013 11:17:11;0040;PBS_Server.17254;Svr;csg.bcmd.bcm.edu;Scheduler was sent the command time
01/14/2013 11:17:17;0002;PBS_Server.1884;Svr;PBS_Server;Torque Server Version = 4.1.2, loglevel = 0
01/14/2013 11:22:22;0002;PBS_Server.1877;Svr;PBS_Server;Torque Server Version = 4.1.2, loglevel = 0
01/14/2013 11:27:21;0040;PBS_Server.17268;Svr;csg.bcmd.bcm.edu;Scheduler was sent the command time
01/14/2013 11:27:27;0002;PBS_Server.1878;Svr;PBS_Server;Torque Server Version = 4.1.2, loglevel = 0
01/14/2013 11:32:32;0002;PBS_Server.1882;Svr;PBS_Server;Torque Server Version = 4.1.2, loglevel = 0
01/14/2013 11:37:31;0040;PBS_Server.17294;Svr;csg.bcmd.bcm.edu;Scheduler was sent the command time
01/14/2013 11:37:37;0002;PBS_Server.1878;Svr;PBS_Server;Torque Server Version = 4.1.2, loglevel = 0
01/14/2013 11:42:42;0002;PBS_Server.1875;Svr;PBS_Server;Torque Server Version = 4.1.2, loglevel = 0
01/14/2013 11:47:41;0040;PBS_Server.17343;Svr;csg.bcmd.bcm.edu;Scheduler was sent the command time
01/14/2013 11:47:47;0002;PBS_Server.1879;Svr;PBS_Server;Torque Server Version = 4.1.2, loglevel = 0
01/14/2013 11:52:52;0002;PBS_Server.1886;Svr;PBS_Server;Torque Server Version = 4.1.2, loglevel = 0
01/14/2013 11:57:51;0040;PBS_Server.17395;Svr;csg.bcmd.bcm.edu;Scheduler was sent the command time
01/14/2013 11:57:57;0002;PBS_Server.1876;Svr;PBS_Server;Torque Server Version = 4.1.2, loglevel = 0
01/14/2013 12:03:02;0002;PBS_Server.1883;Svr;PBS_Server;Torque Server Version = 4.1.2, loglevel = 0
01/14/2013 12:08:01;0040;PBS_Server.17475;Svr;csg.bcmd.bcm.edu;Scheduler was sent the command time
01/14/2013 12:08:07;0002;PBS_Server.1874;Svr;PBS_Server;Torque Server Version = 4.1.2, loglevel = 0
01/14/2013 12:13:12;0002;PBS_Server.1886;Svr;PBS_Server;Torque Server Version = 4.1.2, loglevel = 0
01/14/2013 12:18:11;0040;PBS_Server.17555;Svr;csg.bcmd.bcm.edu;Scheduler was sent the command time
01/14/2013 12:18:17;0002;PBS_Server.1882;Svr;PBS_Server;Torque Server Version = 4.1.2, loglevel = 0
01/14/2013 12:23:22;0002;PBS_Server.1877;Svr;PBS_Server;Torque Server Version = 4.1.2, loglevel = 0
01/14/2013 12:28:21;0040;PBS_Server.17636;Svr;csg.bcmd.bcm.edu;Scheduler was sent the command time
01/14/2013 12:28:27;0002;PBS_Server.1884;Svr;PBS_Server;Torque Server Version = 4.1.2, loglevel = 0
01/14/2013 12:33:32;0002;PBS_Server.1879;Svr;PBS_Server;Torque Server Version = 4.1.2, loglevel = 0
01/14/2013 12:37:03;0100;PBS_Server.1877;Job;928.csg.bcmd.bcm.edu;enqueuing into batch, state 1 hop 1
01/14/2013 12:37:03;0002;PBS_Server.1877;Svr;Act;Account file /var/spool/torque/server_priv/accounting/20130114 opened
01/14/2013 12:37:03;0008;PBS_Server.1877;Job;928.csg.bcmd.bcm.edu;Job Queued at request of hooker@csg.bcmd.bcm.edu, owner = hooker@csg.bcmd.bcm.edu, job name = jobname1, queue = batch
01/14/2013 12:37:03;0100;PBS_Server.1886;Job;929.csg.bcmd.bcm.edu;enqueuing into batch, state 1 hop 1
01/14/2013 12:37:03;0008;PBS_Server.1886;Job;929.csg.bcmd.bcm.edu;Job Queued at request of hooker@csg.bcmd.bcm.edu, owner = hooker@csg.bcmd.bcm.edu, job name = jobname2, queue = batch
01/14/2013 12:37:08;0040;PBS_Server.17676;Svr;csg.bcmd.bcm.edu;Scheduler was sent the command new
01/14/2013 12:37:08;0008;PBS_Server.1885;Job;928.csg.bcmd.bcm.edu;Job Run at request of root@csg.bcmd.bcm.edu
01/14/2013 12:37:08;000d;PBS_Server.1885;Job;928.csg.bcmd.bcm.edu;Not sending email: User does not want mail of this type.
01/14/2013 12:37:08;0008;PBS_Server.1885;Job;929.csg.bcmd.bcm.edu;Job Run at request of root@csg.bcmd.bcm.edu
01/14/2013 12:37:08;000d;PBS_Server.1885;Job;929.csg.bcmd.bcm.edu;Not sending email: User does not want mail of this type.
01/14/2013 12:37:10;000d;PBS_Server.1880;Job;928.csg.bcmd.bcm.edu;Not sending email: User does not want mail of this type.
01/14/2013 12:37:10;0010;PBS_Server.1880;Job;928.csg.bcmd.bcm.edu;Exit_status=1 resources_used.cput=00:00:00 resources_used.mem=0kb resources_used.vmem=0kb resources_used.walltime=00:00:02
01/14/2013 12:37:10;0008;PBS_Server.1886;Job;928.csg.bcmd.bcm.edu;on_job_exit valid pjob: 928.csg.bcmd.bcm.edu (substate=50)
01/14/2013 12:37:10;000d;PBS_Server.1874;Job;929.csg.bcmd.bcm.edu;Not sending email: User does not want mail of this type.
01/14/2013 12:37:10;0010;PBS_Server.1874;Job;929.csg.bcmd.bcm.edu;Exit_status=1 resources_used.cput=00:00:00 resources_used.mem=2928kb resources_used.vmem=31584kb resources_used.walltime=00:00:02
01/14/2013 12:37:10;0008;PBS_Server.1883;Job;929.csg.bcmd.bcm.edu;on_job_exit valid pjob: 929.csg.bcmd.bcm.edu (substate=50)
01/14/2013 12:37:13;0040;PBS_Server.17693;Svr;csg.bcmd.bcm.edu;Scheduler was sent the command term
01/14/2013 12:38:38;0002;PBS_Server.1877;Svr;PBS_Server;Torque Server Version = 4.1.2, loglevel = 0
01/14/2013 12:39:45;0100;PBS_Server.1874;Job;930.csg.bcmd.bcm.edu;enqueuing into batch, state 1 hop 1
01/14/2013 12:39:45;0008;PBS_Server.1874;Job;930.csg.bcmd.bcm.edu;Job Queued at request of hooker@csg.bcmd.bcm.edu, owner = hooker@csg.bcmd.bcm.edu, job name = jobname1, queue = batch
01/14/2013 12:39:46;0100;PBS_Server.1879;Job;931.csg.bcmd.bcm.edu;enqueuing into batch, state 1 hop 1
01/14/2013 12:39:46;0008;PBS_Server.1879;Job;931.csg.bcmd.bcm.edu;Job Queued at request of hooker@csg.bcmd.bcm.edu, owner = hooker@csg.bcmd.bcm.edu, job name = jobname2, queue = batch
01/14/2013 12:39:48;0040;PBS_Server.17712;Svr;csg.bcmd.bcm.edu;Scheduler was sent the command new
01/14/2013 12:39:48;0008;PBS_Server.1885;Job;930.csg.bcmd.bcm.edu;Job Run at request of root@csg.bcmd.bcm.edu
01/14/2013 12:39:48;000d;PBS_Server.1885;Job;930.csg.bcmd.bcm.edu;Not sending email: User does not want mail of this type.
01/14/2013 12:39:48;0008;PBS_Server.1885;Job;931.csg.bcmd.bcm.edu;Job Run at request of root@csg.bcmd.bcm.edu
01/14/2013 12:39:48;000d;PBS_Server.1885;Job;931.csg.bcmd.bcm.edu;Not sending email: User does not want mail of this type.
01/14/2013 12:39:49;000d;PBS_Server.1884;Job;930.csg.bcmd.bcm.edu;Not sending email: User does not want mail of this type.
01/14/2013 12:39:49;0010;PBS_Server.1884;Job;930.csg.bcmd.bcm.edu;Exit_status=1 resources_used.cput=00:00:00 resources_used.mem=0kb resources_used.vmem=0kb resources_used.walltime=00:00:01
01/14/2013 12:39:49;0008;PBS_Server.1882;Job;930.csg.bcmd.bcm.edu;on_job_exit valid pjob: 930.csg.bcmd.bcm.edu (substate=50)
01/14/2013 12:39:49;000d;PBS_Server.1877;Job;931.csg.bcmd.bcm.edu;Not sending email: User does not want mail of this type.
01/14/2013 12:39:49;0010;PBS_Server.1877;Job;931.csg.bcmd.bcm.edu;Exit_status=1 resources_used.cput=00:00:00 resources_used.mem=0kb resources_used.vmem=0kb resources_used.walltime=00:00:01
01/14/2013 12:39:49;0008;PBS_Server.1880;Job;931.csg.bcmd.bcm.edu;on_job_exit valid pjob: 931.csg.bcmd.bcm.edu (substate=50)
01/14/2013 12:39:53;0040;PBS_Server.17729;Svr;csg.bcmd.bcm.edu;Scheduler was sent the command term
01/14/2013 12:41:27;0100;PBS_Server.1875;Job;932.csg.bcmd.bcm.edu;enqueuing into batch, state 1 hop 1
01/14/2013 12:41:27;0008;PBS_Server.1875;Job;932.csg.bcmd.bcm.edu;Job Queued at request of hooker@csg.bcmd.bcm.edu, owner = hooker@csg.bcmd.bcm.edu, job name = jobname1, queue = batch
01/14/2013 12:41:27;0100;PBS_Server.1881;Job;933.csg.bcmd.bcm.edu;enqueuing into batch, state 1 hop 1
01/14/2013 12:41:27;0008;PBS_Server.1881;Job;933.csg.bcmd.bcm.edu;Job Queued at request of hooker@csg.bcmd.bcm.edu, owner = hooker@csg.bcmd.bcm.edu, job name = jobname2, queue = batch
01/14/2013 12:41:28;0040;PBS_Server.17766;Svr;csg.bcmd.bcm.edu;Scheduler was sent the command new
01/14/2013 12:41:29;0008;PBS_Server.1885;Job;932.csg.bcmd.bcm.edu;Job Run at request of root@csg.bcmd.bcm.edu
01/14/2013 12:41:29;000d;PBS_Server.1885;Job;932.csg.bcmd.bcm.edu;Not sending email: User does not want mail of this type.
01/14/2013 12:41:29;0008;PBS_Server.1885;Job;933.csg.bcmd.bcm.edu;Job Run at request of root@csg.bcmd.bcm.edu
01/14/2013 12:41:29;000d;PBS_Server.1885;Job;933.csg.bcmd.bcm.edu;Not sending email: User does not want mail of this type.
01/14/2013 12:41:43;000d;PBS_Server.1874;Job;932.csg.bcmd.bcm.edu;Not sending email: User does not want mail of this type.
01/14/2013 12:41:43;0010;PBS_Server.1874;Job;932.csg.bcmd.bcm.edu;Exit_status=0 resources_used.cput=00:00:09 resources_used.mem=37964kb resources_used.vmem=286864kb resources_used.walltime=00:00:14
01/14/2013 12:41:43;0008;PBS_Server.1886;Job;932.csg.bcmd.bcm.edu;on_job_exit valid pjob: 932.csg.bcmd.bcm.edu (substate=50)
01/14/2013 12:41:46;000d;PBS_Server.1883;Job;933.csg.bcmd.bcm.edu;Not sending email: User does not want mail of this type.
01/14/2013 12:41:46;0010;PBS_Server.1883;Job;933.csg.bcmd.bcm.edu;Exit_status=0 resources_used.cput=00:00:09 resources_used.mem=43260kb resources_used.vmem=291884kb resources_used.walltime=00:00:17
01/14/2013 12:41:46;0008;PBS_Server.1884;Job;933.csg.bcmd.bcm.edu;on_job_exit valid pjob: 933.csg.bcmd.bcm.edu (substate=50)
01/14/2013 12:41:48;0040;PBS_Server.17786;Svr;csg.bcmd.bcm.edu;Scheduler was sent the command term
01/14/2013 12:42:23;0008;PBS_Server.1884;Job;928.csg.bcmd.bcm.edu;on_job_exit valid pjob: 928.csg.bcmd.bcm.edu (substate=59)
01/14/2013 12:42:23;0008;PBS_Server.1877;Job;929.csg.bcmd.bcm.edu;on_job_exit valid pjob: 929.csg.bcmd.bcm.edu (substate=59)
01/14/2013 12:42:23;0100;PBS_Server.1884;Job;928.csg.bcmd.bcm.edu;dequeuing from batch, state COMPLETE
01/14/2013 12:42:23;0100;PBS_Server.1877;Job;929.csg.bcmd.bcm.edu;dequeuing from batch, state COMPLETE
01/14/2013 12:42:28;0040;PBS_Server.17797;Svr;csg.bcmd.bcm.edu;Scheduler was sent the command term
01/14/2013 12:43:38;0002;PBS_Server.1874;Svr;PBS_Server;Torque Server Version = 4.1.2, loglevel = 0
01/14/2013 12:44:49;0008;PBS_Server.1875;Job;931.csg.bcmd.bcm.edu;on_job_exit valid pjob: 931.csg.bcmd.bcm.edu (substate=59)
01/14/2013 12:44:49;0100;PBS_Server.1875;Job;931.csg.bcmd.bcm.edu;dequeuing from batch, state COMPLETE
01/14/2013 12:44:54;0040;PBS_Server.17821;Svr;csg.bcmd.bcm.edu;Scheduler was sent the command term
01/14/2013 12:45:04;0008;PBS_Server.1880;Job;930.csg.bcmd.bcm.edu;on_job_exit valid pjob: 930.csg.bcmd.bcm.edu (substate=59)
01/14/2013 12:45:04;0100;PBS_Server.1880;Job;930.csg.bcmd.bcm.edu;dequeuing from batch, state COMPLETE
01/14/2013 12:45:09;0040;PBS_Server.17826;Svr;csg.bcmd.bcm.edu;Scheduler was sent the command term
01/14/2013 12:46:49;0008;PBS_Server.1883;Job;932.csg.bcmd.bcm.edu;on_job_exit valid pjob: 932.csg.bcmd.bcm.edu (substate=59)
01/14/2013 12:46:49;0008;PBS_Server.1884;Job;933.csg.bcmd.bcm.edu;on_job_exit valid pjob: 933.csg.bcmd.bcm.edu (substate=59)
01/14/2013 12:46:49;0100;PBS_Server.1883;Job;932.csg.bcmd.bcm.edu;dequeuing from batch, state COMPLETE
01/14/2013 12:46:49;0100;PBS_Server.1884;Job;933.csg.bcmd.bcm.edu;dequeuing from batch, state COMPLETE
01/14/2013 12:46:54;0040;PBS_Server.17874;Svr;csg.bcmd.bcm.edu;Scheduler was sent the command term
01/14/2013 12:48:49;0002;PBS_Server.1878;Svr;PBS_Server;Torque Server Version = 4.1.2, loglevel = 0
01/14/2013 12:53:49;0002;PBS_Server.1877;Svr;PBS_Server;Torque Server Version = 4.1.2, loglevel = 0
01/14/2013 12:57:10;0040;PBS_Server.17906;Svr;csg.bcmd.bcm.edu;Scheduler was sent the command time
01/14/2013 12:58:50;0002;PBS_Server.1882;Svr;PBS_Server;Torque Server Version = 4.1.2, loglevel = 0
01/14/2013 13:03:59;0002;PBS_Server.1883;Svr;PBS_Server;Torque Server Version = 4.1.2, loglevel = 0
01/14/2013 13:07:25;0040;PBS_Server.18024;Svr;csg.bcmd.bcm.edu;Scheduler was sent the command time
01/14/2013 13:09:04;0002;PBS_Server.1875;Svr;PBS_Server;Torque Server Version = 4.1.2, loglevel = 0
01/14/2013 13:14:09;0002;PBS_Server.1885;Svr;PBS_Server;Torque Server Version = 4.1.2, loglevel = 0
01/14/2013 13:17:35;0040;PBS_Server.18131;Svr;csg.bcmd.bcm.edu;Scheduler was sent the command time
01/14/2013 13:19:14;0002;PBS_Server.1878;Svr;PBS_Server;Torque Server Version = 4.1.2, loglevel = 0
01/14/2013 13:24:19;0002;PBS_Server.1876;Svr;PBS_Server;Torque Server Version = 4.1.2, loglevel = 0
01/14/2013 13:27:45;0040;PBS_Server.18245;Svr;csg.bcmd.bcm.edu;Scheduler was sent the command time
01/14/2013 13:29:24;0002;PBS_Server.1874;Svr;PBS_Server;Torque Server Version = 4.1.2, loglevel = 0
01/14/2013 13:34:29;0002;PBS_Server.1880;Svr;PBS_Server;Torque Server Version = 4.1.2, loglevel = 0
01/14/2013 13:37:55;0040;PBS_Server.18410;Svr;csg.bcmd.bcm.edu;Scheduler was sent the command time
01/14/2013 13:39:34;0002;PBS_Server.1883;Svr;PBS_Server;Torque Server Version = 4.1.2, loglevel = 0
01/14/2013 13:44:39;0002;PBS_Server.1875;Svr;PBS_Server;Torque Server Version = 4.1.2, loglevel = 0
01/14/2013 13:48:05;0040;PBS_Server.18651;Svr;csg.bcmd.bcm.edu;Scheduler was sent the command time
01/14/2013 13:49:44;0002;PBS_Server.1885;Svr;PBS_Server;Torque Server Version = 4.1.2, loglevel = 0
01/14/2013 13:54:49;0002;PBS_Server.1877;Svr;PBS_Server;Torque Server Version = 4.1.2, loglevel = 0
01/14/2013 13:58:15;0040;PBS_Server.18809;Svr;csg.bcmd.bcm.edu;Scheduler was sent the command time
01/14/2013 13:59:54;0002;PBS_Server.1884;Svr;PBS_Server;Torque Server Version = 4.1.2, loglevel = 0
01/14/2013 14:04:59;0002;PBS_Server.1886;Svr;PBS_Server;Torque Server Version = 4.1.2, loglevel = 0
01/14/2013 14:08:25;0040;PBS_Server.18857;Svr;csg.bcmd.bcm.edu;Scheduler was sent the command time
01/14/2013 14:10:04;0002;PBS_Server.1882;Svr;PBS_Server;Torque Server Version = 4.1.2, loglevel = 0
01/14/2013 14:15:09;0002;PBS_Server.1879;Svr;PBS_Server;Torque Server Version = 4.1.2, loglevel = 0
01/14/2013 14:18:35;0040;PBS_Server.18873;Svr;csg.bcmd.bcm.edu;Scheduler was sent the command time
01/14/2013 14:20:14;0002;PBS_Server.1880;Svr;PBS_Server;Torque Server Version = 4.1.2, loglevel = 0
01/14/2013 14:25:19;0002;PBS_Server.1884;Svr;PBS_Server;Torque Server Version = 4.1.2, loglevel = 0
01/14/2013 14:28:45;0040;PBS_Server.18887;Svr;csg.bcmd.bcm.edu;Scheduler was sent the command time
01/14/2013 14:30:24;0002;PBS_Server.1886;Svr;PBS_Server;Torque Server Version = 4.1.2, loglevel = 0
01/14/2013 14:35:29;0002;PBS_Server.1881;Svr;PBS_Server;Torque Server Version = 4.1.2, loglevel = 0
01/14/2013 14:38:55;0040;PBS_Server.18915;Svr;csg.bcmd.bcm.edu;Scheduler was sent the command time
01/14/2013 14:40:34;0002;PBS_Server.1885;Svr;PBS_Server;Torque Server Version = 4.1.2, loglevel = 0
01/14/2013 14:45:39;0002;PBS_Server.1884;Svr;PBS_Server;Torque Server Version = 4.1.2, loglevel = 0
01/14/2013 14:49:05;0040;PBS_Server.18937;Svr;csg.bcmd.bcm.edu;Scheduler was sent the command time
01/14/2013 14:50:44;0002;PBS_Server.1876;Svr;PBS_Server;Torque Server Version = 4.1.2, loglevel = 0
01/14/2013 14:55:49;0002;PBS_Server.1882;Svr;PBS_Server;Torque Server Version = 4.1.2, loglevel = 0
01/14/2013 14:59:15;0040;PBS_Server.18955;Svr;csg.bcmd.bcm.edu;Scheduler was sent the command time
01/14/2013 15:00:54;0002;PBS_Server.1875;Svr;PBS_Server;Torque Server Version = 4.1.2, loglevel = 0
01/14/2013 15:05:59;0002;PBS_Server.1879;Svr;PBS_Server;Torque Server Version = 4.1.2, loglevel = 0
01/14/2013 15:09:25;0040;PBS_Server.18971;Svr;csg.bcmd.bcm.edu;Scheduler was sent the command time
01/14/2013 15:11:04;0002;PBS_Server.1874;Svr;PBS_Server;Torque Server Version = 4.1.2, loglevel = 0
01/14/2013 15:16:09;0002;PBS_Server.1874;Svr;PBS_Server;Torque Server Version = 4.1.2, loglevel = 0
01/14/2013 15:19:35;0040;PBS_Server.18992;Svr;csg.bcmd.bcm.edu;Scheduler was sent the command time
01/14/2013 15:21:14;0002;PBS_Server.1883;Svr;PBS_Server;Torque Server Version = 4.1.2, loglevel = 0
01/14/2013 15:26:19;0002;PBS_Server.1878;Svr;PBS_Server;Torque Server Version = 4.1.2, loglevel = 0
01/14/2013 15:29:45;0040;PBS_Server.19040;Svr;csg.bcmd.bcm.edu;Scheduler was sent the command time
01/14/2013 15:31:24;0002;PBS_Server.1881;Svr;PBS_Server;Torque Server Version = 4.1.2, loglevel = 0
01/14/2013 15:36:29;0002;PBS_Server.1885;Svr;PBS_Server;Torque Server Version = 4.1.2, loglevel = 0
01/14/2013 15:39:55;0040;PBS_Server.19061;Svr;csg.bcmd.bcm.edu;Scheduler was sent the command time
01/14/2013 15:41:34;0002;PBS_Server.1881;Svr;PBS_Server;Torque Server Version = 4.1.2, loglevel = 0
01/14/2013 15:46:39;0002;PBS_Server.1874;Svr;PBS_Server;Torque Server Version = 4.1.2, loglevel = 0
01/14/2013 15:50:05;0040;PBS_Server.19077;Svr;csg.bcmd.bcm.edu;Scheduler was sent the command time
01/14/2013 15:51:44;0002;PBS_Server.1884;Svr;PBS_Server;Torque Server Version = 4.1.2, loglevel = 0
01/14/2013 15:56:49;0002;PBS_Server.1880;Svr;PBS_Server;Torque Server Version = 4.1.2, loglevel = 0
01/14/2013 16:00:15;0040;PBS_Server.19099;Svr;csg.bcmd.bcm.edu;Scheduler was sent the command time
01/14/2013 16:01:54;0002;PBS_Server.1882;Svr;PBS_Server;Torque Server Version = 4.1.2, loglevel = 0
01/14/2013 16:06:59;0002;PBS_Server.1883;Svr;PBS_Server;Torque Server Version = 4.1.2, loglevel = 0
01/14/2013 16:10:25;0040;PBS_Server.19117;Svr;csg.bcmd.bcm.edu;Scheduler was sent the command time
01/14/2013 16:12:04;0002;PBS_Server.1877;Svr;PBS_Server;Torque Server Version = 4.1.2, loglevel = 0
01/14/2013 16:17:09;0002;PBS_Server.1881;Svr;PBS_Server;Torque Server Version = 4.1.2, loglevel = 0
01/14/2013 16:20:35;0040;PBS_Server.19155;Svr;csg.bcmd.bcm.edu;Scheduler was sent the command time
01/14/2013 16:22:14;0002;PBS_Server.1885;Svr;PBS_Server;Torque Server Version = 4.1.2, loglevel = 0
01/14/2013 16:27:19;0002;PBS_Server.1881;Svr;PBS_Server;Torque Server Version = 4.1.2, loglevel = 0
01/14/2013 16:30:45;0040;PBS_Server.19213;Svr;csg.bcmd.bcm.edu;Scheduler was sent the command time
01/14/2013 16:32:24;0002;PBS_Server.1875;Svr;PBS_Server;Torque Server Version = 4.1.2, loglevel = 0
01/14/2013 16:37:29;0002;PBS_Server.1878;Svr;PBS_Server;Torque Server Version = 4.1.2, loglevel = 0
01/14/2013 16:40:55;0040;PBS_Server.19281;Svr;csg.bcmd.bcm.edu;Scheduler was sent the command time
01/14/2013 16:42:34;0002;PBS_Server.1876;Svr;PBS_Server;Torque Server Version = 4.1.2, loglevel = 0
01/14/2013 16:47:39;0002;PBS_Server.1878;Svr;PBS_Server;Torque Server Version = 4.1.2, loglevel = 0
01/14/2013 16:51:05;0040;PBS_Server.19297;Svr;csg.bcmd.bcm.edu;Scheduler was sent the command time
01/14/2013 16:52:44;0002;PBS_Server.1884;Svr;PBS_Server;Torque Server Version = 4.1.2, loglevel = 0
01/14/2013 16:57:49;0002;PBS_Server.1877;Svr;PBS_Server;Torque Server Version = 4.1.2, loglevel = 0
01/14/2013 17:01:15;0040;PBS_Server.19324;Svr;csg.bcmd.bcm.edu;Scheduler was sent the command time
01/14/2013 17:02:54;0002;PBS_Server.1881;Svr;PBS_Server;Torque Server Version = 4.1.2, loglevel = 0
01/14/2013 17:07:59;0002;PBS_Server.1875;Svr;PBS_Server;Torque Server Version = 4.1.2, loglevel = 0
01/14/2013 17:11:25;0040;PBS_Server.19356;Svr;csg.bcmd.bcm.edu;Scheduler was sent the command time
01/14/2013 17:13:04;0002;PBS_Server.1884;Svr;PBS_Server;Torque Server Version = 4.1.2, loglevel = 0
01/14/2013 17:18:09;0002;PBS_Server.1886;Svr;PBS_Server;Torque Server Version = 4.1.2, loglevel = 0
01/14/2013 17:21:35;0040;PBS_Server.19381;Svr;csg.bcmd.bcm.edu;Scheduler was sent the command time
01/14/2013 17:23:14;0002;PBS_Server.1875;Svr;PBS_Server;Torque Server Version = 4.1.2, loglevel = 0
01/14/2013 17:28:19;0002;PBS_Server.1879;Svr;PBS_Server;Torque Server Version = 4.1.2, loglevel = 0
01/14/2013 17:31:45;0040;PBS_Server.19400;Svr;csg.bcmd.bcm.edu;Scheduler was sent the command time
01/14/2013 17:33:24;0002;PBS_Server.1878;Svr;PBS_Server;Torque Server Version = 4.1.2, loglevel = 0
01/14/2013 17:38:29;0002;PBS_Server.1880;Svr;PBS_Server;Torque Server Version = 4.1.2, loglevel = 0
01/14/2013 17:41:55;0040;PBS_Server.19415;Svr;csg.bcmd.bcm.edu;Scheduler was sent the command time
01/14/2013 17:43:34;0002;PBS_Server.1881;Svr;PBS_Server;Torque Server Version = 4.1.2, loglevel = 0
01/14/2013 17:48:39;0002;PBS_Server.1883;Svr;PBS_Server;Torque Server Version = 4.1.2, loglevel = 0
01/14/2013 17:52:05;0040;PBS_Server.19428;Svr;csg.bcmd.bcm.edu;Scheduler was sent the command time
01/14/2013 17:53:44;0002;PBS_Server.1886;Svr;PBS_Server;Torque Server Version = 4.1.2, loglevel = 0
01/14/2013 17:58:49;0002;PBS_Server.1877;Svr;PBS_Server;Torque Server Version = 4.1.2, loglevel = 0
01/14/2013 18:02:15;0040;PBS_Server.19445;Svr;csg.bcmd.bcm.edu;Scheduler was sent the command time
01/14/2013 18:03:54;0002;PBS_Server.1883;Svr;PBS_Server;Torque Server Version = 4.1.2, loglevel = 0
01/14/2013 18:08:59;0002;PBS_Server.1875;Svr;PBS_Server;Torque Server Version = 4.1.2, loglevel = 0
01/14/2013 18:12:25;0040;PBS_Server.19457;Svr;csg.bcmd.bcm.edu;Scheduler was sent the command time
01/14/2013 18:14:04;0002;PBS_Server.1878;Svr;PBS_Server;Torque Server Version = 4.1.2, loglevel = 0
01/14/2013 18:19:09;0002;PBS_Server.1875;Svr;PBS_Server;Torque Server Version = 4.1.2, loglevel = 0
01/14/2013 18:22:35;0040;PBS_Server.19492;Svr;csg.bcmd.bcm.edu;Scheduler was sent the command time
01/14/2013 18:24:14;0002;PBS_Server.1885;Svr;PBS_Server;Torque Server Version = 4.1.2, loglevel = 0
01/14/2013 18:29:19;0002;PBS_Server.1880;Svr;PBS_Server;Torque Server Version = 4.1.2, loglevel = 0
01/14/2013 18:32:45;0040;PBS_Server.19520;Svr;csg.bcmd.bcm.edu;Scheduler was sent the command time
01/14/2013 18:34:24;0002;PBS_Server.1882;Svr;PBS_Server;Torque Server Version = 4.1.2, loglevel = 0
01/14/2013 18:39:29;0002;PBS_Server.1875;Svr;PBS_Server;Torque Server Version = 4.1.2, loglevel = 0
01/14/2013 18:42:55;0040;PBS_Server.19536;Svr;csg.bcmd.bcm.edu;Scheduler was sent the command time
01/14/2013 18:44:34;0002;PBS_Server.1874;Svr;PBS_Server;Torque Server Version = 4.1.2, loglevel = 0
01/14/2013 18:49:39;0002;PBS_Server.1886;Svr;PBS_Server;Torque Server Version = 4.1.2, loglevel = 0
01/14/2013 18:53:05;0040;PBS_Server.19549;Svr;csg.bcmd.bcm.edu;Scheduler was sent the command time
01/14/2013 18:54:44;0002;PBS_Server.1886;Svr;PBS_Server;Torque Server Version = 4.1.2, loglevel = 0
01/14/2013 18:59:49;0002;PBS_Server.1875;Svr;PBS_Server;Torque Server Version = 4.1.2, loglevel = 0
01/14/2013 19:03:15;0040;PBS_Server.19569;Svr;csg.bcmd.bcm.edu;Scheduler was sent the command time
01/14/2013 19:04:54;0002;PBS_Server.1877;Svr;PBS_Server;Torque Server Version = 4.1.2, loglevel = 0
01/14/2013 19:09:59;0002;PBS_Server.1879;Svr;PBS_Server;Torque Server Version = 4.1.2, loglevel = 0
01/14/2013 19:13:25;0040;PBS_Server.19582;Svr;csg.bcmd.bcm.edu;Scheduler was sent the command time
01/14/2013 19:15:04;0002;PBS_Server.1885;Svr;PBS_Server;Torque Server Version = 4.1.2, loglevel = 0
01/14/2013 19:20:09;0002;PBS_Server.1874;Svr;PBS_Server;Torque Server Version = 4.1.2, loglevel = 0
01/14/2013 19:23:35;0040;PBS_Server.19598;Svr;csg.bcmd.bcm.edu;Scheduler was sent the command time
01/14/2013 19:25:14;0002;PBS_Server.1883;Svr;PBS_Server;Torque Server Version = 4.1.2, loglevel = 0
01/14/2013 19:30:19;0002;PBS_Server.1882;Svr;PBS_Server;Torque Server Version = 4.1.2, loglevel = 0
01/14/2013 19:33:45;0040;PBS_Server.19610;Svr;csg.bcmd.bcm.edu;Scheduler was sent the command time
01/14/2013 19:35:24;0002;PBS_Server.1886;Svr;PBS_Server;Torque Server Version = 4.1.2, loglevel = 0
01/14/2013 19:40:29;0002;PBS_Server.1877;Svr;PBS_Server;Torque Server Version = 4.1.2, loglevel = 0
01/14/2013 19:43:55;0040;PBS_Server.19625;Svr;csg.bcmd.bcm.edu;Scheduler was sent the command time
01/14/2013 19:45:34;0002;PBS_Server.1881;Svr;PBS_Server;Torque Server Version = 4.1.2, loglevel = 0
01/14/2013 19:50:39;0002;PBS_Server.1881;Svr;PBS_Server;Torque Server Version = 4.1.2, loglevel = 0
01/14/2013 19:54:05;0040;PBS_Server.19639;Svr;csg.bcmd.bcm.edu;Scheduler was sent the command time
01/14/2013 19:55:44;0002;PBS_Server.1876;Svr;PBS_Server;Torque Server Version = 4.1.2, loglevel = 0
01/14/2013 20:00:49;0002;PBS_Server.1885;Svr;PBS_Server;Torque Server Version = 4.1.2, loglevel = 0
01/14/2013 20:04:15;0040;PBS_Server.19658;Svr;csg.bcmd.bcm.edu;Scheduler was sent the command time
01/14/2013 20:05:54;0002;PBS_Server.1879;Svr;PBS_Server;Torque Server Version = 4.1.2, loglevel = 0
01/14/2013 20:10:59;0002;PBS_Server.1875;Svr;PBS_Server;Torque Server Version = 4.1.2, loglevel = 0
01/14/2013 20:14:25;0040;PBS_Server.19679;Svr;csg.bcmd.bcm.edu;Scheduler was sent the command time
01/14/2013 20:16:04;0002;PBS_Server.1884;Svr;PBS_Server;Torque Server Version = 4.1.2, loglevel = 0
01/14/2013 20:21:09;0002;PBS_Server.1882;Svr;PBS_Server;Torque Server Version = 4.1.2, loglevel = 0
01/14/2013 20:24:35;0040;PBS_Server.19691;Svr;csg.bcmd.bcm.edu;Scheduler was sent the command time
01/14/2013 20:26:14;0002;PBS_Server.1886;Svr;PBS_Server;Torque Server Version = 4.1.2, loglevel = 0
01/14/2013 20:31:19;0002;PBS_Server.1876;Svr;PBS_Server;Torque Server Version = 4.1.2, loglevel = 0
01/14/2013 20:34:45;0040;PBS_Server.19705;Svr;csg.bcmd.bcm.edu;Scheduler was sent the command time
01/14/2013 20:36:24;0002;PBS_Server.1874;Svr;PBS_Server;Torque Server Version = 4.1.2, loglevel = 0
01/14/2013 20:41:29;0002;PBS_Server.1881;Svr;PBS_Server;Torque Server Version = 4.1.2, loglevel = 0
01/14/2013 20:44:55;0040;PBS_Server.19717;Svr;csg.bcmd.bcm.edu;Scheduler was sent the command time
01/14/2013 20:46:34;0002;PBS_Server.1880;Svr;PBS_Server;Torque Server Version = 4.1.2, loglevel = 0
01/14/2013 20:51:39;0002;PBS_Server.1885;Svr;PBS_Server;Torque Server Version = 4.1.2, loglevel = 0
01/14/2013 20:55:05;0040;PBS_Server.19734;Svr;csg.bcmd.bcm.edu;Scheduler was sent the command time
01/14/2013 20:56:44;0002;PBS_Server.1874;Svr;PBS_Server;Torque Server Version = 4.1.2, loglevel = 0
01/14/2013 21:01:49;0002;PBS_Server.1878;Svr;PBS_Server;Torque Server Version = 4.1.2, loglevel = 0
01/14/2013 21:05:15;0040;PBS_Server.19751;Svr;csg.bcmd.bcm.edu;Scheduler was sent the command time
01/14/2013 21:06:54;0002;PBS_Server.1879;Svr;PBS_Server;Torque Server Version = 4.1.2, loglevel = 0
01/14/2013 21:11:59;0002;PBS_Server.1877;Svr;PBS_Server;Torque Server Version = 4.1.2, loglevel = 0
01/14/2013 21:15:25;0040;PBS_Server.19763;Svr;csg.bcmd.bcm.edu;Scheduler was sent the command time
01/14/2013 21:17:04;0002;PBS_Server.1886;Svr;PBS_Server;Torque Server Version = 4.1.2, loglevel = 0
01/14/2013 21:22:09;0002;PBS_Server.1874;Svr;PBS_Server;Torque Server Version = 4.1.2, loglevel = 0
01/14/2013 21:25:35;0040;PBS_Server.19776;Svr;csg.bcmd.bcm.edu;Scheduler was sent the command time
01/14/2013 21:27:14;0002;PBS_Server.1875;Svr;PBS_Server;Torque Server Version = 4.1.2, loglevel = 0
01/14/2013 21:32:19;0002;PBS_Server.1884;Svr;PBS_Server;Torque Server Version = 4.1.2, loglevel = 0
01/14/2013 21:35:45;0040;PBS_Server.19788;Svr;csg.bcmd.bcm.edu;Scheduler was sent the command time
01/14/2013 21:37:24;0002;PBS_Server.1876;Svr;PBS_Server;Torque Server Version = 4.1.2, loglevel = 0
01/14/2013 21:42:29;0002;PBS_Server.1885;Svr;PBS_Server;Torque Server Version = 4.1.2, loglevel = 0
01/14/2013 21:45:55;0040;PBS_Server.19803;Svr;csg.bcmd.bcm.edu;Scheduler was sent the command time
01/14/2013 21:47:34;0002;PBS_Server.1883;Svr;PBS_Server;Torque Server Version = 4.1.2, loglevel = 0
01/14/2013 21:52:39;0002;PBS_Server.1885;Svr;PBS_Server;Torque Server Version = 4.1.2, loglevel = 0
01/14/2013 21:56:05;0040;PBS_Server.19815;Svr;csg.bcmd.bcm.edu;Scheduler was sent the command time
01/14/2013 21:57:44;0002;PBS_Server.1878;Svr;PBS_Server;Torque Server Version = 4.1.2, loglevel = 0
01/14/2013 22:02:49;0002;PBS_Server.1875;Svr;PBS_Server;Torque Server Version = 4.1.2, loglevel = 0
01/14/2013 22:06:15;0040;PBS_Server.19841;Svr;csg.bcmd.bcm.edu;Scheduler was sent the command time
01/14/2013 22:07:54;0002;PBS_Server.1881;Svr;PBS_Server;Torque Server Version = 4.1.2, loglevel = 0
01/14/2013 22:12:59;0002;PBS_Server.1883;Svr;PBS_Server;Torque Server Version = 4.1.2, loglevel = 0
01/14/2013 22:16:25;0040;PBS_Server.19857;Svr;csg.bcmd.bcm.edu;Scheduler was sent the command time
01/14/2013 22:18:04;0002;PBS_Server.1883;Svr;PBS_Server;Torque Server Version = 4.1.2, loglevel = 0
01/14/2013 22:23:09;0002;PBS_Server.1884;Svr;PBS_Server;Torque Server Version = 4.1.2, loglevel = 0
01/14/2013 22:26:35;0040;PBS_Server.19869;Svr;csg.bcmd.bcm.edu;Scheduler was sent the command time
01/14/2013 22:28:14;0002;PBS_Server.1880;Svr;PBS_Server;Torque Server Version = 4.1.2, loglevel = 0
01/14/2013 22:33:19;0002;PBS_Server.1886;Svr;PBS_Server;Torque Server Version = 4.1.2, loglevel = 0
01/14/2013 22:36:45;0040;PBS_Server.19882;Svr;csg.bcmd.bcm.edu;Scheduler was sent the command time
01/14/2013 22:38:24;0002;PBS_Server.1882;Svr;PBS_Server;Torque Server Version = 4.1.2, loglevel = 0
01/14/2013 22:43:29;0002;PBS_Server.1878;Svr;PBS_Server;Torque Server Version = 4.1.2, loglevel = 0
01/14/2013 22:46:55;0040;PBS_Server.19895;Svr;csg.bcmd.bcm.edu;Scheduler was sent the command time
01/14/2013 22:48:34;0002;PBS_Server.1885;Svr;PBS_Server;Torque Server Version = 4.1.2, loglevel = 0
01/14/2013 22:53:39;0002;PBS_Server.1881;Svr;PBS_Server;Torque Server Version = 4.1.2, loglevel = 0
01/14/2013 22:57:05;0040;PBS_Server.19908;Svr;csg.bcmd.bcm.edu;Scheduler was sent the command time
01/14/2013 22:58:44;0002;PBS_Server.1883;Svr;PBS_Server;Torque Server Version = 4.1.2, loglevel = 0
01/14/2013 23:03:49;0002;PBS_Server.1877;Svr;PBS_Server;Torque Server Version = 4.1.2, loglevel = 0
01/14/2013 23:07:15;0040;PBS_Server.19926;Svr;csg.bcmd.bcm.edu;Scheduler was sent the command time
01/14/2013 23:08:54;0002;PBS_Server.1877;Svr;PBS_Server;Torque Server Version = 4.1.2, loglevel = 0
01/14/2013 23:13:59;0002;PBS_Server.1880;Svr;PBS_Server;Torque Server Version = 4.1.2, loglevel = 0
01/14/2013 23:17:25;0040;PBS_Server.19945;Svr;csg.bcmd.bcm.edu;Scheduler was sent the command time
01/14/2013 23:19:04;0002;PBS_Server.1875;Svr;PBS_Server;Torque Server Version = 4.1.2, loglevel = 0
01/14/2013 23:24:09;0002;PBS_Server.1874;Svr;PBS_Server;Torque Server Version = 4.1.2, loglevel = 0
01/14/2013 23:27:35;0040;PBS_Server.19957;Svr;csg.bcmd.bcm.edu;Scheduler was sent the command time
01/14/2013 23:29:14;0002;PBS_Server.1876;Svr;PBS_Server;Torque Server Version = 4.1.2, loglevel = 0
01/14/2013 23:34:19;0002;PBS_Server.1883;Svr;PBS_Server;Torque Server Version = 4.1.2, loglevel = 0
01/14/2013 23:37:45;0040;PBS_Server.19970;Svr;csg.bcmd.bcm.edu;Scheduler was sent the command time
01/14/2013 23:39:24;0002;PBS_Server.1876;Svr;PBS_Server;Torque Server Version = 4.1.2, loglevel = 0
01/14/2013 23:44:29;0002;PBS_Server.1885;Svr;PBS_Server;Torque Server Version = 4.1.2, loglevel = 0
01/14/2013 23:47:55;0040;PBS_Server.19981;Svr;csg.bcmd.bcm.edu;Scheduler was sent the command time
01/14/2013 23:49:34;0002;PBS_Server.1878;Svr;PBS_Server;Torque Server Version = 4.1.2, loglevel = 0
01/14/2013 23:54:39;0002;PBS_Server.1884;Svr;PBS_Server;Torque Server Version = 4.1.2, loglevel = 0
01/14/2013 23:58:05;0040;PBS_Server.19994;Svr;csg.bcmd.bcm.edu;Scheduler was sent the command time
01/14/2013 23:59:44;0002;PBS_Server.1877;Svr;PBS_Server;Torque Server Version = 4.1.2, loglevel = 0
01/15/2013 00:04:49;0002;PBS_Server.1875;Svr;Log;Log closed
