01/03/2013 00:00:56;0002;PBS_Server.1841;Svr;Log;Log opened
01/03/2013 00:00:56;0002;PBS_Server.1841;Svr;PBS_Server;Torque Server Version = 4.1.2, loglevel = 0
01/03/2013 00:01:53;0040;PBS_Server.13080;Svr;csg.bcmd.bcm.edu;Scheduler was sent the command time
01/03/2013 00:06:01;0002;PBS_Server.1837;Svr;PBS_Server;Torque Server Version = 4.1.2, loglevel = 0
01/03/2013 00:11:06;0002;PBS_Server.1833;Svr;PBS_Server;Torque Server Version = 4.1.2, loglevel = 0
01/03/2013 00:12:03;0040;PBS_Server.13096;Svr;csg.bcmd.bcm.edu;Scheduler was sent the command time
01/03/2013 00:16:11;0002;PBS_Server.1830;Svr;PBS_Server;Torque Server Version = 4.1.2, loglevel = 0
01/03/2013 00:21:16;0002;PBS_Server.1841;Svr;PBS_Server;Torque Server Version = 4.1.2, loglevel = 0
01/03/2013 00:22:13;0040;PBS_Server.13111;Svr;csg.bcmd.bcm.edu;Scheduler was sent the command time
01/03/2013 00:26:21;0002;PBS_Server.1828;Svr;PBS_Server;Torque Server Version = 4.1.2, loglevel = 0
01/03/2013 00:31:26;0002;PBS_Server.1837;Svr;PBS_Server;Torque Server Version = 4.1.2, loglevel = 0
01/03/2013 00:32:23;0040;PBS_Server.13127;Svr;csg.bcmd.bcm.edu;Scheduler was sent the command time
01/03/2013 00:36:31;0002;PBS_Server.1829;Svr;PBS_Server;Torque Server Version = 4.1.2, loglevel = 0
01/03/2013 00:41:36;0002;PBS_Server.1841;Svr;PBS_Server;Torque Server Version = 4.1.2, loglevel = 0
01/03/2013 00:42:33;0040;PBS_Server.13142;Svr;csg.bcmd.bcm.edu;Scheduler was sent the command time
01/03/2013 00:46:41;0002;PBS_Server.1836;Svr;PBS_Server;Torque Server Version = 4.1.2, loglevel = 0
01/03/2013 00:51:46;0002;PBS_Server.1841;Svr;PBS_Server;Torque Server Version = 4.1.2, loglevel = 0
01/03/2013 00:52:43;0040;PBS_Server.13158;Svr;csg.bcmd.bcm.edu;Scheduler was sent the command time
01/03/2013 00:56:51;0002;PBS_Server.1828;Svr;PBS_Server;Torque Server Version = 4.1.2, loglevel = 0
01/03/2013 01:01:56;0002;PBS_Server.1831;Svr;PBS_Server;Torque Server Version = 4.1.2, loglevel = 0
01/03/2013 01:02:53;0040;PBS_Server.13205;Svr;csg.bcmd.bcm.edu;Scheduler was sent the command time
01/03/2013 01:07:01;0002;PBS_Server.1829;Svr;PBS_Server;Torque Server Version = 4.1.2, loglevel = 0
01/03/2013 01:12:06;0002;PBS_Server.1831;Svr;PBS_Server;Torque Server Version = 4.1.2, loglevel = 0
01/03/2013 01:13:03;0040;PBS_Server.13318;Svr;csg.bcmd.bcm.edu;Scheduler was sent the command time
01/03/2013 01:17:11;0002;PBS_Server.1829;Svr;PBS_Server;Torque Server Version = 4.1.2, loglevel = 0
01/03/2013 01:22:16;0002;PBS_Server.1830;Svr;PBS_Server;Torque Server Version = 4.1.2, loglevel = 0
01/03/2013 01:23:13;0040;PBS_Server.13426;Svr;csg.bcmd.bcm.edu;Scheduler was sent the command time
01/03/2013 01:27:21;0002;PBS_Server.1836;Svr;PBS_Server;Torque Server Version = 4.1.2, loglevel = 0
01/03/2013 01:32:26;0002;PBS_Server.1837;Svr;PBS_Server;Torque Server Version = 4.1.2, loglevel = 0
01/03/2013 01:33:23;0040;PBS_Server.13532;Svr;csg.bcmd.bcm.edu;Scheduler was sent the command time
01/03/2013 01:37:31;0002;PBS_Server.1841;Svr;PBS_Server;Torque Server Version = 4.1.2, loglevel = 0
01/03/2013 01:42:36;0002;PBS_Server.1840;Svr;PBS_Server;Torque Server Version = 4.1.2, loglevel = 0
01/03/2013 01:43:33;0040;PBS_Server.13638;Svr;csg.bcmd.bcm.edu;Scheduler was sent the command time
01/03/2013 01:47:41;0002;PBS_Server.1834;Svr;PBS_Server;Torque Server Version = 4.1.2, loglevel = 0
01/03/2013 01:52:46;0002;PBS_Server.1831;Svr;PBS_Server;Torque Server Version = 4.1.2, loglevel = 0
01/03/2013 01:53:43;0040;PBS_Server.13744;Svr;csg.bcmd.bcm.edu;Scheduler was sent the command time
01/03/2013 01:57:51;0002;PBS_Server.1833;Svr;PBS_Server;Torque Server Version = 4.1.2, loglevel = 0
01/03/2013 02:02:56;0002;PBS_Server.1828;Svr;PBS_Server;Torque Server Version = 4.1.2, loglevel = 0
01/03/2013 02:03:53;0040;PBS_Server.13820;Svr;csg.bcmd.bcm.edu;Scheduler was sent the command time
01/03/2013 02:08:01;0002;PBS_Server.1841;Svr;PBS_Server;Torque Server Version = 4.1.2, loglevel = 0
01/03/2013 02:13:06;0002;PBS_Server.1835;Svr;PBS_Server;Torque Server Version = 4.1.2, loglevel = 0
01/03/2013 02:14:03;0040;PBS_Server.13838;Svr;csg.bcmd.bcm.edu;Scheduler was sent the command time
01/03/2013 02:18:11;0002;PBS_Server.1832;Svr;PBS_Server;Torque Server Version = 4.1.2, loglevel = 0
01/03/2013 02:23:16;0002;PBS_Server.1834;Svr;PBS_Server;Torque Server Version = 4.1.2, loglevel = 0
01/03/2013 02:24:13;0040;PBS_Server.13853;Svr;csg.bcmd.bcm.edu;Scheduler was sent the command time
01/03/2013 02:28:21;0002;PBS_Server.1841;Svr;PBS_Server;Torque Server Version = 4.1.2, loglevel = 0
01/03/2013 02:33:26;0002;PBS_Server.1838;Svr;PBS_Server;Torque Server Version = 4.1.2, loglevel = 0
01/03/2013 02:34:23;0040;PBS_Server.13868;Svr;csg.bcmd.bcm.edu;Scheduler was sent the command time
01/03/2013 02:38:31;0002;PBS_Server.1832;Svr;PBS_Server;Torque Server Version = 4.1.2, loglevel = 0
01/03/2013 02:43:36;0002;PBS_Server.1830;Svr;PBS_Server;Torque Server Version = 4.1.2, loglevel = 0
01/03/2013 02:44:33;0040;PBS_Server.13883;Svr;csg.bcmd.bcm.edu;Scheduler was sent the command time
01/03/2013 02:48:41;0002;PBS_Server.1829;Svr;PBS_Server;Torque Server Version = 4.1.2, loglevel = 0
01/03/2013 02:53:46;0002;PBS_Server.1837;Svr;PBS_Server;Torque Server Version = 4.1.2, loglevel = 0
01/03/2013 02:54:43;0040;PBS_Server.13899;Svr;csg.bcmd.bcm.edu;Scheduler was sent the command time
01/03/2013 02:58:51;0002;PBS_Server.1831;Svr;PBS_Server;Torque Server Version = 4.1.2, loglevel = 0
01/03/2013 03:03:56;0002;PBS_Server.1836;Svr;PBS_Server;Torque Server Version = 4.1.2, loglevel = 0
01/03/2013 03:04:53;0040;PBS_Server.13921;Svr;csg.bcmd.bcm.edu;Scheduler was sent the command time
01/03/2013 03:09:01;0002;PBS_Server.1828;Svr;PBS_Server;Torque Server Version = 4.1.2, loglevel = 0
01/03/2013 03:14:06;0002;PBS_Server.1837;Svr;PBS_Server;Torque Server Version = 4.1.2, loglevel = 0
01/03/2013 03:15:03;0040;PBS_Server.13942;Svr;csg.bcmd.bcm.edu;Scheduler was sent the command time
01/03/2013 03:19:11;0002;PBS_Server.1832;Svr;PBS_Server;Torque Server Version = 4.1.2, loglevel = 0
01/03/2013 03:24:16;0002;PBS_Server.1836;Svr;PBS_Server;Torque Server Version = 4.1.2, loglevel = 0
01/03/2013 03:25:13;0040;PBS_Server.13957;Svr;csg.bcmd.bcm.edu;Scheduler was sent the command time
01/03/2013 03:29:21;0002;PBS_Server.1828;Svr;PBS_Server;Torque Server Version = 4.1.2, loglevel = 0
01/03/2013 03:34:26;0002;PBS_Server.1841;Svr;PBS_Server;Torque Server Version = 4.1.2, loglevel = 0
01/03/2013 03:35:23;0040;PBS_Server.13972;Svr;csg.bcmd.bcm.edu;Scheduler was sent the command time
01/03/2013 03:39:31;0002;PBS_Server.1838;Svr;PBS_Server;Torque Server Version = 4.1.2, loglevel = 0
01/03/2013 03:44:36;0002;PBS_Server.1828;Svr;PBS_Server;Torque Server Version = 4.1.2, loglevel = 0
01/03/2013 03:45:33;0040;PBS_Server.13987;Svr;csg.bcmd.bcm.edu;Scheduler was sent the command time
01/03/2013 03:49:41;0002;PBS_Server.1839;Svr;PBS_Server;Torque Server Version = 4.1.2, loglevel = 0
01/03/2013 03:54:46;0002;PBS_Server.1829;Svr;PBS_Server;Torque Server Version = 4.1.2, loglevel = 0
01/03/2013 03:55:43;0040;PBS_Server.14016;Svr;csg.bcmd.bcm.edu;Scheduler was sent the command time
01/03/2013 03:59:51;0002;PBS_Server.1839;Svr;PBS_Server;Torque Server Version = 4.1.2, loglevel = 0
01/03/2013 04:05:01;0002;PBS_Server.1830;Svr;PBS_Server;Torque Server Version = 4.1.2, loglevel = 0
01/03/2013 04:05:58;0040;PBS_Server.14035;Svr;csg.bcmd.bcm.edu;Scheduler was sent the command time
01/03/2013 04:10:06;0002;PBS_Server.1839;Svr;PBS_Server;Torque Server Version = 4.1.2, loglevel = 0
01/03/2013 04:15:11;0002;PBS_Server.1833;Svr;PBS_Server;Torque Server Version = 4.1.2, loglevel = 0
01/03/2013 04:16:08;0040;PBS_Server.14051;Svr;csg.bcmd.bcm.edu;Scheduler was sent the command time
01/03/2013 04:20:16;0002;PBS_Server.1828;Svr;PBS_Server;Torque Server Version = 4.1.2, loglevel = 0
01/03/2013 04:25:21;0002;PBS_Server.1829;Svr;PBS_Server;Torque Server Version = 4.1.2, loglevel = 0
01/03/2013 04:26:18;0040;PBS_Server.14069;Svr;csg.bcmd.bcm.edu;Scheduler was sent the command time
01/03/2013 04:30:26;0002;PBS_Server.1837;Svr;PBS_Server;Torque Server Version = 4.1.2, loglevel = 0
01/03/2013 04:35:31;0002;PBS_Server.1829;Svr;PBS_Server;Torque Server Version = 4.1.2, loglevel = 0
01/03/2013 04:36:28;0040;PBS_Server.14085;Svr;csg.bcmd.bcm.edu;Scheduler was sent the command time
01/03/2013 04:40:36;0002;PBS_Server.1830;Svr;PBS_Server;Torque Server Version = 4.1.2, loglevel = 0
01/03/2013 04:45:41;0002;PBS_Server.1839;Svr;PBS_Server;Torque Server Version = 4.1.2, loglevel = 0
01/03/2013 04:46:38;0040;PBS_Server.14101;Svr;csg.bcmd.bcm.edu;Scheduler was sent the command time
01/03/2013 04:50:46;0002;PBS_Server.1837;Svr;PBS_Server;Torque Server Version = 4.1.2, loglevel = 0
01/03/2013 04:55:51;0002;PBS_Server.1838;Svr;PBS_Server;Torque Server Version = 4.1.2, loglevel = 0
01/03/2013 04:56:48;0040;PBS_Server.14117;Svr;csg.bcmd.bcm.edu;Scheduler was sent the command time
01/03/2013 05:00:56;0002;PBS_Server.1837;Svr;PBS_Server;Torque Server Version = 4.1.2, loglevel = 0
01/03/2013 05:06:01;0002;PBS_Server.1839;Svr;PBS_Server;Torque Server Version = 4.1.2, loglevel = 0
01/03/2013 05:06:58;0040;PBS_Server.14136;Svr;csg.bcmd.bcm.edu;Scheduler was sent the command time
01/03/2013 05:11:06;0002;PBS_Server.1841;Svr;PBS_Server;Torque Server Version = 4.1.2, loglevel = 0
01/03/2013 05:16:11;0002;PBS_Server.1829;Svr;PBS_Server;Torque Server Version = 4.1.2, loglevel = 0
01/03/2013 05:17:08;0040;PBS_Server.14152;Svr;csg.bcmd.bcm.edu;Scheduler was sent the command time
01/03/2013 05:21:16;0002;PBS_Server.1837;Svr;PBS_Server;Torque Server Version = 4.1.2, loglevel = 0
01/03/2013 05:26:21;0002;PBS_Server.1839;Svr;PBS_Server;Torque Server Version = 4.1.2, loglevel = 0
01/03/2013 05:27:18;0040;PBS_Server.14166;Svr;csg.bcmd.bcm.edu;Scheduler was sent the command time
01/03/2013 05:31:26;0002;PBS_Server.1829;Svr;PBS_Server;Torque Server Version = 4.1.2, loglevel = 0
01/03/2013 05:36:31;0002;PBS_Server.1828;Svr;PBS_Server;Torque Server Version = 4.1.2, loglevel = 0
01/03/2013 05:37:28;0040;PBS_Server.14182;Svr;csg.bcmd.bcm.edu;Scheduler was sent the command time
01/03/2013 05:41:36;0002;PBS_Server.1829;Svr;PBS_Server;Torque Server Version = 4.1.2, loglevel = 0
01/03/2013 05:46:41;0002;PBS_Server.1830;Svr;PBS_Server;Torque Server Version = 4.1.2, loglevel = 0
01/03/2013 05:47:38;0040;PBS_Server.14196;Svr;csg.bcmd.bcm.edu;Scheduler was sent the command time
01/03/2013 05:51:46;0002;PBS_Server.1829;Svr;PBS_Server;Torque Server Version = 4.1.2, loglevel = 0
01/03/2013 05:56:51;0002;PBS_Server.1835;Svr;PBS_Server;Torque Server Version = 4.1.2, loglevel = 0
01/03/2013 05:57:48;0040;PBS_Server.14211;Svr;csg.bcmd.bcm.edu;Scheduler was sent the command time
01/03/2013 06:01:56;0002;PBS_Server.1831;Svr;PBS_Server;Torque Server Version = 4.1.2, loglevel = 0
01/03/2013 06:07:01;0002;PBS_Server.1841;Svr;PBS_Server;Torque Server Version = 4.1.2, loglevel = 0
01/03/2013 06:07:58;0040;PBS_Server.14230;Svr;csg.bcmd.bcm.edu;Scheduler was sent the command time
01/03/2013 06:12:06;0002;PBS_Server.1832;Svr;PBS_Server;Torque Server Version = 4.1.2, loglevel = 0
01/03/2013 06:17:11;0002;PBS_Server.1837;Svr;PBS_Server;Torque Server Version = 4.1.2, loglevel = 0
01/03/2013 06:18:08;0040;PBS_Server.14244;Svr;csg.bcmd.bcm.edu;Scheduler was sent the command time
01/03/2013 06:22:16;0002;PBS_Server.1829;Svr;PBS_Server;Torque Server Version = 4.1.2, loglevel = 0
01/03/2013 06:27:21;0002;PBS_Server.1837;Svr;PBS_Server;Torque Server Version = 4.1.2, loglevel = 0
01/03/2013 06:28:18;0040;PBS_Server.14259;Svr;csg.bcmd.bcm.edu;Scheduler was sent the command time
01/03/2013 06:32:26;0002;PBS_Server.1836;Svr;PBS_Server;Torque Server Version = 4.1.2, loglevel = 0
01/03/2013 06:37:31;0002;PBS_Server.1838;Svr;PBS_Server;Torque Server Version = 4.1.2, loglevel = 0
01/03/2013 06:38:28;0040;PBS_Server.14273;Svr;csg.bcmd.bcm.edu;Scheduler was sent the command time
01/03/2013 06:42:36;0002;PBS_Server.1835;Svr;PBS_Server;Torque Server Version = 4.1.2, loglevel = 0
01/03/2013 06:47:41;0002;PBS_Server.1831;Svr;PBS_Server;Torque Server Version = 4.1.2, loglevel = 0
01/03/2013 06:48:38;0040;PBS_Server.14287;Svr;csg.bcmd.bcm.edu;Scheduler was sent the command time
01/03/2013 06:52:46;0002;PBS_Server.1832;Svr;PBS_Server;Torque Server Version = 4.1.2, loglevel = 0
01/03/2013 06:57:51;0002;PBS_Server.1830;Svr;PBS_Server;Torque Server Version = 4.1.2, loglevel = 0
01/03/2013 06:58:48;0040;PBS_Server.14302;Svr;csg.bcmd.bcm.edu;Scheduler was sent the command time
01/03/2013 07:02:56;0002;PBS_Server.1839;Svr;PBS_Server;Torque Server Version = 4.1.2, loglevel = 0
01/03/2013 07:08:01;0002;PBS_Server.1837;Svr;PBS_Server;Torque Server Version = 4.1.2, loglevel = 0
01/03/2013 07:08:58;0040;PBS_Server.14321;Svr;csg.bcmd.bcm.edu;Scheduler was sent the command time
01/03/2013 07:13:06;0002;PBS_Server.1831;Svr;PBS_Server;Torque Server Version = 4.1.2, loglevel = 0
01/03/2013 07:18:11;0002;PBS_Server.1836;Svr;PBS_Server;Torque Server Version = 4.1.2, loglevel = 0
01/03/2013 07:19:08;0040;PBS_Server.14336;Svr;csg.bcmd.bcm.edu;Scheduler was sent the command time
01/03/2013 07:23:16;0002;PBS_Server.1841;Svr;PBS_Server;Torque Server Version = 4.1.2, loglevel = 0
01/03/2013 07:28:21;0002;PBS_Server.1829;Svr;PBS_Server;Torque Server Version = 4.1.2, loglevel = 0
01/03/2013 07:29:18;0040;PBS_Server.14350;Svr;csg.bcmd.bcm.edu;Scheduler was sent the command time
01/03/2013 07:33:26;0002;PBS_Server.1835;Svr;PBS_Server;Torque Server Version = 4.1.2, loglevel = 0
01/03/2013 07:38:31;0002;PBS_Server.1834;Svr;PBS_Server;Torque Server Version = 4.1.2, loglevel = 0
01/03/2013 07:39:28;0040;PBS_Server.14365;Svr;csg.bcmd.bcm.edu;Scheduler was sent the command time
01/03/2013 07:43:36;0002;PBS_Server.1830;Svr;PBS_Server;Torque Server Version = 4.1.2, loglevel = 0
01/03/2013 07:48:41;0002;PBS_Server.1831;Svr;PBS_Server;Torque Server Version = 4.1.2, loglevel = 0
01/03/2013 07:49:38;0040;PBS_Server.14379;Svr;csg.bcmd.bcm.edu;Scheduler was sent the command time
01/03/2013 07:53:46;0002;PBS_Server.1841;Svr;PBS_Server;Torque Server Version = 4.1.2, loglevel = 0
01/03/2013 07:58:51;0002;PBS_Server.1838;Svr;PBS_Server;Torque Server Version = 4.1.2, loglevel = 0
01/03/2013 07:59:48;0040;PBS_Server.14494;Svr;csg.bcmd.bcm.edu;Scheduler was sent the command time
01/03/2013 08:03:56;0002;PBS_Server.1830;Svr;PBS_Server;Torque Server Version = 4.1.2, loglevel = 0
01/03/2013 08:09:01;0002;PBS_Server.1832;Svr;PBS_Server;Torque Server Version = 4.1.2, loglevel = 0
01/03/2013 08:09:58;0040;PBS_Server.14539;Svr;csg.bcmd.bcm.edu;Scheduler was sent the command time
01/03/2013 08:14:06;0002;PBS_Server.1841;Svr;PBS_Server;Torque Server Version = 4.1.2, loglevel = 0
01/03/2013 08:19:11;0002;PBS_Server.1839;Svr;PBS_Server;Torque Server Version = 4.1.2, loglevel = 0
01/03/2013 08:20:08;0040;PBS_Server.14572;Svr;csg.bcmd.bcm.edu;Scheduler was sent the command time
01/03/2013 08:24:16;0002;PBS_Server.1834;Svr;PBS_Server;Torque Server Version = 4.1.2, loglevel = 0
01/03/2013 08:29:21;0002;PBS_Server.1832;Svr;PBS_Server;Torque Server Version = 4.1.2, loglevel = 0
01/03/2013 08:30:18;0040;PBS_Server.14651;Svr;csg.bcmd.bcm.edu;Scheduler was sent the command time
01/03/2013 08:34:26;0002;PBS_Server.1831;Svr;PBS_Server;Torque Server Version = 4.1.2, loglevel = 0
01/03/2013 08:39:31;0002;PBS_Server.1839;Svr;PBS_Server;Torque Server Version = 4.1.2, loglevel = 0
01/03/2013 08:40:28;0040;PBS_Server.14718;Svr;csg.bcmd.bcm.edu;Scheduler was sent the command time
01/03/2013 08:44:36;0002;PBS_Server.1834;Svr;PBS_Server;Torque Server Version = 4.1.2, loglevel = 0
01/03/2013 08:49:41;0002;PBS_Server.1835;Svr;PBS_Server;Torque Server Version = 4.1.2, loglevel = 0
01/03/2013 08:50:38;0040;PBS_Server.14763;Svr;csg.bcmd.bcm.edu;Scheduler was sent the command time
01/03/2013 08:54:46;0002;PBS_Server.1831;Svr;PBS_Server;Torque Server Version = 4.1.2, loglevel = 0
01/03/2013 08:59:51;0002;PBS_Server.1832;Svr;PBS_Server;Torque Server Version = 4.1.2, loglevel = 0
01/03/2013 09:00:48;0040;PBS_Server.14793;Svr;csg.bcmd.bcm.edu;Scheduler was sent the command time
01/03/2013 09:04:56;0002;PBS_Server.1838;Svr;PBS_Server;Torque Server Version = 4.1.2, loglevel = 0
01/03/2013 09:10:01;0002;PBS_Server.1832;Svr;PBS_Server;Torque Server Version = 4.1.2, loglevel = 0
01/03/2013 09:10:58;0040;PBS_Server.14812;Svr;csg.bcmd.bcm.edu;Scheduler was sent the command time
01/03/2013 09:15:06;0002;PBS_Server.1828;Svr;PBS_Server;Torque Server Version = 4.1.2, loglevel = 0
01/03/2013 09:20:11;0002;PBS_Server.1832;Svr;PBS_Server;Torque Server Version = 4.1.2, loglevel = 0
01/03/2013 09:21:08;0040;PBS_Server.14844;Svr;csg.bcmd.bcm.edu;Scheduler was sent the command time
01/03/2013 09:25:16;0002;PBS_Server.1831;Svr;PBS_Server;Torque Server Version = 4.1.2, loglevel = 0
01/03/2013 09:30:21;0002;PBS_Server.1829;Svr;PBS_Server;Torque Server Version = 4.1.2, loglevel = 0
01/03/2013 09:31:18;0040;PBS_Server.14858;Svr;csg.bcmd.bcm.edu;Scheduler was sent the command time
01/03/2013 09:35:26;0002;PBS_Server.1828;Svr;PBS_Server;Torque Server Version = 4.1.2, loglevel = 0
01/03/2013 09:40:31;0002;PBS_Server.1829;Svr;PBS_Server;Torque Server Version = 4.1.2, loglevel = 0
01/03/2013 09:41:28;0040;PBS_Server.14872;Svr;csg.bcmd.bcm.edu;Scheduler was sent the command time
01/03/2013 09:45:36;0002;PBS_Server.1828;Svr;PBS_Server;Torque Server Version = 4.1.2, loglevel = 0
01/03/2013 09:50:41;0002;PBS_Server.1841;Svr;PBS_Server;Torque Server Version = 4.1.2, loglevel = 0
01/03/2013 09:51:38;0040;PBS_Server.14897;Svr;csg.bcmd.bcm.edu;Scheduler was sent the command time
01/03/2013 09:55:46;0002;PBS_Server.1835;Svr;PBS_Server;Torque Server Version = 4.1.2, loglevel = 0
01/03/2013 10:00:51;0002;PBS_Server.1840;Svr;PBS_Server;Torque Server Version = 4.1.2, loglevel = 0
01/03/2013 10:01:48;0040;PBS_Server.14934;Svr;csg.bcmd.bcm.edu;Scheduler was sent the command time
01/03/2013 10:05:56;0002;PBS_Server.1830;Svr;PBS_Server;Torque Server Version = 4.1.2, loglevel = 0
01/03/2013 10:11:01;0002;PBS_Server.1834;Svr;PBS_Server;Torque Server Version = 4.1.2, loglevel = 0
01/03/2013 10:11:58;0040;PBS_Server.14950;Svr;csg.bcmd.bcm.edu;Scheduler was sent the command time
01/03/2013 10:16:06;0002;PBS_Server.1828;Svr;PBS_Server;Torque Server Version = 4.1.2, loglevel = 0
01/03/2013 10:21:11;0002;PBS_Server.1831;Svr;PBS_Server;Torque Server Version = 4.1.2, loglevel = 0
01/03/2013 10:22:08;0040;PBS_Server.15033;Svr;csg.bcmd.bcm.edu;Scheduler was sent the command time
01/03/2013 10:26:16;0002;PBS_Server.1830;Svr;PBS_Server;Torque Server Version = 4.1.2, loglevel = 0
01/03/2013 10:31:21;0002;PBS_Server.1840;Svr;PBS_Server;Torque Server Version = 4.1.2, loglevel = 0
01/03/2013 10:32:18;0040;PBS_Server.15052;Svr;csg.bcmd.bcm.edu;Scheduler was sent the command time
01/03/2013 10:36:26;0002;PBS_Server.1830;Svr;PBS_Server;Torque Server Version = 4.1.2, loglevel = 0
01/03/2013 10:41:31;0002;PBS_Server.1833;Svr;PBS_Server;Torque Server Version = 4.1.2, loglevel = 0
01/03/2013 10:42:28;0040;PBS_Server.15073;Svr;csg.bcmd.bcm.edu;Scheduler was sent the command time
01/03/2013 10:46:36;0002;PBS_Server.1831;Svr;PBS_Server;Torque Server Version = 4.1.2, loglevel = 0
01/03/2013 10:51:41;0002;PBS_Server.1829;Svr;PBS_Server;Torque Server Version = 4.1.2, loglevel = 0
01/03/2013 10:52:38;0040;PBS_Server.15308;Svr;csg.bcmd.bcm.edu;Scheduler was sent the command time
01/03/2013 10:56:46;0002;PBS_Server.1838;Svr;PBS_Server;Torque Server Version = 4.1.2, loglevel = 0
01/03/2013 11:01:51;0002;PBS_Server.1840;Svr;PBS_Server;Torque Server Version = 4.1.2, loglevel = 0
01/03/2013 11:02:48;0040;PBS_Server.15608;Svr;csg.bcmd.bcm.edu;Scheduler was sent the command time
01/03/2013 11:06:56;0002;PBS_Server.1830;Svr;PBS_Server;Torque Server Version = 4.1.2, loglevel = 0
01/03/2013 11:12:01;0002;PBS_Server.1833;Svr;PBS_Server;Torque Server Version = 4.1.2, loglevel = 0
01/03/2013 11:12:58;0040;PBS_Server.15627;Svr;csg.bcmd.bcm.edu;Scheduler was sent the command time
01/03/2013 11:17:06;0002;PBS_Server.1834;Svr;PBS_Server;Torque Server Version = 4.1.2, loglevel = 0
01/03/2013 11:22:11;0002;PBS_Server.1836;Svr;PBS_Server;Torque Server Version = 4.1.2, loglevel = 0
01/03/2013 11:23:08;0040;PBS_Server.15762;Svr;csg.bcmd.bcm.edu;Scheduler was sent the command time
01/03/2013 11:27:16;0002;PBS_Server.1840;Svr;PBS_Server;Torque Server Version = 4.1.2, loglevel = 0
01/03/2013 11:32:21;0002;PBS_Server.1830;Svr;PBS_Server;Torque Server Version = 4.1.2, loglevel = 0
01/03/2013 11:33:18;0040;PBS_Server.16430;Svr;csg.bcmd.bcm.edu;Scheduler was sent the command time
01/03/2013 11:37:26;0002;PBS_Server.1836;Svr;PBS_Server;Torque Server Version = 4.1.2, loglevel = 0
01/03/2013 11:42:31;0002;PBS_Server.1832;Svr;PBS_Server;Torque Server Version = 4.1.2, loglevel = 0
01/03/2013 11:43:28;0040;PBS_Server.16580;Svr;csg.bcmd.bcm.edu;Scheduler was sent the command time
01/03/2013 11:47:36;0002;PBS_Server.1831;Svr;PBS_Server;Torque Server Version = 4.1.2, loglevel = 0
01/03/2013 11:52:41;0002;PBS_Server.1837;Svr;PBS_Server;Torque Server Version = 4.1.2, loglevel = 0
01/03/2013 11:53:38;0040;PBS_Server.16653;Svr;csg.bcmd.bcm.edu;Scheduler was sent the command time
01/03/2013 11:57:46;0002;PBS_Server.1831;Svr;PBS_Server;Torque Server Version = 4.1.2, loglevel = 0
01/03/2013 12:02:51;0002;PBS_Server.1833;Svr;PBS_Server;Torque Server Version = 4.1.2, loglevel = 0
01/03/2013 12:03:48;0040;PBS_Server.16735;Svr;csg.bcmd.bcm.edu;Scheduler was sent the command time
01/03/2013 12:07:56;0002;PBS_Server.1841;Svr;PBS_Server;Torque Server Version = 4.1.2, loglevel = 0
01/03/2013 12:13:01;0002;PBS_Server.1834;Svr;PBS_Server;Torque Server Version = 4.1.2, loglevel = 0
01/03/2013 12:13:58;0040;PBS_Server.16749;Svr;csg.bcmd.bcm.edu;Scheduler was sent the command time
01/03/2013 12:18:06;0002;PBS_Server.1832;Svr;PBS_Server;Torque Server Version = 4.1.2, loglevel = 0
01/03/2013 12:23:11;0002;PBS_Server.1829;Svr;PBS_Server;Torque Server Version = 4.1.2, loglevel = 0
01/03/2013 12:24:08;0040;PBS_Server.16851;Svr;csg.bcmd.bcm.edu;Scheduler was sent the command time
01/03/2013 12:28:16;0002;PBS_Server.1828;Svr;PBS_Server;Torque Server Version = 4.1.2, loglevel = 0
01/03/2013 12:33:21;0002;PBS_Server.1841;Svr;PBS_Server;Torque Server Version = 4.1.2, loglevel = 0
01/03/2013 12:34:18;0040;PBS_Server.16888;Svr;csg.bcmd.bcm.edu;Scheduler was sent the command time
01/03/2013 12:38:26;0002;PBS_Server.1834;Svr;PBS_Server;Torque Server Version = 4.1.2, loglevel = 0
01/03/2013 12:43:31;0002;PBS_Server.1839;Svr;PBS_Server;Torque Server Version = 4.1.2, loglevel = 0
01/03/2013 12:44:28;0040;PBS_Server.17046;Svr;csg.bcmd.bcm.edu;Scheduler was sent the command time
01/03/2013 12:48:36;0002;PBS_Server.1830;Svr;PBS_Server;Torque Server Version = 4.1.2, loglevel = 0
01/03/2013 12:53:41;0002;PBS_Server.1835;Svr;PBS_Server;Torque Server Version = 4.1.2, loglevel = 0
01/03/2013 12:54:38;0040;PBS_Server.17283;Svr;csg.bcmd.bcm.edu;Scheduler was sent the command time
01/03/2013 12:58:46;0002;PBS_Server.1834;Svr;PBS_Server;Torque Server Version = 4.1.2, loglevel = 0
01/03/2013 13:03:46;0002;PBS_Server.1837;Svr;PBS_Server;Torque Server Version = 4.1.2, loglevel = 0
01/03/2013 13:04:43;0040;PBS_Server.18356;Svr;csg.bcmd.bcm.edu;Scheduler was sent the command time
01/03/2013 13:08:51;0002;PBS_Server.1828;Svr;PBS_Server;Torque Server Version = 4.1.2, loglevel = 0
01/03/2013 13:13:51;0002;PBS_Server.1841;Svr;PBS_Server;Torque Server Version = 4.1.2, loglevel = 0
01/03/2013 13:14:48;0040;PBS_Server.19824;Svr;csg.bcmd.bcm.edu;Scheduler was sent the command time
01/03/2013 13:18:56;0002;PBS_Server.1828;Svr;PBS_Server;Torque Server Version = 4.1.2, loglevel = 0
01/03/2013 13:24:01;0002;PBS_Server.1836;Svr;PBS_Server;Torque Server Version = 4.1.2, loglevel = 0
01/03/2013 13:25:02;0040;PBS_Server.21464;Svr;csg.bcmd.bcm.edu;Scheduler was sent the command time
01/03/2013 13:29:10;0002;PBS_Server.1841;Svr;PBS_Server;Torque Server Version = 4.1.2, loglevel = 0
01/03/2013 13:34:17;0002;PBS_Server.1839;Svr;PBS_Server;Torque Server Version = 4.1.2, loglevel = 0
01/03/2013 13:35:07;0040;PBS_Server.23813;Svr;csg.bcmd.bcm.edu;Scheduler was sent the command time
01/03/2013 13:39:31;0002;PBS_Server.1832;Svr;PBS_Server;Torque Server Version = 4.1.2, loglevel = 0
01/03/2013 13:44:36;0002;PBS_Server.1836;Svr;PBS_Server;Torque Server Version = 4.1.2, loglevel = 0
01/03/2013 13:45:22;0040;PBS_Server.28657;Svr;csg.bcmd.bcm.edu;Scheduler was sent the command time
01/03/2013 13:49:46;0002;PBS_Server.1832;Svr;PBS_Server;Torque Server Version = 4.1.2, loglevel = 0
01/03/2013 13:54:46;0002;PBS_Server.1841;Svr;PBS_Server;Torque Server Version = 4.1.2, loglevel = 0
01/03/2013 13:55:32;0040;PBS_Server.2812;Svr;csg.bcmd.bcm.edu;Scheduler was sent the command time
01/03/2013 13:59:56;0002;PBS_Server.1836;Svr;PBS_Server;Torque Server Version = 4.1.2, loglevel = 0
01/03/2013 14:04:08;0100;PBS_Server.1835;Job;861.csg.bcmd.bcm.edu;enqueuing into batch, state 1 hop 1
01/03/2013 14:04:08;0002;PBS_Server.1835;Svr;Act;Account file /var/spool/torque/server_priv/accounting/20130103 opened
01/03/2013 14:04:08;0008;PBS_Server.1835;Job;861.csg.bcmd.bcm.edu;Job Queued at request of hooker@csg.bcmd.bcm.edu, owner = hooker@csg.bcmd.bcm.edu, job name = jobname1, queue = batch
01/03/2013 14:04:09;0040;PBS_Server.5800;Svr;csg.bcmd.bcm.edu;Scheduler was sent the command new
01/03/2013 14:04:09;0100;PBS_Server.1841;Job;862.csg.bcmd.bcm.edu;enqueuing into batch, state 1 hop 1
01/03/2013 14:04:09;0008;PBS_Server.1841;Job;862.csg.bcmd.bcm.edu;Job Queued at request of hooker@csg.bcmd.bcm.edu, owner = hooker@csg.bcmd.bcm.edu, job name = jobname2, queue = batch
01/03/2013 14:04:10;0008;PBS_Server.1840;Job;861.csg.bcmd.bcm.edu;Job Run at request of root@csg.bcmd.bcm.edu
01/03/2013 14:04:10;000d;PBS_Server.1840;Job;861.csg.bcmd.bcm.edu;Not sending email: User does not want mail of this type.
01/03/2013 14:04:10;0008;PBS_Server.1840;Job;862.csg.bcmd.bcm.edu;Job Run at request of root@csg.bcmd.bcm.edu
01/03/2013 14:04:10;000d;PBS_Server.1840;Job;862.csg.bcmd.bcm.edu;Not sending email: User does not want mail of this type.
01/03/2013 14:04:10;0040;PBS_Server.5808;Svr;csg.bcmd.bcm.edu;Scheduler was sent the command new
01/03/2013 14:04:19;000d;PBS_Server.1832;Job;861.csg.bcmd.bcm.edu;Not sending email: User does not want mail of this type.
01/03/2013 14:04:19;0010;PBS_Server.1832;Job;861.csg.bcmd.bcm.edu;Exit_status=0 resources_used.cput=00:00:08 resources_used.mem=0kb resources_used.vmem=0kb resources_used.walltime=00:00:09
01/03/2013 14:04:19;0008;PBS_Server.1839;Job;861.csg.bcmd.bcm.edu;on_job_exit valid pjob: 861.csg.bcmd.bcm.edu (substate=50)
01/03/2013 14:04:20;0040;PBS_Server.5885;Svr;csg.bcmd.bcm.edu;Scheduler was sent the command term
01/03/2013 14:04:20;000d;PBS_Server.1841;Job;862.csg.bcmd.bcm.edu;Not sending email: User does not want mail of this type.
01/03/2013 14:04:20;0010;PBS_Server.1841;Job;862.csg.bcmd.bcm.edu;Exit_status=0 resources_used.cput=00:00:09 resources_used.mem=43376kb resources_used.vmem=292588kb resources_used.walltime=00:00:10
01/03/2013 14:04:20;0008;PBS_Server.1836;Job;862.csg.bcmd.bcm.edu;on_job_exit valid pjob: 862.csg.bcmd.bcm.edu (substate=50)
01/03/2013 14:04:25;0040;PBS_Server.5910;Svr;csg.bcmd.bcm.edu;Scheduler was sent the command term
01/03/2013 14:05:10;0002;PBS_Server.1837;Svr;PBS_Server;Torque Server Version = 4.1.2, loglevel = 0
01/03/2013 14:05:32;0100;PBS_Server.1830;Job;863.csg.bcmd.bcm.edu;enqueuing into batch, state 1 hop 1
01/03/2013 14:05:32;0008;PBS_Server.1830;Job;863.csg.bcmd.bcm.edu;Job Queued at request of hooker@csg.bcmd.bcm.edu, owner = hooker@csg.bcmd.bcm.edu, job name = jobname1, queue = batch
01/03/2013 14:05:32;0100;PBS_Server.1832;Job;864.csg.bcmd.bcm.edu;enqueuing into batch, state 1 hop 1
01/03/2013 14:05:32;0008;PBS_Server.1832;Job;864.csg.bcmd.bcm.edu;Job Queued at request of hooker@csg.bcmd.bcm.edu, owner = hooker@csg.bcmd.bcm.edu, job name = jobname2, queue = batch
01/03/2013 14:05:35;0040;PBS_Server.6297;Svr;csg.bcmd.bcm.edu;Scheduler was sent the command new
01/03/2013 14:05:36;0008;PBS_Server.1840;Job;863.csg.bcmd.bcm.edu;Job Run at request of root@csg.bcmd.bcm.edu
01/03/2013 14:05:36;000d;PBS_Server.1840;Job;863.csg.bcmd.bcm.edu;Not sending email: User does not want mail of this type.
01/03/2013 14:05:36;0008;PBS_Server.1840;Job;864.csg.bcmd.bcm.edu;Job Run at request of root@csg.bcmd.bcm.edu
01/03/2013 14:05:36;000d;PBS_Server.1840;Job;864.csg.bcmd.bcm.edu;Not sending email: User does not want mail of this type.
01/03/2013 14:05:45;000d;PBS_Server.1836;Job;863.csg.bcmd.bcm.edu;Not sending email: User does not want mail of this type.
01/03/2013 14:05:45;0010;PBS_Server.1836;Job;863.csg.bcmd.bcm.edu;Exit_status=0 resources_used.cput=00:00:08 resources_used.mem=0kb resources_used.vmem=0kb resources_used.walltime=00:00:09
01/03/2013 14:05:45;0008;PBS_Server.1829;Job;863.csg.bcmd.bcm.edu;on_job_exit valid pjob: 863.csg.bcmd.bcm.edu (substate=50)
01/03/2013 14:05:45;0040;PBS_Server.6355;Svr;csg.bcmd.bcm.edu;Scheduler was sent the command term
01/03/2013 14:05:46;000d;PBS_Server.1835;Job;864.csg.bcmd.bcm.edu;Not sending email: User does not want mail of this type.
01/03/2013 14:05:46;0010;PBS_Server.1835;Job;864.csg.bcmd.bcm.edu;Exit_status=0 resources_used.cput=00:00:09 resources_used.mem=43660kb resources_used.vmem=292980kb resources_used.walltime=00:00:10
01/03/2013 14:05:46;0008;PBS_Server.1832;Job;864.csg.bcmd.bcm.edu;on_job_exit valid pjob: 864.csg.bcmd.bcm.edu (substate=50)
01/03/2013 14:05:50;0040;PBS_Server.6397;Svr;csg.bcmd.bcm.edu;Scheduler was sent the command term
01/03/2013 14:09:25;0008;PBS_Server.1837;Job;861.csg.bcmd.bcm.edu;on_job_exit valid pjob: 861.csg.bcmd.bcm.edu (substate=59)
01/03/2013 14:09:25;0008;PBS_Server.1836;Job;862.csg.bcmd.bcm.edu;on_job_exit valid pjob: 862.csg.bcmd.bcm.edu (substate=59)
01/03/2013 14:09:25;0100;PBS_Server.1837;Job;861.csg.bcmd.bcm.edu;dequeuing from batch, state COMPLETE
01/03/2013 14:09:25;0100;PBS_Server.1836;Job;862.csg.bcmd.bcm.edu;dequeuing from batch, state COMPLETE
01/03/2013 14:09:30;0040;PBS_Server.7622;Svr;csg.bcmd.bcm.edu;Scheduler was sent the command term
01/03/2013 14:10:10;0002;PBS_Server.1834;Svr;PBS_Server;Torque Server Version = 4.1.2, loglevel = 0
01/03/2013 14:10:55;0008;PBS_Server.1832;Job;863.csg.bcmd.bcm.edu;on_job_exit valid pjob: 863.csg.bcmd.bcm.edu (substate=59)
01/03/2013 14:10:55;0008;PBS_Server.1839;Job;864.csg.bcmd.bcm.edu;on_job_exit valid pjob: 864.csg.bcmd.bcm.edu (substate=59)
01/03/2013 14:10:55;0100;PBS_Server.1832;Job;863.csg.bcmd.bcm.edu;dequeuing from batch, state COMPLETE
01/03/2013 14:10:55;0100;PBS_Server.1839;Job;864.csg.bcmd.bcm.edu;dequeuing from batch, state COMPLETE
01/03/2013 14:11:01;0040;PBS_Server.8005;Svr;csg.bcmd.bcm.edu;Scheduler was sent the command term
01/03/2013 14:15:21;0002;PBS_Server.1837;Svr;PBS_Server;Torque Server Version = 4.1.2, loglevel = 0
01/03/2013 14:20:21;0002;PBS_Server.1835;Svr;PBS_Server;Torque Server Version = 4.1.2, loglevel = 0
01/03/2013 14:21:12;0040;PBS_Server.8150;Svr;csg.bcmd.bcm.edu;Scheduler was sent the command time
01/03/2013 14:25:32;0002;PBS_Server.1828;Svr;PBS_Server;Torque Server Version = 4.1.2, loglevel = 0
01/03/2013 14:30:32;0002;PBS_Server.1828;Svr;PBS_Server;Torque Server Version = 4.1.2, loglevel = 0
01/03/2013 14:31:18;0040;PBS_Server.8260;Svr;csg.bcmd.bcm.edu;Scheduler was sent the command time
01/03/2013 14:35:43;0002;PBS_Server.1830;Svr;PBS_Server;Torque Server Version = 4.1.2, loglevel = 0
01/03/2013 14:40:44;0002;PBS_Server.1837;Svr;PBS_Server;Torque Server Version = 4.1.2, loglevel = 0
01/03/2013 14:41:34;0040;PBS_Server.8373;Svr;csg.bcmd.bcm.edu;Scheduler was sent the command time
01/03/2013 14:45:44;0002;PBS_Server.1838;Svr;PBS_Server;Torque Server Version = 4.1.2, loglevel = 0
01/03/2013 14:50:53;0002;PBS_Server.1834;Svr;PBS_Server;Torque Server Version = 4.1.2, loglevel = 0
01/03/2013 14:51:39;0040;PBS_Server.8449;Svr;csg.bcmd.bcm.edu;Scheduler was sent the command time
01/03/2013 14:55:58;0002;PBS_Server.1841;Svr;PBS_Server;Torque Server Version = 4.1.2, loglevel = 0
01/03/2013 14:57:16;0100;PBS_Server.1833;Job;865.csg.bcmd.bcm.edu;enqueuing into high, state 1 hop 1
01/03/2013 14:57:16;0008;PBS_Server.1833;Job;865.csg.bcmd.bcm.edu;Job Queued at request of lacuesta@csg.bcmd.bcm.edu, owner = lacuesta@csg.bcmd.bcm.edu, job name = LVOTO_impute2_test_chr20, queue = high
01/03/2013 14:57:20;0040;PBS_Server.8482;Svr;csg.bcmd.bcm.edu;Scheduler was sent the command new
01/03/2013 14:57:20;0008;PBS_Server.1829;Job;865.csg.bcmd.bcm.edu;Job Run at request of root@csg.bcmd.bcm.edu
01/03/2013 14:57:20;000d;PBS_Server.1829;Job;865.csg.bcmd.bcm.edu;Not sending email: User does not want mail of this type.
01/03/2013 14:57:21;000d;PBS_Server.1837;Job;865.csg.bcmd.bcm.edu;Not sending email: User does not want mail of this type.
01/03/2013 14:57:21;0010;PBS_Server.1837;Job;865.csg.bcmd.bcm.edu;Exit_status=1 resources_used.cput=00:00:00 resources_used.mem=0kb resources_used.vmem=0kb resources_used.walltime=00:00:01
01/03/2013 14:57:21;0008;PBS_Server.1834;Job;865.csg.bcmd.bcm.edu;on_job_exit valid pjob: 865.csg.bcmd.bcm.edu (substate=50)
01/03/2013 14:57:25;0040;PBS_Server.8492;Svr;csg.bcmd.bcm.edu;Scheduler was sent the command term
01/03/2013 15:01:05;0002;PBS_Server.1836;Svr;PBS_Server;Torque Server Version = 4.1.2, loglevel = 0
01/03/2013 15:02:35;0008;PBS_Server.1839;Job;865.csg.bcmd.bcm.edu;on_job_exit valid pjob: 865.csg.bcmd.bcm.edu (substate=59)
01/03/2013 15:02:35;0100;PBS_Server.1839;Job;865.csg.bcmd.bcm.edu;dequeuing from high, state COMPLETE
01/03/2013 15:02:40;0040;PBS_Server.8537;Svr;csg.bcmd.bcm.edu;Scheduler was sent the command term
01/03/2013 15:03:53;0100;PBS_Server.1838;Job;866.csg.bcmd.bcm.edu;enqueuing into high, state 1 hop 1
01/03/2013 15:03:53;0008;PBS_Server.1838;Job;866.csg.bcmd.bcm.edu;Job Queued at request of lacuesta@csg.bcmd.bcm.edu, owner = lacuesta@csg.bcmd.bcm.edu, job name = SEM177_impute2_test_chr3, queue = high
01/03/2013 15:03:56;0040;PBS_Server.8557;Svr;csg.bcmd.bcm.edu;Scheduler was sent the command new
01/03/2013 15:03:57;0008;PBS_Server.1829;Job;866.csg.bcmd.bcm.edu;Job Run at request of root@csg.bcmd.bcm.edu
01/03/2013 15:03:57;000d;PBS_Server.1829;Job;866.csg.bcmd.bcm.edu;Not sending email: User does not want mail of this type.
01/03/2013 15:03:57;000d;PBS_Server.1832;Job;866.csg.bcmd.bcm.edu;Not sending email: User does not want mail of this type.
01/03/2013 15:03:57;0010;PBS_Server.1832;Job;866.csg.bcmd.bcm.edu;Exit_status=1 resources_used.cput=00:00:00 resources_used.mem=0kb resources_used.vmem=0kb resources_used.walltime=00:00:00
01/03/2013 15:03:57;0008;PBS_Server.1828;Job;866.csg.bcmd.bcm.edu;on_job_exit valid pjob: 866.csg.bcmd.bcm.edu (substate=50)
01/03/2013 15:04:00;0040;PBS_Server.8569;Svr;csg.bcmd.bcm.edu;Scheduler was sent the command term
01/03/2013 15:06:16;0002;PBS_Server.1839;Svr;PBS_Server;Torque Server Version = 4.1.2, loglevel = 0
01/03/2013 15:06:23;0100;PBS_Server.1837;Job;867.csg.bcmd.bcm.edu;enqueuing into high, state 1 hop 1
01/03/2013 15:06:23;0008;PBS_Server.1837;Job;867.csg.bcmd.bcm.edu;Job Queued at request of lacuesta@csg.bcmd.bcm.edu, owner = lacuesta@csg.bcmd.bcm.edu, job name = SEM177_impute2_test_chr3, queue = high
01/03/2013 15:06:26;0040;PBS_Server.8596;Svr;csg.bcmd.bcm.edu;Scheduler was sent the command new
01/03/2013 15:06:27;0008;PBS_Server.1829;Job;867.csg.bcmd.bcm.edu;Job Run at request of root@csg.bcmd.bcm.edu
01/03/2013 15:06:27;000d;PBS_Server.1829;Job;867.csg.bcmd.bcm.edu;Not sending email: User does not want mail of this type.
01/03/2013 15:07:20;000d;PBS_Server.1839;Job;867.csg.bcmd.bcm.edu;Not sending email: User does not want mail of this type.
01/03/2013 15:07:20;0010;PBS_Server.1839;Job;867.csg.bcmd.bcm.edu;Exit_status=0 resources_used.cput=00:00:51 resources_used.mem=246736kb resources_used.vmem=277116kb resources_used.walltime=00:00:53
01/03/2013 15:07:20;0008;PBS_Server.1835;Job;867.csg.bcmd.bcm.edu;on_job_exit valid pjob: 867.csg.bcmd.bcm.edu (substate=50)
01/03/2013 15:07:21;0040;PBS_Server.8626;Svr;csg.bcmd.bcm.edu;Scheduler was sent the command term
01/03/2013 15:09:01;0008;PBS_Server.1834;Job;866.csg.bcmd.bcm.edu;on_job_exit valid pjob: 866.csg.bcmd.bcm.edu (substate=59)
01/03/2013 15:09:01;0100;PBS_Server.1834;Job;866.csg.bcmd.bcm.edu;dequeuing from high, state COMPLETE
01/03/2013 15:09:06;0040;PBS_Server.8653;Svr;csg.bcmd.bcm.edu;Scheduler was sent the command term
01/03/2013 15:11:16;0002;PBS_Server.1837;Svr;PBS_Server;Torque Server Version = 4.1.2, loglevel = 0
01/03/2013 15:12:31;0008;PBS_Server.1833;Job;867.csg.bcmd.bcm.edu;on_job_exit valid pjob: 867.csg.bcmd.bcm.edu (substate=59)
01/03/2013 15:12:31;0100;PBS_Server.1833;Job;867.csg.bcmd.bcm.edu;dequeuing from high, state COMPLETE
01/03/2013 15:12:36;0040;PBS_Server.8673;Svr;csg.bcmd.bcm.edu;Scheduler was sent the command term
01/03/2013 15:16:27;0002;PBS_Server.1830;Svr;PBS_Server;Torque Server Version = 4.1.2, loglevel = 0
01/03/2013 15:17:14;0100;PBS_Server.1833;Job;868.csg.bcmd.bcm.edu;enqueuing into high, state 1 hop 1
01/03/2013 15:17:14;0008;PBS_Server.1833;Job;868.csg.bcmd.bcm.edu;Job Queued at request of lacuesta@csg.bcmd.bcm.edu, owner = lacuesta@csg.bcmd.bcm.edu, job name = ACSS99_impute2_test_chr11, queue = high
01/03/2013 15:17:17;0008;PBS_Server.1829;Job;868.csg.bcmd.bcm.edu;Job Run at request of root@csg.bcmd.bcm.edu
01/03/2013 15:17:17;000d;PBS_Server.1829;Job;868.csg.bcmd.bcm.edu;Not sending email: User does not want mail of this type.
01/03/2013 15:17:17;000d;PBS_Server.1834;Job;868.csg.bcmd.bcm.edu;Not sending email: User does not want mail of this type.
01/03/2013 15:17:17;0010;PBS_Server.1834;Job;868.csg.bcmd.bcm.edu;Exit_status=1 resources_used.cput=00:00:00 resources_used.mem=0kb resources_used.vmem=0kb resources_used.walltime=00:00:00
01/03/2013 15:17:17;0008;PBS_Server.1840;Job;868.csg.bcmd.bcm.edu;on_job_exit valid pjob: 868.csg.bcmd.bcm.edu (substate=50)
01/03/2013 15:17:17;0040;PBS_Server.8692;Svr;csg.bcmd.bcm.edu;Scheduler was sent the command new
01/03/2013 15:17:17;0040;PBS_Server.8697;Svr;csg.bcmd.bcm.edu;Scheduler was sent the command term
01/03/2013 15:19:17;0100;PBS_Server.1839;Job;869.csg.bcmd.bcm.edu;enqueuing into high, state 1 hop 1
01/03/2013 15:19:17;0008;PBS_Server.1839;Job;869.csg.bcmd.bcm.edu;Job Queued at request of lacuesta@csg.bcmd.bcm.edu, owner = lacuesta@csg.bcmd.bcm.edu, job name = ACSS99_impute2_test_chr11, queue = high
01/03/2013 15:19:17;0040;PBS_Server.8768;Svr;csg.bcmd.bcm.edu;Scheduler was sent the command new
01/03/2013 15:19:18;0008;PBS_Server.1829;Job;869.csg.bcmd.bcm.edu;Job Run at request of root@csg.bcmd.bcm.edu
01/03/2013 15:19:18;000d;PBS_Server.1829;Job;869.csg.bcmd.bcm.edu;Not sending email: User does not want mail of this type.
01/03/2013 15:19:18;000d;PBS_Server.1841;Job;869.csg.bcmd.bcm.edu;Not sending email: User does not want mail of this type.
01/03/2013 15:19:18;0010;PBS_Server.1841;Job;869.csg.bcmd.bcm.edu;Exit_status=1 resources_used.cput=00:00:00 resources_used.mem=0kb resources_used.vmem=0kb resources_used.walltime=00:00:00
01/03/2013 15:19:18;0008;PBS_Server.1833;Job;869.csg.bcmd.bcm.edu;on_job_exit valid pjob: 869.csg.bcmd.bcm.edu (substate=50)
01/03/2013 15:19:22;0040;PBS_Server.8779;Svr;csg.bcmd.bcm.edu;Scheduler was sent the command term
01/03/2013 15:20:42;0100;PBS_Server.1832;Job;870.csg.bcmd.bcm.edu;enqueuing into high, state 1 hop 1
01/03/2013 15:20:42;0008;PBS_Server.1832;Job;870.csg.bcmd.bcm.edu;Job Queued at request of lacuesta@csg.bcmd.bcm.edu, owner = lacuesta@csg.bcmd.bcm.edu, job name = ACSS99_impute2_test_chr11, queue = high
01/03/2013 15:20:43;0040;PBS_Server.8804;Svr;csg.bcmd.bcm.edu;Scheduler was sent the command new
01/03/2013 15:20:44;0008;PBS_Server.1829;Job;870.csg.bcmd.bcm.edu;Job Run at request of root@csg.bcmd.bcm.edu
01/03/2013 15:20:44;000d;PBS_Server.1829;Job;870.csg.bcmd.bcm.edu;Not sending email: User does not want mail of this type.
01/03/2013 15:21:13;000d;PBS_Server.1841;Job;870.csg.bcmd.bcm.edu;Not sending email: User does not want mail of this type.
01/03/2013 15:21:13;0010;PBS_Server.1841;Job;870.csg.bcmd.bcm.edu;Exit_status=0 resources_used.cput=00:00:27 resources_used.mem=198004kb resources_used.vmem=228532kb resources_used.walltime=00:00:29
01/03/2013 15:21:13;0008;PBS_Server.1831;Job;870.csg.bcmd.bcm.edu;on_job_exit valid pjob: 870.csg.bcmd.bcm.edu (substate=50)
01/03/2013 15:21:18;0040;PBS_Server.8831;Svr;csg.bcmd.bcm.edu;Scheduler was sent the command term
01/03/2013 15:21:38;0002;PBS_Server.1835;Svr;PBS_Server;Torque Server Version = 4.1.2, loglevel = 0
01/03/2013 15:22:23;0008;PBS_Server.1833;Job;868.csg.bcmd.bcm.edu;on_job_exit valid pjob: 868.csg.bcmd.bcm.edu (substate=59)
01/03/2013 15:22:23;0100;PBS_Server.1833;Job;868.csg.bcmd.bcm.edu;dequeuing from high, state COMPLETE
01/03/2013 15:22:28;0040;PBS_Server.8873;Svr;csg.bcmd.bcm.edu;Scheduler was sent the command term
01/03/2013 15:24:23;0008;PBS_Server.1830;Job;869.csg.bcmd.bcm.edu;on_job_exit valid pjob: 869.csg.bcmd.bcm.edu (substate=59)
01/03/2013 15:24:23;0100;PBS_Server.1830;Job;869.csg.bcmd.bcm.edu;dequeuing from high, state COMPLETE
01/03/2013 15:24:28;0040;PBS_Server.8929;Svr;csg.bcmd.bcm.edu;Scheduler was sent the command term
01/03/2013 15:26:23;0008;PBS_Server.1840;Job;870.csg.bcmd.bcm.edu;on_job_exit valid pjob: 870.csg.bcmd.bcm.edu (substate=59)
01/03/2013 15:26:23;0100;PBS_Server.1840;Job;870.csg.bcmd.bcm.edu;dequeuing from high, state COMPLETE
01/03/2013 15:26:28;0040;PBS_Server.8940;Svr;csg.bcmd.bcm.edu;Scheduler was sent the command term
01/03/2013 15:26:38;0002;PBS_Server.1832;Svr;PBS_Server;Torque Server Version = 4.1.2, loglevel = 0
01/03/2013 15:31:49;0002;PBS_Server.1831;Svr;PBS_Server;Torque Server Version = 4.1.2, loglevel = 0
01/03/2013 15:36:38;0040;PBS_Server.9073;Svr;csg.bcmd.bcm.edu;Scheduler was sent the command time
01/03/2013 15:36:59;0002;PBS_Server.1839;Svr;PBS_Server;Torque Server Version = 4.1.2, loglevel = 0
01/03/2013 15:42:04;0002;PBS_Server.1838;Svr;PBS_Server;Torque Server Version = 4.1.2, loglevel = 0
01/03/2013 15:46:48;0040;PBS_Server.9181;Svr;csg.bcmd.bcm.edu;Scheduler was sent the command time
01/03/2013 15:47:09;0002;PBS_Server.1841;Svr;PBS_Server;Torque Server Version = 4.1.2, loglevel = 0
01/03/2013 15:52:14;0002;PBS_Server.1833;Svr;PBS_Server;Torque Server Version = 4.1.2, loglevel = 0
01/03/2013 15:56:58;0040;PBS_Server.9229;Svr;csg.bcmd.bcm.edu;Scheduler was sent the command time
01/03/2013 15:57:19;0002;PBS_Server.1837;Svr;PBS_Server;Torque Server Version = 4.1.2, loglevel = 0
01/03/2013 16:02:24;0002;PBS_Server.1829;Svr;PBS_Server;Torque Server Version = 4.1.2, loglevel = 0
01/03/2013 16:07:08;0040;PBS_Server.9339;Svr;csg.bcmd.bcm.edu;Scheduler was sent the command time
01/03/2013 16:07:29;0002;PBS_Server.1837;Svr;PBS_Server;Torque Server Version = 4.1.2, loglevel = 0
01/03/2013 16:12:34;0002;PBS_Server.1833;Svr;PBS_Server;Torque Server Version = 4.1.2, loglevel = 0
01/03/2013 16:17:18;0040;PBS_Server.9434;Svr;csg.bcmd.bcm.edu;Scheduler was sent the command time
01/03/2013 16:17:39;0002;PBS_Server.1836;Svr;PBS_Server;Torque Server Version = 4.1.2, loglevel = 0
01/03/2013 16:22:44;0002;PBS_Server.1829;Svr;PBS_Server;Torque Server Version = 4.1.2, loglevel = 0
01/03/2013 16:27:28;0040;PBS_Server.9450;Svr;csg.bcmd.bcm.edu;Scheduler was sent the command time
01/03/2013 16:27:49;0002;PBS_Server.1831;Svr;PBS_Server;Torque Server Version = 4.1.2, loglevel = 0
01/03/2013 16:32:54;0002;PBS_Server.1828;Svr;PBS_Server;Torque Server Version = 4.1.2, loglevel = 0
01/03/2013 16:37:38;0040;PBS_Server.9465;Svr;csg.bcmd.bcm.edu;Scheduler was sent the command time
01/03/2013 16:37:59;0002;PBS_Server.1838;Svr;PBS_Server;Torque Server Version = 4.1.2, loglevel = 0
01/03/2013 16:43:04;0002;PBS_Server.1841;Svr;PBS_Server;Torque Server Version = 4.1.2, loglevel = 0
01/03/2013 16:47:48;0040;PBS_Server.9555;Svr;csg.bcmd.bcm.edu;Scheduler was sent the command time
01/03/2013 16:48:09;0002;PBS_Server.1829;Svr;PBS_Server;Torque Server Version = 4.1.2, loglevel = 0
01/03/2013 16:53:14;0002;PBS_Server.1836;Svr;PBS_Server;Torque Server Version = 4.1.2, loglevel = 0
01/03/2013 16:57:58;0040;PBS_Server.9571;Svr;csg.bcmd.bcm.edu;Scheduler was sent the command time
01/03/2013 16:58:19;0002;PBS_Server.1831;Svr;PBS_Server;Torque Server Version = 4.1.2, loglevel = 0
01/03/2013 17:03:24;0002;PBS_Server.1829;Svr;PBS_Server;Torque Server Version = 4.1.2, loglevel = 0
01/03/2013 17:08:08;0040;PBS_Server.9590;Svr;csg.bcmd.bcm.edu;Scheduler was sent the command time
01/03/2013 17:08:29;0002;PBS_Server.1840;Svr;PBS_Server;Torque Server Version = 4.1.2, loglevel = 0
01/03/2013 17:13:34;0002;PBS_Server.1828;Svr;PBS_Server;Torque Server Version = 4.1.2, loglevel = 0
01/03/2013 17:18:18;0040;PBS_Server.9612;Svr;csg.bcmd.bcm.edu;Scheduler was sent the command time
01/03/2013 17:18:39;0002;PBS_Server.1840;Svr;PBS_Server;Torque Server Version = 4.1.2, loglevel = 0
01/03/2013 17:23:44;0002;PBS_Server.1839;Svr;PBS_Server;Torque Server Version = 4.1.2, loglevel = 0
01/03/2013 17:28:28;0040;PBS_Server.9627;Svr;csg.bcmd.bcm.edu;Scheduler was sent the command time
01/03/2013 17:28:49;0002;PBS_Server.1840;Svr;PBS_Server;Torque Server Version = 4.1.2, loglevel = 0
01/03/2013 17:33:54;0002;PBS_Server.1835;Svr;PBS_Server;Torque Server Version = 4.1.2, loglevel = 0
01/03/2013 17:38:38;0040;PBS_Server.9642;Svr;csg.bcmd.bcm.edu;Scheduler was sent the command time
01/03/2013 17:38:59;0002;PBS_Server.1830;Svr;PBS_Server;Torque Server Version = 4.1.2, loglevel = 0
01/03/2013 17:44:04;0002;PBS_Server.1839;Svr;PBS_Server;Torque Server Version = 4.1.2, loglevel = 0
01/03/2013 17:48:48;0040;PBS_Server.9676;Svr;csg.bcmd.bcm.edu;Scheduler was sent the command time
01/03/2013 17:49:09;0002;PBS_Server.1841;Svr;PBS_Server;Torque Server Version = 4.1.2, loglevel = 0
01/03/2013 17:54:14;0002;PBS_Server.1839;Svr;PBS_Server;Torque Server Version = 4.1.2, loglevel = 0
01/03/2013 17:58:58;0040;PBS_Server.9798;Svr;csg.bcmd.bcm.edu;Scheduler was sent the command time
01/03/2013 17:59:19;0002;PBS_Server.1841;Svr;PBS_Server;Torque Server Version = 4.1.2, loglevel = 0
01/03/2013 18:04:24;0002;PBS_Server.1833;Svr;PBS_Server;Torque Server Version = 4.1.2, loglevel = 0
01/03/2013 18:09:08;0040;PBS_Server.9819;Svr;csg.bcmd.bcm.edu;Scheduler was sent the command time
01/03/2013 18:09:29;0002;PBS_Server.1830;Svr;PBS_Server;Torque Server Version = 4.1.2, loglevel = 0
01/03/2013 18:14:34;0002;PBS_Server.1835;Svr;PBS_Server;Torque Server Version = 4.1.2, loglevel = 0
01/03/2013 18:19:18;0040;PBS_Server.9833;Svr;csg.bcmd.bcm.edu;Scheduler was sent the command time
01/03/2013 18:19:39;0002;PBS_Server.1836;Svr;PBS_Server;Torque Server Version = 4.1.2, loglevel = 0
01/03/2013 18:24:44;0002;PBS_Server.1840;Svr;PBS_Server;Torque Server Version = 4.1.2, loglevel = 0
01/03/2013 18:29:28;0040;PBS_Server.9848;Svr;csg.bcmd.bcm.edu;Scheduler was sent the command time
01/03/2013 18:29:49;0002;PBS_Server.1841;Svr;PBS_Server;Torque Server Version = 4.1.2, loglevel = 0
01/03/2013 18:34:54;0002;PBS_Server.1832;Svr;PBS_Server;Torque Server Version = 4.1.2, loglevel = 0
01/03/2013 18:39:38;0040;PBS_Server.9879;Svr;csg.bcmd.bcm.edu;Scheduler was sent the command time
01/03/2013 18:39:59;0002;PBS_Server.1839;Svr;PBS_Server;Torque Server Version = 4.1.2, loglevel = 0
01/03/2013 18:41:56;0100;PBS_Server.1832;Job;871.csg.bcmd.bcm.edu;enqueuing into batch, state 1 hop 1
01/03/2013 18:41:56;0008;PBS_Server.1832;Job;871.csg.bcmd.bcm.edu;Job Queued at request of hooker@csg.bcmd.bcm.edu, owner = hooker@csg.bcmd.bcm.edu, job name = jobname1, queue = batch
01/03/2013 18:41:56;0100;PBS_Server.1840;Job;872.csg.bcmd.bcm.edu;enqueuing into batch, state 1 hop 1
01/03/2013 18:41:56;0008;PBS_Server.1840;Job;872.csg.bcmd.bcm.edu;Job Queued at request of hooker@csg.bcmd.bcm.edu, owner = hooker@csg.bcmd.bcm.edu, job name = jobname2, queue = batch
01/03/2013 18:41:58;0040;PBS_Server.9906;Svr;csg.bcmd.bcm.edu;Scheduler was sent the command new
01/03/2013 18:41:59;0008;PBS_Server.1831;Job;871.csg.bcmd.bcm.edu;Job Run at request of root@csg.bcmd.bcm.edu
01/03/2013 18:41:59;000d;PBS_Server.1831;Job;871.csg.bcmd.bcm.edu;Not sending email: User does not want mail of this type.
01/03/2013 18:41:59;0008;PBS_Server.1831;Job;872.csg.bcmd.bcm.edu;Job Run at request of root@csg.bcmd.bcm.edu
01/03/2013 18:41:59;000d;PBS_Server.1831;Job;872.csg.bcmd.bcm.edu;Not sending email: User does not want mail of this type.
01/03/2013 18:42:09;000d;PBS_Server.1837;Job;871.csg.bcmd.bcm.edu;Not sending email: User does not want mail of this type.
01/03/2013 18:42:09;0010;PBS_Server.1837;Job;871.csg.bcmd.bcm.edu;Exit_status=0 resources_used.cput=00:00:09 resources_used.mem=0kb resources_used.vmem=0kb resources_used.walltime=00:00:10
01/03/2013 18:42:09;0008;PBS_Server.1832;Job;871.csg.bcmd.bcm.edu;on_job_exit valid pjob: 871.csg.bcmd.bcm.edu (substate=50)
01/03/2013 18:42:10;000d;PBS_Server.1840;Job;872.csg.bcmd.bcm.edu;Not sending email: User does not want mail of this type.
01/03/2013 18:42:10;0010;PBS_Server.1840;Job;872.csg.bcmd.bcm.edu;Exit_status=0 resources_used.cput=00:00:10 resources_used.mem=43388kb resources_used.vmem=292608kb resources_used.walltime=00:00:11
01/03/2013 18:42:10;0008;PBS_Server.1834;Job;872.csg.bcmd.bcm.edu;on_job_exit valid pjob: 872.csg.bcmd.bcm.edu (substate=50)
01/03/2013 18:42:14;0040;PBS_Server.9925;Svr;csg.bcmd.bcm.edu;Scheduler was sent the command term
01/03/2013 18:45:09;0002;PBS_Server.1830;Svr;PBS_Server;Torque Server Version = 4.1.2, loglevel = 0
01/03/2013 18:45:10;0100;PBS_Server.1833;Job;873.csg.bcmd.bcm.edu;enqueuing into batch, state 1 hop 1
01/03/2013 18:45:10;0008;PBS_Server.1833;Job;873.csg.bcmd.bcm.edu;Job Queued at request of hooker@csg.bcmd.bcm.edu, owner = hooker@csg.bcmd.bcm.edu, job name = jobname1, queue = batch
01/03/2013 18:45:11;0100;PBS_Server.1839;Job;874.csg.bcmd.bcm.edu;enqueuing into batch, state 1 hop 1
01/03/2013 18:45:11;0008;PBS_Server.1839;Job;874.csg.bcmd.bcm.edu;Job Queued at request of hooker@csg.bcmd.bcm.edu, owner = hooker@csg.bcmd.bcm.edu, job name = jobname2, queue = batch
01/03/2013 18:45:14;0040;PBS_Server.9942;Svr;csg.bcmd.bcm.edu;Scheduler was sent the command new
01/03/2013 18:45:15;0008;PBS_Server.1831;Job;873.csg.bcmd.bcm.edu;Job Run at request of root@csg.bcmd.bcm.edu
01/03/2013 18:45:15;000d;PBS_Server.1831;Job;873.csg.bcmd.bcm.edu;Not sending email: User does not want mail of this type.
01/03/2013 18:45:15;0008;PBS_Server.1831;Job;874.csg.bcmd.bcm.edu;Job Run at request of root@csg.bcmd.bcm.edu
01/03/2013 18:45:15;000d;PBS_Server.1831;Job;874.csg.bcmd.bcm.edu;Not sending email: User does not want mail of this type.
01/03/2013 18:45:26;000d;PBS_Server.1829;Job;873.csg.bcmd.bcm.edu;Not sending email: User does not want mail of this type.
01/03/2013 18:45:26;0010;PBS_Server.1829;Job;873.csg.bcmd.bcm.edu;Exit_status=0 resources_used.cput=00:00:09 resources_used.mem=0kb resources_used.vmem=0kb resources_used.walltime=00:00:11
01/03/2013 18:45:26;0008;PBS_Server.1838;Job;873.csg.bcmd.bcm.edu;on_job_exit valid pjob: 873.csg.bcmd.bcm.edu (substate=50)
01/03/2013 18:45:27;000d;PBS_Server.1830;Job;874.csg.bcmd.bcm.edu;Not sending email: User does not want mail of this type.
01/03/2013 18:45:27;0010;PBS_Server.1830;Job;874.csg.bcmd.bcm.edu;Exit_status=0 resources_used.cput=00:00:10 resources_used.mem=45144kb resources_used.vmem=298124kb resources_used.walltime=00:00:12
01/03/2013 18:45:27;0008;PBS_Server.1841;Job;874.csg.bcmd.bcm.edu;on_job_exit valid pjob: 874.csg.bcmd.bcm.edu (substate=50)
01/03/2013 18:45:29;0040;PBS_Server.9963;Svr;csg.bcmd.bcm.edu;Scheduler was sent the command term
01/03/2013 18:47:09;0008;PBS_Server.1839;Job;871.csg.bcmd.bcm.edu;on_job_exit valid pjob: 871.csg.bcmd.bcm.edu (substate=59)
01/03/2013 18:47:09;0100;PBS_Server.1839;Job;871.csg.bcmd.bcm.edu;dequeuing from batch, state COMPLETE
01/03/2013 18:47:14;0040;PBS_Server.10002;Svr;csg.bcmd.bcm.edu;Scheduler was sent the command term
01/03/2013 18:47:24;0008;PBS_Server.1830;Job;872.csg.bcmd.bcm.edu;on_job_exit valid pjob: 872.csg.bcmd.bcm.edu (substate=59)
01/03/2013 18:47:24;0100;PBS_Server.1830;Job;872.csg.bcmd.bcm.edu;dequeuing from batch, state COMPLETE
01/03/2013 18:47:29;0040;PBS_Server.10005;Svr;csg.bcmd.bcm.edu;Scheduler was sent the command term
01/03/2013 18:49:46;0100;PBS_Server.1836;Job;875.csg.bcmd.bcm.edu;enqueuing into batch, state 1 hop 1
01/03/2013 18:49:46;0008;PBS_Server.1836;Job;875.csg.bcmd.bcm.edu;Job Queued at request of hooker@csg.bcmd.bcm.edu, owner = hooker@csg.bcmd.bcm.edu, job name = jobname1, queue = batch
01/03/2013 18:49:46;0100;PBS_Server.1830;Job;876.csg.bcmd.bcm.edu;enqueuing into batch, state 1 hop 1
01/03/2013 18:49:46;0008;PBS_Server.1830;Job;876.csg.bcmd.bcm.edu;Job Queued at request of hooker@csg.bcmd.bcm.edu, owner = hooker@csg.bcmd.bcm.edu, job name = jobname2, queue = batch
01/03/2013 18:49:49;0040;PBS_Server.10028;Svr;csg.bcmd.bcm.edu;Scheduler was sent the command new
01/03/2013 18:49:51;0008;PBS_Server.1831;Job;875.csg.bcmd.bcm.edu;Job Run at request of root@csg.bcmd.bcm.edu
01/03/2013 18:49:51;000d;PBS_Server.1831;Job;875.csg.bcmd.bcm.edu;Not sending email: User does not want mail of this type.
01/03/2013 18:49:51;0008;PBS_Server.1831;Job;876.csg.bcmd.bcm.edu;Job Run at request of root@csg.bcmd.bcm.edu
01/03/2013 18:49:51;000d;PBS_Server.1831;Job;876.csg.bcmd.bcm.edu;Not sending email: User does not want mail of this type.
01/03/2013 18:50:00;0100;PBS_Server.1837;Job;877.csg.bcmd.bcm.edu;enqueuing into batch, state 1 hop 1
01/03/2013 18:50:00;0008;PBS_Server.1837;Job;877.csg.bcmd.bcm.edu;Job Queued at request of hooker@csg.bcmd.bcm.edu, owner = hooker@csg.bcmd.bcm.edu, job name = jobname1, queue = batch
01/03/2013 18:50:00;0100;PBS_Server.1834;Job;878.csg.bcmd.bcm.edu;enqueuing into batch, state 1 hop 1
01/03/2013 18:50:00;0008;PBS_Server.1834;Job;878.csg.bcmd.bcm.edu;Job Queued at request of hooker@csg.bcmd.bcm.edu, owner = hooker@csg.bcmd.bcm.edu, job name = jobname2, queue = batch
01/03/2013 18:50:01;000d;PBS_Server.1841;Job;875.csg.bcmd.bcm.edu;Not sending email: User does not want mail of this type.
01/03/2013 18:50:01;0010;PBS_Server.1841;Job;875.csg.bcmd.bcm.edu;Exit_status=0 resources_used.cput=00:00:09 resources_used.mem=0kb resources_used.vmem=0kb resources_used.walltime=00:00:10
01/03/2013 18:50:01;0008;PBS_Server.1836;Job;875.csg.bcmd.bcm.edu;on_job_exit valid pjob: 875.csg.bcmd.bcm.edu (substate=50)
01/03/2013 18:50:02;000d;PBS_Server.1828;Job;876.csg.bcmd.bcm.edu;Not sending email: User does not want mail of this type.
01/03/2013 18:50:02;0010;PBS_Server.1828;Job;876.csg.bcmd.bcm.edu;Exit_status=0 resources_used.cput=00:00:10 resources_used.mem=43388kb resources_used.vmem=292608kb resources_used.walltime=00:00:11
01/03/2013 18:50:02;0008;PBS_Server.1839;Job;876.csg.bcmd.bcm.edu;on_job_exit valid pjob: 876.csg.bcmd.bcm.edu (substate=50)
01/03/2013 18:50:04;0040;PBS_Server.10062;Svr;csg.bcmd.bcm.edu;Scheduler was sent the command term
01/03/2013 18:50:06;0008;PBS_Server.1831;Job;877.csg.bcmd.bcm.edu;Job Run at request of root@csg.bcmd.bcm.edu
01/03/2013 18:50:06;000d;PBS_Server.1831;Job;877.csg.bcmd.bcm.edu;Not sending email: User does not want mail of this type.
01/03/2013 18:50:06;0008;PBS_Server.1831;Job;878.csg.bcmd.bcm.edu;Job Run at request of root@csg.bcmd.bcm.edu
01/03/2013 18:50:06;000d;PBS_Server.1831;Job;878.csg.bcmd.bcm.edu;Not sending email: User does not want mail of this type.
01/03/2013 18:50:09;0002;PBS_Server.1841;Svr;PBS_Server;Torque Server Version = 4.1.2, loglevel = 0
01/03/2013 18:50:16;000d;PBS_Server.1828;Job;877.csg.bcmd.bcm.edu;Not sending email: User does not want mail of this type.
01/03/2013 18:50:16;0010;PBS_Server.1828;Job;877.csg.bcmd.bcm.edu;Exit_status=0 resources_used.cput=00:00:09 resources_used.mem=0kb resources_used.vmem=0kb resources_used.walltime=00:00:10
01/03/2013 18:50:16;0008;PBS_Server.1832;Job;877.csg.bcmd.bcm.edu;on_job_exit valid pjob: 877.csg.bcmd.bcm.edu (substate=50)
01/03/2013 18:50:18;000d;PBS_Server.1837;Job;878.csg.bcmd.bcm.edu;Not sending email: User does not want mail of this type.
01/03/2013 18:50:18;0010;PBS_Server.1837;Job;878.csg.bcmd.bcm.edu;Exit_status=0 resources_used.cput=00:00:10 resources_used.mem=50684kb resources_used.vmem=197996kb resources_used.walltime=00:00:12
01/03/2013 18:50:18;0008;PBS_Server.1840;Job;878.csg.bcmd.bcm.edu;on_job_exit valid pjob: 878.csg.bcmd.bcm.edu (substate=50)
01/03/2013 18:50:19;0040;PBS_Server.10079;Svr;csg.bcmd.bcm.edu;Scheduler was sent the command term
01/03/2013 18:50:39;0008;PBS_Server.1839;Job;873.csg.bcmd.bcm.edu;on_job_exit valid pjob: 873.csg.bcmd.bcm.edu (substate=59)
01/03/2013 18:50:39;0008;PBS_Server.1829;Job;874.csg.bcmd.bcm.edu;on_job_exit valid pjob: 874.csg.bcmd.bcm.edu (substate=59)
01/03/2013 18:50:39;0100;PBS_Server.1839;Job;873.csg.bcmd.bcm.edu;dequeuing from batch, state COMPLETE
01/03/2013 18:50:39;0100;PBS_Server.1829;Job;874.csg.bcmd.bcm.edu;dequeuing from batch, state COMPLETE
01/03/2013 18:50:44;0040;PBS_Server.10080;Svr;csg.bcmd.bcm.edu;Scheduler was sent the command term
01/03/2013 18:55:05;0008;PBS_Server.1832;Job;875.csg.bcmd.bcm.edu;on_job_exit valid pjob: 875.csg.bcmd.bcm.edu (substate=59)
01/03/2013 18:55:05;0008;PBS_Server.1830;Job;876.csg.bcmd.bcm.edu;on_job_exit valid pjob: 876.csg.bcmd.bcm.edu (substate=59)
01/03/2013 18:55:05;0100;PBS_Server.1832;Job;875.csg.bcmd.bcm.edu;dequeuing from batch, state COMPLETE
01/03/2013 18:55:05;0100;PBS_Server.1830;Job;876.csg.bcmd.bcm.edu;dequeuing from batch, state COMPLETE
01/03/2013 18:55:10;0040;PBS_Server.10103;Svr;csg.bcmd.bcm.edu;Scheduler was sent the command term
01/03/2013 18:55:20;0002;PBS_Server.1834;Svr;PBS_Server;Torque Server Version = 4.1.2, loglevel = 0
01/03/2013 18:55:20;0008;PBS_Server.1835;Job;877.csg.bcmd.bcm.edu;on_job_exit valid pjob: 877.csg.bcmd.bcm.edu (substate=59)
01/03/2013 18:55:20;0008;PBS_Server.1838;Job;878.csg.bcmd.bcm.edu;on_job_exit valid pjob: 878.csg.bcmd.bcm.edu (substate=59)
01/03/2013 18:55:20;0100;PBS_Server.1835;Job;877.csg.bcmd.bcm.edu;dequeuing from batch, state COMPLETE
01/03/2013 18:55:20;0100;PBS_Server.1838;Job;878.csg.bcmd.bcm.edu;dequeuing from batch, state COMPLETE
01/03/2013 18:55:25;0040;PBS_Server.10104;Svr;csg.bcmd.bcm.edu;Scheduler was sent the command term
01/03/2013 19:00:30;0002;PBS_Server.1829;Svr;PBS_Server;Torque Server Version = 4.1.2, loglevel = 0
01/03/2013 19:05:35;0002;PBS_Server.1830;Svr;PBS_Server;Torque Server Version = 4.1.2, loglevel = 0
01/03/2013 19:05:40;0040;PBS_Server.10125;Svr;csg.bcmd.bcm.edu;Scheduler was sent the command time
01/03/2013 19:10:40;0002;PBS_Server.1841;Svr;PBS_Server;Torque Server Version = 4.1.2, loglevel = 0
01/03/2013 19:15:45;0002;PBS_Server.1833;Svr;PBS_Server;Torque Server Version = 4.1.2, loglevel = 0
01/03/2013 19:15:50;0040;PBS_Server.10140;Svr;csg.bcmd.bcm.edu;Scheduler was sent the command time
01/03/2013 19:20:50;0002;PBS_Server.1828;Svr;PBS_Server;Torque Server Version = 4.1.2, loglevel = 0
01/03/2013 19:25:55;0002;PBS_Server.1836;Svr;PBS_Server;Torque Server Version = 4.1.2, loglevel = 0
01/03/2013 19:26:00;0040;PBS_Server.10154;Svr;csg.bcmd.bcm.edu;Scheduler was sent the command time
01/03/2013 19:31:00;0002;PBS_Server.1835;Svr;PBS_Server;Torque Server Version = 4.1.2, loglevel = 0
01/03/2013 19:36:05;0002;PBS_Server.1829;Svr;PBS_Server;Torque Server Version = 4.1.2, loglevel = 0
01/03/2013 19:36:10;0040;PBS_Server.10169;Svr;csg.bcmd.bcm.edu;Scheduler was sent the command time
01/03/2013 19:41:10;0002;PBS_Server.1841;Svr;PBS_Server;Torque Server Version = 4.1.2, loglevel = 0
01/03/2013 19:46:15;0002;PBS_Server.1832;Svr;PBS_Server;Torque Server Version = 4.1.2, loglevel = 0
01/03/2013 19:46:20;0040;PBS_Server.10184;Svr;csg.bcmd.bcm.edu;Scheduler was sent the command time
01/03/2013 19:51:20;0002;PBS_Server.1841;Svr;PBS_Server;Torque Server Version = 4.1.2, loglevel = 0
01/03/2013 19:56:25;0002;PBS_Server.1834;Svr;PBS_Server;Torque Server Version = 4.1.2, loglevel = 0
01/03/2013 19:56:30;0040;PBS_Server.10201;Svr;csg.bcmd.bcm.edu;Scheduler was sent the command time
01/03/2013 20:01:30;0002;PBS_Server.1841;Svr;PBS_Server;Torque Server Version = 4.1.2, loglevel = 0
01/03/2013 20:06:35;0002;PBS_Server.1840;Svr;PBS_Server;Torque Server Version = 4.1.2, loglevel = 0
01/03/2013 20:06:40;0040;PBS_Server.10223;Svr;csg.bcmd.bcm.edu;Scheduler was sent the command time
01/03/2013 20:11:40;0002;PBS_Server.1832;Svr;PBS_Server;Torque Server Version = 4.1.2, loglevel = 0
01/03/2013 20:16:45;0002;PBS_Server.1831;Svr;PBS_Server;Torque Server Version = 4.1.2, loglevel = 0
01/03/2013 20:16:50;0040;PBS_Server.10237;Svr;csg.bcmd.bcm.edu;Scheduler was sent the command time
01/03/2013 20:21:50;0002;PBS_Server.1832;Svr;PBS_Server;Torque Server Version = 4.1.2, loglevel = 0
01/03/2013 20:26:55;0002;PBS_Server.1840;Svr;PBS_Server;Torque Server Version = 4.1.2, loglevel = 0
01/03/2013 20:27:00;0040;PBS_Server.10251;Svr;csg.bcmd.bcm.edu;Scheduler was sent the command time
01/03/2013 20:32:00;0002;PBS_Server.1837;Svr;PBS_Server;Torque Server Version = 4.1.2, loglevel = 0
01/03/2013 20:37:05;0002;PBS_Server.1839;Svr;PBS_Server;Torque Server Version = 4.1.2, loglevel = 0
01/03/2013 20:37:10;0040;PBS_Server.10266;Svr;csg.bcmd.bcm.edu;Scheduler was sent the command time
01/03/2013 20:42:10;0002;PBS_Server.1833;Svr;PBS_Server;Torque Server Version = 4.1.2, loglevel = 0
01/03/2013 20:47:15;0002;PBS_Server.1831;Svr;PBS_Server;Torque Server Version = 4.1.2, loglevel = 0
01/03/2013 20:47:20;0040;PBS_Server.10281;Svr;csg.bcmd.bcm.edu;Scheduler was sent the command time
01/03/2013 20:52:20;0002;PBS_Server.1828;Svr;PBS_Server;Torque Server Version = 4.1.2, loglevel = 0
01/03/2013 20:57:25;0002;PBS_Server.1834;Svr;PBS_Server;Torque Server Version = 4.1.2, loglevel = 0
01/03/2013 20:57:30;0040;PBS_Server.10296;Svr;csg.bcmd.bcm.edu;Scheduler was sent the command time
01/03/2013 21:02:30;0002;PBS_Server.1838;Svr;PBS_Server;Torque Server Version = 4.1.2, loglevel = 0
01/03/2013 21:07:35;0002;PBS_Server.1835;Svr;PBS_Server;Torque Server Version = 4.1.2, loglevel = 0
01/03/2013 21:07:40;0040;PBS_Server.10315;Svr;csg.bcmd.bcm.edu;Scheduler was sent the command time
01/03/2013 21:12:40;0002;PBS_Server.1838;Svr;PBS_Server;Torque Server Version = 4.1.2, loglevel = 0
01/03/2013 21:17:45;0002;PBS_Server.1833;Svr;PBS_Server;Torque Server Version = 4.1.2, loglevel = 0
01/03/2013 21:17:50;0040;PBS_Server.10330;Svr;csg.bcmd.bcm.edu;Scheduler was sent the command time
01/03/2013 21:22:50;0002;PBS_Server.1828;Svr;PBS_Server;Torque Server Version = 4.1.2, loglevel = 0
01/03/2013 21:27:55;0002;PBS_Server.1835;Svr;PBS_Server;Torque Server Version = 4.1.2, loglevel = 0
01/03/2013 21:28:00;0040;PBS_Server.10344;Svr;csg.bcmd.bcm.edu;Scheduler was sent the command time
01/03/2013 21:33:00;0002;PBS_Server.1832;Svr;PBS_Server;Torque Server Version = 4.1.2, loglevel = 0
01/03/2013 21:38:05;0002;PBS_Server.1835;Svr;PBS_Server;Torque Server Version = 4.1.2, loglevel = 0
01/03/2013 21:38:10;0040;PBS_Server.10360;Svr;csg.bcmd.bcm.edu;Scheduler was sent the command time
01/03/2013 21:43:10;0002;PBS_Server.1834;Svr;PBS_Server;Torque Server Version = 4.1.2, loglevel = 0
01/03/2013 21:48:15;0002;PBS_Server.1837;Svr;PBS_Server;Torque Server Version = 4.1.2, loglevel = 0
01/03/2013 21:48:20;0040;PBS_Server.10374;Svr;csg.bcmd.bcm.edu;Scheduler was sent the command time
01/03/2013 21:53:20;0002;PBS_Server.1839;Svr;PBS_Server;Torque Server Version = 4.1.2, loglevel = 0
01/03/2013 21:58:25;0002;PBS_Server.1837;Svr;PBS_Server;Torque Server Version = 4.1.2, loglevel = 0
01/03/2013 21:58:30;0040;PBS_Server.10388;Svr;csg.bcmd.bcm.edu;Scheduler was sent the command time
01/03/2013 22:03:30;0002;PBS_Server.1840;Svr;PBS_Server;Torque Server Version = 4.1.2, loglevel = 0
01/03/2013 22:08:35;0002;PBS_Server.1828;Svr;PBS_Server;Torque Server Version = 4.1.2, loglevel = 0
01/03/2013 22:08:40;0040;PBS_Server.10407;Svr;csg.bcmd.bcm.edu;Scheduler was sent the command time
01/03/2013 22:13:40;0002;PBS_Server.1833;Svr;PBS_Server;Torque Server Version = 4.1.2, loglevel = 0
01/03/2013 22:18:45;0002;PBS_Server.1831;Svr;PBS_Server;Torque Server Version = 4.1.2, loglevel = 0
01/03/2013 22:18:50;0040;PBS_Server.10423;Svr;csg.bcmd.bcm.edu;Scheduler was sent the command time
01/03/2013 22:23:50;0002;PBS_Server.1839;Svr;PBS_Server;Torque Server Version = 4.1.2, loglevel = 0
01/03/2013 22:28:55;0002;PBS_Server.1829;Svr;PBS_Server;Torque Server Version = 4.1.2, loglevel = 0
01/03/2013 22:29:00;0040;PBS_Server.10437;Svr;csg.bcmd.bcm.edu;Scheduler was sent the command time
01/03/2013 22:34:00;0002;PBS_Server.1833;Svr;PBS_Server;Torque Server Version = 4.1.2, loglevel = 0
01/03/2013 22:39:05;0002;PBS_Server.1841;Svr;PBS_Server;Torque Server Version = 4.1.2, loglevel = 0
01/03/2013 22:39:10;0040;PBS_Server.10452;Svr;csg.bcmd.bcm.edu;Scheduler was sent the command time
01/03/2013 22:44:10;0002;PBS_Server.1837;Svr;PBS_Server;Torque Server Version = 4.1.2, loglevel = 0
01/03/2013 22:49:15;0002;PBS_Server.1838;Svr;PBS_Server;Torque Server Version = 4.1.2, loglevel = 0
01/03/2013 22:49:20;0040;PBS_Server.10466;Svr;csg.bcmd.bcm.edu;Scheduler was sent the command time
01/03/2013 22:54:20;0002;PBS_Server.1839;Svr;PBS_Server;Torque Server Version = 4.1.2, loglevel = 0
01/03/2013 22:59:25;0002;PBS_Server.1832;Svr;PBS_Server;Torque Server Version = 4.1.2, loglevel = 0
01/03/2013 22:59:30;0040;PBS_Server.10480;Svr;csg.bcmd.bcm.edu;Scheduler was sent the command time
01/03/2013 23:04:30;0002;PBS_Server.1828;Svr;PBS_Server;Torque Server Version = 4.1.2, loglevel = 0
01/03/2013 23:09:35;0002;PBS_Server.1830;Svr;PBS_Server;Torque Server Version = 4.1.2, loglevel = 0
01/03/2013 23:09:40;0040;PBS_Server.10500;Svr;csg.bcmd.bcm.edu;Scheduler was sent the command time
01/03/2013 23:14:40;0002;PBS_Server.1839;Svr;PBS_Server;Torque Server Version = 4.1.2, loglevel = 0
01/03/2013 23:19:45;0002;PBS_Server.1830;Svr;PBS_Server;Torque Server Version = 4.1.2, loglevel = 0
01/03/2013 23:19:50;0040;PBS_Server.10515;Svr;csg.bcmd.bcm.edu;Scheduler was sent the command time
01/03/2013 23:24:50;0002;PBS_Server.1839;Svr;PBS_Server;Torque Server Version = 4.1.2, loglevel = 0
01/03/2013 23:29:55;0002;PBS_Server.1829;Svr;PBS_Server;Torque Server Version = 4.1.2, loglevel = 0
01/03/2013 23:30:00;0040;PBS_Server.10529;Svr;csg.bcmd.bcm.edu;Scheduler was sent the command time
01/03/2013 23:35:00;0002;PBS_Server.1834;Svr;PBS_Server;Torque Server Version = 4.1.2, loglevel = 0
01/03/2013 23:40:05;0002;PBS_Server.1832;Svr;PBS_Server;Torque Server Version = 4.1.2, loglevel = 0
01/03/2013 23:40:10;0040;PBS_Server.10549;Svr;csg.bcmd.bcm.edu;Scheduler was sent the command time
01/03/2013 23:45:10;0002;PBS_Server.1836;Svr;PBS_Server;Torque Server Version = 4.1.2, loglevel = 0
01/03/2013 23:50:15;0002;PBS_Server.1830;Svr;PBS_Server;Torque Server Version = 4.1.2, loglevel = 0
01/03/2013 23:50:20;0040;PBS_Server.10563;Svr;csg.bcmd.bcm.edu;Scheduler was sent the command time
01/03/2013 23:55:20;0002;PBS_Server.1837;Svr;PBS_Server;Torque Server Version = 4.1.2, loglevel = 0
01/04/2013 00:00:25;0002;PBS_Server.1830;Svr;Log;Log closed
